2018-04-07 11:17:20,420 INFO org.apache.hadoop.yarn.server.resourcemanager.ResourceManager: STARTUP_MSG: 
/************************************************************
STARTUP_MSG: Starting ResourceManager
STARTUP_MSG:   host = d1/172.17.0.2
STARTUP_MSG:   args = []
STARTUP_MSG:   version = 2.7.1
STARTUP_MSG:   build = https://git-wip-us.apache.org/repos/asf/hadoop.git -r 15ecc87ccf4a0228f35af08fc56de536e6ce657a; compiled by 'jenkins' on 2015-06-29T06:04Z
STARTUP_MSG:   java = 1.8.0_161
************************************************************/
2018-04-07 11:17:21,013 INFO org.apache.hadoop.yarn.server.resourcemanager.ResourceManager: registered UNIX signal handlers for [TERM, HUP, INT]
2018-04-07 11:18:49,561 INFO org.apache.hadoop.conf.Configuration: found resource core-site.xml at file:/usr/local/hadoop/etc/hadoop/core-site.xml
2018-04-07 11:19:18,160 INFO org.apache.hadoop.security.Groups: clearing userToGroupsMap cache
2018-04-07 11:19:46,022 INFO org.apache.hadoop.conf.Configuration: found resource yarn-site.xml at file:/usr/local/hadoop/etc/hadoop/yarn-site.xml
2018-04-07 11:20:29,549 INFO org.apache.hadoop.yarn.event.AsyncDispatcher: Registering class org.apache.hadoop.yarn.server.resourcemanager.RMFatalEventType for class org.apache.hadoop.yarn.server.resourcemanager.ResourceManager$RMFatalEventDispatcher
2018-04-07 11:21:46,181 INFO org.apache.hadoop.yarn.server.resourcemanager.security.NMTokenSecretManagerInRM: NMTokenKeyRollingInterval: 86400000ms and NMTokenKeyActivationDelay: 900000ms
2018-04-07 11:21:46,917 INFO org.apache.hadoop.yarn.server.resourcemanager.security.RMContainerTokenSecretManager: ContainerTokenKeyRollingInterval: 86400000ms and ContainerTokenKeyActivationDelay: 900000ms
2018-04-07 11:21:48,977 INFO org.apache.hadoop.yarn.server.resourcemanager.security.AMRMTokenSecretManager: AMRMTokenKeyRollingInterval: 86400000ms and AMRMTokenKeyActivationDelay: 900000 ms
2018-04-07 11:21:56,637 INFO org.apache.hadoop.yarn.event.AsyncDispatcher: Registering class org.apache.hadoop.yarn.server.resourcemanager.recovery.RMStateStoreEventType for class org.apache.hadoop.yarn.server.resourcemanager.recovery.RMStateStore$ForwardingEventHandler
2018-04-07 11:21:57,879 INFO org.apache.hadoop.yarn.event.AsyncDispatcher: Registering class org.apache.hadoop.yarn.server.resourcemanager.NodesListManagerEventType for class org.apache.hadoop.yarn.server.resourcemanager.NodesListManager
2018-04-07 11:21:57,970 INFO org.apache.hadoop.yarn.server.resourcemanager.ResourceManager: Using Scheduler: org.apache.hadoop.yarn.server.resourcemanager.scheduler.fair.FairScheduler
2018-04-07 11:22:01,413 INFO org.apache.hadoop.yarn.event.AsyncDispatcher: Registering class org.apache.hadoop.yarn.server.resourcemanager.scheduler.event.SchedulerEventType for class org.apache.hadoop.yarn.server.resourcemanager.ResourceManager$SchedulerEventDispatcher
2018-04-07 11:22:01,435 INFO org.apache.hadoop.yarn.event.AsyncDispatcher: Registering class org.apache.hadoop.yarn.server.resourcemanager.rmapp.RMAppEventType for class org.apache.hadoop.yarn.server.resourcemanager.ResourceManager$ApplicationEventDispatcher
2018-04-07 11:22:01,438 INFO org.apache.hadoop.yarn.event.AsyncDispatcher: Registering class org.apache.hadoop.yarn.server.resourcemanager.rmapp.attempt.RMAppAttemptEventType for class org.apache.hadoop.yarn.server.resourcemanager.ResourceManager$ApplicationAttemptEventDispatcher
2018-04-07 11:22:01,514 INFO org.apache.hadoop.yarn.event.AsyncDispatcher: Registering class org.apache.hadoop.yarn.server.resourcemanager.rmnode.RMNodeEventType for class org.apache.hadoop.yarn.server.resourcemanager.ResourceManager$NodeEventDispatcher
2018-04-07 11:22:06,525 INFO org.apache.hadoop.metrics2.impl.MetricsConfig: loaded properties from hadoop-metrics2.properties
2018-04-07 11:22:21,875 INFO org.apache.hadoop.metrics2.impl.MetricsSystemImpl: Scheduled snapshot period at 10 second(s).
2018-04-07 11:22:21,875 INFO org.apache.hadoop.metrics2.impl.MetricsSystemImpl: ResourceManager metrics system started
2018-04-07 11:22:27,107 INFO org.apache.hadoop.yarn.event.AsyncDispatcher: Registering class org.apache.hadoop.yarn.server.resourcemanager.RMAppManagerEventType for class org.apache.hadoop.yarn.server.resourcemanager.RMAppManager
2018-04-07 11:22:29,262 INFO org.apache.hadoop.yarn.event.AsyncDispatcher: Registering class org.apache.hadoop.yarn.server.resourcemanager.amlauncher.AMLauncherEventType for class org.apache.hadoop.yarn.server.resourcemanager.amlauncher.ApplicationMasterLauncher
2018-04-07 11:22:29,602 INFO org.apache.hadoop.yarn.server.resourcemanager.RMNMInfo: Registered RMNMInfo MBean
2018-04-07 11:22:30,101 INFO org.apache.hadoop.yarn.security.YarnAuthorizationProvider: org.apache.hadoop.yarn.security.ConfiguredYarnAuthorizer is instiantiated.
2018-04-07 11:22:30,102 INFO org.apache.hadoop.yarn.server.resourcemanager.metrics.SystemMetricsPublisher: YARN system metrics publishing service is not enabled
2018-04-07 11:22:30,287 INFO org.apache.hadoop.util.HostsFileReader: Refreshing hosts (include/exclude) list
2018-04-07 11:22:36,841 WARN org.apache.hadoop.yarn.server.resourcemanager.scheduler.fair.AllocationFileLoaderService: fair-scheduler.xml not found on the classpath.
2018-04-07 11:22:38,451 INFO org.apache.hadoop.yarn.server.resourcemanager.ResourceManager: Transitioning to active state
2018-04-07 11:22:41,650 INFO org.apache.hadoop.yarn.server.resourcemanager.recovery.RMStateStore: Updating AMRMToken
2018-04-07 11:22:41,721 INFO org.apache.hadoop.yarn.server.resourcemanager.security.RMContainerTokenSecretManager: Rolling master-key for container-tokens
2018-04-07 11:22:41,793 INFO org.apache.hadoop.yarn.server.resourcemanager.security.NMTokenSecretManagerInRM: Rolling master-key for nm-tokens
2018-04-07 11:22:41,829 INFO org.apache.hadoop.security.token.delegation.AbstractDelegationTokenSecretManager: Updating the current master key for generating delegation tokens
2018-04-07 11:22:42,147 INFO org.apache.hadoop.yarn.server.resourcemanager.security.RMDelegationTokenSecretManager: storing master key with keyID 1
2018-04-07 11:22:42,366 INFO org.apache.hadoop.yarn.server.resourcemanager.recovery.RMStateStore: Storing RMDTMasterKey.
2018-04-07 11:22:42,597 INFO org.apache.hadoop.security.token.delegation.AbstractDelegationTokenSecretManager: Starting expired delegation token remover thread, tokenRemoverScanInterval=60 min(s)
2018-04-07 11:22:42,702 INFO org.apache.hadoop.security.token.delegation.AbstractDelegationTokenSecretManager: Updating the current master key for generating delegation tokens
2018-04-07 11:22:42,714 INFO org.apache.hadoop.yarn.server.resourcemanager.security.RMDelegationTokenSecretManager: storing master key with keyID 2
2018-04-07 11:22:43,707 INFO org.apache.hadoop.yarn.event.AsyncDispatcher: Registering class org.apache.hadoop.yarn.nodelabels.event.NodeLabelsStoreEventType for class org.apache.hadoop.yarn.nodelabels.CommonNodeLabelsManager$ForwardingEventHandler
2018-04-07 11:22:43,283 INFO org.apache.hadoop.yarn.server.resourcemanager.recovery.RMStateStore: Storing RMDTMasterKey.
2018-04-07 11:22:49,150 INFO org.apache.hadoop.ipc.CallQueueManager: Using callQueue class java.util.concurrent.LinkedBlockingQueue
2018-04-07 11:22:51,409 INFO org.apache.hadoop.ipc.Server: Starting Socket Reader #1 for port 8031
2018-04-07 11:22:51,908 INFO org.apache.hadoop.yarn.factories.impl.pb.RpcServerFactoryPBImpl: Adding protocol org.apache.hadoop.yarn.server.api.ResourceTrackerPB to the server
2018-04-07 11:22:51,935 INFO org.apache.hadoop.ipc.Server: IPC Server listener on 8031: starting
2018-04-07 11:22:52,128 INFO org.apache.hadoop.ipc.Server: IPC Server Responder: starting
2018-04-07 11:22:52,872 INFO org.apache.hadoop.ipc.CallQueueManager: Using callQueue class java.util.concurrent.LinkedBlockingQueue
2018-04-07 11:22:52,951 INFO org.apache.hadoop.ipc.Server: Starting Socket Reader #1 for port 8030
2018-04-07 11:22:53,082 INFO org.apache.hadoop.yarn.factories.impl.pb.RpcServerFactoryPBImpl: Adding protocol org.apache.hadoop.yarn.api.ApplicationMasterProtocolPB to the server
2018-04-07 11:22:53,083 INFO org.apache.hadoop.ipc.Server: IPC Server Responder: starting
2018-04-07 11:22:53,273 INFO org.apache.hadoop.ipc.Server: IPC Server listener on 8030: starting
2018-04-07 11:23:05,595 INFO org.apache.hadoop.ipc.CallQueueManager: Using callQueue class java.util.concurrent.LinkedBlockingQueue
2018-04-07 11:23:05,800 INFO org.apache.hadoop.ipc.Server: Starting Socket Reader #1 for port 8032
2018-04-07 11:23:06,213 INFO org.apache.hadoop.yarn.factories.impl.pb.RpcServerFactoryPBImpl: Adding protocol org.apache.hadoop.yarn.api.ApplicationClientProtocolPB to the server
2018-04-07 11:23:06,228 INFO org.apache.hadoop.ipc.Server: IPC Server Responder: starting
2018-04-07 11:23:06,254 INFO org.apache.hadoop.ipc.Server: IPC Server listener on 8032: starting
2018-04-07 11:23:08,458 INFO org.apache.hadoop.yarn.server.resourcemanager.ResourceManager: Transitioned to active state
2018-04-07 11:23:42,316 INFO org.mortbay.log: Logging to org.slf4j.impl.Log4jLoggerAdapter(org.mortbay.log) via org.mortbay.log.Slf4jLog
2018-04-07 11:23:43,933 INFO org.apache.hadoop.security.authentication.server.AuthenticationFilter: Unable to initialize FileSignerSecretProvider, falling back to use random secrets.
2018-04-07 11:23:45,553 INFO org.apache.hadoop.http.HttpRequestLog: Http request log for http.requests.resourcemanager is not defined
2018-04-07 11:23:47,930 INFO org.apache.hadoop.http.HttpServer2: Added global filter 'safety' (class=org.apache.hadoop.http.HttpServer2$QuotingInputFilter)
2018-04-07 11:23:51,133 INFO org.apache.hadoop.http.HttpServer2: Added filter RMAuthenticationFilter (class=org.apache.hadoop.yarn.server.security.http.RMAuthenticationFilter) to context cluster
2018-04-07 11:23:51,133 INFO org.apache.hadoop.http.HttpServer2: Added filter RMAuthenticationFilter (class=org.apache.hadoop.yarn.server.security.http.RMAuthenticationFilter) to context logs
2018-04-07 11:23:51,650 INFO org.apache.hadoop.http.HttpServer2: Added filter RMAuthenticationFilter (class=org.apache.hadoop.yarn.server.security.http.RMAuthenticationFilter) to context static
2018-04-07 11:23:52,343 INFO org.apache.hadoop.http.HttpServer2: Added filter static_user_filter (class=org.apache.hadoop.http.lib.StaticUserWebFilter$StaticUserFilter) to context cluster
2018-04-07 11:23:52,634 INFO org.apache.hadoop.http.HttpServer2: Added filter static_user_filter (class=org.apache.hadoop.http.lib.StaticUserWebFilter$StaticUserFilter) to context logs
2018-04-07 11:23:52,793 INFO org.apache.hadoop.http.HttpServer2: Added filter static_user_filter (class=org.apache.hadoop.http.lib.StaticUserWebFilter$StaticUserFilter) to context static
2018-04-07 11:23:54,341 INFO org.apache.hadoop.http.HttpServer2: adding path spec: /cluster/*
2018-04-07 11:23:54,342 INFO org.apache.hadoop.http.HttpServer2: adding path spec: /ws/*
2018-04-07 11:23:57,612 INFO org.apache.hadoop.http.HttpServer2: Jetty bound to port 8088
2018-04-07 11:23:57,649 INFO org.mortbay.log: jetty-6.1.26
2018-04-07 11:24:00,022 INFO org.mortbay.log: Extract jar:file:/usr/local/hadoop/share/hadoop/yarn/hadoop-yarn-common-2.7.1.jar!/webapps/cluster to /tmp/Jetty_0_0_0_0_8088_cluster____u0rgz3/webapp
2018-04-07 11:24:34,101 INFO org.apache.hadoop.security.token.delegation.AbstractDelegationTokenSecretManager: Updating the current master key for generating delegation tokens
2018-04-07 11:24:34,157 INFO org.apache.hadoop.security.token.delegation.AbstractDelegationTokenSecretManager: Starting expired delegation token remover thread, tokenRemoverScanInterval=60 min(s)
2018-04-07 11:24:34,206 INFO org.apache.hadoop.security.token.delegation.AbstractDelegationTokenSecretManager: Updating the current master key for generating delegation tokens
2018-04-07 11:24:34,834 INFO org.mortbay.log: Started HttpServer2$SelectChannelConnectorWithSafeStartup@0.0.0.0:8088
2018-04-07 11:24:34,836 INFO org.apache.hadoop.yarn.webapp.WebApps: Web app /cluster started at 8088
2018-04-07 11:25:11,303 INFO org.apache.hadoop.yarn.webapp.WebApps: Registered webapp guice modules
2018-04-07 11:25:12,700 INFO org.apache.hadoop.ipc.CallQueueManager: Using callQueue class java.util.concurrent.LinkedBlockingQueue
2018-04-07 11:25:12,730 INFO org.apache.hadoop.ipc.Server: Starting Socket Reader #1 for port 8033
2018-04-07 11:25:12,746 INFO org.apache.hadoop.yarn.factories.impl.pb.RpcServerFactoryPBImpl: Adding protocol org.apache.hadoop.yarn.server.api.ResourceManagerAdministrationProtocolPB to the server
2018-04-07 11:25:12,753 INFO org.apache.hadoop.ipc.Server: IPC Server Responder: starting
2018-04-07 11:25:12,766 INFO org.apache.hadoop.ipc.Server: IPC Server listener on 8033: starting
2018-04-07 11:25:57,422 INFO org.apache.hadoop.yarn.util.RackResolver: Resolved d1 to /default-rack
2018-04-07 11:25:58,301 INFO org.apache.hadoop.yarn.server.resourcemanager.ResourceTrackerService: NodeManager from node d1(cmPort: 59470 httpPort: 8042) registered with capability: <memory:8192, vCores:8>, assigned nodeId d1:59470
2018-04-07 11:25:58,917 INFO org.apache.hadoop.yarn.server.resourcemanager.rmnode.RMNodeImpl: d1:59470 Node Transitioned from NEW to RUNNING
2018-04-07 11:26:00,160 INFO org.apache.hadoop.yarn.server.resourcemanager.scheduler.fair.FairScheduler: Added node d1:59470 cluster capacity: <memory:8192, vCores:8>
2018-04-07 11:29:47,475 INFO org.apache.hadoop.yarn.server.resourcemanager.ClientRMService: Allocated new applicationId: 1
2018-04-07 11:30:04,925 INFO org.apache.hadoop.yarn.server.resourcemanager.rmapp.RMAppImpl: Storing application with id application_1523100158662_0001
2018-04-07 11:30:04,936 INFO org.apache.hadoop.yarn.server.resourcemanager.ClientRMService: Application with id 1 submitted by user root
2018-04-07 11:30:04,984 INFO org.apache.hadoop.yarn.server.resourcemanager.RMAuditLogger: USER=root	IP=172.17.0.2	OPERATION=Submit Application Request	TARGET=ClientRMService	RESULT=SUCCESS	APPID=application_1523100158662_0001
2018-04-07 11:30:05,129 INFO org.apache.hadoop.yarn.server.resourcemanager.rmapp.RMAppImpl: application_1523100158662_0001 State change from NEW to NEW_SAVING
2018-04-07 11:30:05,133 INFO org.apache.hadoop.yarn.server.resourcemanager.recovery.RMStateStore: Storing info for app: application_1523100158662_0001
2018-04-07 11:30:05,144 INFO org.apache.hadoop.yarn.server.resourcemanager.rmapp.RMAppImpl: application_1523100158662_0001 State change from NEW_SAVING to SUBMITTED
2018-04-07 11:30:06,154 INFO org.apache.hadoop.yarn.server.resourcemanager.scheduler.fair.FairScheduler: Accepted application application_1523100158662_0001 from user: root, in queue: default, currently num of applications: 1
2018-04-07 11:30:06,599 INFO org.apache.hadoop.yarn.server.resourcemanager.rmapp.RMAppImpl: application_1523100158662_0001 State change from SUBMITTED to ACCEPTED
2018-04-07 11:30:07,401 INFO org.apache.hadoop.yarn.server.resourcemanager.ApplicationMasterService: Registering app attempt : appattempt_1523100158662_0001_000001
2018-04-07 11:30:07,427 INFO org.apache.hadoop.yarn.server.resourcemanager.rmapp.attempt.RMAppAttemptImpl: appattempt_1523100158662_0001_000001 State change from NEW to SUBMITTED
2018-04-07 11:30:07,962 INFO org.apache.hadoop.yarn.server.resourcemanager.scheduler.fair.FairScheduler: Added Application Attempt appattempt_1523100158662_0001_000001 to scheduler from user: root
2018-04-07 11:30:08,025 INFO org.apache.hadoop.yarn.server.resourcemanager.rmapp.attempt.RMAppAttemptImpl: appattempt_1523100158662_0001_000001 State change from SUBMITTED to SCHEDULED
2018-04-07 11:30:09,332 INFO org.apache.hadoop.yarn.server.resourcemanager.rmcontainer.RMContainerImpl: container_1523100158662_0001_01_000001 Container Transitioned from NEW to ALLOCATED
2018-04-07 11:30:09,333 INFO org.apache.hadoop.yarn.server.resourcemanager.RMAuditLogger: USER=root	OPERATION=AM Allocated Container	TARGET=SchedulerApp	RESULT=SUCCESS	APPID=application_1523100158662_0001	CONTAINERID=container_1523100158662_0001_01_000001
2018-04-07 11:30:09,337 INFO org.apache.hadoop.yarn.server.resourcemanager.scheduler.SchedulerNode: Assigned container container_1523100158662_0001_01_000001 of capacity <memory:2048, vCores:1> on host d1:59470, which has 1 containers, <memory:2048, vCores:1> used and <memory:6144, vCores:7> available after allocation
2018-04-07 11:30:09,615 INFO org.apache.hadoop.yarn.server.resourcemanager.security.NMTokenSecretManagerInRM: Sending NMToken for nodeId : d1:59470 for container : container_1523100158662_0001_01_000001
2018-04-07 11:30:09,716 INFO org.apache.hadoop.yarn.server.resourcemanager.rmcontainer.RMContainerImpl: container_1523100158662_0001_01_000001 Container Transitioned from ALLOCATED to ACQUIRED
2018-04-07 11:30:09,729 INFO org.apache.hadoop.yarn.server.resourcemanager.security.NMTokenSecretManagerInRM: Clear node set for appattempt_1523100158662_0001_000001
2018-04-07 11:30:09,758 INFO org.apache.hadoop.yarn.server.resourcemanager.rmapp.attempt.RMAppAttemptImpl: Storing attempt: AppId: application_1523100158662_0001 AttemptId: appattempt_1523100158662_0001_000001 MasterContainer: Container: [ContainerId: container_1523100158662_0001_01_000001, NodeId: d1:59470, NodeHttpAddress: d1:8042, Resource: <memory:2048, vCores:1>, Priority: 0, Token: Token { kind: ContainerToken, service: 172.17.0.2:59470 }, ]
2018-04-07 11:30:09,929 INFO org.apache.hadoop.yarn.server.resourcemanager.rmapp.attempt.RMAppAttemptImpl: appattempt_1523100158662_0001_000001 State change from SCHEDULED to ALLOCATED_SAVING
2018-04-07 11:30:10,042 INFO org.apache.hadoop.yarn.server.resourcemanager.rmapp.attempt.RMAppAttemptImpl: appattempt_1523100158662_0001_000001 State change from ALLOCATED_SAVING to ALLOCATED
2018-04-07 11:30:10,100 INFO org.apache.hadoop.yarn.server.resourcemanager.amlauncher.AMLauncher: Launching masterappattempt_1523100158662_0001_000001
2018-04-07 11:30:10,573 INFO org.apache.hadoop.yarn.server.resourcemanager.amlauncher.AMLauncher: Setting up container Container: [ContainerId: container_1523100158662_0001_01_000001, NodeId: d1:59470, NodeHttpAddress: d1:8042, Resource: <memory:2048, vCores:1>, Priority: 0, Token: Token { kind: ContainerToken, service: 172.17.0.2:59470 }, ] for AM appattempt_1523100158662_0001_000001
2018-04-07 11:30:10,574 INFO org.apache.hadoop.yarn.server.resourcemanager.amlauncher.AMLauncher: Command to launch container container_1523100158662_0001_01_000001 : $JAVA_HOME/bin/java -Dlog4j.configuration=container-log4j.properties -Dyarn.app.container.log.dir=<LOG_DIR> -Dyarn.app.container.log.filesize=0 -Dhadoop.root.logger=INFO,CLA -Dhadoop.root.logfile=syslog  -Xmx1024m org.apache.hadoop.mapreduce.v2.app.MRAppMaster 1><LOG_DIR>/stdout 2><LOG_DIR>/stderr 
2018-04-07 11:30:10,601 INFO org.apache.hadoop.yarn.server.resourcemanager.security.AMRMTokenSecretManager: Create AMRMToken for ApplicationAttempt: appattempt_1523100158662_0001_000001
2018-04-07 11:30:10,647 INFO org.apache.hadoop.yarn.server.resourcemanager.security.AMRMTokenSecretManager: Creating password for appattempt_1523100158662_0001_000001
2018-04-07 11:30:16,509 INFO org.apache.hadoop.yarn.server.resourcemanager.amlauncher.AMLauncher: Done launching container Container: [ContainerId: container_1523100158662_0001_01_000001, NodeId: d1:59470, NodeHttpAddress: d1:8042, Resource: <memory:2048, vCores:1>, Priority: 0, Token: Token { kind: ContainerToken, service: 172.17.0.2:59470 }, ] for AM appattempt_1523100158662_0001_000001
2018-04-07 11:30:16,550 INFO org.apache.hadoop.yarn.server.resourcemanager.rmapp.attempt.RMAppAttemptImpl: appattempt_1523100158662_0001_000001 State change from ALLOCATED to LAUNCHED
2018-04-07 11:30:16,601 INFO org.apache.hadoop.yarn.server.resourcemanager.rmcontainer.RMContainerImpl: container_1523100158662_0001_01_000001 Container Transitioned from ACQUIRED to RUNNING
2018-04-07 11:31:08,999 INFO SecurityLogger.org.apache.hadoop.ipc.Server: Auth successful for appattempt_1523100158662_0001_000001 (auth:SIMPLE)
2018-04-07 11:31:09,050 INFO org.apache.hadoop.yarn.server.resourcemanager.ApplicationMasterService: AM registration appattempt_1523100158662_0001_000001
2018-04-07 11:31:09,055 INFO org.apache.hadoop.yarn.server.resourcemanager.RMAuditLogger: USER=root	IP=172.17.0.2	OPERATION=Register App Master	TARGET=ApplicationMasterService	RESULT=SUCCESS	APPID=application_1523100158662_0001	APPATTEMPTID=appattempt_1523100158662_0001_000001
2018-04-07 11:31:09,056 INFO org.apache.hadoop.yarn.server.resourcemanager.rmapp.attempt.RMAppAttemptImpl: appattempt_1523100158662_0001_000001 State change from LAUNCHED to RUNNING
2018-04-07 11:31:09,057 INFO org.apache.hadoop.yarn.server.resourcemanager.rmapp.RMAppImpl: application_1523100158662_0001 State change from ACCEPTED to RUNNING
2018-04-07 11:31:11,782 INFO org.apache.hadoop.yarn.server.resourcemanager.rmcontainer.RMContainerImpl: container_1523100158662_0001_01_000002 Container Transitioned from NEW to ALLOCATED
2018-04-07 11:31:11,783 INFO org.apache.hadoop.yarn.server.resourcemanager.RMAuditLogger: USER=root	OPERATION=AM Allocated Container	TARGET=SchedulerApp	RESULT=SUCCESS	APPID=application_1523100158662_0001	CONTAINERID=container_1523100158662_0001_01_000002
2018-04-07 11:31:11,786 INFO org.apache.hadoop.yarn.server.resourcemanager.scheduler.SchedulerNode: Assigned container container_1523100158662_0001_01_000002 of capacity <memory:1024, vCores:1> on host d1:59470, which has 2 containers, <memory:3072, vCores:2> used and <memory:5120, vCores:6> available after allocation
2018-04-07 11:31:12,689 INFO org.apache.hadoop.yarn.server.resourcemanager.security.NMTokenSecretManagerInRM: Sending NMToken for nodeId : d1:59470 for container : container_1523100158662_0001_01_000002
2018-04-07 11:31:12,710 INFO org.apache.hadoop.yarn.server.resourcemanager.rmcontainer.RMContainerImpl: container_1523100158662_0001_01_000002 Container Transitioned from ALLOCATED to ACQUIRED
2018-04-07 11:31:13,939 INFO org.apache.hadoop.yarn.server.resourcemanager.scheduler.AppSchedulingInfo: checking for deactivate of application :application_1523100158662_0001
2018-04-07 11:31:14,813 INFO org.apache.hadoop.yarn.server.resourcemanager.rmcontainer.RMContainerImpl: container_1523100158662_0001_01_000002 Container Transitioned from ACQUIRED to RUNNING
2018-04-07 11:31:41,304 INFO org.apache.hadoop.yarn.server.resourcemanager.rmcontainer.RMContainerImpl: container_1523100158662_0001_01_000002 Container Transitioned from RUNNING to COMPLETED
2018-04-07 11:31:41,305 INFO org.apache.hadoop.yarn.server.resourcemanager.scheduler.fair.FSAppAttempt: Completed container: container_1523100158662_0001_01_000002 in state: COMPLETED event:FINISHED
2018-04-07 11:31:41,305 INFO org.apache.hadoop.yarn.server.resourcemanager.RMAuditLogger: USER=root	OPERATION=AM Released Container	TARGET=SchedulerApp	RESULT=SUCCESS	APPID=application_1523100158662_0001	CONTAINERID=container_1523100158662_0001_01_000002
2018-04-07 11:31:41,305 INFO org.apache.hadoop.yarn.server.resourcemanager.scheduler.SchedulerNode: Released container container_1523100158662_0001_01_000002 of capacity <memory:1024, vCores:1> on host d1:59470, which currently has 1 containers, <memory:2048, vCores:1> used and <memory:6144, vCores:7> available, release resources=true
2018-04-07 11:31:41,305 INFO org.apache.hadoop.yarn.server.resourcemanager.scheduler.fair.FairScheduler: Application attempt appattempt_1523100158662_0001_000001 released container container_1523100158662_0001_01_000002 on node: host: d1:59470 #containers=1 available=<memory:6144, vCores:7> used=<memory:2048, vCores:1> with event: FINISHED
2018-04-07 11:31:42,473 INFO org.apache.hadoop.yarn.server.resourcemanager.rmcontainer.RMContainerImpl: container_1523100158662_0001_01_000003 Container Transitioned from NEW to ALLOCATED
2018-04-07 11:31:42,514 INFO org.apache.hadoop.yarn.server.resourcemanager.RMAuditLogger: USER=root	OPERATION=AM Allocated Container	TARGET=SchedulerApp	RESULT=SUCCESS	APPID=application_1523100158662_0001	CONTAINERID=container_1523100158662_0001_01_000003
2018-04-07 11:31:42,514 INFO org.apache.hadoop.yarn.server.resourcemanager.scheduler.SchedulerNode: Assigned container container_1523100158662_0001_01_000003 of capacity <memory:1024, vCores:1> on host d1:59470, which has 2 containers, <memory:3072, vCores:2> used and <memory:5120, vCores:6> available after allocation
2018-04-07 11:31:43,553 INFO org.apache.hadoop.yarn.server.resourcemanager.rmcontainer.RMContainerImpl: container_1523100158662_0001_01_000003 Container Transitioned from ALLOCATED to ACQUIRED
2018-04-07 11:31:44,497 INFO org.apache.hadoop.yarn.server.resourcemanager.rmcontainer.RMContainerImpl: container_1523100158662_0001_01_000003 Container Transitioned from ACQUIRED to RUNNING
2018-04-07 11:31:44,614 INFO org.apache.hadoop.yarn.server.resourcemanager.scheduler.AppSchedulingInfo: checking for deactivate of application :application_1523100158662_0001
2018-04-07 11:32:36,947 INFO org.apache.hadoop.yarn.server.resourcemanager.scheduler.AbstractYarnScheduler: Release request cache is cleaned up
2018-04-07 11:32:40,822 INFO org.apache.hadoop.yarn.server.resourcemanager.rmcontainer.RMContainerImpl: container_1523100158662_0001_01_000003 Container Transitioned from RUNNING to COMPLETED
2018-04-07 11:32:40,823 INFO org.apache.hadoop.yarn.server.resourcemanager.scheduler.fair.FSAppAttempt: Completed container: container_1523100158662_0001_01_000003 in state: COMPLETED event:FINISHED
2018-04-07 11:32:40,823 INFO org.apache.hadoop.yarn.server.resourcemanager.RMAuditLogger: USER=root	OPERATION=AM Released Container	TARGET=SchedulerApp	RESULT=SUCCESS	APPID=application_1523100158662_0001	CONTAINERID=container_1523100158662_0001_01_000003
2018-04-07 11:32:40,825 INFO org.apache.hadoop.yarn.server.resourcemanager.scheduler.SchedulerNode: Released container container_1523100158662_0001_01_000003 of capacity <memory:1024, vCores:1> on host d1:59470, which currently has 1 containers, <memory:2048, vCores:1> used and <memory:6144, vCores:7> available, release resources=true
2018-04-07 11:32:40,825 INFO org.apache.hadoop.yarn.server.resourcemanager.scheduler.fair.FairScheduler: Application attempt appattempt_1523100158662_0001_000001 released container container_1523100158662_0001_01_000003 on node: host: d1:59470 #containers=1 available=<memory:6144, vCores:7> used=<memory:2048, vCores:1> with event: FINISHED
2018-04-07 11:32:42,758 INFO org.apache.hadoop.yarn.server.resourcemanager.rmapp.attempt.RMAppAttemptImpl: Updating application attempt appattempt_1523100158662_0001_000001 with final state: FINISHING, and exit status: -1000
2018-04-07 11:32:42,774 INFO org.apache.hadoop.yarn.server.resourcemanager.rmapp.attempt.RMAppAttemptImpl: appattempt_1523100158662_0001_000001 State change from RUNNING to FINAL_SAVING
2018-04-07 11:32:42,779 INFO org.apache.hadoop.yarn.server.resourcemanager.rmapp.RMAppImpl: Updating application application_1523100158662_0001 with final state: FINISHING
2018-04-07 11:32:42,803 INFO org.apache.hadoop.yarn.server.resourcemanager.rmapp.RMAppImpl: application_1523100158662_0001 State change from RUNNING to FINAL_SAVING
2018-04-07 11:32:42,804 INFO org.apache.hadoop.yarn.server.resourcemanager.recovery.RMStateStore: Updating info for app: application_1523100158662_0001
2018-04-07 11:32:42,813 INFO org.apache.hadoop.yarn.server.resourcemanager.rmapp.attempt.RMAppAttemptImpl: appattempt_1523100158662_0001_000001 State change from FINAL_SAVING to FINISHING
2018-04-07 11:32:42,816 INFO org.apache.hadoop.yarn.server.resourcemanager.rmapp.RMAppImpl: application_1523100158662_0001 State change from FINAL_SAVING to FINISHING
2018-04-07 11:32:43,851 INFO org.apache.hadoop.yarn.server.resourcemanager.ApplicationMasterService: application_1523100158662_0001 unregistered successfully. 
2018-04-07 11:32:50,142 INFO org.apache.hadoop.yarn.server.resourcemanager.ApplicationMasterService: Unregistering app attempt : appattempt_1523100158662_0001_000001
2018-04-07 11:32:50,145 INFO org.apache.hadoop.yarn.server.resourcemanager.rmcontainer.RMContainerImpl: container_1523100158662_0001_01_000001 Container Transitioned from RUNNING to COMPLETED
2018-04-07 11:32:50,145 INFO org.apache.hadoop.yarn.server.resourcemanager.scheduler.fair.FSAppAttempt: Completed container: container_1523100158662_0001_01_000001 in state: COMPLETED event:FINISHED
2018-04-07 11:32:50,146 INFO org.apache.hadoop.yarn.server.resourcemanager.RMAuditLogger: USER=root	OPERATION=AM Released Container	TARGET=SchedulerApp	RESULT=SUCCESS	APPID=application_1523100158662_0001	CONTAINERID=container_1523100158662_0001_01_000001
2018-04-07 11:32:50,147 INFO org.apache.hadoop.yarn.server.resourcemanager.scheduler.SchedulerNode: Released container container_1523100158662_0001_01_000001 of capacity <memory:2048, vCores:1> on host d1:59470, which currently has 0 containers, <memory:0, vCores:0> used and <memory:8192, vCores:8> available, release resources=true
2018-04-07 11:32:50,149 INFO org.apache.hadoop.yarn.server.resourcemanager.scheduler.fair.FairScheduler: Application attempt appattempt_1523100158662_0001_000001 released container container_1523100158662_0001_01_000001 on node: host: d1:59470 #containers=0 available=<memory:8192, vCores:8> used=<memory:0, vCores:0> with event: FINISHED
2018-04-07 11:32:50,161 INFO org.apache.hadoop.yarn.server.resourcemanager.security.AMRMTokenSecretManager: Application finished, removing password for appattempt_1523100158662_0001_000001
2018-04-07 11:32:50,162 INFO org.apache.hadoop.yarn.server.resourcemanager.rmapp.attempt.RMAppAttemptImpl: appattempt_1523100158662_0001_000001 State change from FINISHING to FINISHED
2018-04-07 11:32:50,182 INFO org.apache.hadoop.yarn.server.resourcemanager.rmapp.RMAppImpl: application_1523100158662_0001 State change from FINISHING to FINISHED
2018-04-07 11:32:50,186 INFO org.apache.hadoop.yarn.server.resourcemanager.scheduler.fair.FairScheduler: Application appattempt_1523100158662_0001_000001 is done. finalState=FINISHED
2018-04-07 11:32:50,189 INFO org.apache.hadoop.yarn.server.resourcemanager.scheduler.AppSchedulingInfo: Application application_1523100158662_0001 requests cleared
2018-04-07 11:32:50,214 INFO org.apache.hadoop.yarn.server.resourcemanager.RMAuditLogger: USER=root	OPERATION=Application Finished - Succeeded	TARGET=RMAppManager	RESULT=SUCCESS	APPID=application_1523100158662_0001
2018-04-07 11:32:50,211 INFO org.apache.hadoop.yarn.server.resourcemanager.amlauncher.AMLauncher: Cleaning master appattempt_1523100158662_0001_000001
2018-04-07 11:32:50,336 INFO org.apache.hadoop.yarn.server.resourcemanager.RMAppManager$ApplicationSummary: appId=application_1523100158662_0001,name=word count,user=root,queue=root.root,state=FINISHED,trackingUrl=http://d1:8088/proxy/application_1523100158662_0001/,appMasterHost=d1,startTime=1523100604818,finishTime=1523100762778,finalStatus=SUCCEEDED,memorySeconds=419381,vcoreSeconds=247,preemptedAMContainers=0,preemptedNonAMContainers=0,preemptedResources=<memory:0\, vCores:0>,applicationType=MAPREDUCE
2018-04-07 12:11:48,408 INFO org.apache.hadoop.yarn.server.resourcemanager.ClientRMService: Allocated new applicationId: 2
2018-04-07 12:12:03,222 INFO org.apache.hadoop.yarn.server.resourcemanager.ClientRMService: Application with id 2 submitted by user root
2018-04-07 12:12:03,223 INFO org.apache.hadoop.yarn.server.resourcemanager.rmapp.RMAppImpl: Storing application with id application_1523100158662_0002
2018-04-07 12:12:03,225 INFO org.apache.hadoop.yarn.server.resourcemanager.rmapp.RMAppImpl: application_1523100158662_0002 State change from NEW to NEW_SAVING
2018-04-07 12:12:03,225 INFO org.apache.hadoop.yarn.server.resourcemanager.recovery.RMStateStore: Storing info for app: application_1523100158662_0002
2018-04-07 12:12:03,229 INFO org.apache.hadoop.yarn.server.resourcemanager.rmapp.RMAppImpl: application_1523100158662_0002 State change from NEW_SAVING to SUBMITTED
2018-04-07 12:12:03,231 INFO org.apache.hadoop.yarn.server.resourcemanager.RMAuditLogger: USER=root	IP=172.17.0.2	OPERATION=Submit Application Request	TARGET=ClientRMService	RESULT=SUCCESS	APPID=application_1523100158662_0002
2018-04-07 12:12:03,383 INFO org.apache.hadoop.yarn.server.resourcemanager.scheduler.fair.FairScheduler: Accepted application application_1523100158662_0002 from user: root, in queue: default, currently num of applications: 1
2018-04-07 12:12:03,386 INFO org.apache.hadoop.yarn.server.resourcemanager.rmapp.RMAppImpl: application_1523100158662_0002 State change from SUBMITTED to ACCEPTED
2018-04-07 12:12:03,387 INFO org.apache.hadoop.yarn.server.resourcemanager.ApplicationMasterService: Registering app attempt : appattempt_1523100158662_0002_000001
2018-04-07 12:12:03,387 INFO org.apache.hadoop.yarn.server.resourcemanager.rmapp.attempt.RMAppAttemptImpl: appattempt_1523100158662_0002_000001 State change from NEW to SUBMITTED
2018-04-07 12:12:03,405 INFO org.apache.hadoop.yarn.server.resourcemanager.scheduler.fair.FairScheduler: Added Application Attempt appattempt_1523100158662_0002_000001 to scheduler from user: root
2018-04-07 12:12:03,448 INFO org.apache.hadoop.yarn.server.resourcemanager.rmapp.attempt.RMAppAttemptImpl: appattempt_1523100158662_0002_000001 State change from SUBMITTED to SCHEDULED
2018-04-07 12:12:04,324 INFO org.apache.hadoop.yarn.server.resourcemanager.rmcontainer.RMContainerImpl: container_1523100158662_0002_01_000001 Container Transitioned from NEW to ALLOCATED
2018-04-07 12:12:04,324 INFO org.apache.hadoop.yarn.server.resourcemanager.RMAuditLogger: USER=root	OPERATION=AM Allocated Container	TARGET=SchedulerApp	RESULT=SUCCESS	APPID=application_1523100158662_0002	CONTAINERID=container_1523100158662_0002_01_000001
2018-04-07 12:12:04,324 INFO org.apache.hadoop.yarn.server.resourcemanager.scheduler.SchedulerNode: Assigned container container_1523100158662_0002_01_000001 of capacity <memory:2048, vCores:1> on host d1:59470, which has 1 containers, <memory:2048, vCores:1> used and <memory:6144, vCores:7> available after allocation
2018-04-07 12:12:04,421 INFO org.apache.hadoop.yarn.server.resourcemanager.security.NMTokenSecretManagerInRM: Sending NMToken for nodeId : d1:59470 for container : container_1523100158662_0002_01_000001
2018-04-07 12:12:04,443 INFO org.apache.hadoop.yarn.server.resourcemanager.rmcontainer.RMContainerImpl: container_1523100158662_0002_01_000001 Container Transitioned from ALLOCATED to ACQUIRED
2018-04-07 12:12:04,444 INFO org.apache.hadoop.yarn.server.resourcemanager.security.NMTokenSecretManagerInRM: Clear node set for appattempt_1523100158662_0002_000001
2018-04-07 12:12:04,445 INFO org.apache.hadoop.yarn.server.resourcemanager.rmapp.attempt.RMAppAttemptImpl: Storing attempt: AppId: application_1523100158662_0002 AttemptId: appattempt_1523100158662_0002_000001 MasterContainer: Container: [ContainerId: container_1523100158662_0002_01_000001, NodeId: d1:59470, NodeHttpAddress: d1:8042, Resource: <memory:2048, vCores:1>, Priority: 0, Token: Token { kind: ContainerToken, service: 172.17.0.2:59470 }, ]
2018-04-07 12:12:04,456 INFO org.apache.hadoop.yarn.server.resourcemanager.rmapp.attempt.RMAppAttemptImpl: appattempt_1523100158662_0002_000001 State change from SCHEDULED to ALLOCATED_SAVING
2018-04-07 12:12:04,456 INFO org.apache.hadoop.yarn.server.resourcemanager.rmapp.attempt.RMAppAttemptImpl: appattempt_1523100158662_0002_000001 State change from ALLOCATED_SAVING to ALLOCATED
2018-04-07 12:12:04,481 INFO org.apache.hadoop.yarn.server.resourcemanager.amlauncher.AMLauncher: Launching masterappattempt_1523100158662_0002_000001
2018-04-07 12:12:04,524 INFO org.apache.hadoop.yarn.server.resourcemanager.amlauncher.AMLauncher: Setting up container Container: [ContainerId: container_1523100158662_0002_01_000001, NodeId: d1:59470, NodeHttpAddress: d1:8042, Resource: <memory:2048, vCores:1>, Priority: 0, Token: Token { kind: ContainerToken, service: 172.17.0.2:59470 }, ] for AM appattempt_1523100158662_0002_000001
2018-04-07 12:12:04,525 INFO org.apache.hadoop.yarn.server.resourcemanager.amlauncher.AMLauncher: Command to launch container container_1523100158662_0002_01_000001 : $JAVA_HOME/bin/java -Dlog4j.configuration=container-log4j.properties -Dyarn.app.container.log.dir=<LOG_DIR> -Dyarn.app.container.log.filesize=0 -Dhadoop.root.logger=INFO,CLA -Dhadoop.root.logfile=syslog  -Xmx1024m org.apache.hadoop.mapreduce.v2.app.MRAppMaster 1><LOG_DIR>/stdout 2><LOG_DIR>/stderr 
2018-04-07 12:12:04,525 INFO org.apache.hadoop.yarn.server.resourcemanager.security.AMRMTokenSecretManager: Create AMRMToken for ApplicationAttempt: appattempt_1523100158662_0002_000001
2018-04-07 12:12:04,526 INFO org.apache.hadoop.yarn.server.resourcemanager.security.AMRMTokenSecretManager: Creating password for appattempt_1523100158662_0002_000001
2018-04-07 12:12:04,875 INFO org.apache.hadoop.yarn.server.resourcemanager.amlauncher.AMLauncher: Done launching container Container: [ContainerId: container_1523100158662_0002_01_000001, NodeId: d1:59470, NodeHttpAddress: d1:8042, Resource: <memory:2048, vCores:1>, Priority: 0, Token: Token { kind: ContainerToken, service: 172.17.0.2:59470 }, ] for AM appattempt_1523100158662_0002_000001
2018-04-07 12:12:04,876 INFO org.apache.hadoop.yarn.server.resourcemanager.rmapp.attempt.RMAppAttemptImpl: appattempt_1523100158662_0002_000001 State change from ALLOCATED to LAUNCHED
2018-04-07 12:12:05,392 INFO org.apache.hadoop.yarn.server.resourcemanager.rmcontainer.RMContainerImpl: container_1523100158662_0002_01_000001 Container Transitioned from ACQUIRED to RUNNING
2018-04-07 12:12:40,620 INFO SecurityLogger.org.apache.hadoop.ipc.Server: Auth successful for appattempt_1523100158662_0002_000001 (auth:SIMPLE)
2018-04-07 12:12:40,721 INFO org.apache.hadoop.yarn.server.resourcemanager.ApplicationMasterService: AM registration appattempt_1523100158662_0002_000001
2018-04-07 12:12:40,721 INFO org.apache.hadoop.yarn.server.resourcemanager.RMAuditLogger: USER=root	IP=172.17.0.2	OPERATION=Register App Master	TARGET=ApplicationMasterService	RESULT=SUCCESS	APPID=application_1523100158662_0002	APPATTEMPTID=appattempt_1523100158662_0002_000001
2018-04-07 12:12:40,723 INFO org.apache.hadoop.yarn.server.resourcemanager.rmapp.attempt.RMAppAttemptImpl: appattempt_1523100158662_0002_000001 State change from LAUNCHED to RUNNING
2018-04-07 12:12:40,738 INFO org.apache.hadoop.yarn.server.resourcemanager.rmapp.RMAppImpl: application_1523100158662_0002 State change from ACCEPTED to RUNNING
2018-04-07 12:12:47,384 INFO org.apache.hadoop.yarn.server.resourcemanager.rmcontainer.RMContainerImpl: container_1523100158662_0002_01_000002 Container Transitioned from NEW to ALLOCATED
2018-04-07 12:12:47,404 INFO org.apache.hadoop.yarn.server.resourcemanager.RMAuditLogger: USER=root	OPERATION=AM Allocated Container	TARGET=SchedulerApp	RESULT=SUCCESS	APPID=application_1523100158662_0002	CONTAINERID=container_1523100158662_0002_01_000002
2018-04-07 12:12:47,405 INFO org.apache.hadoop.yarn.server.resourcemanager.scheduler.SchedulerNode: Assigned container container_1523100158662_0002_01_000002 of capacity <memory:1024, vCores:1> on host d1:59470, which has 2 containers, <memory:3072, vCores:2> used and <memory:5120, vCores:6> available after allocation
2018-04-07 12:12:47,540 INFO org.apache.hadoop.yarn.server.resourcemanager.security.NMTokenSecretManagerInRM: Sending NMToken for nodeId : d1:59470 for container : container_1523100158662_0002_01_000002
2018-04-07 12:12:47,662 INFO org.apache.hadoop.yarn.server.resourcemanager.rmcontainer.RMContainerImpl: container_1523100158662_0002_01_000002 Container Transitioned from ALLOCATED to ACQUIRED
2018-04-07 12:12:48,380 INFO org.apache.hadoop.yarn.server.resourcemanager.rmcontainer.RMContainerImpl: container_1523100158662_0002_01_000003 Container Transitioned from NEW to ALLOCATED
2018-04-07 12:12:48,388 INFO org.apache.hadoop.yarn.server.resourcemanager.RMAuditLogger: USER=root	OPERATION=AM Allocated Container	TARGET=SchedulerApp	RESULT=SUCCESS	APPID=application_1523100158662_0002	CONTAINERID=container_1523100158662_0002_01_000003
2018-04-07 12:12:48,388 INFO org.apache.hadoop.yarn.server.resourcemanager.scheduler.SchedulerNode: Assigned container container_1523100158662_0002_01_000003 of capacity <memory:1024, vCores:1> on host d1:59470, which has 3 containers, <memory:4096, vCores:3> used and <memory:4096, vCores:5> available after allocation
2018-04-07 12:12:50,861 INFO org.apache.hadoop.yarn.server.resourcemanager.rmcontainer.RMContainerImpl: container_1523100158662_0002_01_000003 Container Transitioned from ALLOCATED to ACQUIRED
2018-04-07 12:12:51,453 INFO org.apache.hadoop.yarn.server.resourcemanager.rmcontainer.RMContainerImpl: container_1523100158662_0002_01_000004 Container Transitioned from NEW to ALLOCATED
2018-04-07 12:12:51,454 INFO org.apache.hadoop.yarn.server.resourcemanager.RMAuditLogger: USER=root	OPERATION=AM Allocated Container	TARGET=SchedulerApp	RESULT=SUCCESS	APPID=application_1523100158662_0002	CONTAINERID=container_1523100158662_0002_01_000004
2018-04-07 12:12:51,454 INFO org.apache.hadoop.yarn.server.resourcemanager.scheduler.SchedulerNode: Assigned container container_1523100158662_0002_01_000004 of capacity <memory:1024, vCores:1> on host d1:59470, which has 4 containers, <memory:5120, vCores:4> used and <memory:3072, vCores:4> available after allocation
2018-04-07 12:12:52,040 INFO org.apache.hadoop.yarn.server.resourcemanager.scheduler.AppSchedulingInfo: checking for deactivate of application :application_1523100158662_0002
2018-04-07 12:12:52,138 INFO org.apache.hadoop.yarn.server.resourcemanager.rmcontainer.RMContainerImpl: container_1523100158662_0002_01_000004 Container Transitioned from ALLOCATED to ACQUIRED
2018-04-07 12:12:52,465 INFO org.apache.hadoop.yarn.server.resourcemanager.rmcontainer.RMContainerImpl: container_1523100158662_0002_01_000002 Container Transitioned from ACQUIRED to RUNNING
2018-04-07 12:12:52,481 INFO org.apache.hadoop.yarn.server.resourcemanager.rmcontainer.RMContainerImpl: container_1523100158662_0002_01_000003 Container Transitioned from ACQUIRED to RUNNING
2018-04-07 12:12:53,335 INFO org.apache.hadoop.yarn.server.resourcemanager.rmcontainer.RMContainerImpl: container_1523100158662_0002_01_000004 Container Transitioned from ACQUIRED to RELEASED
2018-04-07 12:12:53,372 INFO org.apache.hadoop.yarn.server.resourcemanager.scheduler.fair.FSAppAttempt: Completed container: container_1523100158662_0002_01_000004 in state: RELEASED event:RELEASED
2018-04-07 12:12:53,382 INFO org.apache.hadoop.yarn.server.resourcemanager.RMAuditLogger: USER=root	IP=172.17.0.2	OPERATION=AM Released Container	TARGET=SchedulerApp	RESULT=SUCCESS	APPID=application_1523100158662_0002	CONTAINERID=container_1523100158662_0002_01_000004
2018-04-07 12:12:53,425 INFO org.apache.hadoop.yarn.server.resourcemanager.scheduler.SchedulerNode: Released container container_1523100158662_0002_01_000004 of capacity <memory:1024, vCores:1> on host d1:59470, which currently has 3 containers, <memory:4096, vCores:3> used and <memory:4096, vCores:5> available, release resources=true
2018-04-07 12:12:53,437 INFO org.apache.hadoop.yarn.server.resourcemanager.scheduler.fair.FairScheduler: Application attempt appattempt_1523100158662_0002_000001 released container container_1523100158662_0002_01_000004 on node: host: d1:59470 #containers=3 available=<memory:4096, vCores:5> used=<memory:4096, vCores:3> with event: RELEASED
2018-04-07 12:14:06,237 INFO org.apache.hadoop.yarn.server.resourcemanager.rmcontainer.RMContainerImpl: container_1523100158662_0002_01_000003 Container Transitioned from RUNNING to COMPLETED
2018-04-07 12:14:06,241 INFO org.apache.hadoop.yarn.server.resourcemanager.scheduler.fair.FSAppAttempt: Completed container: container_1523100158662_0002_01_000003 in state: COMPLETED event:FINISHED
2018-04-07 12:14:06,241 INFO org.apache.hadoop.yarn.server.resourcemanager.RMAuditLogger: USER=root	OPERATION=AM Released Container	TARGET=SchedulerApp	RESULT=SUCCESS	APPID=application_1523100158662_0002	CONTAINERID=container_1523100158662_0002_01_000003
2018-04-07 12:14:06,241 INFO org.apache.hadoop.yarn.server.resourcemanager.scheduler.SchedulerNode: Released container container_1523100158662_0002_01_000003 of capacity <memory:1024, vCores:1> on host d1:59470, which currently has 2 containers, <memory:3072, vCores:2> used and <memory:5120, vCores:6> available, release resources=true
2018-04-07 12:14:06,242 INFO org.apache.hadoop.yarn.server.resourcemanager.scheduler.fair.FairScheduler: Application attempt appattempt_1523100158662_0002_000001 released container container_1523100158662_0002_01_000003 on node: host: d1:59470 #containers=2 available=<memory:5120, vCores:6> used=<memory:3072, vCores:2> with event: FINISHED
2018-04-07 12:14:06,275 INFO org.apache.hadoop.yarn.server.resourcemanager.rmcontainer.RMContainerImpl: container_1523100158662_0002_01_000005 Container Transitioned from NEW to ALLOCATED
2018-04-07 12:14:06,276 INFO org.apache.hadoop.yarn.server.resourcemanager.RMAuditLogger: USER=root	OPERATION=AM Allocated Container	TARGET=SchedulerApp	RESULT=SUCCESS	APPID=application_1523100158662_0002	CONTAINERID=container_1523100158662_0002_01_000005
2018-04-07 12:14:06,282 INFO org.apache.hadoop.yarn.server.resourcemanager.scheduler.SchedulerNode: Assigned container container_1523100158662_0002_01_000005 of capacity <memory:1024, vCores:1> on host d1:59470, which has 3 containers, <memory:4096, vCores:3> used and <memory:4096, vCores:5> available after allocation
2018-04-07 12:14:07,111 INFO org.apache.hadoop.yarn.server.resourcemanager.scheduler.AppSchedulingInfo: checking for deactivate of application :application_1523100158662_0002
2018-04-07 12:14:07,475 INFO org.apache.hadoop.yarn.server.resourcemanager.rmcontainer.RMContainerImpl: container_1523100158662_0002_01_000005 Container Transitioned from ALLOCATED to ACQUIRED
2018-04-07 12:14:07,553 INFO org.apache.hadoop.yarn.server.resourcemanager.rmcontainer.RMContainerImpl: container_1523100158662_0002_01_000002 Container Transitioned from RUNNING to COMPLETED
2018-04-07 12:14:07,553 INFO org.apache.hadoop.yarn.server.resourcemanager.scheduler.fair.FSAppAttempt: Completed container: container_1523100158662_0002_01_000002 in state: COMPLETED event:FINISHED
2018-04-07 12:14:07,553 INFO org.apache.hadoop.yarn.server.resourcemanager.RMAuditLogger: USER=root	OPERATION=AM Released Container	TARGET=SchedulerApp	RESULT=SUCCESS	APPID=application_1523100158662_0002	CONTAINERID=container_1523100158662_0002_01_000002
2018-04-07 12:14:07,554 INFO org.apache.hadoop.yarn.server.resourcemanager.scheduler.SchedulerNode: Released container container_1523100158662_0002_01_000002 of capacity <memory:1024, vCores:1> on host d1:59470, which currently has 2 containers, <memory:3072, vCores:2> used and <memory:5120, vCores:6> available, release resources=true
2018-04-07 12:14:07,554 INFO org.apache.hadoop.yarn.server.resourcemanager.scheduler.fair.FairScheduler: Application attempt appattempt_1523100158662_0002_000001 released container container_1523100158662_0002_01_000002 on node: host: d1:59470 #containers=2 available=<memory:5120, vCores:6> used=<memory:3072, vCores:2> with event: FINISHED
2018-04-07 12:14:07,572 INFO org.apache.hadoop.yarn.server.resourcemanager.rmcontainer.RMContainerImpl: container_1523100158662_0002_01_000006 Container Transitioned from NEW to ALLOCATED
2018-04-07 12:14:07,573 INFO org.apache.hadoop.yarn.server.resourcemanager.RMAuditLogger: USER=root	OPERATION=AM Allocated Container	TARGET=SchedulerApp	RESULT=SUCCESS	APPID=application_1523100158662_0002	CONTAINERID=container_1523100158662_0002_01_000006
2018-04-07 12:14:07,573 INFO org.apache.hadoop.yarn.server.resourcemanager.scheduler.SchedulerNode: Assigned container container_1523100158662_0002_01_000006 of capacity <memory:1024, vCores:1> on host d1:59470, which has 3 containers, <memory:4096, vCores:3> used and <memory:4096, vCores:5> available after allocation
2018-04-07 12:14:08,366 INFO org.apache.hadoop.yarn.server.resourcemanager.rmcontainer.RMContainerImpl: container_1523100158662_0002_01_000007 Container Transitioned from NEW to ALLOCATED
2018-04-07 12:14:08,366 INFO org.apache.hadoop.yarn.server.resourcemanager.RMAuditLogger: USER=root	OPERATION=AM Allocated Container	TARGET=SchedulerApp	RESULT=SUCCESS	APPID=application_1523100158662_0002	CONTAINERID=container_1523100158662_0002_01_000007
2018-04-07 12:14:08,372 INFO org.apache.hadoop.yarn.server.resourcemanager.scheduler.SchedulerNode: Assigned container container_1523100158662_0002_01_000007 of capacity <memory:1024, vCores:1> on host d1:59470, which has 4 containers, <memory:5120, vCores:4> used and <memory:3072, vCores:4> available after allocation
2018-04-07 12:14:08,575 INFO org.apache.hadoop.yarn.server.resourcemanager.rmcontainer.RMContainerImpl: container_1523100158662_0002_01_000005 Container Transitioned from ACQUIRED to RELEASED
2018-04-07 12:14:08,577 INFO org.apache.hadoop.yarn.server.resourcemanager.scheduler.fair.FSAppAttempt: Completed container: container_1523100158662_0002_01_000005 in state: RELEASED event:RELEASED
2018-04-07 12:14:08,577 INFO org.apache.hadoop.yarn.server.resourcemanager.RMAuditLogger: USER=root	IP=172.17.0.2	OPERATION=AM Released Container	TARGET=SchedulerApp	RESULT=SUCCESS	APPID=application_1523100158662_0002	CONTAINERID=container_1523100158662_0002_01_000005
2018-04-07 12:14:08,577 INFO org.apache.hadoop.yarn.server.resourcemanager.scheduler.SchedulerNode: Released container container_1523100158662_0002_01_000005 of capacity <memory:1024, vCores:1> on host d1:59470, which currently has 3 containers, <memory:4096, vCores:3> used and <memory:4096, vCores:5> available, release resources=true
2018-04-07 12:14:08,577 INFO org.apache.hadoop.yarn.server.resourcemanager.scheduler.fair.FairScheduler: Application attempt appattempt_1523100158662_0002_000001 released container container_1523100158662_0002_01_000005 on node: host: d1:59470 #containers=3 available=<memory:4096, vCores:5> used=<memory:4096, vCores:3> with event: RELEASED
2018-04-07 12:14:08,601 INFO org.apache.hadoop.yarn.server.resourcemanager.rmcontainer.RMContainerImpl: container_1523100158662_0002_01_000006 Container Transitioned from ALLOCATED to ACQUIRED
2018-04-07 12:14:08,633 INFO org.apache.hadoop.yarn.server.resourcemanager.rmcontainer.RMContainerImpl: container_1523100158662_0002_01_000007 Container Transitioned from ALLOCATED to ACQUIRED
2018-04-07 12:14:09,407 INFO org.apache.hadoop.yarn.server.resourcemanager.rmcontainer.RMContainerImpl: container_1523100158662_0002_01_000006 Container Transitioned from ACQUIRED to RUNNING
2018-04-07 12:14:09,413 INFO org.apache.hadoop.yarn.server.resourcemanager.rmcontainer.RMContainerImpl: container_1523100158662_0002_01_000007 Container Transitioned from ACQUIRED to RUNNING
2018-04-07 12:14:09,416 INFO org.apache.hadoop.yarn.server.resourcemanager.rmcontainer.RMContainerImpl: container_1523100158662_0002_01_000008 Container Transitioned from NEW to ALLOCATED
2018-04-07 12:14:09,416 INFO org.apache.hadoop.yarn.server.resourcemanager.RMAuditLogger: USER=root	OPERATION=AM Allocated Container	TARGET=SchedulerApp	RESULT=SUCCESS	APPID=application_1523100158662_0002	CONTAINERID=container_1523100158662_0002_01_000008
2018-04-07 12:14:09,416 INFO org.apache.hadoop.yarn.server.resourcemanager.scheduler.SchedulerNode: Assigned container container_1523100158662_0002_01_000008 of capacity <memory:1024, vCores:1> on host d1:59470, which has 4 containers, <memory:5120, vCores:4> used and <memory:3072, vCores:4> available after allocation
2018-04-07 12:14:09,710 INFO org.apache.hadoop.yarn.server.resourcemanager.rmcontainer.RMContainerImpl: container_1523100158662_0002_01_000008 Container Transitioned from ALLOCATED to ACQUIRED
2018-04-07 12:14:10,408 INFO org.apache.hadoop.yarn.server.resourcemanager.rmcontainer.RMContainerImpl: container_1523100158662_0002_01_000008 Container Transitioned from ACQUIRED to RUNNING
2018-04-07 12:14:10,410 INFO org.apache.hadoop.yarn.server.resourcemanager.rmcontainer.RMContainerImpl: container_1523100158662_0002_01_000009 Container Transitioned from NEW to ALLOCATED
2018-04-07 12:14:10,410 INFO org.apache.hadoop.yarn.server.resourcemanager.RMAuditLogger: USER=root	OPERATION=AM Allocated Container	TARGET=SchedulerApp	RESULT=SUCCESS	APPID=application_1523100158662_0002	CONTAINERID=container_1523100158662_0002_01_000009
2018-04-07 12:14:10,410 INFO org.apache.hadoop.yarn.server.resourcemanager.scheduler.SchedulerNode: Assigned container container_1523100158662_0002_01_000009 of capacity <memory:1024, vCores:1> on host d1:59470, which has 5 containers, <memory:6144, vCores:5> used and <memory:2048, vCores:3> available after allocation
2018-04-07 12:14:10,789 INFO org.apache.hadoop.yarn.server.resourcemanager.rmcontainer.RMContainerImpl: container_1523100158662_0002_01_000009 Container Transitioned from ALLOCATED to ACQUIRED
2018-04-07 12:14:11,463 INFO org.apache.hadoop.yarn.server.resourcemanager.rmcontainer.RMContainerImpl: container_1523100158662_0002_01_000009 Container Transitioned from ACQUIRED to RUNNING
2018-04-07 12:14:11,470 INFO org.apache.hadoop.yarn.server.resourcemanager.rmcontainer.RMContainerImpl: container_1523100158662_0002_01_000010 Container Transitioned from NEW to ALLOCATED
2018-04-07 12:14:11,470 INFO org.apache.hadoop.yarn.server.resourcemanager.RMAuditLogger: USER=root	OPERATION=AM Allocated Container	TARGET=SchedulerApp	RESULT=SUCCESS	APPID=application_1523100158662_0002	CONTAINERID=container_1523100158662_0002_01_000010
2018-04-07 12:14:11,471 INFO org.apache.hadoop.yarn.server.resourcemanager.scheduler.SchedulerNode: Assigned container container_1523100158662_0002_01_000010 of capacity <memory:1024, vCores:1> on host d1:59470, which has 6 containers, <memory:7168, vCores:6> used and <memory:1024, vCores:2> available after allocation
2018-04-07 12:14:11,861 INFO org.apache.hadoop.yarn.server.resourcemanager.scheduler.AppSchedulingInfo: checking for deactivate of application :application_1523100158662_0002
2018-04-07 12:14:11,896 INFO org.apache.hadoop.yarn.server.resourcemanager.rmcontainer.RMContainerImpl: container_1523100158662_0002_01_000010 Container Transitioned from ALLOCATED to ACQUIRED
2018-04-07 12:14:12,953 INFO org.apache.hadoop.yarn.server.resourcemanager.rmcontainer.RMContainerImpl: container_1523100158662_0002_01_000010 Container Transitioned from ACQUIRED to RELEASED
2018-04-07 12:14:12,954 INFO org.apache.hadoop.yarn.server.resourcemanager.scheduler.fair.FSAppAttempt: Completed container: container_1523100158662_0002_01_000010 in state: RELEASED event:RELEASED
2018-04-07 12:14:12,954 INFO org.apache.hadoop.yarn.server.resourcemanager.RMAuditLogger: USER=root	IP=172.17.0.2	OPERATION=AM Released Container	TARGET=SchedulerApp	RESULT=SUCCESS	APPID=application_1523100158662_0002	CONTAINERID=container_1523100158662_0002_01_000010
2018-04-07 12:14:12,977 INFO org.apache.hadoop.yarn.server.resourcemanager.scheduler.SchedulerNode: Released container container_1523100158662_0002_01_000010 of capacity <memory:1024, vCores:1> on host d1:59470, which currently has 5 containers, <memory:6144, vCores:5> used and <memory:2048, vCores:3> available, release resources=true
2018-04-07 12:14:12,978 INFO org.apache.hadoop.yarn.server.resourcemanager.scheduler.fair.FairScheduler: Application attempt appattempt_1523100158662_0002_000001 released container container_1523100158662_0002_01_000010 on node: host: d1:59470 #containers=5 available=<memory:2048, vCores:3> used=<memory:6144, vCores:5> with event: RELEASED
2018-04-07 12:15:51,391 INFO org.apache.hadoop.yarn.server.resourcemanager.rmcontainer.RMContainerImpl: container_1523100158662_0002_01_000008 Container Transitioned from RUNNING to COMPLETED
2018-04-07 12:15:51,391 INFO org.apache.hadoop.yarn.server.resourcemanager.scheduler.fair.FSAppAttempt: Completed container: container_1523100158662_0002_01_000008 in state: COMPLETED event:FINISHED
2018-04-07 12:15:51,392 INFO org.apache.hadoop.yarn.server.resourcemanager.RMAuditLogger: USER=root	OPERATION=AM Released Container	TARGET=SchedulerApp	RESULT=SUCCESS	APPID=application_1523100158662_0002	CONTAINERID=container_1523100158662_0002_01_000008
2018-04-07 12:15:51,392 INFO org.apache.hadoop.yarn.server.resourcemanager.scheduler.SchedulerNode: Released container container_1523100158662_0002_01_000008 of capacity <memory:1024, vCores:1> on host d1:59470, which currently has 4 containers, <memory:5120, vCores:4> used and <memory:3072, vCores:4> available, release resources=true
2018-04-07 12:15:51,392 INFO org.apache.hadoop.yarn.server.resourcemanager.scheduler.fair.FairScheduler: Application attempt appattempt_1523100158662_0002_000001 released container container_1523100158662_0002_01_000008 on node: host: d1:59470 #containers=4 available=<memory:3072, vCores:4> used=<memory:5120, vCores:4> with event: FINISHED
2018-04-07 12:15:52,331 INFO org.apache.hadoop.yarn.server.resourcemanager.rmcontainer.RMContainerImpl: container_1523100158662_0002_01_000009 Container Transitioned from RUNNING to COMPLETED
2018-04-07 12:15:52,331 INFO org.apache.hadoop.yarn.server.resourcemanager.scheduler.fair.FSAppAttempt: Completed container: container_1523100158662_0002_01_000009 in state: COMPLETED event:FINISHED
2018-04-07 12:15:52,331 INFO org.apache.hadoop.yarn.server.resourcemanager.RMAuditLogger: USER=root	OPERATION=AM Released Container	TARGET=SchedulerApp	RESULT=SUCCESS	APPID=application_1523100158662_0002	CONTAINERID=container_1523100158662_0002_01_000009
2018-04-07 12:15:52,332 INFO org.apache.hadoop.yarn.server.resourcemanager.scheduler.SchedulerNode: Released container container_1523100158662_0002_01_000009 of capacity <memory:1024, vCores:1> on host d1:59470, which currently has 3 containers, <memory:4096, vCores:3> used and <memory:4096, vCores:5> available, release resources=true
2018-04-07 12:15:52,332 INFO org.apache.hadoop.yarn.server.resourcemanager.scheduler.fair.FairScheduler: Application attempt appattempt_1523100158662_0002_000001 released container container_1523100158662_0002_01_000009 on node: host: d1:59470 #containers=3 available=<memory:4096, vCores:5> used=<memory:4096, vCores:3> with event: FINISHED
2018-04-07 12:15:52,335 INFO org.apache.hadoop.yarn.server.resourcemanager.rmcontainer.RMContainerImpl: container_1523100158662_0002_01_000011 Container Transitioned from NEW to ALLOCATED
2018-04-07 12:15:52,335 INFO org.apache.hadoop.yarn.server.resourcemanager.RMAuditLogger: USER=root	OPERATION=AM Allocated Container	TARGET=SchedulerApp	RESULT=SUCCESS	APPID=application_1523100158662_0002	CONTAINERID=container_1523100158662_0002_01_000011
2018-04-07 12:15:52,335 INFO org.apache.hadoop.yarn.server.resourcemanager.scheduler.SchedulerNode: Assigned container container_1523100158662_0002_01_000011 of capacity <memory:1024, vCores:1> on host d1:59470, which has 4 containers, <memory:5120, vCores:4> used and <memory:3072, vCores:4> available after allocation
2018-04-07 12:15:53,914 INFO org.apache.hadoop.yarn.server.resourcemanager.rmcontainer.RMContainerImpl: container_1523100158662_0002_01_000011 Container Transitioned from ALLOCATED to ACQUIRED
2018-04-07 12:15:53,934 INFO org.apache.hadoop.yarn.server.resourcemanager.rmcontainer.RMContainerImpl: container_1523100158662_0002_01_000007 Container Transitioned from RUNNING to COMPLETED
2018-04-07 12:15:53,934 INFO org.apache.hadoop.yarn.server.resourcemanager.scheduler.fair.FSAppAttempt: Completed container: container_1523100158662_0002_01_000007 in state: COMPLETED event:FINISHED
2018-04-07 12:15:53,935 INFO org.apache.hadoop.yarn.server.resourcemanager.RMAuditLogger: USER=root	OPERATION=AM Released Container	TARGET=SchedulerApp	RESULT=SUCCESS	APPID=application_1523100158662_0002	CONTAINERID=container_1523100158662_0002_01_000007
2018-04-07 12:15:53,935 INFO org.apache.hadoop.yarn.server.resourcemanager.scheduler.SchedulerNode: Released container container_1523100158662_0002_01_000007 of capacity <memory:1024, vCores:1> on host d1:59470, which currently has 3 containers, <memory:4096, vCores:3> used and <memory:4096, vCores:5> available, release resources=true
2018-04-07 12:15:53,935 INFO org.apache.hadoop.yarn.server.resourcemanager.scheduler.fair.FairScheduler: Application attempt appattempt_1523100158662_0002_000001 released container container_1523100158662_0002_01_000007 on node: host: d1:59470 #containers=3 available=<memory:4096, vCores:5> used=<memory:4096, vCores:3> with event: FINISHED
2018-04-07 12:15:54,982 INFO org.apache.hadoop.yarn.server.resourcemanager.scheduler.AppSchedulingInfo: checking for deactivate of application :application_1523100158662_0002
2018-04-07 12:15:55,553 INFO org.apache.hadoop.yarn.server.resourcemanager.rmcontainer.RMContainerImpl: container_1523100158662_0002_01_000011 Container Transitioned from ACQUIRED to RUNNING
2018-04-07 12:15:58,053 INFO org.apache.hadoop.yarn.server.resourcemanager.rmcontainer.RMContainerImpl: container_1523100158662_0002_01_000011 Container Transitioned from RUNNING to COMPLETED
2018-04-07 12:15:58,053 INFO org.apache.hadoop.yarn.server.resourcemanager.scheduler.fair.FSAppAttempt: Completed container: container_1523100158662_0002_01_000011 in state: COMPLETED event:FINISHED
2018-04-07 12:15:58,053 INFO org.apache.hadoop.yarn.server.resourcemanager.RMAuditLogger: USER=root	OPERATION=AM Released Container	TARGET=SchedulerApp	RESULT=SUCCESS	APPID=application_1523100158662_0002	CONTAINERID=container_1523100158662_0002_01_000011
2018-04-07 12:15:58,053 INFO org.apache.hadoop.yarn.server.resourcemanager.scheduler.SchedulerNode: Released container container_1523100158662_0002_01_000011 of capacity <memory:1024, vCores:1> on host d1:59470, which currently has 2 containers, <memory:3072, vCores:2> used and <memory:5120, vCores:6> available, release resources=true
2018-04-07 12:15:58,053 INFO org.apache.hadoop.yarn.server.resourcemanager.scheduler.fair.FairScheduler: Application attempt appattempt_1523100158662_0002_000001 released container container_1523100158662_0002_01_000011 on node: host: d1:59470 #containers=2 available=<memory:5120, vCores:6> used=<memory:3072, vCores:2> with event: FINISHED
2018-04-07 12:15:58,076 INFO org.apache.hadoop.yarn.server.resourcemanager.rmcontainer.RMContainerImpl: container_1523100158662_0002_01_000006 Container Transitioned from RUNNING to COMPLETED
2018-04-07 12:15:58,077 INFO org.apache.hadoop.yarn.server.resourcemanager.scheduler.fair.FSAppAttempt: Completed container: container_1523100158662_0002_01_000006 in state: COMPLETED event:FINISHED
2018-04-07 12:15:58,077 INFO org.apache.hadoop.yarn.server.resourcemanager.RMAuditLogger: USER=root	OPERATION=AM Released Container	TARGET=SchedulerApp	RESULT=SUCCESS	APPID=application_1523100158662_0002	CONTAINERID=container_1523100158662_0002_01_000006
2018-04-07 12:15:58,077 INFO org.apache.hadoop.yarn.server.resourcemanager.scheduler.SchedulerNode: Released container container_1523100158662_0002_01_000006 of capacity <memory:1024, vCores:1> on host d1:59470, which currently has 1 containers, <memory:2048, vCores:1> used and <memory:6144, vCores:7> available, release resources=true
2018-04-07 12:15:58,077 INFO org.apache.hadoop.yarn.server.resourcemanager.scheduler.fair.FairScheduler: Application attempt appattempt_1523100158662_0002_000001 released container container_1523100158662_0002_01_000006 on node: host: d1:59470 #containers=1 available=<memory:6144, vCores:7> used=<memory:2048, vCores:1> with event: FINISHED
2018-04-07 12:15:58,728 INFO org.apache.hadoop.yarn.server.resourcemanager.rmapp.attempt.RMAppAttemptImpl: Updating application attempt appattempt_1523100158662_0002_000001 with final state: FINISHING, and exit status: -1000
2018-04-07 12:15:58,728 INFO org.apache.hadoop.yarn.server.resourcemanager.rmapp.attempt.RMAppAttemptImpl: appattempt_1523100158662_0002_000001 State change from RUNNING to FINAL_SAVING
2018-04-07 12:15:58,729 INFO org.apache.hadoop.yarn.server.resourcemanager.rmapp.RMAppImpl: Updating application application_1523100158662_0002 with final state: FINISHING
2018-04-07 12:15:58,729 INFO org.apache.hadoop.yarn.server.resourcemanager.rmapp.RMAppImpl: application_1523100158662_0002 State change from RUNNING to FINAL_SAVING
2018-04-07 12:15:58,729 INFO org.apache.hadoop.yarn.server.resourcemanager.recovery.RMStateStore: Updating info for app: application_1523100158662_0002
2018-04-07 12:15:58,731 INFO org.apache.hadoop.yarn.server.resourcemanager.rmapp.attempt.RMAppAttemptImpl: appattempt_1523100158662_0002_000001 State change from FINAL_SAVING to FINISHING
2018-04-07 12:15:58,731 INFO org.apache.hadoop.yarn.server.resourcemanager.rmapp.RMAppImpl: application_1523100158662_0002 State change from FINAL_SAVING to FINISHING
2018-04-07 12:15:59,759 INFO org.apache.hadoop.yarn.server.resourcemanager.ApplicationMasterService: application_1523100158662_0002 unregistered successfully. 
2018-04-07 12:16:06,115 INFO org.apache.hadoop.yarn.server.resourcemanager.rmcontainer.RMContainerImpl: container_1523100158662_0002_01_000001 Container Transitioned from RUNNING to COMPLETED
2018-04-07 12:16:06,116 INFO org.apache.hadoop.yarn.server.resourcemanager.scheduler.fair.FSAppAttempt: Completed container: container_1523100158662_0002_01_000001 in state: COMPLETED event:FINISHED
2018-04-07 12:16:06,116 INFO org.apache.hadoop.yarn.server.resourcemanager.ApplicationMasterService: Unregistering app attempt : appattempt_1523100158662_0002_000001
2018-04-07 12:16:06,116 INFO org.apache.hadoop.yarn.server.resourcemanager.security.AMRMTokenSecretManager: Application finished, removing password for appattempt_1523100158662_0002_000001
2018-04-07 12:16:06,116 INFO org.apache.hadoop.yarn.server.resourcemanager.rmapp.attempt.RMAppAttemptImpl: appattempt_1523100158662_0002_000001 State change from FINISHING to FINISHED
2018-04-07 12:16:06,116 INFO org.apache.hadoop.yarn.server.resourcemanager.RMAuditLogger: USER=root	OPERATION=AM Released Container	TARGET=SchedulerApp	RESULT=SUCCESS	APPID=application_1523100158662_0002	CONTAINERID=container_1523100158662_0002_01_000001
2018-04-07 12:16:06,116 INFO org.apache.hadoop.yarn.server.resourcemanager.scheduler.SchedulerNode: Released container container_1523100158662_0002_01_000001 of capacity <memory:2048, vCores:1> on host d1:59470, which currently has 0 containers, <memory:0, vCores:0> used and <memory:8192, vCores:8> available, release resources=true
2018-04-07 12:16:06,116 INFO org.apache.hadoop.yarn.server.resourcemanager.scheduler.fair.FairScheduler: Application attempt appattempt_1523100158662_0002_000001 released container container_1523100158662_0002_01_000001 on node: host: d1:59470 #containers=0 available=<memory:8192, vCores:8> used=<memory:0, vCores:0> with event: FINISHED
2018-04-07 12:16:06,116 INFO org.apache.hadoop.yarn.server.resourcemanager.rmapp.RMAppImpl: application_1523100158662_0002 State change from FINISHING to FINISHED
2018-04-07 12:16:06,117 INFO org.apache.hadoop.yarn.server.resourcemanager.RMAuditLogger: USER=root	OPERATION=Application Finished - Succeeded	TARGET=RMAppManager	RESULT=SUCCESS	APPID=application_1523100158662_0002
2018-04-07 12:16:06,117 INFO org.apache.hadoop.yarn.server.resourcemanager.RMAppManager$ApplicationSummary: appId=application_1523100158662_0002,name=word count,user=root,queue=root.root,state=FINISHED,trackingUrl=http://d1:8088/proxy/application_1523100158662_0002/,appMasterHost=d1,startTime=1523103123221,finishTime=1523103358729,finalStatus=SUCCEEDED,memorySeconds=1098782,vcoreSeconds=824,preemptedAMContainers=0,preemptedNonAMContainers=0,preemptedResources=<memory:0\, vCores:0>,applicationType=MAPREDUCE
2018-04-07 12:16:06,121 INFO org.apache.hadoop.yarn.server.resourcemanager.scheduler.fair.FairScheduler: Application appattempt_1523100158662_0002_000001 is done. finalState=FINISHED
2018-04-07 12:16:06,121 INFO org.apache.hadoop.yarn.server.resourcemanager.scheduler.AppSchedulingInfo: Application application_1523100158662_0002 requests cleared
2018-04-07 12:16:06,122 INFO org.apache.hadoop.yarn.server.resourcemanager.amlauncher.AMLauncher: Cleaning master appattempt_1523100158662_0002_000001
2018-04-07 14:20:52,608 INFO org.apache.hadoop.yarn.server.resourcemanager.ClientRMService: Allocated new applicationId: 3
2018-04-07 14:21:06,268 INFO org.apache.hadoop.yarn.server.resourcemanager.rmapp.RMAppImpl: Storing application with id application_1523100158662_0003
2018-04-07 14:21:06,268 INFO org.apache.hadoop.yarn.server.resourcemanager.ClientRMService: Application with id 3 submitted by user root
2018-04-07 14:21:06,269 INFO org.apache.hadoop.yarn.server.resourcemanager.RMAuditLogger: USER=root	IP=172.17.0.2	OPERATION=Submit Application Request	TARGET=ClientRMService	RESULT=SUCCESS	APPID=application_1523100158662_0003
2018-04-07 14:21:06,269 INFO org.apache.hadoop.yarn.server.resourcemanager.rmapp.RMAppImpl: application_1523100158662_0003 State change from NEW to NEW_SAVING
2018-04-07 14:21:06,269 INFO org.apache.hadoop.yarn.server.resourcemanager.recovery.RMStateStore: Storing info for app: application_1523100158662_0003
2018-04-07 14:21:06,271 INFO org.apache.hadoop.yarn.server.resourcemanager.rmapp.RMAppImpl: application_1523100158662_0003 State change from NEW_SAVING to SUBMITTED
2018-04-07 14:21:06,277 INFO org.apache.hadoop.yarn.server.resourcemanager.scheduler.fair.FairScheduler: Accepted application application_1523100158662_0003 from user: root, in queue: default, currently num of applications: 1
2018-04-07 14:21:06,284 INFO org.apache.hadoop.yarn.server.resourcemanager.rmapp.RMAppImpl: application_1523100158662_0003 State change from SUBMITTED to ACCEPTED
2018-04-07 14:21:06,286 INFO org.apache.hadoop.yarn.server.resourcemanager.ApplicationMasterService: Registering app attempt : appattempt_1523100158662_0003_000001
2018-04-07 14:21:06,286 INFO org.apache.hadoop.yarn.server.resourcemanager.rmapp.attempt.RMAppAttemptImpl: appattempt_1523100158662_0003_000001 State change from NEW to SUBMITTED
2018-04-07 14:21:06,290 INFO org.apache.hadoop.yarn.server.resourcemanager.scheduler.fair.FairScheduler: Added Application Attempt appattempt_1523100158662_0003_000001 to scheduler from user: root
2018-04-07 14:21:06,302 INFO org.apache.hadoop.yarn.server.resourcemanager.rmapp.attempt.RMAppAttemptImpl: appattempt_1523100158662_0003_000001 State change from SUBMITTED to SCHEDULED
2018-04-07 14:21:06,923 INFO org.apache.hadoop.yarn.server.resourcemanager.rmcontainer.RMContainerImpl: container_1523100158662_0003_01_000001 Container Transitioned from NEW to ALLOCATED
2018-04-07 14:21:06,926 INFO org.apache.hadoop.yarn.server.resourcemanager.RMAuditLogger: USER=root	OPERATION=AM Allocated Container	TARGET=SchedulerApp	RESULT=SUCCESS	APPID=application_1523100158662_0003	CONTAINERID=container_1523100158662_0003_01_000001
2018-04-07 14:21:06,936 INFO org.apache.hadoop.yarn.server.resourcemanager.scheduler.SchedulerNode: Assigned container container_1523100158662_0003_01_000001 of capacity <memory:2048, vCores:1> on host d1:59470, which has 1 containers, <memory:2048, vCores:1> used and <memory:6144, vCores:7> available after allocation
2018-04-07 14:21:06,972 INFO org.apache.hadoop.yarn.server.resourcemanager.security.NMTokenSecretManagerInRM: Sending NMToken for nodeId : d1:59470 for container : container_1523100158662_0003_01_000001
2018-04-07 14:21:06,989 INFO org.apache.hadoop.yarn.server.resourcemanager.rmcontainer.RMContainerImpl: container_1523100158662_0003_01_000001 Container Transitioned from ALLOCATED to ACQUIRED
2018-04-07 14:21:06,992 INFO org.apache.hadoop.yarn.server.resourcemanager.security.NMTokenSecretManagerInRM: Clear node set for appattempt_1523100158662_0003_000001
2018-04-07 14:21:06,993 INFO org.apache.hadoop.yarn.server.resourcemanager.rmapp.attempt.RMAppAttemptImpl: Storing attempt: AppId: application_1523100158662_0003 AttemptId: appattempt_1523100158662_0003_000001 MasterContainer: Container: [ContainerId: container_1523100158662_0003_01_000001, NodeId: d1:59470, NodeHttpAddress: d1:8042, Resource: <memory:2048, vCores:1>, Priority: 0, Token: Token { kind: ContainerToken, service: 172.17.0.2:59470 }, ]
2018-04-07 14:21:07,000 INFO org.apache.hadoop.yarn.server.resourcemanager.rmapp.attempt.RMAppAttemptImpl: appattempt_1523100158662_0003_000001 State change from SCHEDULED to ALLOCATED_SAVING
2018-04-07 14:21:07,001 INFO org.apache.hadoop.yarn.server.resourcemanager.rmapp.attempt.RMAppAttemptImpl: appattempt_1523100158662_0003_000001 State change from ALLOCATED_SAVING to ALLOCATED
2018-04-07 14:21:07,015 INFO org.apache.hadoop.yarn.server.resourcemanager.amlauncher.AMLauncher: Launching masterappattempt_1523100158662_0003_000001
2018-04-07 14:21:07,078 INFO org.apache.hadoop.yarn.server.resourcemanager.amlauncher.AMLauncher: Setting up container Container: [ContainerId: container_1523100158662_0003_01_000001, NodeId: d1:59470, NodeHttpAddress: d1:8042, Resource: <memory:2048, vCores:1>, Priority: 0, Token: Token { kind: ContainerToken, service: 172.17.0.2:59470 }, ] for AM appattempt_1523100158662_0003_000001
2018-04-07 14:21:07,078 INFO org.apache.hadoop.yarn.server.resourcemanager.amlauncher.AMLauncher: Command to launch container container_1523100158662_0003_01_000001 : $JAVA_HOME/bin/java -Dlog4j.configuration=container-log4j.properties -Dyarn.app.container.log.dir=<LOG_DIR> -Dyarn.app.container.log.filesize=0 -Dhadoop.root.logger=INFO,CLA -Dhadoop.root.logfile=syslog  -Xmx1024m org.apache.hadoop.mapreduce.v2.app.MRAppMaster 1><LOG_DIR>/stdout 2><LOG_DIR>/stderr 
2018-04-07 14:21:07,081 INFO org.apache.hadoop.yarn.server.resourcemanager.security.AMRMTokenSecretManager: Create AMRMToken for ApplicationAttempt: appattempt_1523100158662_0003_000001
2018-04-07 14:21:07,082 INFO org.apache.hadoop.yarn.server.resourcemanager.security.AMRMTokenSecretManager: Creating password for appattempt_1523100158662_0003_000001
2018-04-07 14:21:07,677 INFO org.apache.hadoop.yarn.server.resourcemanager.amlauncher.AMLauncher: Done launching container Container: [ContainerId: container_1523100158662_0003_01_000001, NodeId: d1:59470, NodeHttpAddress: d1:8042, Resource: <memory:2048, vCores:1>, Priority: 0, Token: Token { kind: ContainerToken, service: 172.17.0.2:59470 }, ] for AM appattempt_1523100158662_0003_000001
2018-04-07 14:21:07,682 INFO org.apache.hadoop.yarn.server.resourcemanager.rmapp.attempt.RMAppAttemptImpl: appattempt_1523100158662_0003_000001 State change from ALLOCATED to LAUNCHED
2018-04-07 14:21:07,977 INFO org.apache.hadoop.yarn.server.resourcemanager.rmcontainer.RMContainerImpl: container_1523100158662_0003_01_000001 Container Transitioned from ACQUIRED to RUNNING
2018-04-07 14:21:36,527 INFO SecurityLogger.org.apache.hadoop.ipc.Server: Auth successful for appattempt_1523100158662_0003_000001 (auth:SIMPLE)
2018-04-07 14:21:36,544 INFO org.apache.hadoop.yarn.server.resourcemanager.ApplicationMasterService: AM registration appattempt_1523100158662_0003_000001
2018-04-07 14:21:36,544 INFO org.apache.hadoop.yarn.server.resourcemanager.RMAuditLogger: USER=root	IP=172.17.0.2	OPERATION=Register App Master	TARGET=ApplicationMasterService	RESULT=SUCCESS	APPID=application_1523100158662_0003	APPATTEMPTID=appattempt_1523100158662_0003_000001
2018-04-07 14:21:36,549 INFO org.apache.hadoop.yarn.server.resourcemanager.rmapp.attempt.RMAppAttemptImpl: appattempt_1523100158662_0003_000001 State change from LAUNCHED to RUNNING
2018-04-07 14:21:36,549 INFO org.apache.hadoop.yarn.server.resourcemanager.rmapp.RMAppImpl: application_1523100158662_0003 State change from ACCEPTED to RUNNING
2018-04-07 14:21:38,419 INFO org.apache.hadoop.yarn.server.resourcemanager.rmcontainer.RMContainerImpl: container_1523100158662_0003_01_000002 Container Transitioned from NEW to ALLOCATED
2018-04-07 14:21:38,423 INFO org.apache.hadoop.yarn.server.resourcemanager.RMAuditLogger: USER=root	OPERATION=AM Allocated Container	TARGET=SchedulerApp	RESULT=SUCCESS	APPID=application_1523100158662_0003	CONTAINERID=container_1523100158662_0003_01_000002
2018-04-07 14:21:38,424 INFO org.apache.hadoop.yarn.server.resourcemanager.scheduler.SchedulerNode: Assigned container container_1523100158662_0003_01_000002 of capacity <memory:1024, vCores:1> on host d1:59470, which has 2 containers, <memory:3072, vCores:2> used and <memory:5120, vCores:6> available after allocation
2018-04-07 14:21:39,021 INFO org.apache.hadoop.yarn.server.resourcemanager.security.NMTokenSecretManagerInRM: Sending NMToken for nodeId : d1:59470 for container : container_1523100158662_0003_01_000002
2018-04-07 14:21:39,025 INFO org.apache.hadoop.yarn.server.resourcemanager.rmcontainer.RMContainerImpl: container_1523100158662_0003_01_000002 Container Transitioned from ALLOCATED to ACQUIRED
2018-04-07 14:21:40,380 INFO org.apache.hadoop.yarn.server.resourcemanager.scheduler.AppSchedulingInfo: checking for deactivate of application :application_1523100158662_0003
2018-04-07 14:21:41,419 INFO org.apache.hadoop.yarn.server.resourcemanager.rmcontainer.RMContainerImpl: container_1523100158662_0003_01_000002 Container Transitioned from ACQUIRED to RUNNING
2018-04-07 14:22:00,293 INFO org.apache.hadoop.yarn.server.resourcemanager.rmcontainer.RMContainerImpl: container_1523100158662_0003_01_000002 Container Transitioned from RUNNING to COMPLETED
2018-04-07 14:22:00,293 INFO org.apache.hadoop.yarn.server.resourcemanager.scheduler.fair.FSAppAttempt: Completed container: container_1523100158662_0003_01_000002 in state: COMPLETED event:FINISHED
2018-04-07 14:22:00,293 INFO org.apache.hadoop.yarn.server.resourcemanager.RMAuditLogger: USER=root	OPERATION=AM Released Container	TARGET=SchedulerApp	RESULT=SUCCESS	APPID=application_1523100158662_0003	CONTAINERID=container_1523100158662_0003_01_000002
2018-04-07 14:22:00,293 INFO org.apache.hadoop.yarn.server.resourcemanager.scheduler.SchedulerNode: Released container container_1523100158662_0003_01_000002 of capacity <memory:1024, vCores:1> on host d1:59470, which currently has 1 containers, <memory:2048, vCores:1> used and <memory:6144, vCores:7> available, release resources=true
2018-04-07 14:22:00,293 INFO org.apache.hadoop.yarn.server.resourcemanager.scheduler.fair.FairScheduler: Application attempt appattempt_1523100158662_0003_000001 released container container_1523100158662_0003_01_000002 on node: host: d1:59470 #containers=1 available=<memory:6144, vCores:7> used=<memory:2048, vCores:1> with event: FINISHED
2018-04-07 14:22:01,422 INFO org.apache.hadoop.yarn.server.resourcemanager.rmcontainer.RMContainerImpl: container_1523100158662_0003_01_000003 Container Transitioned from NEW to ALLOCATED
2018-04-07 14:22:01,424 INFO org.apache.hadoop.yarn.server.resourcemanager.RMAuditLogger: USER=root	OPERATION=AM Allocated Container	TARGET=SchedulerApp	RESULT=SUCCESS	APPID=application_1523100158662_0003	CONTAINERID=container_1523100158662_0003_01_000003
2018-04-07 14:22:01,425 INFO org.apache.hadoop.yarn.server.resourcemanager.scheduler.SchedulerNode: Assigned container container_1523100158662_0003_01_000003 of capacity <memory:1024, vCores:1> on host d1:59470, which has 2 containers, <memory:3072, vCores:2> used and <memory:5120, vCores:6> available after allocation
2018-04-07 14:22:02,353 INFO org.apache.hadoop.yarn.server.resourcemanager.rmcontainer.RMContainerImpl: container_1523100158662_0003_01_000004 Container Transitioned from NEW to ALLOCATED
2018-04-07 14:22:02,359 INFO org.apache.hadoop.yarn.server.resourcemanager.RMAuditLogger: USER=root	OPERATION=AM Allocated Container	TARGET=SchedulerApp	RESULT=SUCCESS	APPID=application_1523100158662_0003	CONTAINERID=container_1523100158662_0003_01_000004
2018-04-07 14:22:02,361 INFO org.apache.hadoop.yarn.server.resourcemanager.scheduler.SchedulerNode: Assigned container container_1523100158662_0003_01_000004 of capacity <memory:1024, vCores:1> on host d1:59470, which has 3 containers, <memory:4096, vCores:3> used and <memory:4096, vCores:5> available after allocation
2018-04-07 14:22:02,605 INFO org.apache.hadoop.yarn.server.resourcemanager.rmcontainer.RMContainerImpl: container_1523100158662_0003_01_000003 Container Transitioned from ALLOCATED to ACQUIRED
2018-04-07 14:22:02,643 INFO org.apache.hadoop.yarn.server.resourcemanager.rmcontainer.RMContainerImpl: container_1523100158662_0003_01_000004 Container Transitioned from ALLOCATED to ACQUIRED
2018-04-07 14:22:03,470 INFO org.apache.hadoop.yarn.server.resourcemanager.rmcontainer.RMContainerImpl: container_1523100158662_0003_01_000003 Container Transitioned from ACQUIRED to RUNNING
2018-04-07 14:22:03,476 INFO org.apache.hadoop.yarn.server.resourcemanager.rmcontainer.RMContainerImpl: container_1523100158662_0003_01_000004 Container Transitioned from ACQUIRED to RUNNING
2018-04-07 14:22:03,477 INFO org.apache.hadoop.yarn.server.resourcemanager.rmcontainer.RMContainerImpl: container_1523100158662_0003_01_000005 Container Transitioned from NEW to ALLOCATED
2018-04-07 14:22:03,477 INFO org.apache.hadoop.yarn.server.resourcemanager.RMAuditLogger: USER=root	OPERATION=AM Allocated Container	TARGET=SchedulerApp	RESULT=SUCCESS	APPID=application_1523100158662_0003	CONTAINERID=container_1523100158662_0003_01_000005
2018-04-07 14:22:03,477 INFO org.apache.hadoop.yarn.server.resourcemanager.scheduler.SchedulerNode: Assigned container container_1523100158662_0003_01_000005 of capacity <memory:1024, vCores:1> on host d1:59470, which has 4 containers, <memory:5120, vCores:4> used and <memory:3072, vCores:4> available after allocation
2018-04-07 14:22:03,713 INFO org.apache.hadoop.yarn.server.resourcemanager.rmcontainer.RMContainerImpl: container_1523100158662_0003_01_000005 Container Transitioned from ALLOCATED to ACQUIRED
2018-04-07 14:22:04,475 INFO org.apache.hadoop.yarn.server.resourcemanager.rmcontainer.RMContainerImpl: container_1523100158662_0003_01_000005 Container Transitioned from ACQUIRED to RUNNING
2018-04-07 14:22:04,477 INFO org.apache.hadoop.yarn.server.resourcemanager.rmcontainer.RMContainerImpl: container_1523100158662_0003_01_000006 Container Transitioned from NEW to ALLOCATED
2018-04-07 14:22:04,477 INFO org.apache.hadoop.yarn.server.resourcemanager.RMAuditLogger: USER=root	OPERATION=AM Allocated Container	TARGET=SchedulerApp	RESULT=SUCCESS	APPID=application_1523100158662_0003	CONTAINERID=container_1523100158662_0003_01_000006
2018-04-07 14:22:04,477 INFO org.apache.hadoop.yarn.server.resourcemanager.scheduler.SchedulerNode: Assigned container container_1523100158662_0003_01_000006 of capacity <memory:1024, vCores:1> on host d1:59470, which has 5 containers, <memory:6144, vCores:5> used and <memory:2048, vCores:3> available after allocation
2018-04-07 14:22:04,754 INFO org.apache.hadoop.yarn.server.resourcemanager.rmcontainer.RMContainerImpl: container_1523100158662_0003_01_000006 Container Transitioned from ALLOCATED to ACQUIRED
2018-04-07 14:22:05,481 INFO org.apache.hadoop.yarn.server.resourcemanager.rmcontainer.RMContainerImpl: container_1523100158662_0003_01_000006 Container Transitioned from ACQUIRED to RUNNING
2018-04-07 14:22:05,482 INFO org.apache.hadoop.yarn.server.resourcemanager.rmcontainer.RMContainerImpl: container_1523100158662_0003_01_000007 Container Transitioned from NEW to ALLOCATED
2018-04-07 14:22:05,482 INFO org.apache.hadoop.yarn.server.resourcemanager.RMAuditLogger: USER=root	OPERATION=AM Allocated Container	TARGET=SchedulerApp	RESULT=SUCCESS	APPID=application_1523100158662_0003	CONTAINERID=container_1523100158662_0003_01_000007
2018-04-07 14:22:05,482 INFO org.apache.hadoop.yarn.server.resourcemanager.scheduler.SchedulerNode: Assigned container container_1523100158662_0003_01_000007 of capacity <memory:1024, vCores:1> on host d1:59470, which has 6 containers, <memory:7168, vCores:6> used and <memory:1024, vCores:2> available after allocation
2018-04-07 14:22:05,772 INFO org.apache.hadoop.yarn.server.resourcemanager.rmcontainer.RMContainerImpl: container_1523100158662_0003_01_000007 Container Transitioned from ALLOCATED to ACQUIRED
2018-04-07 14:22:06,485 INFO org.apache.hadoop.yarn.server.resourcemanager.rmcontainer.RMContainerImpl: container_1523100158662_0003_01_000007 Container Transitioned from ACQUIRED to RUNNING
2018-04-07 14:22:06,488 INFO org.apache.hadoop.yarn.server.resourcemanager.rmcontainer.RMContainerImpl: container_1523100158662_0003_01_000008 Container Transitioned from NEW to ALLOCATED
2018-04-07 14:22:06,488 INFO org.apache.hadoop.yarn.server.resourcemanager.RMAuditLogger: USER=root	OPERATION=AM Allocated Container	TARGET=SchedulerApp	RESULT=SUCCESS	APPID=application_1523100158662_0003	CONTAINERID=container_1523100158662_0003_01_000008
2018-04-07 14:22:06,489 INFO org.apache.hadoop.yarn.server.resourcemanager.scheduler.SchedulerNode: Assigned container container_1523100158662_0003_01_000008 of capacity <memory:1024, vCores:1> on host d1:59470, which has 7 containers, <memory:8192, vCores:7> used and <memory:0, vCores:1> available after allocation
2018-04-07 14:22:06,805 INFO org.apache.hadoop.yarn.server.resourcemanager.rmcontainer.RMContainerImpl: container_1523100158662_0003_01_000008 Container Transitioned from ALLOCATED to ACQUIRED
2018-04-07 14:22:07,487 INFO org.apache.hadoop.yarn.server.resourcemanager.rmcontainer.RMContainerImpl: container_1523100158662_0003_01_000008 Container Transitioned from ACQUIRED to RUNNING
2018-04-07 14:22:07,488 INFO org.apache.hadoop.yarn.server.resourcemanager.scheduler.fair.FSAppAttempt: Making reservation: node=d1 app_id=application_1523100158662_0003
2018-04-07 14:22:07,489 INFO org.apache.hadoop.yarn.server.resourcemanager.rmcontainer.RMContainerImpl: container_1523100158662_0003_01_000009 Container Transitioned from NEW to RESERVED
2018-04-07 14:22:07,489 INFO org.apache.hadoop.yarn.server.resourcemanager.scheduler.fair.FSSchedulerNode: Reserved container container_1523100158662_0003_01_000009 on node host: d1:59470 #containers=7 available=<memory:0, vCores:1> used=<memory:8192, vCores:7> for application org.apache.hadoop.yarn.server.resourcemanager.scheduler.fair.FSAppAttempt@6d8384b4
2018-04-07 14:23:04,391 INFO org.apache.hadoop.yarn.server.resourcemanager.rmcontainer.RMContainerImpl: container_1523100158662_0003_01_000003 Container Transitioned from RUNNING to COMPLETED
2018-04-07 14:23:04,392 INFO org.apache.hadoop.yarn.server.resourcemanager.scheduler.fair.FSAppAttempt: Completed container: container_1523100158662_0003_01_000003 in state: COMPLETED event:FINISHED
2018-04-07 14:23:04,392 INFO org.apache.hadoop.yarn.server.resourcemanager.RMAuditLogger: USER=root	OPERATION=AM Released Container	TARGET=SchedulerApp	RESULT=SUCCESS	APPID=application_1523100158662_0003	CONTAINERID=container_1523100158662_0003_01_000003
2018-04-07 14:23:04,392 INFO org.apache.hadoop.yarn.server.resourcemanager.scheduler.SchedulerNode: Released container container_1523100158662_0003_01_000003 of capacity <memory:1024, vCores:1> on host d1:59470, which currently has 6 containers, <memory:7168, vCores:6> used and <memory:1024, vCores:2> available, release resources=true
2018-04-07 14:23:04,392 INFO org.apache.hadoop.yarn.server.resourcemanager.scheduler.fair.FairScheduler: Application attempt appattempt_1523100158662_0003_000001 released container container_1523100158662_0003_01_000003 on node: host: d1:59470 #containers=6 available=<memory:1024, vCores:2> used=<memory:7168, vCores:6> with event: FINISHED
2018-04-07 14:23:04,393 INFO org.apache.hadoop.yarn.server.resourcemanager.rmcontainer.RMContainerImpl: container_1523100158662_0003_01_000009 Container Transitioned from NEW to ALLOCATED
2018-04-07 14:23:04,393 INFO org.apache.hadoop.yarn.server.resourcemanager.RMAuditLogger: USER=root	OPERATION=AM Allocated Container	TARGET=SchedulerApp	RESULT=SUCCESS	APPID=application_1523100158662_0003	CONTAINERID=container_1523100158662_0003_01_000009
2018-04-07 14:23:04,393 INFO org.apache.hadoop.yarn.server.resourcemanager.scheduler.fair.FSAppAttempt: Application application_1523100158662_0003 unreserved  on node host: d1:59470 #containers=6 available=<memory:1024, vCores:2> used=<memory:7168, vCores:6>, currently has 0 at priority 10; currentReservation <memory:0, vCores:0>
2018-04-07 14:23:04,393 INFO org.apache.hadoop.yarn.server.resourcemanager.scheduler.SchedulerNode: Assigned container container_1523100158662_0003_01_000009 of capacity <memory:1024, vCores:1> on host d1:59470, which has 7 containers, <memory:8192, vCores:7> used and <memory:0, vCores:1> available after allocation
2018-04-07 14:23:04,649 INFO org.apache.hadoop.yarn.server.resourcemanager.rmcontainer.RMContainerImpl: container_1523100158662_0003_01_000009 Container Transitioned from ALLOCATED to ACQUIRED
2018-04-07 14:23:05,019 INFO org.apache.hadoop.yarn.server.resourcemanager.rmcontainer.RMContainerImpl: container_1523100158662_0003_01_000009 Container Transitioned from ACQUIRED to RUNNING
2018-04-07 14:23:05,020 INFO org.apache.hadoop.yarn.server.resourcemanager.scheduler.fair.FSAppAttempt: Making reservation: node=d1 app_id=application_1523100158662_0003
2018-04-07 14:23:05,020 INFO org.apache.hadoop.yarn.server.resourcemanager.rmcontainer.RMContainerImpl: container_1523100158662_0003_01_000010 Container Transitioned from NEW to RESERVED
2018-04-07 14:23:05,020 INFO org.apache.hadoop.yarn.server.resourcemanager.scheduler.fair.FSSchedulerNode: Reserved container container_1523100158662_0003_01_000010 on node host: d1:59470 #containers=7 available=<memory:0, vCores:1> used=<memory:8192, vCores:7> for application org.apache.hadoop.yarn.server.resourcemanager.scheduler.fair.FSAppAttempt@6d8384b4
2018-04-07 14:23:06,397 INFO org.apache.hadoop.yarn.server.resourcemanager.rmcontainer.RMContainerImpl: container_1523100158662_0003_01_000004 Container Transitioned from RUNNING to COMPLETED
2018-04-07 14:23:06,397 INFO org.apache.hadoop.yarn.server.resourcemanager.scheduler.fair.FSAppAttempt: Completed container: container_1523100158662_0003_01_000004 in state: COMPLETED event:FINISHED
2018-04-07 14:23:06,397 INFO org.apache.hadoop.yarn.server.resourcemanager.RMAuditLogger: USER=root	OPERATION=AM Released Container	TARGET=SchedulerApp	RESULT=SUCCESS	APPID=application_1523100158662_0003	CONTAINERID=container_1523100158662_0003_01_000004
2018-04-07 14:23:06,397 INFO org.apache.hadoop.yarn.server.resourcemanager.scheduler.SchedulerNode: Released container container_1523100158662_0003_01_000004 of capacity <memory:1024, vCores:1> on host d1:59470, which currently has 6 containers, <memory:7168, vCores:6> used and <memory:1024, vCores:2> available, release resources=true
2018-04-07 14:23:06,397 INFO org.apache.hadoop.yarn.server.resourcemanager.scheduler.fair.FairScheduler: Application attempt appattempt_1523100158662_0003_000001 released container container_1523100158662_0003_01_000004 on node: host: d1:59470 #containers=6 available=<memory:1024, vCores:2> used=<memory:7168, vCores:6> with event: FINISHED
2018-04-07 14:23:06,398 INFO org.apache.hadoop.yarn.server.resourcemanager.rmcontainer.RMContainerImpl: container_1523100158662_0003_01_000006 Container Transitioned from RUNNING to COMPLETED
2018-04-07 14:23:06,398 INFO org.apache.hadoop.yarn.server.resourcemanager.scheduler.fair.FSAppAttempt: Completed container: container_1523100158662_0003_01_000006 in state: COMPLETED event:FINISHED
2018-04-07 14:23:06,398 INFO org.apache.hadoop.yarn.server.resourcemanager.RMAuditLogger: USER=root	OPERATION=AM Released Container	TARGET=SchedulerApp	RESULT=SUCCESS	APPID=application_1523100158662_0003	CONTAINERID=container_1523100158662_0003_01_000006
2018-04-07 14:23:06,398 INFO org.apache.hadoop.yarn.server.resourcemanager.scheduler.SchedulerNode: Released container container_1523100158662_0003_01_000006 of capacity <memory:1024, vCores:1> on host d1:59470, which currently has 5 containers, <memory:6144, vCores:5> used and <memory:2048, vCores:3> available, release resources=true
2018-04-07 14:23:06,399 INFO org.apache.hadoop.yarn.server.resourcemanager.scheduler.fair.FairScheduler: Application attempt appattempt_1523100158662_0003_000001 released container container_1523100158662_0003_01_000006 on node: host: d1:59470 #containers=5 available=<memory:2048, vCores:3> used=<memory:6144, vCores:5> with event: FINISHED
2018-04-07 14:23:06,401 INFO org.apache.hadoop.yarn.server.resourcemanager.rmcontainer.RMContainerImpl: container_1523100158662_0003_01_000005 Container Transitioned from RUNNING to COMPLETED
2018-04-07 14:23:06,401 INFO org.apache.hadoop.yarn.server.resourcemanager.scheduler.fair.FSAppAttempt: Completed container: container_1523100158662_0003_01_000005 in state: COMPLETED event:FINISHED
2018-04-07 14:23:06,401 INFO org.apache.hadoop.yarn.server.resourcemanager.RMAuditLogger: USER=root	OPERATION=AM Released Container	TARGET=SchedulerApp	RESULT=SUCCESS	APPID=application_1523100158662_0003	CONTAINERID=container_1523100158662_0003_01_000005
2018-04-07 14:23:06,401 INFO org.apache.hadoop.yarn.server.resourcemanager.scheduler.SchedulerNode: Released container container_1523100158662_0003_01_000005 of capacity <memory:1024, vCores:1> on host d1:59470, which currently has 4 containers, <memory:5120, vCores:4> used and <memory:3072, vCores:4> available, release resources=true
2018-04-07 14:23:06,401 INFO org.apache.hadoop.yarn.server.resourcemanager.scheduler.fair.FairScheduler: Application attempt appattempt_1523100158662_0003_000001 released container container_1523100158662_0003_01_000005 on node: host: d1:59470 #containers=4 available=<memory:3072, vCores:4> used=<memory:5120, vCores:4> with event: FINISHED
2018-04-07 14:23:06,401 INFO org.apache.hadoop.yarn.server.resourcemanager.rmcontainer.RMContainerImpl: container_1523100158662_0003_01_000010 Container Transitioned from NEW to ALLOCATED
2018-04-07 14:23:06,401 INFO org.apache.hadoop.yarn.server.resourcemanager.RMAuditLogger: USER=root	OPERATION=AM Allocated Container	TARGET=SchedulerApp	RESULT=SUCCESS	APPID=application_1523100158662_0003	CONTAINERID=container_1523100158662_0003_01_000010
2018-04-07 14:23:06,401 INFO org.apache.hadoop.yarn.server.resourcemanager.scheduler.fair.FSAppAttempt: Application application_1523100158662_0003 unreserved  on node host: d1:59470 #containers=4 available=<memory:3072, vCores:4> used=<memory:5120, vCores:4>, currently has 0 at priority 10; currentReservation <memory:0, vCores:0>
2018-04-07 14:23:06,401 INFO org.apache.hadoop.yarn.server.resourcemanager.scheduler.SchedulerNode: Assigned container container_1523100158662_0003_01_000010 of capacity <memory:1024, vCores:1> on host d1:59470, which has 5 containers, <memory:6144, vCores:5> used and <memory:2048, vCores:3> available after allocation
2018-04-07 14:23:06,663 INFO org.apache.hadoop.yarn.server.resourcemanager.rmcontainer.RMContainerImpl: container_1523100158662_0003_01_000010 Container Transitioned from ALLOCATED to ACQUIRED
2018-04-07 14:23:06,938 INFO org.apache.hadoop.yarn.server.resourcemanager.rmcontainer.RMContainerImpl: container_1523100158662_0003_01_000010 Container Transitioned from ACQUIRED to RUNNING
2018-04-07 14:23:06,938 INFO org.apache.hadoop.yarn.server.resourcemanager.rmcontainer.RMContainerImpl: container_1523100158662_0003_01_000007 Container Transitioned from RUNNING to COMPLETED
2018-04-07 14:23:06,938 INFO org.apache.hadoop.yarn.server.resourcemanager.scheduler.fair.FSAppAttempt: Completed container: container_1523100158662_0003_01_000007 in state: COMPLETED event:FINISHED
2018-04-07 14:23:06,938 INFO org.apache.hadoop.yarn.server.resourcemanager.RMAuditLogger: USER=root	OPERATION=AM Released Container	TARGET=SchedulerApp	RESULT=SUCCESS	APPID=application_1523100158662_0003	CONTAINERID=container_1523100158662_0003_01_000007
2018-04-07 14:23:06,938 INFO org.apache.hadoop.yarn.server.resourcemanager.scheduler.SchedulerNode: Released container container_1523100158662_0003_01_000007 of capacity <memory:1024, vCores:1> on host d1:59470, which currently has 4 containers, <memory:5120, vCores:4> used and <memory:3072, vCores:4> available, release resources=true
2018-04-07 14:23:06,938 INFO org.apache.hadoop.yarn.server.resourcemanager.scheduler.fair.FairScheduler: Application attempt appattempt_1523100158662_0003_000001 released container container_1523100158662_0003_01_000007 on node: host: d1:59470 #containers=4 available=<memory:3072, vCores:4> used=<memory:5120, vCores:4> with event: FINISHED
2018-04-07 14:23:06,939 INFO org.apache.hadoop.yarn.server.resourcemanager.rmcontainer.RMContainerImpl: container_1523100158662_0003_01_000011 Container Transitioned from NEW to ALLOCATED
2018-04-07 14:23:06,939 INFO org.apache.hadoop.yarn.server.resourcemanager.RMAuditLogger: USER=root	OPERATION=AM Allocated Container	TARGET=SchedulerApp	RESULT=SUCCESS	APPID=application_1523100158662_0003	CONTAINERID=container_1523100158662_0003_01_000011
2018-04-07 14:23:06,939 INFO org.apache.hadoop.yarn.server.resourcemanager.scheduler.SchedulerNode: Assigned container container_1523100158662_0003_01_000011 of capacity <memory:1024, vCores:1> on host d1:59470, which has 5 containers, <memory:6144, vCores:5> used and <memory:2048, vCores:3> available after allocation
2018-04-07 14:23:07,672 INFO org.apache.hadoop.yarn.server.resourcemanager.rmcontainer.RMContainerImpl: container_1523100158662_0003_01_000011 Container Transitioned from ALLOCATED to ACQUIRED
2018-04-07 14:23:07,942 INFO org.apache.hadoop.yarn.server.resourcemanager.rmcontainer.RMContainerImpl: container_1523100158662_0003_01_000011 Container Transitioned from ACQUIRED to RUNNING
2018-04-07 14:23:07,943 INFO org.apache.hadoop.yarn.server.resourcemanager.rmcontainer.RMContainerImpl: container_1523100158662_0003_01_000008 Container Transitioned from RUNNING to COMPLETED
2018-04-07 14:23:07,943 INFO org.apache.hadoop.yarn.server.resourcemanager.scheduler.fair.FSAppAttempt: Completed container: container_1523100158662_0003_01_000008 in state: COMPLETED event:FINISHED
2018-04-07 14:23:07,944 INFO org.apache.hadoop.yarn.server.resourcemanager.RMAuditLogger: USER=root	OPERATION=AM Released Container	TARGET=SchedulerApp	RESULT=SUCCESS	APPID=application_1523100158662_0003	CONTAINERID=container_1523100158662_0003_01_000008
2018-04-07 14:23:07,944 INFO org.apache.hadoop.yarn.server.resourcemanager.scheduler.SchedulerNode: Released container container_1523100158662_0003_01_000008 of capacity <memory:1024, vCores:1> on host d1:59470, which currently has 4 containers, <memory:5120, vCores:4> used and <memory:3072, vCores:4> available, release resources=true
2018-04-07 14:23:07,944 INFO org.apache.hadoop.yarn.server.resourcemanager.scheduler.fair.FairScheduler: Application attempt appattempt_1523100158662_0003_000001 released container container_1523100158662_0003_01_000008 on node: host: d1:59470 #containers=4 available=<memory:3072, vCores:4> used=<memory:5120, vCores:4> with event: FINISHED
2018-04-07 14:23:07,945 INFO org.apache.hadoop.yarn.server.resourcemanager.rmcontainer.RMContainerImpl: container_1523100158662_0003_01_000012 Container Transitioned from NEW to ALLOCATED
2018-04-07 14:23:07,945 INFO org.apache.hadoop.yarn.server.resourcemanager.RMAuditLogger: USER=root	OPERATION=AM Allocated Container	TARGET=SchedulerApp	RESULT=SUCCESS	APPID=application_1523100158662_0003	CONTAINERID=container_1523100158662_0003_01_000012
2018-04-07 14:23:07,945 INFO org.apache.hadoop.yarn.server.resourcemanager.scheduler.SchedulerNode: Assigned container container_1523100158662_0003_01_000012 of capacity <memory:1024, vCores:1> on host d1:59470, which has 5 containers, <memory:6144, vCores:5> used and <memory:2048, vCores:3> available after allocation
2018-04-07 14:23:08,678 INFO org.apache.hadoop.yarn.server.resourcemanager.rmcontainer.RMContainerImpl: container_1523100158662_0003_01_000012 Container Transitioned from ALLOCATED to ACQUIRED
2018-04-07 14:23:08,947 INFO org.apache.hadoop.yarn.server.resourcemanager.rmcontainer.RMContainerImpl: container_1523100158662_0003_01_000012 Container Transitioned from ACQUIRED to RUNNING
2018-04-07 14:23:08,948 INFO org.apache.hadoop.yarn.server.resourcemanager.rmcontainer.RMContainerImpl: container_1523100158662_0003_01_000013 Container Transitioned from NEW to ALLOCATED
2018-04-07 14:23:08,948 INFO org.apache.hadoop.yarn.server.resourcemanager.RMAuditLogger: USER=root	OPERATION=AM Allocated Container	TARGET=SchedulerApp	RESULT=SUCCESS	APPID=application_1523100158662_0003	CONTAINERID=container_1523100158662_0003_01_000013
2018-04-07 14:23:08,948 INFO org.apache.hadoop.yarn.server.resourcemanager.scheduler.SchedulerNode: Assigned container container_1523100158662_0003_01_000013 of capacity <memory:1024, vCores:1> on host d1:59470, which has 6 containers, <memory:7168, vCores:6> used and <memory:1024, vCores:2> available after allocation
2018-04-07 14:23:09,682 INFO org.apache.hadoop.yarn.server.resourcemanager.scheduler.AppSchedulingInfo: checking for deactivate of application :application_1523100158662_0003
2018-04-07 14:23:09,685 INFO org.apache.hadoop.yarn.server.resourcemanager.rmcontainer.RMContainerImpl: container_1523100158662_0003_01_000013 Container Transitioned from ALLOCATED to ACQUIRED
2018-04-07 14:23:10,702 INFO org.apache.hadoop.yarn.server.resourcemanager.rmcontainer.RMContainerImpl: container_1523100158662_0003_01_000013 Container Transitioned from ACQUIRED to RELEASED
2018-04-07 14:23:10,702 INFO org.apache.hadoop.yarn.server.resourcemanager.scheduler.fair.FSAppAttempt: Completed container: container_1523100158662_0003_01_000013 in state: RELEASED event:RELEASED
2018-04-07 14:23:10,703 INFO org.apache.hadoop.yarn.server.resourcemanager.RMAuditLogger: USER=root	IP=172.17.0.2	OPERATION=AM Released Container	TARGET=SchedulerApp	RESULT=SUCCESS	APPID=application_1523100158662_0003	CONTAINERID=container_1523100158662_0003_01_000013
2018-04-07 14:23:10,703 INFO org.apache.hadoop.yarn.server.resourcemanager.scheduler.SchedulerNode: Released container container_1523100158662_0003_01_000013 of capacity <memory:1024, vCores:1> on host d1:59470, which currently has 5 containers, <memory:6144, vCores:5> used and <memory:2048, vCores:3> available, release resources=true
2018-04-07 14:23:10,703 INFO org.apache.hadoop.yarn.server.resourcemanager.scheduler.fair.FairScheduler: Application attempt appattempt_1523100158662_0003_000001 released container container_1523100158662_0003_01_000013 on node: host: d1:59470 #containers=5 available=<memory:2048, vCores:3> used=<memory:6144, vCores:5> with event: RELEASED
2018-04-07 14:23:18,901 INFO org.apache.hadoop.yarn.server.resourcemanager.rmcontainer.RMContainerImpl: container_1523100158662_0003_01_000014 Container Transitioned from NEW to ALLOCATED
2018-04-07 14:23:18,901 INFO org.apache.hadoop.yarn.server.resourcemanager.RMAuditLogger: USER=root	OPERATION=AM Allocated Container	TARGET=SchedulerApp	RESULT=SUCCESS	APPID=application_1523100158662_0003	CONTAINERID=container_1523100158662_0003_01_000014
2018-04-07 14:23:18,901 INFO org.apache.hadoop.yarn.server.resourcemanager.scheduler.SchedulerNode: Assigned container container_1523100158662_0003_01_000014 of capacity <memory:1024, vCores:1> on host d1:59470, which has 6 containers, <memory:7168, vCores:6> used and <memory:1024, vCores:2> available after allocation
2018-04-07 14:23:19,737 INFO org.apache.hadoop.yarn.server.resourcemanager.scheduler.AppSchedulingInfo: checking for deactivate of application :application_1523100158662_0003
2018-04-07 14:23:19,741 INFO org.apache.hadoop.yarn.server.resourcemanager.rmcontainer.RMContainerImpl: container_1523100158662_0003_01_000014 Container Transitioned from ALLOCATED to ACQUIRED
2018-04-07 14:23:19,911 INFO org.apache.hadoop.yarn.server.resourcemanager.rmcontainer.RMContainerImpl: container_1523100158662_0003_01_000009 Container Transitioned from RUNNING to COMPLETED
2018-04-07 14:23:19,911 INFO org.apache.hadoop.yarn.server.resourcemanager.scheduler.fair.FSAppAttempt: Completed container: container_1523100158662_0003_01_000009 in state: COMPLETED event:FINISHED
2018-04-07 14:23:19,911 INFO org.apache.hadoop.yarn.server.resourcemanager.RMAuditLogger: USER=root	OPERATION=AM Released Container	TARGET=SchedulerApp	RESULT=SUCCESS	APPID=application_1523100158662_0003	CONTAINERID=container_1523100158662_0003_01_000009
2018-04-07 14:23:19,911 INFO org.apache.hadoop.yarn.server.resourcemanager.scheduler.SchedulerNode: Released container container_1523100158662_0003_01_000009 of capacity <memory:1024, vCores:1> on host d1:59470, which currently has 5 containers, <memory:6144, vCores:5> used and <memory:2048, vCores:3> available, release resources=true
2018-04-07 14:23:19,911 INFO org.apache.hadoop.yarn.server.resourcemanager.scheduler.fair.FairScheduler: Application attempt appattempt_1523100158662_0003_000001 released container container_1523100158662_0003_01_000009 on node: host: d1:59470 #containers=5 available=<memory:2048, vCores:3> used=<memory:6144, vCores:5> with event: FINISHED
2018-04-07 14:23:20,746 INFO org.apache.hadoop.yarn.server.resourcemanager.rmcontainer.RMContainerImpl: container_1523100158662_0003_01_000014 Container Transitioned from ACQUIRED to RELEASED
2018-04-07 14:23:20,747 INFO org.apache.hadoop.yarn.server.resourcemanager.scheduler.fair.FSAppAttempt: Completed container: container_1523100158662_0003_01_000014 in state: RELEASED event:RELEASED
2018-04-07 14:23:20,747 INFO org.apache.hadoop.yarn.server.resourcemanager.RMAuditLogger: USER=root	IP=172.17.0.2	OPERATION=AM Released Container	TARGET=SchedulerApp	RESULT=SUCCESS	APPID=application_1523100158662_0003	CONTAINERID=container_1523100158662_0003_01_000014
2018-04-07 14:23:20,747 INFO org.apache.hadoop.yarn.server.resourcemanager.scheduler.SchedulerNode: Released container container_1523100158662_0003_01_000014 of capacity <memory:1024, vCores:1> on host d1:59470, which currently has 4 containers, <memory:5120, vCores:4> used and <memory:3072, vCores:4> available, release resources=true
2018-04-07 14:23:20,747 INFO org.apache.hadoop.yarn.server.resourcemanager.scheduler.fair.FairScheduler: Application attempt appattempt_1523100158662_0003_000001 released container container_1523100158662_0003_01_000014 on node: host: d1:59470 #containers=4 available=<memory:3072, vCores:4> used=<memory:5120, vCores:4> with event: RELEASED
2018-04-07 14:23:22,222 INFO org.apache.hadoop.yarn.server.resourcemanager.rmcontainer.RMContainerImpl: container_1523100158662_0003_01_000010 Container Transitioned from RUNNING to COMPLETED
2018-04-07 14:23:22,222 INFO org.apache.hadoop.yarn.server.resourcemanager.scheduler.fair.FSAppAttempt: Completed container: container_1523100158662_0003_01_000010 in state: COMPLETED event:FINISHED
2018-04-07 14:23:22,222 INFO org.apache.hadoop.yarn.server.resourcemanager.RMAuditLogger: USER=root	OPERATION=AM Released Container	TARGET=SchedulerApp	RESULT=SUCCESS	APPID=application_1523100158662_0003	CONTAINERID=container_1523100158662_0003_01_000010
2018-04-07 14:23:22,222 INFO org.apache.hadoop.yarn.server.resourcemanager.scheduler.SchedulerNode: Released container container_1523100158662_0003_01_000010 of capacity <memory:1024, vCores:1> on host d1:59470, which currently has 3 containers, <memory:4096, vCores:3> used and <memory:4096, vCores:5> available, release resources=true
2018-04-07 14:23:22,222 INFO org.apache.hadoop.yarn.server.resourcemanager.scheduler.fair.FairScheduler: Application attempt appattempt_1523100158662_0003_000001 released container container_1523100158662_0003_01_000010 on node: host: d1:59470 #containers=3 available=<memory:4096, vCores:5> used=<memory:4096, vCores:3> with event: FINISHED
2018-04-07 14:23:23,306 INFO org.apache.hadoop.yarn.server.resourcemanager.rmcontainer.RMContainerImpl: container_1523100158662_0003_01_000011 Container Transitioned from RUNNING to COMPLETED
2018-04-07 14:23:23,306 INFO org.apache.hadoop.yarn.server.resourcemanager.scheduler.fair.FSAppAttempt: Completed container: container_1523100158662_0003_01_000011 in state: COMPLETED event:FINISHED
2018-04-07 14:23:23,306 INFO org.apache.hadoop.yarn.server.resourcemanager.RMAuditLogger: USER=root	OPERATION=AM Released Container	TARGET=SchedulerApp	RESULT=SUCCESS	APPID=application_1523100158662_0003	CONTAINERID=container_1523100158662_0003_01_000011
2018-04-07 14:23:23,306 INFO org.apache.hadoop.yarn.server.resourcemanager.scheduler.SchedulerNode: Released container container_1523100158662_0003_01_000011 of capacity <memory:1024, vCores:1> on host d1:59470, which currently has 2 containers, <memory:3072, vCores:2> used and <memory:5120, vCores:6> available, release resources=true
2018-04-07 14:23:23,306 INFO org.apache.hadoop.yarn.server.resourcemanager.scheduler.fair.FairScheduler: Application attempt appattempt_1523100158662_0003_000001 released container container_1523100158662_0003_01_000011 on node: host: d1:59470 #containers=2 available=<memory:5120, vCores:6> used=<memory:3072, vCores:2> with event: FINISHED
2018-04-07 14:23:24,449 INFO org.apache.hadoop.yarn.server.resourcemanager.rmcontainer.RMContainerImpl: container_1523100158662_0003_01_000012 Container Transitioned from RUNNING to COMPLETED
2018-04-07 14:23:24,449 INFO org.apache.hadoop.yarn.server.resourcemanager.scheduler.fair.FSAppAttempt: Completed container: container_1523100158662_0003_01_000012 in state: COMPLETED event:FINISHED
2018-04-07 14:23:24,449 INFO org.apache.hadoop.yarn.server.resourcemanager.RMAuditLogger: USER=root	OPERATION=AM Released Container	TARGET=SchedulerApp	RESULT=SUCCESS	APPID=application_1523100158662_0003	CONTAINERID=container_1523100158662_0003_01_000012
2018-04-07 14:23:24,449 INFO org.apache.hadoop.yarn.server.resourcemanager.scheduler.SchedulerNode: Released container container_1523100158662_0003_01_000012 of capacity <memory:1024, vCores:1> on host d1:59470, which currently has 1 containers, <memory:2048, vCores:1> used and <memory:6144, vCores:7> available, release resources=true
2018-04-07 14:23:24,468 INFO org.apache.hadoop.yarn.server.resourcemanager.scheduler.fair.FairScheduler: Application attempt appattempt_1523100158662_0003_000001 released container container_1523100158662_0003_01_000012 on node: host: d1:59470 #containers=1 available=<memory:6144, vCores:7> used=<memory:2048, vCores:1> with event: FINISHED
2018-04-07 14:23:27,110 INFO org.apache.hadoop.yarn.server.resourcemanager.rmapp.attempt.RMAppAttemptImpl: Updating application attempt appattempt_1523100158662_0003_000001 with final state: FINISHING, and exit status: -1000
2018-04-07 14:23:27,117 INFO org.apache.hadoop.yarn.server.resourcemanager.rmapp.attempt.RMAppAttemptImpl: appattempt_1523100158662_0003_000001 State change from RUNNING to FINAL_SAVING
2018-04-07 14:23:27,117 INFO org.apache.hadoop.yarn.server.resourcemanager.rmapp.attempt.RMAppAttemptImpl: appattempt_1523100158662_0003_000001 State change from FINAL_SAVING to FINISHING
2018-04-07 14:23:27,118 INFO org.apache.hadoop.yarn.server.resourcemanager.rmapp.RMAppImpl: Updating application application_1523100158662_0003 with final state: FINISHING
2018-04-07 14:23:27,118 INFO org.apache.hadoop.yarn.server.resourcemanager.recovery.RMStateStore: Updating info for app: application_1523100158662_0003
2018-04-07 14:23:27,118 INFO org.apache.hadoop.yarn.server.resourcemanager.rmapp.RMAppImpl: application_1523100158662_0003 State change from RUNNING to FINAL_SAVING
2018-04-07 14:23:27,118 INFO org.apache.hadoop.yarn.server.resourcemanager.rmapp.RMAppImpl: application_1523100158662_0003 State change from FINAL_SAVING to FINISHING
2018-04-07 14:23:28,153 INFO org.apache.hadoop.yarn.server.resourcemanager.ApplicationMasterService: application_1523100158662_0003 unregistered successfully. 
2018-04-07 14:23:35,559 INFO org.apache.hadoop.yarn.server.resourcemanager.rmcontainer.RMContainerImpl: container_1523100158662_0003_01_000001 Container Transitioned from RUNNING to COMPLETED
2018-04-07 14:23:35,562 INFO org.apache.hadoop.yarn.server.resourcemanager.ApplicationMasterService: Unregistering app attempt : appattempt_1523100158662_0003_000001
2018-04-07 14:23:35,564 INFO org.apache.hadoop.yarn.server.resourcemanager.scheduler.fair.FSAppAttempt: Completed container: container_1523100158662_0003_01_000001 in state: COMPLETED event:FINISHED
2018-04-07 14:23:35,564 INFO org.apache.hadoop.yarn.server.resourcemanager.RMAuditLogger: USER=root	OPERATION=AM Released Container	TARGET=SchedulerApp	RESULT=SUCCESS	APPID=application_1523100158662_0003	CONTAINERID=container_1523100158662_0003_01_000001
2018-04-07 14:23:35,564 INFO org.apache.hadoop.yarn.server.resourcemanager.scheduler.SchedulerNode: Released container container_1523100158662_0003_01_000001 of capacity <memory:2048, vCores:1> on host d1:59470, which currently has 0 containers, <memory:0, vCores:0> used and <memory:8192, vCores:8> available, release resources=true
2018-04-07 14:23:35,568 INFO org.apache.hadoop.yarn.server.resourcemanager.scheduler.fair.FairScheduler: Application attempt appattempt_1523100158662_0003_000001 released container container_1523100158662_0003_01_000001 on node: host: d1:59470 #containers=0 available=<memory:8192, vCores:8> used=<memory:0, vCores:0> with event: FINISHED
2018-04-07 14:23:35,566 INFO org.apache.hadoop.yarn.server.resourcemanager.security.AMRMTokenSecretManager: Application finished, removing password for appattempt_1523100158662_0003_000001
2018-04-07 14:23:35,570 INFO org.apache.hadoop.yarn.server.resourcemanager.rmapp.attempt.RMAppAttemptImpl: appattempt_1523100158662_0003_000001 State change from FINISHING to FINISHED
2018-04-07 14:23:35,570 INFO org.apache.hadoop.yarn.server.resourcemanager.rmapp.RMAppImpl: application_1523100158662_0003 State change from FINISHING to FINISHED
2018-04-07 14:23:35,570 INFO org.apache.hadoop.yarn.server.resourcemanager.RMAuditLogger: USER=root	OPERATION=Application Finished - Succeeded	TARGET=RMAppManager	RESULT=SUCCESS	APPID=application_1523100158662_0003
2018-04-07 14:23:35,571 INFO org.apache.hadoop.yarn.server.resourcemanager.RMAppManager$ApplicationSummary: appId=application_1523100158662_0003,name=word count,user=root,queue=root.root,state=FINISHED,trackingUrl=http://d1:8088/proxy/application_1523100158662_0003/,appMasterHost=d1,startTime=1523110866265,finishTime=1523111007118,finalStatus=SUCCEEDED,memorySeconds=780015,vcoreSeconds=604,preemptedAMContainers=0,preemptedNonAMContainers=0,preemptedResources=<memory:0\, vCores:0>,applicationType=MAPREDUCE
2018-04-07 14:23:35,577 INFO org.apache.hadoop.yarn.server.resourcemanager.scheduler.fair.FairScheduler: Application appattempt_1523100158662_0003_000001 is done. finalState=FINISHED
2018-04-07 14:23:35,581 INFO org.apache.hadoop.yarn.server.resourcemanager.scheduler.AppSchedulingInfo: Application application_1523100158662_0003 requests cleared
2018-04-07 14:23:35,579 INFO org.apache.hadoop.yarn.server.resourcemanager.amlauncher.AMLauncher: Cleaning master appattempt_1523100158662_0003_000001
2018-04-07 14:31:56,746 INFO org.apache.hadoop.yarn.server.resourcemanager.ClientRMService: Allocated new applicationId: 4
2018-04-07 14:32:11,213 INFO org.apache.hadoop.yarn.server.resourcemanager.rmapp.RMAppImpl: Storing application with id application_1523100158662_0004
2018-04-07 14:32:11,215 INFO org.apache.hadoop.yarn.server.resourcemanager.rmapp.RMAppImpl: application_1523100158662_0004 State change from NEW to NEW_SAVING
2018-04-07 14:32:11,218 INFO org.apache.hadoop.yarn.server.resourcemanager.recovery.RMStateStore: Storing info for app: application_1523100158662_0004
2018-04-07 14:32:11,229 INFO org.apache.hadoop.yarn.server.resourcemanager.rmapp.RMAppImpl: application_1523100158662_0004 State change from NEW_SAVING to SUBMITTED
2018-04-07 14:32:11,233 INFO org.apache.hadoop.yarn.server.resourcemanager.scheduler.fair.FairScheduler: Accepted application application_1523100158662_0004 from user: root, in queue: default, currently num of applications: 1
2018-04-07 14:32:11,236 INFO org.apache.hadoop.yarn.server.resourcemanager.rmapp.RMAppImpl: application_1523100158662_0004 State change from SUBMITTED to ACCEPTED
2018-04-07 14:32:11,236 INFO org.apache.hadoop.yarn.server.resourcemanager.ClientRMService: Application with id 4 submitted by user root
2018-04-07 14:32:11,236 INFO org.apache.hadoop.yarn.server.resourcemanager.RMAuditLogger: USER=root	IP=172.17.0.2	OPERATION=Submit Application Request	TARGET=ClientRMService	RESULT=SUCCESS	APPID=application_1523100158662_0004
2018-04-07 14:32:11,249 INFO org.apache.hadoop.yarn.server.resourcemanager.ApplicationMasterService: Registering app attempt : appattempt_1523100158662_0004_000001
2018-04-07 14:32:11,249 INFO org.apache.hadoop.yarn.server.resourcemanager.rmapp.attempt.RMAppAttemptImpl: appattempt_1523100158662_0004_000001 State change from NEW to SUBMITTED
2018-04-07 14:32:11,250 INFO org.apache.hadoop.yarn.server.resourcemanager.scheduler.fair.FairScheduler: Added Application Attempt appattempt_1523100158662_0004_000001 to scheduler from user: root
2018-04-07 14:32:11,278 INFO org.apache.hadoop.yarn.server.resourcemanager.rmapp.attempt.RMAppAttemptImpl: appattempt_1523100158662_0004_000001 State change from SUBMITTED to SCHEDULED
2018-04-07 14:32:11,950 INFO org.apache.hadoop.yarn.server.resourcemanager.rmcontainer.RMContainerImpl: container_1523100158662_0004_01_000001 Container Transitioned from NEW to ALLOCATED
2018-04-07 14:32:11,950 INFO org.apache.hadoop.yarn.server.resourcemanager.RMAuditLogger: USER=root	OPERATION=AM Allocated Container	TARGET=SchedulerApp	RESULT=SUCCESS	APPID=application_1523100158662_0004	CONTAINERID=container_1523100158662_0004_01_000001
2018-04-07 14:32:11,950 INFO org.apache.hadoop.yarn.server.resourcemanager.scheduler.SchedulerNode: Assigned container container_1523100158662_0004_01_000001 of capacity <memory:2048, vCores:1> on host d1:59470, which has 1 containers, <memory:2048, vCores:1> used and <memory:6144, vCores:7> available after allocation
2018-04-07 14:32:11,974 INFO org.apache.hadoop.yarn.server.resourcemanager.security.NMTokenSecretManagerInRM: Sending NMToken for nodeId : d1:59470 for container : container_1523100158662_0004_01_000001
2018-04-07 14:32:11,981 INFO org.apache.hadoop.yarn.server.resourcemanager.rmcontainer.RMContainerImpl: container_1523100158662_0004_01_000001 Container Transitioned from ALLOCATED to ACQUIRED
2018-04-07 14:32:11,982 INFO org.apache.hadoop.yarn.server.resourcemanager.security.NMTokenSecretManagerInRM: Clear node set for appattempt_1523100158662_0004_000001
2018-04-07 14:32:11,982 INFO org.apache.hadoop.yarn.server.resourcemanager.rmapp.attempt.RMAppAttemptImpl: Storing attempt: AppId: application_1523100158662_0004 AttemptId: appattempt_1523100158662_0004_000001 MasterContainer: Container: [ContainerId: container_1523100158662_0004_01_000001, NodeId: d1:59470, NodeHttpAddress: d1:8042, Resource: <memory:2048, vCores:1>, Priority: 0, Token: Token { kind: ContainerToken, service: 172.17.0.2:59470 }, ]
2018-04-07 14:32:11,986 INFO org.apache.hadoop.yarn.server.resourcemanager.rmapp.attempt.RMAppAttemptImpl: appattempt_1523100158662_0004_000001 State change from SCHEDULED to ALLOCATED_SAVING
2018-04-07 14:32:11,986 INFO org.apache.hadoop.yarn.server.resourcemanager.rmapp.attempt.RMAppAttemptImpl: appattempt_1523100158662_0004_000001 State change from ALLOCATED_SAVING to ALLOCATED
2018-04-07 14:32:11,995 INFO org.apache.hadoop.yarn.server.resourcemanager.amlauncher.AMLauncher: Launching masterappattempt_1523100158662_0004_000001
2018-04-07 14:32:12,026 INFO org.apache.hadoop.yarn.server.resourcemanager.amlauncher.AMLauncher: Setting up container Container: [ContainerId: container_1523100158662_0004_01_000001, NodeId: d1:59470, NodeHttpAddress: d1:8042, Resource: <memory:2048, vCores:1>, Priority: 0, Token: Token { kind: ContainerToken, service: 172.17.0.2:59470 }, ] for AM appattempt_1523100158662_0004_000001
2018-04-07 14:32:12,033 INFO org.apache.hadoop.yarn.server.resourcemanager.amlauncher.AMLauncher: Command to launch container container_1523100158662_0004_01_000001 : $JAVA_HOME/bin/java -Dlog4j.configuration=container-log4j.properties -Dyarn.app.container.log.dir=<LOG_DIR> -Dyarn.app.container.log.filesize=0 -Dhadoop.root.logger=INFO,CLA -Dhadoop.root.logfile=syslog  -Xmx1024m org.apache.hadoop.mapreduce.v2.app.MRAppMaster 1><LOG_DIR>/stdout 2><LOG_DIR>/stderr 
2018-04-07 14:32:12,034 INFO org.apache.hadoop.yarn.server.resourcemanager.security.AMRMTokenSecretManager: Create AMRMToken for ApplicationAttempt: appattempt_1523100158662_0004_000001
2018-04-07 14:32:12,034 INFO org.apache.hadoop.yarn.server.resourcemanager.security.AMRMTokenSecretManager: Creating password for appattempt_1523100158662_0004_000001
2018-04-07 14:32:12,213 INFO org.apache.hadoop.yarn.server.resourcemanager.amlauncher.AMLauncher: Done launching container Container: [ContainerId: container_1523100158662_0004_01_000001, NodeId: d1:59470, NodeHttpAddress: d1:8042, Resource: <memory:2048, vCores:1>, Priority: 0, Token: Token { kind: ContainerToken, service: 172.17.0.2:59470 }, ] for AM appattempt_1523100158662_0004_000001
2018-04-07 14:32:12,214 INFO org.apache.hadoop.yarn.server.resourcemanager.rmapp.attempt.RMAppAttemptImpl: appattempt_1523100158662_0004_000001 State change from ALLOCATED to LAUNCHED
2018-04-07 14:32:12,976 INFO org.apache.hadoop.yarn.server.resourcemanager.rmcontainer.RMContainerImpl: container_1523100158662_0004_01_000001 Container Transitioned from ACQUIRED to RUNNING
2018-04-07 14:33:19,541 INFO SecurityLogger.org.apache.hadoop.ipc.Server: Auth successful for appattempt_1523100158662_0004_000001 (auth:SIMPLE)
2018-04-07 14:33:19,594 INFO org.apache.hadoop.yarn.server.resourcemanager.ApplicationMasterService: AM registration appattempt_1523100158662_0004_000001
2018-04-07 14:33:19,594 INFO org.apache.hadoop.yarn.server.resourcemanager.RMAuditLogger: USER=root	IP=172.17.0.2	OPERATION=Register App Master	TARGET=ApplicationMasterService	RESULT=SUCCESS	APPID=application_1523100158662_0004	APPATTEMPTID=appattempt_1523100158662_0004_000001
2018-04-07 14:33:19,595 INFO org.apache.hadoop.yarn.server.resourcemanager.rmapp.attempt.RMAppAttemptImpl: appattempt_1523100158662_0004_000001 State change from LAUNCHED to RUNNING
2018-04-07 14:33:19,596 INFO org.apache.hadoop.yarn.server.resourcemanager.rmapp.RMAppImpl: application_1523100158662_0004 State change from ACCEPTED to RUNNING
2018-04-07 14:33:24,149 INFO org.apache.hadoop.yarn.server.resourcemanager.rmcontainer.RMContainerImpl: container_1523100158662_0004_01_000002 Container Transitioned from NEW to ALLOCATED
2018-04-07 14:33:24,150 INFO org.apache.hadoop.yarn.server.resourcemanager.RMAuditLogger: USER=root	OPERATION=AM Allocated Container	TARGET=SchedulerApp	RESULT=SUCCESS	APPID=application_1523100158662_0004	CONTAINERID=container_1523100158662_0004_01_000002
2018-04-07 14:33:24,150 INFO org.apache.hadoop.yarn.server.resourcemanager.scheduler.SchedulerNode: Assigned container container_1523100158662_0004_01_000002 of capacity <memory:1024, vCores:1> on host d1:59470, which has 2 containers, <memory:3072, vCores:2> used and <memory:5120, vCores:6> available after allocation
2018-04-07 14:33:24,594 INFO org.apache.hadoop.yarn.server.resourcemanager.security.NMTokenSecretManagerInRM: Sending NMToken for nodeId : d1:59470 for container : container_1523100158662_0004_01_000002
2018-04-07 14:33:24,600 INFO org.apache.hadoop.yarn.server.resourcemanager.rmcontainer.RMContainerImpl: container_1523100158662_0004_01_000002 Container Transitioned from ALLOCATED to ACQUIRED
2018-04-07 14:33:26,114 INFO org.apache.hadoop.yarn.server.resourcemanager.scheduler.AppSchedulingInfo: checking for deactivate of application :application_1523100158662_0004
2018-04-07 14:33:27,161 INFO org.apache.hadoop.yarn.server.resourcemanager.rmcontainer.RMContainerImpl: container_1523100158662_0004_01_000002 Container Transitioned from ACQUIRED to RUNNING
2018-04-07 14:33:59,193 INFO org.apache.hadoop.yarn.server.resourcemanager.rmcontainer.RMContainerImpl: container_1523100158662_0004_01_000003 Container Transitioned from NEW to ALLOCATED
2018-04-07 14:33:59,194 INFO org.apache.hadoop.yarn.server.resourcemanager.RMAuditLogger: USER=root	OPERATION=AM Allocated Container	TARGET=SchedulerApp	RESULT=SUCCESS	APPID=application_1523100158662_0004	CONTAINERID=container_1523100158662_0004_01_000003
2018-04-07 14:33:59,202 INFO org.apache.hadoop.yarn.server.resourcemanager.scheduler.SchedulerNode: Assigned container container_1523100158662_0004_01_000003 of capacity <memory:1024, vCores:1> on host d1:59470, which has 3 containers, <memory:4096, vCores:3> used and <memory:4096, vCores:5> available after allocation
2018-04-07 14:34:00,258 INFO org.apache.hadoop.yarn.server.resourcemanager.rmcontainer.RMContainerImpl: container_1523100158662_0004_01_000002 Container Transitioned from RUNNING to COMPLETED
2018-04-07 14:34:00,258 INFO org.apache.hadoop.yarn.server.resourcemanager.scheduler.fair.FSAppAttempt: Completed container: container_1523100158662_0004_01_000002 in state: COMPLETED event:FINISHED
2018-04-07 14:34:00,314 INFO org.apache.hadoop.yarn.server.resourcemanager.RMAuditLogger: USER=root	OPERATION=AM Released Container	TARGET=SchedulerApp	RESULT=SUCCESS	APPID=application_1523100158662_0004	CONTAINERID=container_1523100158662_0004_01_000002
2018-04-07 14:34:00,340 INFO org.apache.hadoop.yarn.server.resourcemanager.scheduler.SchedulerNode: Released container container_1523100158662_0004_01_000002 of capacity <memory:1024, vCores:1> on host d1:59470, which currently has 2 containers, <memory:3072, vCores:2> used and <memory:5120, vCores:6> available, release resources=true
2018-04-07 14:34:00,400 INFO org.apache.hadoop.yarn.server.resourcemanager.scheduler.fair.FairScheduler: Application attempt appattempt_1523100158662_0004_000001 released container container_1523100158662_0004_01_000002 on node: host: d1:59470 #containers=2 available=<memory:5120, vCores:6> used=<memory:3072, vCores:2> with event: FINISHED
2018-04-07 14:34:00,472 INFO org.apache.hadoop.yarn.server.resourcemanager.rmcontainer.RMContainerImpl: container_1523100158662_0004_01_000003 Container Transitioned from ALLOCATED to ACQUIRED
2018-04-07 14:34:00,474 INFO org.apache.hadoop.yarn.server.resourcemanager.rmcontainer.RMContainerImpl: container_1523100158662_0004_01_000004 Container Transitioned from NEW to ALLOCATED
2018-04-07 14:34:00,474 INFO org.apache.hadoop.yarn.server.resourcemanager.RMAuditLogger: USER=root	OPERATION=AM Allocated Container	TARGET=SchedulerApp	RESULT=SUCCESS	APPID=application_1523100158662_0004	CONTAINERID=container_1523100158662_0004_01_000004
2018-04-07 14:34:00,474 INFO org.apache.hadoop.yarn.server.resourcemanager.scheduler.SchedulerNode: Assigned container container_1523100158662_0004_01_000004 of capacity <memory:1024, vCores:1> on host d1:59470, which has 3 containers, <memory:4096, vCores:3> used and <memory:4096, vCores:5> available after allocation
2018-04-07 14:34:01,272 INFO org.apache.hadoop.yarn.server.resourcemanager.rmcontainer.RMContainerImpl: container_1523100158662_0004_01_000003 Container Transitioned from ACQUIRED to RUNNING
2018-04-07 14:34:01,273 INFO org.apache.hadoop.yarn.server.resourcemanager.rmcontainer.RMContainerImpl: container_1523100158662_0004_01_000005 Container Transitioned from NEW to ALLOCATED
2018-04-07 14:34:01,273 INFO org.apache.hadoop.yarn.server.resourcemanager.RMAuditLogger: USER=root	OPERATION=AM Allocated Container	TARGET=SchedulerApp	RESULT=SUCCESS	APPID=application_1523100158662_0004	CONTAINERID=container_1523100158662_0004_01_000005
2018-04-07 14:34:01,273 INFO org.apache.hadoop.yarn.server.resourcemanager.scheduler.SchedulerNode: Assigned container container_1523100158662_0004_01_000005 of capacity <memory:1024, vCores:1> on host d1:59470, which has 4 containers, <memory:5120, vCores:4> used and <memory:3072, vCores:4> available after allocation
2018-04-07 14:34:01,623 INFO org.apache.hadoop.yarn.server.resourcemanager.rmcontainer.RMContainerImpl: container_1523100158662_0004_01_000004 Container Transitioned from ALLOCATED to ACQUIRED
2018-04-07 14:34:01,637 INFO org.apache.hadoop.yarn.server.resourcemanager.rmcontainer.RMContainerImpl: container_1523100158662_0004_01_000005 Container Transitioned from ALLOCATED to ACQUIRED
2018-04-07 14:34:02,315 INFO org.apache.hadoop.yarn.server.resourcemanager.rmcontainer.RMContainerImpl: container_1523100158662_0004_01_000006 Container Transitioned from NEW to ALLOCATED
2018-04-07 14:34:02,315 INFO org.apache.hadoop.yarn.server.resourcemanager.RMAuditLogger: USER=root	OPERATION=AM Allocated Container	TARGET=SchedulerApp	RESULT=SUCCESS	APPID=application_1523100158662_0004	CONTAINERID=container_1523100158662_0004_01_000006
2018-04-07 14:34:02,315 INFO org.apache.hadoop.yarn.server.resourcemanager.scheduler.SchedulerNode: Assigned container container_1523100158662_0004_01_000006 of capacity <memory:1024, vCores:1> on host d1:59470, which has 5 containers, <memory:6144, vCores:5> used and <memory:2048, vCores:3> available after allocation
2018-04-07 14:34:02,764 INFO org.apache.hadoop.yarn.server.resourcemanager.rmcontainer.RMContainerImpl: container_1523100158662_0004_01_000006 Container Transitioned from ALLOCATED to ACQUIRED
2018-04-07 14:34:03,637 INFO org.apache.hadoop.yarn.server.resourcemanager.rmcontainer.RMContainerImpl: container_1523100158662_0004_01_000004 Container Transitioned from ACQUIRED to RUNNING
2018-04-07 14:34:03,669 INFO org.apache.hadoop.yarn.server.resourcemanager.rmcontainer.RMContainerImpl: container_1523100158662_0004_01_000005 Container Transitioned from ACQUIRED to RUNNING
2018-04-07 14:34:03,686 INFO org.apache.hadoop.yarn.server.resourcemanager.rmcontainer.RMContainerImpl: container_1523100158662_0004_01_000006 Container Transitioned from ACQUIRED to RUNNING
2018-04-07 14:34:03,705 INFO org.apache.hadoop.yarn.server.resourcemanager.rmcontainer.RMContainerImpl: container_1523100158662_0004_01_000007 Container Transitioned from NEW to ALLOCATED
2018-04-07 14:34:03,705 INFO org.apache.hadoop.yarn.server.resourcemanager.RMAuditLogger: USER=root	OPERATION=AM Allocated Container	TARGET=SchedulerApp	RESULT=SUCCESS	APPID=application_1523100158662_0004	CONTAINERID=container_1523100158662_0004_01_000007
2018-04-07 14:34:03,705 INFO org.apache.hadoop.yarn.server.resourcemanager.scheduler.SchedulerNode: Assigned container container_1523100158662_0004_01_000007 of capacity <memory:1024, vCores:1> on host d1:59470, which has 6 containers, <memory:7168, vCores:6> used and <memory:1024, vCores:2> available after allocation
2018-04-07 14:34:03,822 INFO org.apache.hadoop.yarn.server.resourcemanager.rmcontainer.RMContainerImpl: container_1523100158662_0004_01_000007 Container Transitioned from ALLOCATED to ACQUIRED
2018-04-07 14:34:04,654 INFO org.apache.hadoop.yarn.server.resourcemanager.rmcontainer.RMContainerImpl: container_1523100158662_0004_01_000007 Container Transitioned from ACQUIRED to RUNNING
2018-04-07 14:34:04,659 INFO org.apache.hadoop.yarn.server.resourcemanager.rmcontainer.RMContainerImpl: container_1523100158662_0004_01_000008 Container Transitioned from NEW to ALLOCATED
2018-04-07 14:34:04,659 INFO org.apache.hadoop.yarn.server.resourcemanager.RMAuditLogger: USER=root	OPERATION=AM Allocated Container	TARGET=SchedulerApp	RESULT=SUCCESS	APPID=application_1523100158662_0004	CONTAINERID=container_1523100158662_0004_01_000008
2018-04-07 14:34:04,673 INFO org.apache.hadoop.yarn.server.resourcemanager.scheduler.SchedulerNode: Assigned container container_1523100158662_0004_01_000008 of capacity <memory:1024, vCores:1> on host d1:59470, which has 7 containers, <memory:8192, vCores:7> used and <memory:0, vCores:1> available after allocation
2018-04-07 14:34:04,899 INFO org.apache.hadoop.yarn.server.resourcemanager.rmcontainer.RMContainerImpl: container_1523100158662_0004_01_000008 Container Transitioned from ALLOCATED to ACQUIRED
2018-04-07 14:34:05,691 INFO org.apache.hadoop.yarn.server.resourcemanager.rmcontainer.RMContainerImpl: container_1523100158662_0004_01_000008 Container Transitioned from ACQUIRED to RUNNING
2018-04-07 14:34:05,691 INFO org.apache.hadoop.yarn.server.resourcemanager.scheduler.fair.FSAppAttempt: Making reservation: node=d1 app_id=application_1523100158662_0004
2018-04-07 14:34:05,692 INFO org.apache.hadoop.yarn.server.resourcemanager.rmcontainer.RMContainerImpl: container_1523100158662_0004_01_000009 Container Transitioned from NEW to RESERVED
2018-04-07 14:34:05,692 INFO org.apache.hadoop.yarn.server.resourcemanager.scheduler.fair.FSSchedulerNode: Reserved container container_1523100158662_0004_01_000009 on node host: d1:59470 #containers=7 available=<memory:0, vCores:1> used=<memory:8192, vCores:7> for application org.apache.hadoop.yarn.server.resourcemanager.scheduler.fair.FSAppAttempt@6e78f187
2018-04-07 14:35:22,194 INFO org.apache.hadoop.yarn.server.resourcemanager.rmcontainer.RMContainerImpl: container_1523100158662_0004_01_000003 Container Transitioned from RUNNING to COMPLETED
2018-04-07 14:35:22,194 INFO org.apache.hadoop.yarn.server.resourcemanager.scheduler.fair.FSAppAttempt: Completed container: container_1523100158662_0004_01_000003 in state: COMPLETED event:FINISHED
2018-04-07 14:35:22,194 INFO org.apache.hadoop.yarn.server.resourcemanager.RMAuditLogger: USER=root	OPERATION=AM Released Container	TARGET=SchedulerApp	RESULT=SUCCESS	APPID=application_1523100158662_0004	CONTAINERID=container_1523100158662_0004_01_000003
2018-04-07 14:35:22,194 INFO org.apache.hadoop.yarn.server.resourcemanager.scheduler.SchedulerNode: Released container container_1523100158662_0004_01_000003 of capacity <memory:1024, vCores:1> on host d1:59470, which currently has 6 containers, <memory:7168, vCores:6> used and <memory:1024, vCores:2> available, release resources=true
2018-04-07 14:35:22,194 INFO org.apache.hadoop.yarn.server.resourcemanager.scheduler.fair.FairScheduler: Application attempt appattempt_1523100158662_0004_000001 released container container_1523100158662_0004_01_000003 on node: host: d1:59470 #containers=6 available=<memory:1024, vCores:2> used=<memory:7168, vCores:6> with event: FINISHED
2018-04-07 14:35:22,195 INFO org.apache.hadoop.yarn.server.resourcemanager.rmcontainer.RMContainerImpl: container_1523100158662_0004_01_000009 Container Transitioned from NEW to ALLOCATED
2018-04-07 14:35:22,195 INFO org.apache.hadoop.yarn.server.resourcemanager.RMAuditLogger: USER=root	OPERATION=AM Allocated Container	TARGET=SchedulerApp	RESULT=SUCCESS	APPID=application_1523100158662_0004	CONTAINERID=container_1523100158662_0004_01_000009
2018-04-07 14:35:22,195 INFO org.apache.hadoop.yarn.server.resourcemanager.scheduler.fair.FSAppAttempt: Application application_1523100158662_0004 unreserved  on node host: d1:59470 #containers=6 available=<memory:1024, vCores:2> used=<memory:7168, vCores:6>, currently has 0 at priority 10; currentReservation <memory:0, vCores:0>
2018-04-07 14:35:22,195 INFO org.apache.hadoop.yarn.server.resourcemanager.scheduler.SchedulerNode: Assigned container container_1523100158662_0004_01_000009 of capacity <memory:1024, vCores:1> on host d1:59470, which has 7 containers, <memory:8192, vCores:7> used and <memory:0, vCores:1> available after allocation
2018-04-07 14:35:22,584 INFO org.apache.hadoop.yarn.server.resourcemanager.rmcontainer.RMContainerImpl: container_1523100158662_0004_01_000009 Container Transitioned from ALLOCATED to ACQUIRED
2018-04-07 14:35:23,198 INFO org.apache.hadoop.yarn.server.resourcemanager.rmcontainer.RMContainerImpl: container_1523100158662_0004_01_000009 Container Transitioned from ACQUIRED to RUNNING
2018-04-07 14:35:23,198 INFO org.apache.hadoop.yarn.server.resourcemanager.scheduler.fair.FSAppAttempt: Making reservation: node=d1 app_id=application_1523100158662_0004
2018-04-07 14:35:23,198 INFO org.apache.hadoop.yarn.server.resourcemanager.rmcontainer.RMContainerImpl: container_1523100158662_0004_01_000010 Container Transitioned from NEW to RESERVED
2018-04-07 14:35:23,198 INFO org.apache.hadoop.yarn.server.resourcemanager.scheduler.fair.FSSchedulerNode: Reserved container container_1523100158662_0004_01_000010 on node host: d1:59470 #containers=7 available=<memory:0, vCores:1> used=<memory:8192, vCores:7> for application org.apache.hadoop.yarn.server.resourcemanager.scheduler.fair.FSAppAttempt@6e78f187
2018-04-07 14:35:27,105 INFO org.apache.hadoop.yarn.server.resourcemanager.rmcontainer.RMContainerImpl: container_1523100158662_0004_01_000004 Container Transitioned from RUNNING to COMPLETED
2018-04-07 14:35:27,105 INFO org.apache.hadoop.yarn.server.resourcemanager.scheduler.fair.FSAppAttempt: Completed container: container_1523100158662_0004_01_000004 in state: COMPLETED event:FINISHED
2018-04-07 14:35:27,105 INFO org.apache.hadoop.yarn.server.resourcemanager.RMAuditLogger: USER=root	OPERATION=AM Released Container	TARGET=SchedulerApp	RESULT=SUCCESS	APPID=application_1523100158662_0004	CONTAINERID=container_1523100158662_0004_01_000004
2018-04-07 14:35:27,105 INFO org.apache.hadoop.yarn.server.resourcemanager.scheduler.SchedulerNode: Released container container_1523100158662_0004_01_000004 of capacity <memory:1024, vCores:1> on host d1:59470, which currently has 6 containers, <memory:7168, vCores:6> used and <memory:1024, vCores:2> available, release resources=true
2018-04-07 14:35:27,105 INFO org.apache.hadoop.yarn.server.resourcemanager.scheduler.fair.FairScheduler: Application attempt appattempt_1523100158662_0004_000001 released container container_1523100158662_0004_01_000004 on node: host: d1:59470 #containers=6 available=<memory:1024, vCores:2> used=<memory:7168, vCores:6> with event: FINISHED
2018-04-07 14:35:27,110 INFO org.apache.hadoop.yarn.server.resourcemanager.rmcontainer.RMContainerImpl: container_1523100158662_0004_01_000005 Container Transitioned from RUNNING to COMPLETED
2018-04-07 14:35:27,111 INFO org.apache.hadoop.yarn.server.resourcemanager.scheduler.fair.FSAppAttempt: Completed container: container_1523100158662_0004_01_000005 in state: COMPLETED event:FINISHED
2018-04-07 14:35:27,111 INFO org.apache.hadoop.yarn.server.resourcemanager.RMAuditLogger: USER=root	OPERATION=AM Released Container	TARGET=SchedulerApp	RESULT=SUCCESS	APPID=application_1523100158662_0004	CONTAINERID=container_1523100158662_0004_01_000005
2018-04-07 14:35:27,112 INFO org.apache.hadoop.yarn.server.resourcemanager.scheduler.SchedulerNode: Released container container_1523100158662_0004_01_000005 of capacity <memory:1024, vCores:1> on host d1:59470, which currently has 5 containers, <memory:6144, vCores:5> used and <memory:2048, vCores:3> available, release resources=true
2018-04-07 14:35:27,112 INFO org.apache.hadoop.yarn.server.resourcemanager.scheduler.fair.FairScheduler: Application attempt appattempt_1523100158662_0004_000001 released container container_1523100158662_0004_01_000005 on node: host: d1:59470 #containers=5 available=<memory:2048, vCores:3> used=<memory:6144, vCores:5> with event: FINISHED
2018-04-07 14:35:27,112 INFO org.apache.hadoop.yarn.server.resourcemanager.rmcontainer.RMContainerImpl: container_1523100158662_0004_01_000010 Container Transitioned from NEW to ALLOCATED
2018-04-07 14:35:27,112 INFO org.apache.hadoop.yarn.server.resourcemanager.RMAuditLogger: USER=root	OPERATION=AM Allocated Container	TARGET=SchedulerApp	RESULT=SUCCESS	APPID=application_1523100158662_0004	CONTAINERID=container_1523100158662_0004_01_000010
2018-04-07 14:35:27,113 INFO org.apache.hadoop.yarn.server.resourcemanager.scheduler.fair.FSAppAttempt: Application application_1523100158662_0004 unreserved  on node host: d1:59470 #containers=5 available=<memory:2048, vCores:3> used=<memory:6144, vCores:5>, currently has 0 at priority 10; currentReservation <memory:0, vCores:0>
2018-04-07 14:35:27,113 INFO org.apache.hadoop.yarn.server.resourcemanager.scheduler.SchedulerNode: Assigned container container_1523100158662_0004_01_000010 of capacity <memory:1024, vCores:1> on host d1:59470, which has 6 containers, <memory:7168, vCores:6> used and <memory:1024, vCores:2> available after allocation
2018-04-07 14:35:27,585 INFO org.apache.hadoop.yarn.server.resourcemanager.rmcontainer.RMContainerImpl: container_1523100158662_0004_01_000011 Container Transitioned from NEW to ALLOCATED
2018-04-07 14:35:27,585 INFO org.apache.hadoop.yarn.server.resourcemanager.RMAuditLogger: USER=root	OPERATION=AM Allocated Container	TARGET=SchedulerApp	RESULT=SUCCESS	APPID=application_1523100158662_0004	CONTAINERID=container_1523100158662_0004_01_000011
2018-04-07 14:35:27,585 INFO org.apache.hadoop.yarn.server.resourcemanager.scheduler.SchedulerNode: Assigned container container_1523100158662_0004_01_000011 of capacity <memory:1024, vCores:1> on host d1:59470, which has 7 containers, <memory:8192, vCores:7> used and <memory:0, vCores:1> available after allocation
2018-04-07 14:35:27,662 INFO org.apache.hadoop.yarn.server.resourcemanager.rmcontainer.RMContainerImpl: container_1523100158662_0004_01_000010 Container Transitioned from ALLOCATED to ACQUIRED
2018-04-07 14:35:27,673 INFO org.apache.hadoop.yarn.server.resourcemanager.rmcontainer.RMContainerImpl: container_1523100158662_0004_01_000011 Container Transitioned from ALLOCATED to ACQUIRED
2018-04-07 14:35:28,628 INFO org.apache.hadoop.yarn.server.resourcemanager.rmcontainer.RMContainerImpl: container_1523100158662_0004_01_000010 Container Transitioned from ACQUIRED to RUNNING
2018-04-07 14:35:28,640 INFO org.apache.hadoop.yarn.server.resourcemanager.rmcontainer.RMContainerImpl: container_1523100158662_0004_01_000011 Container Transitioned from ACQUIRED to RUNNING
2018-04-07 14:35:28,640 INFO org.apache.hadoop.yarn.server.resourcemanager.scheduler.fair.FSAppAttempt: Making reservation: node=d1 app_id=application_1523100158662_0004
2018-04-07 14:35:28,640 INFO org.apache.hadoop.yarn.server.resourcemanager.rmcontainer.RMContainerImpl: container_1523100158662_0004_01_000012 Container Transitioned from NEW to RESERVED
2018-04-07 14:35:28,640 INFO org.apache.hadoop.yarn.server.resourcemanager.scheduler.fair.FSSchedulerNode: Reserved container container_1523100158662_0004_01_000012 on node host: d1:59470 #containers=7 available=<memory:0, vCores:1> used=<memory:8192, vCores:7> for application org.apache.hadoop.yarn.server.resourcemanager.scheduler.fair.FSAppAttempt@6e78f187
2018-04-07 14:35:29,622 INFO org.apache.hadoop.yarn.server.resourcemanager.rmcontainer.RMContainerImpl: container_1523100158662_0004_01_000006 Container Transitioned from RUNNING to COMPLETED
2018-04-07 14:35:29,623 INFO org.apache.hadoop.yarn.server.resourcemanager.scheduler.fair.FSAppAttempt: Completed container: container_1523100158662_0004_01_000006 in state: COMPLETED event:FINISHED
2018-04-07 14:35:29,623 INFO org.apache.hadoop.yarn.server.resourcemanager.RMAuditLogger: USER=root	OPERATION=AM Released Container	TARGET=SchedulerApp	RESULT=SUCCESS	APPID=application_1523100158662_0004	CONTAINERID=container_1523100158662_0004_01_000006
2018-04-07 14:35:29,632 INFO org.apache.hadoop.yarn.server.resourcemanager.scheduler.SchedulerNode: Released container container_1523100158662_0004_01_000006 of capacity <memory:1024, vCores:1> on host d1:59470, which currently has 6 containers, <memory:7168, vCores:6> used and <memory:1024, vCores:2> available, release resources=true
2018-04-07 14:35:29,632 INFO org.apache.hadoop.yarn.server.resourcemanager.scheduler.fair.FairScheduler: Application attempt appattempt_1523100158662_0004_000001 released container container_1523100158662_0004_01_000006 on node: host: d1:59470 #containers=6 available=<memory:1024, vCores:2> used=<memory:7168, vCores:6> with event: FINISHED
2018-04-07 14:35:29,633 INFO org.apache.hadoop.yarn.server.resourcemanager.rmcontainer.RMContainerImpl: container_1523100158662_0004_01_000012 Container Transitioned from NEW to ALLOCATED
2018-04-07 14:35:29,633 INFO org.apache.hadoop.yarn.server.resourcemanager.RMAuditLogger: USER=root	OPERATION=AM Allocated Container	TARGET=SchedulerApp	RESULT=SUCCESS	APPID=application_1523100158662_0004	CONTAINERID=container_1523100158662_0004_01_000012
2018-04-07 14:35:29,633 INFO org.apache.hadoop.yarn.server.resourcemanager.scheduler.fair.FSAppAttempt: Application application_1523100158662_0004 unreserved  on node host: d1:59470 #containers=6 available=<memory:1024, vCores:2> used=<memory:7168, vCores:6>, currently has 0 at priority 10; currentReservation <memory:0, vCores:0>
2018-04-07 14:35:29,633 INFO org.apache.hadoop.yarn.server.resourcemanager.scheduler.SchedulerNode: Assigned container container_1523100158662_0004_01_000012 of capacity <memory:1024, vCores:1> on host d1:59470, which has 7 containers, <memory:8192, vCores:7> used and <memory:0, vCores:1> available after allocation
2018-04-07 14:35:29,691 INFO org.apache.hadoop.yarn.server.resourcemanager.rmcontainer.RMContainerImpl: container_1523100158662_0004_01_000012 Container Transitioned from ALLOCATED to ACQUIRED
2018-04-07 14:35:30,638 INFO org.apache.hadoop.yarn.server.resourcemanager.rmcontainer.RMContainerImpl: container_1523100158662_0004_01_000012 Container Transitioned from ACQUIRED to RUNNING
2018-04-07 14:35:30,773 INFO org.apache.hadoop.yarn.server.resourcemanager.scheduler.AppSchedulingInfo: checking for deactivate of application :application_1523100158662_0004
2018-04-07 14:35:32,481 INFO org.apache.hadoop.yarn.server.resourcemanager.rmcontainer.RMContainerImpl: container_1523100158662_0004_01_000007 Container Transitioned from RUNNING to COMPLETED
2018-04-07 14:35:32,481 INFO org.apache.hadoop.yarn.server.resourcemanager.scheduler.fair.FSAppAttempt: Completed container: container_1523100158662_0004_01_000007 in state: COMPLETED event:FINISHED
2018-04-07 14:35:32,481 INFO org.apache.hadoop.yarn.server.resourcemanager.RMAuditLogger: USER=root	OPERATION=AM Released Container	TARGET=SchedulerApp	RESULT=SUCCESS	APPID=application_1523100158662_0004	CONTAINERID=container_1523100158662_0004_01_000007
2018-04-07 14:35:32,481 INFO org.apache.hadoop.yarn.server.resourcemanager.scheduler.SchedulerNode: Released container container_1523100158662_0004_01_000007 of capacity <memory:1024, vCores:1> on host d1:59470, which currently has 6 containers, <memory:7168, vCores:6> used and <memory:1024, vCores:2> available, release resources=true
2018-04-07 14:35:32,481 INFO org.apache.hadoop.yarn.server.resourcemanager.scheduler.fair.FairScheduler: Application attempt appattempt_1523100158662_0004_000001 released container container_1523100158662_0004_01_000007 on node: host: d1:59470 #containers=6 available=<memory:1024, vCores:2> used=<memory:7168, vCores:6> with event: FINISHED
2018-04-07 14:35:32,482 INFO org.apache.hadoop.yarn.server.resourcemanager.rmcontainer.RMContainerImpl: container_1523100158662_0004_01_000008 Container Transitioned from RUNNING to COMPLETED
2018-04-07 14:35:32,482 INFO org.apache.hadoop.yarn.server.resourcemanager.scheduler.fair.FSAppAttempt: Completed container: container_1523100158662_0004_01_000008 in state: COMPLETED event:FINISHED
2018-04-07 14:35:32,482 INFO org.apache.hadoop.yarn.server.resourcemanager.RMAuditLogger: USER=root	OPERATION=AM Released Container	TARGET=SchedulerApp	RESULT=SUCCESS	APPID=application_1523100158662_0004	CONTAINERID=container_1523100158662_0004_01_000008
2018-04-07 14:35:32,482 INFO org.apache.hadoop.yarn.server.resourcemanager.scheduler.SchedulerNode: Released container container_1523100158662_0004_01_000008 of capacity <memory:1024, vCores:1> on host d1:59470, which currently has 5 containers, <memory:6144, vCores:5> used and <memory:2048, vCores:3> available, release resources=true
2018-04-07 14:35:32,482 INFO org.apache.hadoop.yarn.server.resourcemanager.scheduler.fair.FairScheduler: Application attempt appattempt_1523100158662_0004_000001 released container container_1523100158662_0004_01_000008 on node: host: d1:59470 #containers=5 available=<memory:2048, vCores:3> used=<memory:6144, vCores:5> with event: FINISHED
2018-04-07 14:35:42,545 INFO org.apache.hadoop.yarn.server.resourcemanager.rmcontainer.RMContainerImpl: container_1523100158662_0004_01_000013 Container Transitioned from NEW to ALLOCATED
2018-04-07 14:35:42,545 INFO org.apache.hadoop.yarn.server.resourcemanager.RMAuditLogger: USER=root	OPERATION=AM Allocated Container	TARGET=SchedulerApp	RESULT=SUCCESS	APPID=application_1523100158662_0004	CONTAINERID=container_1523100158662_0004_01_000013
2018-04-07 14:35:42,545 INFO org.apache.hadoop.yarn.server.resourcemanager.scheduler.SchedulerNode: Assigned container container_1523100158662_0004_01_000013 of capacity <memory:1024, vCores:1> on host d1:59470, which has 6 containers, <memory:7168, vCores:6> used and <memory:1024, vCores:2> available after allocation
2018-04-07 14:35:42,828 INFO org.apache.hadoop.yarn.server.resourcemanager.rmcontainer.RMContainerImpl: container_1523100158662_0004_01_000013 Container Transitioned from ALLOCATED to ACQUIRED
2018-04-07 14:35:43,552 INFO org.apache.hadoop.yarn.server.resourcemanager.rmcontainer.RMContainerImpl: container_1523100158662_0004_01_000013 Container Transitioned from ACQUIRED to RUNNING
2018-04-07 14:35:43,886 INFO org.apache.hadoop.yarn.server.resourcemanager.scheduler.AppSchedulingInfo: checking for deactivate of application :application_1523100158662_0004
2018-04-07 14:35:56,939 INFO org.apache.hadoop.yarn.server.resourcemanager.rmcontainer.RMContainerImpl: container_1523100158662_0004_01_000014 Container Transitioned from NEW to ALLOCATED
2018-04-07 14:35:56,940 INFO org.apache.hadoop.yarn.server.resourcemanager.RMAuditLogger: USER=root	OPERATION=AM Allocated Container	TARGET=SchedulerApp	RESULT=SUCCESS	APPID=application_1523100158662_0004	CONTAINERID=container_1523100158662_0004_01_000014
2018-04-07 14:35:56,940 INFO org.apache.hadoop.yarn.server.resourcemanager.scheduler.SchedulerNode: Assigned container container_1523100158662_0004_01_000014 of capacity <memory:1024, vCores:1> on host d1:59470, which has 7 containers, <memory:8192, vCores:7> used and <memory:0, vCores:1> available after allocation
2018-04-07 14:35:57,400 INFO org.apache.hadoop.yarn.server.resourcemanager.rmcontainer.RMContainerImpl: container_1523100158662_0004_01_000014 Container Transitioned from ALLOCATED to ACQUIRED
2018-04-07 14:35:57,946 INFO org.apache.hadoop.yarn.server.resourcemanager.rmcontainer.RMContainerImpl: container_1523100158662_0004_01_000014 Container Transitioned from ACQUIRED to RUNNING
2018-04-07 14:35:58,410 INFO org.apache.hadoop.yarn.server.resourcemanager.scheduler.AppSchedulingInfo: checking for deactivate of application :application_1523100158662_0004
2018-04-07 14:36:11,992 INFO org.apache.hadoop.yarn.server.resourcemanager.scheduler.fair.FSAppAttempt: Making reservation: node=d1 app_id=application_1523100158662_0004
2018-04-07 14:36:11,992 INFO org.apache.hadoop.yarn.server.resourcemanager.rmcontainer.RMContainerImpl: container_1523100158662_0004_01_000015 Container Transitioned from NEW to RESERVED
2018-04-07 14:36:11,992 INFO org.apache.hadoop.yarn.server.resourcemanager.scheduler.fair.FSSchedulerNode: Reserved container container_1523100158662_0004_01_000015 on node host: d1:59470 #containers=7 available=<memory:0, vCores:1> used=<memory:8192, vCores:7> for application org.apache.hadoop.yarn.server.resourcemanager.scheduler.fair.FSAppAttempt@6e78f187
2018-04-07 14:36:18,210 INFO org.apache.hadoop.yarn.server.resourcemanager.rmcontainer.RMContainerImpl: container_1523100158662_0004_01_000009 Container Transitioned from RUNNING to COMPLETED
2018-04-07 14:36:18,210 INFO org.apache.hadoop.yarn.server.resourcemanager.scheduler.fair.FSAppAttempt: Completed container: container_1523100158662_0004_01_000009 in state: COMPLETED event:FINISHED
2018-04-07 14:36:18,210 INFO org.apache.hadoop.yarn.server.resourcemanager.RMAuditLogger: USER=root	OPERATION=AM Released Container	TARGET=SchedulerApp	RESULT=SUCCESS	APPID=application_1523100158662_0004	CONTAINERID=container_1523100158662_0004_01_000009
2018-04-07 14:36:18,210 INFO org.apache.hadoop.yarn.server.resourcemanager.scheduler.SchedulerNode: Released container container_1523100158662_0004_01_000009 of capacity <memory:1024, vCores:1> on host d1:59470, which currently has 6 containers, <memory:7168, vCores:6> used and <memory:1024, vCores:2> available, release resources=true
2018-04-07 14:36:18,211 INFO org.apache.hadoop.yarn.server.resourcemanager.scheduler.fair.FairScheduler: Application attempt appattempt_1523100158662_0004_000001 released container container_1523100158662_0004_01_000009 on node: host: d1:59470 #containers=6 available=<memory:1024, vCores:2> used=<memory:7168, vCores:6> with event: FINISHED
2018-04-07 14:36:18,213 INFO org.apache.hadoop.yarn.server.resourcemanager.rmcontainer.RMContainerImpl: container_1523100158662_0004_01_000013 Container Transitioned from RUNNING to COMPLETED
2018-04-07 14:36:18,213 INFO org.apache.hadoop.yarn.server.resourcemanager.scheduler.fair.FSAppAttempt: Completed container: container_1523100158662_0004_01_000013 in state: COMPLETED event:FINISHED
2018-04-07 14:36:18,213 INFO org.apache.hadoop.yarn.server.resourcemanager.RMAuditLogger: USER=root	OPERATION=AM Released Container	TARGET=SchedulerApp	RESULT=SUCCESS	APPID=application_1523100158662_0004	CONTAINERID=container_1523100158662_0004_01_000013
2018-04-07 14:36:18,213 INFO org.apache.hadoop.yarn.server.resourcemanager.scheduler.SchedulerNode: Released container container_1523100158662_0004_01_000013 of capacity <memory:1024, vCores:1> on host d1:59470, which currently has 5 containers, <memory:6144, vCores:5> used and <memory:2048, vCores:3> available, release resources=true
2018-04-07 14:36:18,213 INFO org.apache.hadoop.yarn.server.resourcemanager.scheduler.fair.FairScheduler: Application attempt appattempt_1523100158662_0004_000001 released container container_1523100158662_0004_01_000013 on node: host: d1:59470 #containers=5 available=<memory:2048, vCores:3> used=<memory:6144, vCores:5> with event: FINISHED
2018-04-07 14:36:18,214 INFO org.apache.hadoop.yarn.server.resourcemanager.rmcontainer.RMContainerImpl: container_1523100158662_0004_01_000015 Container Transitioned from NEW to ALLOCATED
2018-04-07 14:36:18,214 INFO org.apache.hadoop.yarn.server.resourcemanager.RMAuditLogger: USER=root	OPERATION=AM Allocated Container	TARGET=SchedulerApp	RESULT=SUCCESS	APPID=application_1523100158662_0004	CONTAINERID=container_1523100158662_0004_01_000015
2018-04-07 14:36:18,214 INFO org.apache.hadoop.yarn.server.resourcemanager.scheduler.fair.FSAppAttempt: Application application_1523100158662_0004 unreserved  on node host: d1:59470 #containers=5 available=<memory:2048, vCores:3> used=<memory:6144, vCores:5>, currently has 0 at priority 10; currentReservation <memory:0, vCores:0>
2018-04-07 14:36:18,214 INFO org.apache.hadoop.yarn.server.resourcemanager.scheduler.SchedulerNode: Assigned container container_1523100158662_0004_01_000015 of capacity <memory:1024, vCores:1> on host d1:59470, which has 6 containers, <memory:7168, vCores:6> used and <memory:1024, vCores:2> available after allocation
2018-04-07 14:36:18,516 INFO org.apache.hadoop.yarn.server.resourcemanager.scheduler.AppSchedulingInfo: checking for deactivate of application :application_1523100158662_0004
2018-04-07 14:36:18,518 INFO org.apache.hadoop.yarn.server.resourcemanager.rmcontainer.RMContainerImpl: container_1523100158662_0004_01_000015 Container Transitioned from ALLOCATED to ACQUIRED
2018-04-07 14:36:19,072 INFO org.apache.hadoop.yarn.server.resourcemanager.rmcontainer.RMContainerImpl: container_1523100158662_0004_01_000011 Container Transitioned from RUNNING to COMPLETED
2018-04-07 14:36:19,072 INFO org.apache.hadoop.yarn.server.resourcemanager.scheduler.fair.FSAppAttempt: Completed container: container_1523100158662_0004_01_000011 in state: COMPLETED event:FINISHED
2018-04-07 14:36:19,072 INFO org.apache.hadoop.yarn.server.resourcemanager.RMAuditLogger: USER=root	OPERATION=AM Released Container	TARGET=SchedulerApp	RESULT=SUCCESS	APPID=application_1523100158662_0004	CONTAINERID=container_1523100158662_0004_01_000011
2018-04-07 14:36:19,072 INFO org.apache.hadoop.yarn.server.resourcemanager.scheduler.SchedulerNode: Released container container_1523100158662_0004_01_000011 of capacity <memory:1024, vCores:1> on host d1:59470, which currently has 5 containers, <memory:6144, vCores:5> used and <memory:2048, vCores:3> available, release resources=true
2018-04-07 14:36:19,072 INFO org.apache.hadoop.yarn.server.resourcemanager.scheduler.fair.FairScheduler: Application attempt appattempt_1523100158662_0004_000001 released container container_1523100158662_0004_01_000011 on node: host: d1:59470 #containers=5 available=<memory:2048, vCores:3> used=<memory:6144, vCores:5> with event: FINISHED
2018-04-07 14:36:19,495 INFO org.apache.hadoop.yarn.server.resourcemanager.rmcontainer.RMContainerImpl: container_1523100158662_0004_01_000014 Container Transitioned from RUNNING to COMPLETED
2018-04-07 14:36:19,495 INFO org.apache.hadoop.yarn.server.resourcemanager.scheduler.fair.FSAppAttempt: Completed container: container_1523100158662_0004_01_000014 in state: COMPLETED event:FINISHED
2018-04-07 14:36:19,495 INFO org.apache.hadoop.yarn.server.resourcemanager.RMAuditLogger: USER=root	OPERATION=AM Released Container	TARGET=SchedulerApp	RESULT=SUCCESS	APPID=application_1523100158662_0004	CONTAINERID=container_1523100158662_0004_01_000014
2018-04-07 14:36:19,495 INFO org.apache.hadoop.yarn.server.resourcemanager.scheduler.SchedulerNode: Released container container_1523100158662_0004_01_000014 of capacity <memory:1024, vCores:1> on host d1:59470, which currently has 4 containers, <memory:5120, vCores:4> used and <memory:3072, vCores:4> available, release resources=true
2018-04-07 14:36:19,495 INFO org.apache.hadoop.yarn.server.resourcemanager.scheduler.fair.FairScheduler: Application attempt appattempt_1523100158662_0004_000001 released container container_1523100158662_0004_01_000014 on node: host: d1:59470 #containers=4 available=<memory:3072, vCores:4> used=<memory:5120, vCores:4> with event: FINISHED
2018-04-07 14:36:19,496 INFO org.apache.hadoop.yarn.server.resourcemanager.rmcontainer.RMContainerImpl: container_1523100158662_0004_01_000010 Container Transitioned from RUNNING to COMPLETED
2018-04-07 14:36:19,496 INFO org.apache.hadoop.yarn.server.resourcemanager.scheduler.fair.FSAppAttempt: Completed container: container_1523100158662_0004_01_000010 in state: COMPLETED event:FINISHED
2018-04-07 14:36:19,496 INFO org.apache.hadoop.yarn.server.resourcemanager.RMAuditLogger: USER=root	OPERATION=AM Released Container	TARGET=SchedulerApp	RESULT=SUCCESS	APPID=application_1523100158662_0004	CONTAINERID=container_1523100158662_0004_01_000010
2018-04-07 14:36:19,496 INFO org.apache.hadoop.yarn.server.resourcemanager.scheduler.SchedulerNode: Released container container_1523100158662_0004_01_000010 of capacity <memory:1024, vCores:1> on host d1:59470, which currently has 3 containers, <memory:4096, vCores:3> used and <memory:4096, vCores:5> available, release resources=true
2018-04-07 14:36:19,496 INFO org.apache.hadoop.yarn.server.resourcemanager.scheduler.fair.FairScheduler: Application attempt appattempt_1523100158662_0004_000001 released container container_1523100158662_0004_01_000010 on node: host: d1:59470 #containers=3 available=<memory:4096, vCores:5> used=<memory:4096, vCores:3> with event: FINISHED
2018-04-07 14:36:19,524 INFO org.apache.hadoop.yarn.server.resourcemanager.rmcontainer.RMContainerImpl: container_1523100158662_0004_01_000015 Container Transitioned from ACQUIRED to RELEASED
2018-04-07 14:36:19,524 INFO org.apache.hadoop.yarn.server.resourcemanager.scheduler.fair.FSAppAttempt: Completed container: container_1523100158662_0004_01_000015 in state: RELEASED event:RELEASED
2018-04-07 14:36:19,524 INFO org.apache.hadoop.yarn.server.resourcemanager.RMAuditLogger: USER=root	IP=172.17.0.2	OPERATION=AM Released Container	TARGET=SchedulerApp	RESULT=SUCCESS	APPID=application_1523100158662_0004	CONTAINERID=container_1523100158662_0004_01_000015
2018-04-07 14:36:19,524 INFO org.apache.hadoop.yarn.server.resourcemanager.scheduler.SchedulerNode: Released container container_1523100158662_0004_01_000015 of capacity <memory:1024, vCores:1> on host d1:59470, which currently has 2 containers, <memory:3072, vCores:2> used and <memory:5120, vCores:6> available, release resources=true
2018-04-07 14:36:19,526 INFO org.apache.hadoop.yarn.server.resourcemanager.scheduler.fair.FairScheduler: Application attempt appattempt_1523100158662_0004_000001 released container container_1523100158662_0004_01_000015 on node: host: d1:59470 #containers=2 available=<memory:5120, vCores:6> used=<memory:3072, vCores:2> with event: RELEASED
2018-04-07 14:36:20,609 INFO org.apache.hadoop.yarn.server.resourcemanager.rmcontainer.RMContainerImpl: container_1523100158662_0004_01_000012 Container Transitioned from RUNNING to COMPLETED
2018-04-07 14:36:20,609 INFO org.apache.hadoop.yarn.server.resourcemanager.scheduler.fair.FSAppAttempt: Completed container: container_1523100158662_0004_01_000012 in state: COMPLETED event:FINISHED
2018-04-07 14:36:20,610 INFO org.apache.hadoop.yarn.server.resourcemanager.RMAuditLogger: USER=root	OPERATION=AM Released Container	TARGET=SchedulerApp	RESULT=SUCCESS	APPID=application_1523100158662_0004	CONTAINERID=container_1523100158662_0004_01_000012
2018-04-07 14:36:20,610 INFO org.apache.hadoop.yarn.server.resourcemanager.scheduler.SchedulerNode: Released container container_1523100158662_0004_01_000012 of capacity <memory:1024, vCores:1> on host d1:59470, which currently has 1 containers, <memory:2048, vCores:1> used and <memory:6144, vCores:7> available, release resources=true
2018-04-07 14:36:20,610 INFO org.apache.hadoop.yarn.server.resourcemanager.scheduler.fair.FairScheduler: Application attempt appattempt_1523100158662_0004_000001 released container container_1523100158662_0004_01_000012 on node: host: d1:59470 #containers=1 available=<memory:6144, vCores:7> used=<memory:2048, vCores:1> with event: FINISHED
2018-04-07 14:36:26,932 INFO org.apache.hadoop.yarn.server.resourcemanager.rmapp.attempt.RMAppAttemptImpl: Updating application attempt appattempt_1523100158662_0004_000001 with final state: FINISHING, and exit status: -1000
2018-04-07 14:36:26,946 INFO org.apache.hadoop.yarn.server.resourcemanager.rmapp.attempt.RMAppAttemptImpl: appattempt_1523100158662_0004_000001 State change from RUNNING to FINAL_SAVING
2018-04-07 14:36:26,947 INFO org.apache.hadoop.yarn.server.resourcemanager.rmapp.attempt.RMAppAttemptImpl: appattempt_1523100158662_0004_000001 State change from FINAL_SAVING to FINISHING
2018-04-07 14:36:26,947 INFO org.apache.hadoop.yarn.server.resourcemanager.rmapp.RMAppImpl: Updating application application_1523100158662_0004 with final state: FINISHING
2018-04-07 14:36:26,957 INFO org.apache.hadoop.yarn.server.resourcemanager.recovery.RMStateStore: Updating info for app: application_1523100158662_0004
2018-04-07 14:36:26,958 INFO org.apache.hadoop.yarn.server.resourcemanager.rmapp.RMAppImpl: application_1523100158662_0004 State change from RUNNING to FINAL_SAVING
2018-04-07 14:36:26,958 INFO org.apache.hadoop.yarn.server.resourcemanager.rmapp.RMAppImpl: application_1523100158662_0004 State change from FINAL_SAVING to FINISHING
2018-04-07 14:36:28,099 INFO org.apache.hadoop.yarn.server.resourcemanager.ApplicationMasterService: application_1523100158662_0004 unregistered successfully. 
2018-04-07 14:36:35,207 INFO org.apache.hadoop.yarn.server.resourcemanager.rmcontainer.RMContainerImpl: container_1523100158662_0004_01_000001 Container Transitioned from RUNNING to COMPLETED
2018-04-07 14:36:35,207 INFO org.apache.hadoop.yarn.server.resourcemanager.scheduler.fair.FSAppAttempt: Completed container: container_1523100158662_0004_01_000001 in state: COMPLETED event:FINISHED
2018-04-07 14:36:35,207 INFO org.apache.hadoop.yarn.server.resourcemanager.RMAuditLogger: USER=root	OPERATION=AM Released Container	TARGET=SchedulerApp	RESULT=SUCCESS	APPID=application_1523100158662_0004	CONTAINERID=container_1523100158662_0004_01_000001
2018-04-07 14:36:35,207 INFO org.apache.hadoop.yarn.server.resourcemanager.scheduler.SchedulerNode: Released container container_1523100158662_0004_01_000001 of capacity <memory:2048, vCores:1> on host d1:59470, which currently has 0 containers, <memory:0, vCores:0> used and <memory:8192, vCores:8> available, release resources=true
2018-04-07 14:36:35,207 INFO org.apache.hadoop.yarn.server.resourcemanager.scheduler.fair.FairScheduler: Application attempt appattempt_1523100158662_0004_000001 released container container_1523100158662_0004_01_000001 on node: host: d1:59470 #containers=0 available=<memory:8192, vCores:8> used=<memory:0, vCores:0> with event: FINISHED
2018-04-07 14:36:35,208 INFO org.apache.hadoop.yarn.server.resourcemanager.ApplicationMasterService: Unregistering app attempt : appattempt_1523100158662_0004_000001
2018-04-07 14:36:35,208 INFO org.apache.hadoop.yarn.server.resourcemanager.security.AMRMTokenSecretManager: Application finished, removing password for appattempt_1523100158662_0004_000001
2018-04-07 14:36:35,208 INFO org.apache.hadoop.yarn.server.resourcemanager.rmapp.attempt.RMAppAttemptImpl: appattempt_1523100158662_0004_000001 State change from FINISHING to FINISHED
2018-04-07 14:36:35,208 INFO org.apache.hadoop.yarn.server.resourcemanager.rmapp.RMAppImpl: application_1523100158662_0004 State change from FINISHING to FINISHED
2018-04-07 14:36:35,210 INFO org.apache.hadoop.yarn.server.resourcemanager.RMAuditLogger: USER=root	OPERATION=Application Finished - Succeeded	TARGET=RMAppManager	RESULT=SUCCESS	APPID=application_1523100158662_0004
2018-04-07 14:36:35,225 INFO org.apache.hadoop.yarn.server.resourcemanager.scheduler.fair.FairScheduler: Application appattempt_1523100158662_0004_000001 is done. finalState=FINISHED
2018-04-07 14:36:35,226 INFO org.apache.hadoop.yarn.server.resourcemanager.scheduler.AppSchedulingInfo: Application application_1523100158662_0004 requests cleared
2018-04-07 14:36:35,229 INFO org.apache.hadoop.yarn.server.resourcemanager.RMAppManager$ApplicationSummary: appId=application_1523100158662_0004,name=word count,user=root,queue=root.root,state=FINISHED,trackingUrl=http://d1:8088/proxy/application_1523100158662_0004/,appMasterHost=d1,startTime=1523111531212,finishTime=1523111786947,finalStatus=SUCCEEDED,memorySeconds=1384889,vcoreSeconds=1082,preemptedAMContainers=0,preemptedNonAMContainers=0,preemptedResources=<memory:0\, vCores:0>,applicationType=MAPREDUCE
2018-04-07 14:36:35,246 INFO org.apache.hadoop.yarn.server.resourcemanager.amlauncher.AMLauncher: Cleaning master appattempt_1523100158662_0004_000001
2018-04-07 14:50:36,449 INFO org.apache.hadoop.yarn.server.resourcemanager.ClientRMService: Allocated new applicationId: 5
2018-04-07 14:50:50,756 INFO org.apache.hadoop.yarn.server.resourcemanager.rmapp.RMAppImpl: Storing application with id application_1523100158662_0005
2018-04-07 14:50:50,757 INFO org.apache.hadoop.yarn.server.resourcemanager.rmapp.RMAppImpl: application_1523100158662_0005 State change from NEW to NEW_SAVING
2018-04-07 14:50:50,759 INFO org.apache.hadoop.yarn.server.resourcemanager.recovery.RMStateStore: Storing info for app: application_1523100158662_0005
2018-04-07 14:50:50,760 INFO org.apache.hadoop.yarn.server.resourcemanager.rmapp.RMAppImpl: application_1523100158662_0005 State change from NEW_SAVING to SUBMITTED
2018-04-07 14:50:50,760 INFO org.apache.hadoop.yarn.server.resourcemanager.ClientRMService: Application with id 5 submitted by user root
2018-04-07 14:50:50,760 INFO org.apache.hadoop.yarn.server.resourcemanager.RMAuditLogger: USER=root	IP=172.17.0.2	OPERATION=Submit Application Request	TARGET=ClientRMService	RESULT=SUCCESS	APPID=application_1523100158662_0005
2018-04-07 14:50:50,765 INFO org.apache.hadoop.yarn.server.resourcemanager.scheduler.fair.FairScheduler: Accepted application application_1523100158662_0005 from user: root, in queue: default, currently num of applications: 1
2018-04-07 14:50:50,769 INFO org.apache.hadoop.yarn.server.resourcemanager.rmapp.RMAppImpl: application_1523100158662_0005 State change from SUBMITTED to ACCEPTED
2018-04-07 14:50:50,769 INFO org.apache.hadoop.yarn.server.resourcemanager.ApplicationMasterService: Registering app attempt : appattempt_1523100158662_0005_000001
2018-04-07 14:50:50,769 INFO org.apache.hadoop.yarn.server.resourcemanager.rmapp.attempt.RMAppAttemptImpl: appattempt_1523100158662_0005_000001 State change from NEW to SUBMITTED
2018-04-07 14:50:50,770 INFO org.apache.hadoop.yarn.server.resourcemanager.scheduler.fair.FairScheduler: Added Application Attempt appattempt_1523100158662_0005_000001 to scheduler from user: root
2018-04-07 14:50:50,774 INFO org.apache.hadoop.yarn.server.resourcemanager.rmapp.attempt.RMAppAttemptImpl: appattempt_1523100158662_0005_000001 State change from SUBMITTED to SCHEDULED
2018-04-07 14:50:51,273 INFO org.apache.hadoop.yarn.server.resourcemanager.rmcontainer.RMContainerImpl: container_1523100158662_0005_01_000001 Container Transitioned from NEW to ALLOCATED
2018-04-07 14:50:51,295 INFO org.apache.hadoop.yarn.server.resourcemanager.RMAuditLogger: USER=root	OPERATION=AM Allocated Container	TARGET=SchedulerApp	RESULT=SUCCESS	APPID=application_1523100158662_0005	CONTAINERID=container_1523100158662_0005_01_000001
2018-04-07 14:50:51,295 INFO org.apache.hadoop.yarn.server.resourcemanager.scheduler.SchedulerNode: Assigned container container_1523100158662_0005_01_000001 of capacity <memory:2048, vCores:1> on host d1:59470, which has 1 containers, <memory:2048, vCores:1> used and <memory:6144, vCores:7> available after allocation
2018-04-07 14:50:51,297 INFO org.apache.hadoop.yarn.server.resourcemanager.security.NMTokenSecretManagerInRM: Sending NMToken for nodeId : d1:59470 for container : container_1523100158662_0005_01_000001
2018-04-07 14:50:51,309 INFO org.apache.hadoop.yarn.server.resourcemanager.rmcontainer.RMContainerImpl: container_1523100158662_0005_01_000001 Container Transitioned from ALLOCATED to ACQUIRED
2018-04-07 14:50:51,309 INFO org.apache.hadoop.yarn.server.resourcemanager.security.NMTokenSecretManagerInRM: Clear node set for appattempt_1523100158662_0005_000001
2018-04-07 14:50:51,309 INFO org.apache.hadoop.yarn.server.resourcemanager.rmapp.attempt.RMAppAttemptImpl: Storing attempt: AppId: application_1523100158662_0005 AttemptId: appattempt_1523100158662_0005_000001 MasterContainer: Container: [ContainerId: container_1523100158662_0005_01_000001, NodeId: d1:59470, NodeHttpAddress: d1:8042, Resource: <memory:2048, vCores:1>, Priority: 0, Token: Token { kind: ContainerToken, service: 172.17.0.2:59470 }, ]
2018-04-07 14:50:51,309 INFO org.apache.hadoop.yarn.server.resourcemanager.rmapp.attempt.RMAppAttemptImpl: appattempt_1523100158662_0005_000001 State change from SCHEDULED to ALLOCATED_SAVING
2018-04-07 14:50:51,310 INFO org.apache.hadoop.yarn.server.resourcemanager.rmapp.attempt.RMAppAttemptImpl: appattempt_1523100158662_0005_000001 State change from ALLOCATED_SAVING to ALLOCATED
2018-04-07 14:50:51,332 INFO org.apache.hadoop.yarn.server.resourcemanager.amlauncher.AMLauncher: Launching masterappattempt_1523100158662_0005_000001
2018-04-07 14:50:51,350 INFO org.apache.hadoop.yarn.server.resourcemanager.amlauncher.AMLauncher: Setting up container Container: [ContainerId: container_1523100158662_0005_01_000001, NodeId: d1:59470, NodeHttpAddress: d1:8042, Resource: <memory:2048, vCores:1>, Priority: 0, Token: Token { kind: ContainerToken, service: 172.17.0.2:59470 }, ] for AM appattempt_1523100158662_0005_000001
2018-04-07 14:50:51,351 INFO org.apache.hadoop.yarn.server.resourcemanager.amlauncher.AMLauncher: Command to launch container container_1523100158662_0005_01_000001 : $JAVA_HOME/bin/java -Dlog4j.configuration=container-log4j.properties -Dyarn.app.container.log.dir=<LOG_DIR> -Dyarn.app.container.log.filesize=0 -Dhadoop.root.logger=INFO,CLA -Dhadoop.root.logfile=syslog  -Xmx1024m org.apache.hadoop.mapreduce.v2.app.MRAppMaster 1><LOG_DIR>/stdout 2><LOG_DIR>/stderr 
2018-04-07 14:50:51,361 INFO org.apache.hadoop.yarn.server.resourcemanager.security.AMRMTokenSecretManager: Create AMRMToken for ApplicationAttempt: appattempt_1523100158662_0005_000001
2018-04-07 14:50:51,361 INFO org.apache.hadoop.yarn.server.resourcemanager.security.AMRMTokenSecretManager: Creating password for appattempt_1523100158662_0005_000001
2018-04-07 14:50:51,616 INFO org.apache.hadoop.yarn.server.resourcemanager.amlauncher.AMLauncher: Done launching container Container: [ContainerId: container_1523100158662_0005_01_000001, NodeId: d1:59470, NodeHttpAddress: d1:8042, Resource: <memory:2048, vCores:1>, Priority: 0, Token: Token { kind: ContainerToken, service: 172.17.0.2:59470 }, ] for AM appattempt_1523100158662_0005_000001
2018-04-07 14:50:51,618 INFO org.apache.hadoop.yarn.server.resourcemanager.rmapp.attempt.RMAppAttemptImpl: appattempt_1523100158662_0005_000001 State change from ALLOCATED to LAUNCHED
2018-04-07 14:50:52,274 INFO org.apache.hadoop.yarn.server.resourcemanager.rmcontainer.RMContainerImpl: container_1523100158662_0005_01_000001 Container Transitioned from ACQUIRED to RUNNING
2018-04-07 14:51:35,058 INFO SecurityLogger.org.apache.hadoop.ipc.Server: Auth successful for appattempt_1523100158662_0005_000001 (auth:SIMPLE)
2018-04-07 14:51:35,078 INFO org.apache.hadoop.yarn.server.resourcemanager.ApplicationMasterService: AM registration appattempt_1523100158662_0005_000001
2018-04-07 14:51:35,078 INFO org.apache.hadoop.yarn.server.resourcemanager.RMAuditLogger: USER=root	IP=172.17.0.2	OPERATION=Register App Master	TARGET=ApplicationMasterService	RESULT=SUCCESS	APPID=application_1523100158662_0005	APPATTEMPTID=appattempt_1523100158662_0005_000001
2018-04-07 14:51:35,078 INFO org.apache.hadoop.yarn.server.resourcemanager.rmapp.attempt.RMAppAttemptImpl: appattempt_1523100158662_0005_000001 State change from LAUNCHED to RUNNING
2018-04-07 14:51:35,079 INFO org.apache.hadoop.yarn.server.resourcemanager.rmapp.RMAppImpl: application_1523100158662_0005 State change from ACCEPTED to RUNNING
2018-04-07 14:51:40,235 INFO org.apache.hadoop.yarn.server.resourcemanager.rmcontainer.RMContainerImpl: container_1523100158662_0005_01_000002 Container Transitioned from NEW to ALLOCATED
2018-04-07 14:51:40,235 INFO org.apache.hadoop.yarn.server.resourcemanager.RMAuditLogger: USER=root	OPERATION=AM Allocated Container	TARGET=SchedulerApp	RESULT=SUCCESS	APPID=application_1523100158662_0005	CONTAINERID=container_1523100158662_0005_01_000002
2018-04-07 14:51:40,235 INFO org.apache.hadoop.yarn.server.resourcemanager.scheduler.SchedulerNode: Assigned container container_1523100158662_0005_01_000002 of capacity <memory:1024, vCores:1> on host d1:59470, which has 2 containers, <memory:3072, vCores:2> used and <memory:5120, vCores:6> available after allocation
2018-04-07 14:51:43,117 INFO org.apache.hadoop.yarn.server.resourcemanager.security.NMTokenSecretManagerInRM: Sending NMToken for nodeId : d1:59470 for container : container_1523100158662_0005_01_000002
2018-04-07 14:51:43,125 INFO org.apache.hadoop.yarn.server.resourcemanager.rmcontainer.RMContainerImpl: container_1523100158662_0005_01_000002 Container Transitioned from ALLOCATED to ACQUIRED
2018-04-07 14:51:53,707 INFO SecurityLogger.org.apache.hadoop.ipc.Server: Auth successful for appattempt_1523100158662_0005_000001 (auth:SIMPLE)
2018-04-07 14:51:53,753 INFO org.apache.hadoop.yarn.server.resourcemanager.scheduler.AppSchedulingInfo: checking for deactivate of application :application_1523100158662_0005
2018-04-07 14:51:54,659 INFO org.apache.hadoop.yarn.server.resourcemanager.rmcontainer.RMContainerImpl: container_1523100158662_0005_01_000002 Container Transitioned from ACQUIRED to RUNNING
2018-04-07 14:52:37,665 INFO org.apache.hadoop.yarn.server.resourcemanager.rmcontainer.RMContainerImpl: container_1523100158662_0005_01_000002 Container Transitioned from RUNNING to COMPLETED
2018-04-07 14:52:37,665 INFO org.apache.hadoop.yarn.server.resourcemanager.scheduler.fair.FSAppAttempt: Completed container: container_1523100158662_0005_01_000002 in state: COMPLETED event:FINISHED
2018-04-07 14:52:37,665 INFO org.apache.hadoop.yarn.server.resourcemanager.RMAuditLogger: USER=root	OPERATION=AM Released Container	TARGET=SchedulerApp	RESULT=SUCCESS	APPID=application_1523100158662_0005	CONTAINERID=container_1523100158662_0005_01_000002
2018-04-07 14:52:37,665 INFO org.apache.hadoop.yarn.server.resourcemanager.scheduler.SchedulerNode: Released container container_1523100158662_0005_01_000002 of capacity <memory:1024, vCores:1> on host d1:59470, which currently has 1 containers, <memory:2048, vCores:1> used and <memory:6144, vCores:7> available, release resources=true
2018-04-07 14:52:37,665 INFO org.apache.hadoop.yarn.server.resourcemanager.scheduler.fair.FairScheduler: Application attempt appattempt_1523100158662_0005_000001 released container container_1523100158662_0005_01_000002 on node: host: d1:59470 #containers=1 available=<memory:6144, vCores:7> used=<memory:2048, vCores:1> with event: FINISHED
2018-04-07 14:52:38,685 INFO org.apache.hadoop.yarn.server.resourcemanager.rmcontainer.RMContainerImpl: container_1523100158662_0005_01_000003 Container Transitioned from NEW to ALLOCATED
2018-04-07 14:52:38,685 INFO org.apache.hadoop.yarn.server.resourcemanager.RMAuditLogger: USER=root	OPERATION=AM Allocated Container	TARGET=SchedulerApp	RESULT=SUCCESS	APPID=application_1523100158662_0005	CONTAINERID=container_1523100158662_0005_01_000003
2018-04-07 14:52:38,686 INFO org.apache.hadoop.yarn.server.resourcemanager.scheduler.SchedulerNode: Assigned container container_1523100158662_0005_01_000003 of capacity <memory:1024, vCores:1> on host d1:59470, which has 2 containers, <memory:3072, vCores:2> used and <memory:5120, vCores:6> available after allocation
2018-04-07 14:52:39,703 INFO org.apache.hadoop.yarn.server.resourcemanager.rmcontainer.RMContainerImpl: container_1523100158662_0005_01_000004 Container Transitioned from NEW to ALLOCATED
2018-04-07 14:52:39,708 INFO org.apache.hadoop.yarn.server.resourcemanager.RMAuditLogger: USER=root	OPERATION=AM Allocated Container	TARGET=SchedulerApp	RESULT=SUCCESS	APPID=application_1523100158662_0005	CONTAINERID=container_1523100158662_0005_01_000004
2018-04-07 14:52:39,714 INFO org.apache.hadoop.yarn.server.resourcemanager.scheduler.SchedulerNode: Assigned container container_1523100158662_0005_01_000004 of capacity <memory:1024, vCores:1> on host d1:59470, which has 3 containers, <memory:4096, vCores:3> used and <memory:4096, vCores:5> available after allocation
2018-04-07 14:52:40,044 INFO org.apache.hadoop.yarn.server.resourcemanager.rmcontainer.RMContainerImpl: container_1523100158662_0005_01_000003 Container Transitioned from ALLOCATED to ACQUIRED
2018-04-07 14:52:40,055 INFO org.apache.hadoop.yarn.server.resourcemanager.rmcontainer.RMContainerImpl: container_1523100158662_0005_01_000004 Container Transitioned from ALLOCATED to ACQUIRED
2018-04-07 14:52:40,870 INFO org.apache.hadoop.yarn.server.resourcemanager.rmcontainer.RMContainerImpl: container_1523100158662_0005_01_000005 Container Transitioned from NEW to ALLOCATED
2018-04-07 14:52:40,871 INFO org.apache.hadoop.yarn.server.resourcemanager.RMAuditLogger: USER=root	OPERATION=AM Allocated Container	TARGET=SchedulerApp	RESULT=SUCCESS	APPID=application_1523100158662_0005	CONTAINERID=container_1523100158662_0005_01_000005
2018-04-07 14:52:40,902 INFO org.apache.hadoop.yarn.server.resourcemanager.scheduler.SchedulerNode: Assigned container container_1523100158662_0005_01_000005 of capacity <memory:1024, vCores:1> on host d1:59470, which has 4 containers, <memory:5120, vCores:4> used and <memory:3072, vCores:4> available after allocation
2018-04-07 14:52:41,401 INFO org.apache.hadoop.yarn.server.resourcemanager.rmcontainer.RMContainerImpl: container_1523100158662_0005_01_000005 Container Transitioned from ALLOCATED to ACQUIRED
2018-04-07 14:52:42,066 INFO org.apache.hadoop.yarn.server.resourcemanager.rmcontainer.RMContainerImpl: container_1523100158662_0005_01_000003 Container Transitioned from ACQUIRED to RUNNING
2018-04-07 14:52:42,085 INFO org.apache.hadoop.yarn.server.resourcemanager.rmcontainer.RMContainerImpl: container_1523100158662_0005_01_000004 Container Transitioned from ACQUIRED to RUNNING
2018-04-07 14:52:42,086 INFO org.apache.hadoop.yarn.server.resourcemanager.rmcontainer.RMContainerImpl: container_1523100158662_0005_01_000006 Container Transitioned from NEW to ALLOCATED
2018-04-07 14:52:42,086 INFO org.apache.hadoop.yarn.server.resourcemanager.RMAuditLogger: USER=root	OPERATION=AM Allocated Container	TARGET=SchedulerApp	RESULT=SUCCESS	APPID=application_1523100158662_0005	CONTAINERID=container_1523100158662_0005_01_000006
2018-04-07 14:52:42,086 INFO org.apache.hadoop.yarn.server.resourcemanager.scheduler.SchedulerNode: Assigned container container_1523100158662_0005_01_000006 of capacity <memory:1024, vCores:1> on host d1:59470, which has 5 containers, <memory:6144, vCores:5> used and <memory:2048, vCores:3> available after allocation
2018-04-07 14:52:42,797 INFO org.apache.hadoop.yarn.server.resourcemanager.rmcontainer.RMContainerImpl: container_1523100158662_0005_01_000006 Container Transitioned from ALLOCATED to ACQUIRED
2018-04-07 14:52:43,187 INFO org.apache.hadoop.yarn.server.resourcemanager.rmcontainer.RMContainerImpl: container_1523100158662_0005_01_000005 Container Transitioned from ACQUIRED to RUNNING
2018-04-07 14:52:43,191 INFO org.apache.hadoop.yarn.server.resourcemanager.rmcontainer.RMContainerImpl: container_1523100158662_0005_01_000007 Container Transitioned from NEW to ALLOCATED
2018-04-07 14:52:43,200 INFO org.apache.hadoop.yarn.server.resourcemanager.RMAuditLogger: USER=root	OPERATION=AM Allocated Container	TARGET=SchedulerApp	RESULT=SUCCESS	APPID=application_1523100158662_0005	CONTAINERID=container_1523100158662_0005_01_000007
2018-04-07 14:52:43,200 INFO org.apache.hadoop.yarn.server.resourcemanager.scheduler.SchedulerNode: Assigned container container_1523100158662_0005_01_000007 of capacity <memory:1024, vCores:1> on host d1:59470, which has 6 containers, <memory:7168, vCores:6> used and <memory:1024, vCores:2> available after allocation
2018-04-07 14:52:44,307 INFO org.apache.hadoop.yarn.server.resourcemanager.rmcontainer.RMContainerImpl: container_1523100158662_0005_01_000007 Container Transitioned from ALLOCATED to ACQUIRED
2018-04-07 14:52:44,553 INFO org.apache.hadoop.yarn.server.resourcemanager.rmcontainer.RMContainerImpl: container_1523100158662_0005_01_000008 Container Transitioned from NEW to ALLOCATED
2018-04-07 14:52:44,553 INFO org.apache.hadoop.yarn.server.resourcemanager.RMAuditLogger: USER=root	OPERATION=AM Allocated Container	TARGET=SchedulerApp	RESULT=SUCCESS	APPID=application_1523100158662_0005	CONTAINERID=container_1523100158662_0005_01_000008
2018-04-07 14:52:44,553 INFO org.apache.hadoop.yarn.server.resourcemanager.scheduler.SchedulerNode: Assigned container container_1523100158662_0005_01_000008 of capacity <memory:1024, vCores:1> on host d1:59470, which has 7 containers, <memory:8192, vCores:7> used and <memory:0, vCores:1> available after allocation
2018-04-07 14:52:45,429 INFO org.apache.hadoop.yarn.server.resourcemanager.rmcontainer.RMContainerImpl: container_1523100158662_0005_01_000006 Container Transitioned from ACQUIRED to RUNNING
2018-04-07 14:52:45,429 INFO org.apache.hadoop.yarn.server.resourcemanager.scheduler.fair.FSAppAttempt: Making reservation: node=d1 app_id=application_1523100158662_0005
2018-04-07 14:52:45,429 INFO org.apache.hadoop.yarn.server.resourcemanager.rmcontainer.RMContainerImpl: container_1523100158662_0005_01_000009 Container Transitioned from NEW to RESERVED
2018-04-07 14:52:45,429 INFO org.apache.hadoop.yarn.server.resourcemanager.scheduler.fair.FSSchedulerNode: Reserved container container_1523100158662_0005_01_000009 on node host: d1:59470 #containers=7 available=<memory:0, vCores:1> used=<memory:8192, vCores:7> for application org.apache.hadoop.yarn.server.resourcemanager.scheduler.fair.FSAppAttempt@323e6645
2018-04-07 14:52:45,882 INFO org.apache.hadoop.yarn.server.resourcemanager.rmcontainer.RMContainerImpl: container_1523100158662_0005_01_000008 Container Transitioned from ALLOCATED to ACQUIRED
2018-04-07 14:52:46,346 INFO org.apache.hadoop.yarn.server.resourcemanager.rmcontainer.RMContainerImpl: container_1523100158662_0005_01_000007 Container Transitioned from ACQUIRED to RUNNING
2018-04-07 14:52:47,613 INFO org.apache.hadoop.yarn.server.resourcemanager.rmcontainer.RMContainerImpl: container_1523100158662_0005_01_000008 Container Transitioned from ACQUIRED to RUNNING
2018-04-07 14:55:35,121 INFO org.apache.hadoop.yarn.server.resourcemanager.rmcontainer.RMContainerImpl: container_1523100158662_0005_01_000003 Container Transitioned from RUNNING to COMPLETED
2018-04-07 14:55:35,121 INFO org.apache.hadoop.yarn.server.resourcemanager.scheduler.fair.FSAppAttempt: Completed container: container_1523100158662_0005_01_000003 in state: COMPLETED event:FINISHED
2018-04-07 14:55:35,121 INFO org.apache.hadoop.yarn.server.resourcemanager.RMAuditLogger: USER=root	OPERATION=AM Released Container	TARGET=SchedulerApp	RESULT=SUCCESS	APPID=application_1523100158662_0005	CONTAINERID=container_1523100158662_0005_01_000003
2018-04-07 14:55:35,122 INFO org.apache.hadoop.yarn.server.resourcemanager.scheduler.SchedulerNode: Released container container_1523100158662_0005_01_000003 of capacity <memory:1024, vCores:1> on host d1:59470, which currently has 6 containers, <memory:7168, vCores:6> used and <memory:1024, vCores:2> available, release resources=true
2018-04-07 14:55:35,122 INFO org.apache.hadoop.yarn.server.resourcemanager.scheduler.fair.FairScheduler: Application attempt appattempt_1523100158662_0005_000001 released container container_1523100158662_0005_01_000003 on node: host: d1:59470 #containers=6 available=<memory:1024, vCores:2> used=<memory:7168, vCores:6> with event: FINISHED
2018-04-07 14:55:35,155 INFO org.apache.hadoop.yarn.server.resourcemanager.rmcontainer.RMContainerImpl: container_1523100158662_0005_01_000006 Container Transitioned from RUNNING to COMPLETED
2018-04-07 14:55:35,158 INFO org.apache.hadoop.yarn.server.resourcemanager.scheduler.fair.FSAppAttempt: Completed container: container_1523100158662_0005_01_000006 in state: COMPLETED event:FINISHED
2018-04-07 14:55:35,158 INFO org.apache.hadoop.yarn.server.resourcemanager.RMAuditLogger: USER=root	OPERATION=AM Released Container	TARGET=SchedulerApp	RESULT=SUCCESS	APPID=application_1523100158662_0005	CONTAINERID=container_1523100158662_0005_01_000006
2018-04-07 14:55:35,158 INFO org.apache.hadoop.yarn.server.resourcemanager.scheduler.SchedulerNode: Released container container_1523100158662_0005_01_000006 of capacity <memory:1024, vCores:1> on host d1:59470, which currently has 5 containers, <memory:6144, vCores:5> used and <memory:2048, vCores:3> available, release resources=true
2018-04-07 14:55:35,159 INFO org.apache.hadoop.yarn.server.resourcemanager.scheduler.fair.FairScheduler: Application attempt appattempt_1523100158662_0005_000001 released container container_1523100158662_0005_01_000006 on node: host: d1:59470 #containers=5 available=<memory:2048, vCores:3> used=<memory:6144, vCores:5> with event: FINISHED
2018-04-07 14:55:35,173 INFO org.apache.hadoop.yarn.server.resourcemanager.rmcontainer.RMContainerImpl: container_1523100158662_0005_01_000009 Container Transitioned from NEW to ALLOCATED
2018-04-07 14:55:35,174 INFO org.apache.hadoop.yarn.server.resourcemanager.RMAuditLogger: USER=root	OPERATION=AM Allocated Container	TARGET=SchedulerApp	RESULT=SUCCESS	APPID=application_1523100158662_0005	CONTAINERID=container_1523100158662_0005_01_000009
2018-04-07 14:55:35,174 INFO org.apache.hadoop.yarn.server.resourcemanager.scheduler.fair.FSAppAttempt: Application application_1523100158662_0005 unreserved  on node host: d1:59470 #containers=5 available=<memory:2048, vCores:3> used=<memory:6144, vCores:5>, currently has 0 at priority 10; currentReservation <memory:0, vCores:0>
2018-04-07 14:55:35,174 INFO org.apache.hadoop.yarn.server.resourcemanager.scheduler.SchedulerNode: Assigned container container_1523100158662_0005_01_000009 of capacity <memory:1024, vCores:1> on host d1:59470, which has 6 containers, <memory:7168, vCores:6> used and <memory:1024, vCores:2> available after allocation
2018-04-07 14:55:35,602 INFO org.apache.hadoop.yarn.server.resourcemanager.rmcontainer.RMContainerImpl: container_1523100158662_0005_01_000009 Container Transitioned from ALLOCATED to ACQUIRED
2018-04-07 14:55:36,168 INFO org.apache.hadoop.yarn.server.resourcemanager.rmcontainer.RMContainerImpl: container_1523100158662_0005_01_000010 Container Transitioned from NEW to ALLOCATED
2018-04-07 14:55:36,177 INFO org.apache.hadoop.yarn.server.resourcemanager.RMAuditLogger: USER=root	OPERATION=AM Allocated Container	TARGET=SchedulerApp	RESULT=SUCCESS	APPID=application_1523100158662_0005	CONTAINERID=container_1523100158662_0005_01_000010
2018-04-07 14:55:36,177 INFO org.apache.hadoop.yarn.server.resourcemanager.scheduler.SchedulerNode: Assigned container container_1523100158662_0005_01_000010 of capacity <memory:1024, vCores:1> on host d1:59470, which has 7 containers, <memory:8192, vCores:7> used and <memory:0, vCores:1> available after allocation
2018-04-07 14:55:38,650 INFO org.apache.hadoop.yarn.server.resourcemanager.rmcontainer.RMContainerImpl: container_1523100158662_0005_01_000010 Container Transitioned from ALLOCATED to ACQUIRED
2018-04-07 14:55:38,940 INFO org.apache.hadoop.yarn.server.resourcemanager.scheduler.fair.FSAppAttempt: Making reservation: node=d1 app_id=application_1523100158662_0005
2018-04-07 14:55:38,941 INFO org.apache.hadoop.yarn.server.resourcemanager.rmcontainer.RMContainerImpl: container_1523100158662_0005_01_000011 Container Transitioned from NEW to RESERVED
2018-04-07 14:55:38,941 INFO org.apache.hadoop.yarn.server.resourcemanager.scheduler.fair.FSSchedulerNode: Reserved container container_1523100158662_0005_01_000011 on node host: d1:59470 #containers=7 available=<memory:0, vCores:1> used=<memory:8192, vCores:7> for application org.apache.hadoop.yarn.server.resourcemanager.scheduler.fair.FSAppAttempt@323e6645
2018-04-07 14:55:40,601 INFO org.apache.hadoop.yarn.server.resourcemanager.rmcontainer.RMContainerImpl: container_1523100158662_0005_01_000009 Container Transitioned from ACQUIRED to RUNNING
2018-04-07 14:55:41,507 INFO org.apache.hadoop.yarn.server.resourcemanager.rmcontainer.RMContainerImpl: container_1523100158662_0005_01_000010 Container Transitioned from ACQUIRED to RUNNING
2018-04-07 14:55:49,296 INFO org.apache.hadoop.yarn.server.resourcemanager.rmcontainer.RMContainerImpl: container_1523100158662_0005_01_000007 Container Transitioned from RUNNING to COMPLETED
2018-04-07 14:55:49,296 INFO org.apache.hadoop.yarn.server.resourcemanager.scheduler.fair.FSAppAttempt: Completed container: container_1523100158662_0005_01_000007 in state: COMPLETED event:FINISHED
2018-04-07 14:55:49,296 INFO org.apache.hadoop.yarn.server.resourcemanager.RMAuditLogger: USER=root	OPERATION=AM Released Container	TARGET=SchedulerApp	RESULT=SUCCESS	APPID=application_1523100158662_0005	CONTAINERID=container_1523100158662_0005_01_000007
2018-04-07 14:55:49,296 INFO org.apache.hadoop.yarn.server.resourcemanager.scheduler.SchedulerNode: Released container container_1523100158662_0005_01_000007 of capacity <memory:1024, vCores:1> on host d1:59470, which currently has 6 containers, <memory:7168, vCores:6> used and <memory:1024, vCores:2> available, release resources=true
2018-04-07 14:55:49,296 INFO org.apache.hadoop.yarn.server.resourcemanager.scheduler.fair.FairScheduler: Application attempt appattempt_1523100158662_0005_000001 released container container_1523100158662_0005_01_000007 on node: host: d1:59470 #containers=6 available=<memory:1024, vCores:2> used=<memory:7168, vCores:6> with event: FINISHED
2018-04-07 14:55:49,296 INFO org.apache.hadoop.yarn.server.resourcemanager.rmcontainer.RMContainerImpl: container_1523100158662_0005_01_000011 Container Transitioned from NEW to ALLOCATED
2018-04-07 14:55:49,296 INFO org.apache.hadoop.yarn.server.resourcemanager.RMAuditLogger: USER=root	OPERATION=AM Allocated Container	TARGET=SchedulerApp	RESULT=SUCCESS	APPID=application_1523100158662_0005	CONTAINERID=container_1523100158662_0005_01_000011
2018-04-07 14:55:49,297 INFO org.apache.hadoop.yarn.server.resourcemanager.scheduler.fair.FSAppAttempt: Application application_1523100158662_0005 unreserved  on node host: d1:59470 #containers=6 available=<memory:1024, vCores:2> used=<memory:7168, vCores:6>, currently has 0 at priority 10; currentReservation <memory:0, vCores:0>
2018-04-07 14:55:49,297 INFO org.apache.hadoop.yarn.server.resourcemanager.scheduler.SchedulerNode: Assigned container container_1523100158662_0005_01_000011 of capacity <memory:1024, vCores:1> on host d1:59470, which has 7 containers, <memory:8192, vCores:7> used and <memory:0, vCores:1> available after allocation
2018-04-07 14:55:49,412 INFO org.apache.hadoop.yarn.server.resourcemanager.rmcontainer.RMContainerImpl: container_1523100158662_0005_01_000011 Container Transitioned from ALLOCATED to ACQUIRED
2018-04-07 14:55:50,302 INFO org.apache.hadoop.yarn.server.resourcemanager.rmcontainer.RMContainerImpl: container_1523100158662_0005_01_000011 Container Transitioned from ACQUIRED to RUNNING
2018-04-07 14:55:50,305 INFO org.apache.hadoop.yarn.server.resourcemanager.rmcontainer.RMContainerImpl: container_1523100158662_0005_01_000004 Container Transitioned from RUNNING to COMPLETED
2018-04-07 14:55:50,305 INFO org.apache.hadoop.yarn.server.resourcemanager.scheduler.fair.FSAppAttempt: Completed container: container_1523100158662_0005_01_000004 in state: COMPLETED event:FINISHED
2018-04-07 14:55:50,305 INFO org.apache.hadoop.yarn.server.resourcemanager.RMAuditLogger: USER=root	OPERATION=AM Released Container	TARGET=SchedulerApp	RESULT=SUCCESS	APPID=application_1523100158662_0005	CONTAINERID=container_1523100158662_0005_01_000004
2018-04-07 14:55:50,305 INFO org.apache.hadoop.yarn.server.resourcemanager.scheduler.SchedulerNode: Released container container_1523100158662_0005_01_000004 of capacity <memory:1024, vCores:1> on host d1:59470, which currently has 6 containers, <memory:7168, vCores:6> used and <memory:1024, vCores:2> available, release resources=true
2018-04-07 14:55:50,306 INFO org.apache.hadoop.yarn.server.resourcemanager.scheduler.fair.FairScheduler: Application attempt appattempt_1523100158662_0005_000001 released container container_1523100158662_0005_01_000004 on node: host: d1:59470 #containers=6 available=<memory:1024, vCores:2> used=<memory:7168, vCores:6> with event: FINISHED
2018-04-07 14:55:50,309 INFO org.apache.hadoop.yarn.server.resourcemanager.rmcontainer.RMContainerImpl: container_1523100158662_0005_01_000008 Container Transitioned from RUNNING to COMPLETED
2018-04-07 14:55:50,309 INFO org.apache.hadoop.yarn.server.resourcemanager.scheduler.fair.FSAppAttempt: Completed container: container_1523100158662_0005_01_000008 in state: COMPLETED event:FINISHED
2018-04-07 14:55:50,309 INFO org.apache.hadoop.yarn.server.resourcemanager.RMAuditLogger: USER=root	OPERATION=AM Released Container	TARGET=SchedulerApp	RESULT=SUCCESS	APPID=application_1523100158662_0005	CONTAINERID=container_1523100158662_0005_01_000008
2018-04-07 14:55:50,309 INFO org.apache.hadoop.yarn.server.resourcemanager.scheduler.SchedulerNode: Released container container_1523100158662_0005_01_000008 of capacity <memory:1024, vCores:1> on host d1:59470, which currently has 5 containers, <memory:6144, vCores:5> used and <memory:2048, vCores:3> available, release resources=true
2018-04-07 14:55:50,309 INFO org.apache.hadoop.yarn.server.resourcemanager.scheduler.fair.FairScheduler: Application attempt appattempt_1523100158662_0005_000001 released container container_1523100158662_0005_01_000008 on node: host: d1:59470 #containers=5 available=<memory:2048, vCores:3> used=<memory:6144, vCores:5> with event: FINISHED
2018-04-07 14:55:50,313 INFO org.apache.hadoop.yarn.server.resourcemanager.rmcontainer.RMContainerImpl: container_1523100158662_0005_01_000005 Container Transitioned from RUNNING to COMPLETED
2018-04-07 14:55:50,313 INFO org.apache.hadoop.yarn.server.resourcemanager.scheduler.fair.FSAppAttempt: Completed container: container_1523100158662_0005_01_000005 in state: COMPLETED event:FINISHED
2018-04-07 14:55:50,313 INFO org.apache.hadoop.yarn.server.resourcemanager.RMAuditLogger: USER=root	OPERATION=AM Released Container	TARGET=SchedulerApp	RESULT=SUCCESS	APPID=application_1523100158662_0005	CONTAINERID=container_1523100158662_0005_01_000005
2018-04-07 14:55:50,313 INFO org.apache.hadoop.yarn.server.resourcemanager.scheduler.SchedulerNode: Released container container_1523100158662_0005_01_000005 of capacity <memory:1024, vCores:1> on host d1:59470, which currently has 4 containers, <memory:5120, vCores:4> used and <memory:3072, vCores:4> available, release resources=true
2018-04-07 14:55:50,313 INFO org.apache.hadoop.yarn.server.resourcemanager.scheduler.fair.FairScheduler: Application attempt appattempt_1523100158662_0005_000001 released container container_1523100158662_0005_01_000005 on node: host: d1:59470 #containers=4 available=<memory:3072, vCores:4> used=<memory:5120, vCores:4> with event: FINISHED
2018-04-07 14:55:50,314 INFO org.apache.hadoop.yarn.server.resourcemanager.rmcontainer.RMContainerImpl: container_1523100158662_0005_01_000012 Container Transitioned from NEW to ALLOCATED
2018-04-07 14:55:50,314 INFO org.apache.hadoop.yarn.server.resourcemanager.RMAuditLogger: USER=root	OPERATION=AM Allocated Container	TARGET=SchedulerApp	RESULT=SUCCESS	APPID=application_1523100158662_0005	CONTAINERID=container_1523100158662_0005_01_000012
2018-04-07 14:55:50,314 INFO org.apache.hadoop.yarn.server.resourcemanager.scheduler.SchedulerNode: Assigned container container_1523100158662_0005_01_000012 of capacity <memory:1024, vCores:1> on host d1:59470, which has 5 containers, <memory:6144, vCores:5> used and <memory:2048, vCores:3> available after allocation
2018-04-07 14:55:50,442 INFO org.apache.hadoop.yarn.server.resourcemanager.rmcontainer.RMContainerImpl: container_1523100158662_0005_01_000012 Container Transitioned from ALLOCATED to ACQUIRED
2018-04-07 14:55:51,304 INFO org.apache.hadoop.yarn.server.resourcemanager.rmcontainer.RMContainerImpl: container_1523100158662_0005_01_000012 Container Transitioned from ACQUIRED to RUNNING
2018-04-07 14:55:51,304 INFO org.apache.hadoop.yarn.server.resourcemanager.rmcontainer.RMContainerImpl: container_1523100158662_0005_01_000013 Container Transitioned from NEW to ALLOCATED
2018-04-07 14:55:51,305 INFO org.apache.hadoop.yarn.server.resourcemanager.RMAuditLogger: USER=root	OPERATION=AM Allocated Container	TARGET=SchedulerApp	RESULT=SUCCESS	APPID=application_1523100158662_0005	CONTAINERID=container_1523100158662_0005_01_000013
2018-04-07 14:55:51,305 INFO org.apache.hadoop.yarn.server.resourcemanager.scheduler.SchedulerNode: Assigned container container_1523100158662_0005_01_000013 of capacity <memory:1024, vCores:1> on host d1:59470, which has 6 containers, <memory:7168, vCores:6> used and <memory:1024, vCores:2> available after allocation
2018-04-07 14:55:51,465 INFO org.apache.hadoop.yarn.server.resourcemanager.scheduler.AppSchedulingInfo: checking for deactivate of application :application_1523100158662_0005
2018-04-07 14:55:51,467 INFO org.apache.hadoop.yarn.server.resourcemanager.rmcontainer.RMContainerImpl: container_1523100158662_0005_01_000013 Container Transitioned from ALLOCATED to ACQUIRED
2018-04-07 14:55:52,474 INFO org.apache.hadoop.yarn.server.resourcemanager.rmcontainer.RMContainerImpl: container_1523100158662_0005_01_000013 Container Transitioned from ACQUIRED to RELEASED
2018-04-07 14:55:52,474 INFO org.apache.hadoop.yarn.server.resourcemanager.scheduler.fair.FSAppAttempt: Completed container: container_1523100158662_0005_01_000013 in state: RELEASED event:RELEASED
2018-04-07 14:55:52,475 INFO org.apache.hadoop.yarn.server.resourcemanager.RMAuditLogger: USER=root	IP=172.17.0.2	OPERATION=AM Released Container	TARGET=SchedulerApp	RESULT=SUCCESS	APPID=application_1523100158662_0005	CONTAINERID=container_1523100158662_0005_01_000013
2018-04-07 14:55:52,475 INFO org.apache.hadoop.yarn.server.resourcemanager.scheduler.SchedulerNode: Released container container_1523100158662_0005_01_000013 of capacity <memory:1024, vCores:1> on host d1:59470, which currently has 5 containers, <memory:6144, vCores:5> used and <memory:2048, vCores:3> available, release resources=true
2018-04-07 14:55:52,475 INFO org.apache.hadoop.yarn.server.resourcemanager.scheduler.fair.FairScheduler: Application attempt appattempt_1523100158662_0005_000001 released container container_1523100158662_0005_01_000013 on node: host: d1:59470 #containers=5 available=<memory:2048, vCores:3> used=<memory:6144, vCores:5> with event: RELEASED
2018-04-07 14:56:03,407 INFO org.apache.hadoop.yarn.server.resourcemanager.rmcontainer.RMContainerImpl: container_1523100158662_0005_01_000014 Container Transitioned from NEW to ALLOCATED
2018-04-07 14:56:03,408 INFO org.apache.hadoop.yarn.server.resourcemanager.RMAuditLogger: USER=root	OPERATION=AM Allocated Container	TARGET=SchedulerApp	RESULT=SUCCESS	APPID=application_1523100158662_0005	CONTAINERID=container_1523100158662_0005_01_000014
2018-04-07 14:56:03,408 INFO org.apache.hadoop.yarn.server.resourcemanager.scheduler.SchedulerNode: Assigned container container_1523100158662_0005_01_000014 of capacity <memory:1024, vCores:1> on host d1:59470, which has 6 containers, <memory:7168, vCores:6> used and <memory:1024, vCores:2> available after allocation
2018-04-07 14:56:03,581 INFO org.apache.hadoop.yarn.server.resourcemanager.rmcontainer.RMContainerImpl: container_1523100158662_0005_01_000014 Container Transitioned from ALLOCATED to ACQUIRED
2018-04-07 14:56:04,413 INFO org.apache.hadoop.yarn.server.resourcemanager.rmcontainer.RMContainerImpl: container_1523100158662_0005_01_000014 Container Transitioned from ACQUIRED to RUNNING
2018-04-07 14:56:04,585 INFO org.apache.hadoop.yarn.server.resourcemanager.scheduler.AppSchedulingInfo: checking for deactivate of application :application_1523100158662_0005
2018-04-07 14:56:18,498 INFO org.apache.hadoop.yarn.server.resourcemanager.rmcontainer.RMContainerImpl: container_1523100158662_0005_01_000015 Container Transitioned from NEW to ALLOCATED
2018-04-07 14:56:18,499 INFO org.apache.hadoop.yarn.server.resourcemanager.RMAuditLogger: USER=root	OPERATION=AM Allocated Container	TARGET=SchedulerApp	RESULT=SUCCESS	APPID=application_1523100158662_0005	CONTAINERID=container_1523100158662_0005_01_000015
2018-04-07 14:56:18,499 INFO org.apache.hadoop.yarn.server.resourcemanager.scheduler.SchedulerNode: Assigned container container_1523100158662_0005_01_000015 of capacity <memory:1024, vCores:1> on host d1:59470, which has 7 containers, <memory:8192, vCores:7> used and <memory:0, vCores:1> available after allocation
2018-04-07 14:56:18,889 INFO org.apache.hadoop.yarn.server.resourcemanager.rmcontainer.RMContainerImpl: container_1523100158662_0005_01_000015 Container Transitioned from ALLOCATED to ACQUIRED
2018-04-07 14:56:19,506 INFO org.apache.hadoop.yarn.server.resourcemanager.rmcontainer.RMContainerImpl: container_1523100158662_0005_01_000015 Container Transitioned from ACQUIRED to RUNNING
2018-04-07 14:56:19,938 INFO org.apache.hadoop.yarn.server.resourcemanager.scheduler.AppSchedulingInfo: checking for deactivate of application :application_1523100158662_0005
2018-04-07 14:56:33,542 INFO org.apache.hadoop.yarn.server.resourcemanager.scheduler.fair.FSAppAttempt: Making reservation: node=d1 app_id=application_1523100158662_0005
2018-04-07 14:56:33,542 INFO org.apache.hadoop.yarn.server.resourcemanager.rmcontainer.RMContainerImpl: container_1523100158662_0005_01_000016 Container Transitioned from NEW to RESERVED
2018-04-07 14:56:33,542 INFO org.apache.hadoop.yarn.server.resourcemanager.scheduler.fair.FSSchedulerNode: Reserved container container_1523100158662_0005_01_000016 on node host: d1:59470 #containers=7 available=<memory:0, vCores:1> used=<memory:8192, vCores:7> for application org.apache.hadoop.yarn.server.resourcemanager.scheduler.fair.FSAppAttempt@323e6645
2018-04-07 14:56:49,909 INFO org.apache.hadoop.yarn.server.resourcemanager.rmcontainer.RMContainerImpl: container_1523100158662_0005_01_000014 Container Transitioned from RUNNING to COMPLETED
2018-04-07 14:56:49,909 INFO org.apache.hadoop.yarn.server.resourcemanager.scheduler.fair.FSAppAttempt: Completed container: container_1523100158662_0005_01_000014 in state: COMPLETED event:FINISHED
2018-04-07 14:56:49,911 INFO org.apache.hadoop.yarn.server.resourcemanager.RMAuditLogger: USER=root	OPERATION=AM Released Container	TARGET=SchedulerApp	RESULT=SUCCESS	APPID=application_1523100158662_0005	CONTAINERID=container_1523100158662_0005_01_000014
2018-04-07 14:56:49,911 INFO org.apache.hadoop.yarn.server.resourcemanager.scheduler.SchedulerNode: Released container container_1523100158662_0005_01_000014 of capacity <memory:1024, vCores:1> on host d1:59470, which currently has 6 containers, <memory:7168, vCores:6> used and <memory:1024, vCores:2> available, release resources=true
2018-04-07 14:56:49,911 INFO org.apache.hadoop.yarn.server.resourcemanager.scheduler.fair.FairScheduler: Application attempt appattempt_1523100158662_0005_000001 released container container_1523100158662_0005_01_000014 on node: host: d1:59470 #containers=6 available=<memory:1024, vCores:2> used=<memory:7168, vCores:6> with event: FINISHED
2018-04-07 14:56:49,913 INFO org.apache.hadoop.yarn.server.resourcemanager.rmcontainer.RMContainerImpl: container_1523100158662_0005_01_000009 Container Transitioned from RUNNING to COMPLETED
2018-04-07 14:56:49,913 INFO org.apache.hadoop.yarn.server.resourcemanager.scheduler.fair.FSAppAttempt: Completed container: container_1523100158662_0005_01_000009 in state: COMPLETED event:FINISHED
2018-04-07 14:56:49,913 INFO org.apache.hadoop.yarn.server.resourcemanager.RMAuditLogger: USER=root	OPERATION=AM Released Container	TARGET=SchedulerApp	RESULT=SUCCESS	APPID=application_1523100158662_0005	CONTAINERID=container_1523100158662_0005_01_000009
2018-04-07 14:56:49,913 INFO org.apache.hadoop.yarn.server.resourcemanager.scheduler.SchedulerNode: Released container container_1523100158662_0005_01_000009 of capacity <memory:1024, vCores:1> on host d1:59470, which currently has 5 containers, <memory:6144, vCores:5> used and <memory:2048, vCores:3> available, release resources=true
2018-04-07 14:56:49,913 INFO org.apache.hadoop.yarn.server.resourcemanager.scheduler.fair.FairScheduler: Application attempt appattempt_1523100158662_0005_000001 released container container_1523100158662_0005_01_000009 on node: host: d1:59470 #containers=5 available=<memory:2048, vCores:3> used=<memory:6144, vCores:5> with event: FINISHED
2018-04-07 14:56:49,913 INFO org.apache.hadoop.yarn.server.resourcemanager.rmcontainer.RMContainerImpl: container_1523100158662_0005_01_000016 Container Transitioned from NEW to ALLOCATED
2018-04-07 14:56:49,913 INFO org.apache.hadoop.yarn.server.resourcemanager.RMAuditLogger: USER=root	OPERATION=AM Allocated Container	TARGET=SchedulerApp	RESULT=SUCCESS	APPID=application_1523100158662_0005	CONTAINERID=container_1523100158662_0005_01_000016
2018-04-07 14:56:49,914 INFO org.apache.hadoop.yarn.server.resourcemanager.scheduler.fair.FSAppAttempt: Application application_1523100158662_0005 unreserved  on node host: d1:59470 #containers=5 available=<memory:2048, vCores:3> used=<memory:6144, vCores:5>, currently has 0 at priority 10; currentReservation <memory:0, vCores:0>
2018-04-07 14:56:49,914 INFO org.apache.hadoop.yarn.server.resourcemanager.scheduler.SchedulerNode: Assigned container container_1523100158662_0005_01_000016 of capacity <memory:1024, vCores:1> on host d1:59470, which has 6 containers, <memory:7168, vCores:6> used and <memory:1024, vCores:2> available after allocation
2018-04-07 14:56:50,173 INFO org.apache.hadoop.yarn.server.resourcemanager.rmcontainer.RMContainerImpl: container_1523100158662_0005_01_000016 Container Transitioned from ALLOCATED to ACQUIRED
2018-04-07 14:56:50,791 INFO org.apache.hadoop.yarn.server.resourcemanager.rmcontainer.RMContainerImpl: container_1523100158662_0005_01_000016 Container Transitioned from ACQUIRED to RUNNING
2018-04-07 14:56:51,192 INFO org.apache.hadoop.yarn.server.resourcemanager.scheduler.AppSchedulingInfo: checking for deactivate of application :application_1523100158662_0005
2018-04-07 14:56:51,972 INFO org.apache.hadoop.yarn.server.resourcemanager.rmcontainer.RMContainerImpl: container_1523100158662_0005_01_000015 Container Transitioned from RUNNING to COMPLETED
2018-04-07 14:56:51,972 INFO org.apache.hadoop.yarn.server.resourcemanager.scheduler.fair.FSAppAttempt: Completed container: container_1523100158662_0005_01_000015 in state: COMPLETED event:FINISHED
2018-04-07 14:56:51,972 INFO org.apache.hadoop.yarn.server.resourcemanager.RMAuditLogger: USER=root	OPERATION=AM Released Container	TARGET=SchedulerApp	RESULT=SUCCESS	APPID=application_1523100158662_0005	CONTAINERID=container_1523100158662_0005_01_000015
2018-04-07 14:56:51,972 INFO org.apache.hadoop.yarn.server.resourcemanager.scheduler.SchedulerNode: Released container container_1523100158662_0005_01_000015 of capacity <memory:1024, vCores:1> on host d1:59470, which currently has 5 containers, <memory:6144, vCores:5> used and <memory:2048, vCores:3> available, release resources=true
2018-04-07 14:56:51,972 INFO org.apache.hadoop.yarn.server.resourcemanager.scheduler.fair.FairScheduler: Application attempt appattempt_1523100158662_0005_000001 released container container_1523100158662_0005_01_000015 on node: host: d1:59470 #containers=5 available=<memory:2048, vCores:3> used=<memory:6144, vCores:5> with event: FINISHED
2018-04-07 14:56:51,973 INFO org.apache.hadoop.yarn.server.resourcemanager.rmcontainer.RMContainerImpl: container_1523100158662_0005_01_000010 Container Transitioned from RUNNING to COMPLETED
2018-04-07 14:56:51,974 INFO org.apache.hadoop.yarn.server.resourcemanager.scheduler.fair.FSAppAttempt: Completed container: container_1523100158662_0005_01_000010 in state: COMPLETED event:FINISHED
2018-04-07 14:56:51,974 INFO org.apache.hadoop.yarn.server.resourcemanager.RMAuditLogger: USER=root	OPERATION=AM Released Container	TARGET=SchedulerApp	RESULT=SUCCESS	APPID=application_1523100158662_0005	CONTAINERID=container_1523100158662_0005_01_000010
2018-04-07 14:56:51,974 INFO org.apache.hadoop.yarn.server.resourcemanager.scheduler.SchedulerNode: Released container container_1523100158662_0005_01_000010 of capacity <memory:1024, vCores:1> on host d1:59470, which currently has 4 containers, <memory:5120, vCores:4> used and <memory:3072, vCores:4> available, release resources=true
2018-04-07 14:56:51,974 INFO org.apache.hadoop.yarn.server.resourcemanager.scheduler.fair.FairScheduler: Application attempt appattempt_1523100158662_0005_000001 released container container_1523100158662_0005_01_000010 on node: host: d1:59470 #containers=4 available=<memory:3072, vCores:4> used=<memory:5120, vCores:4> with event: FINISHED
2018-04-07 14:56:52,976 INFO org.apache.hadoop.yarn.server.resourcemanager.rmcontainer.RMContainerImpl: container_1523100158662_0005_01_000017 Container Transitioned from NEW to ALLOCATED
2018-04-07 14:56:52,977 INFO org.apache.hadoop.yarn.server.resourcemanager.RMAuditLogger: USER=root	OPERATION=AM Allocated Container	TARGET=SchedulerApp	RESULT=SUCCESS	APPID=application_1523100158662_0005	CONTAINERID=container_1523100158662_0005_01_000017
2018-04-07 14:56:52,977 INFO org.apache.hadoop.yarn.server.resourcemanager.scheduler.SchedulerNode: Assigned container container_1523100158662_0005_01_000017 of capacity <memory:1024, vCores:1> on host d1:59470, which has 5 containers, <memory:6144, vCores:5> used and <memory:2048, vCores:3> available after allocation
2018-04-07 14:56:53,217 INFO org.apache.hadoop.yarn.server.resourcemanager.rmcontainer.RMContainerImpl: container_1523100158662_0005_01_000017 Container Transitioned from ALLOCATED to ACQUIRED
2018-04-07 14:56:53,512 INFO org.apache.hadoop.yarn.server.resourcemanager.rmcontainer.RMContainerImpl: container_1523100158662_0005_01_000017 Container Transitioned from ACQUIRED to RUNNING
2018-04-07 14:56:54,227 INFO org.apache.hadoop.yarn.server.resourcemanager.scheduler.AppSchedulingInfo: checking for deactivate of application :application_1523100158662_0005
2018-04-07 14:56:54,664 INFO org.apache.hadoop.yarn.server.resourcemanager.rmcontainer.RMContainerImpl: container_1523100158662_0005_01_000016 Container Transitioned from RUNNING to COMPLETED
2018-04-07 14:56:54,665 INFO org.apache.hadoop.yarn.server.resourcemanager.scheduler.fair.FSAppAttempt: Completed container: container_1523100158662_0005_01_000016 in state: COMPLETED event:FINISHED
2018-04-07 14:56:54,665 INFO org.apache.hadoop.yarn.server.resourcemanager.RMAuditLogger: USER=root	OPERATION=AM Released Container	TARGET=SchedulerApp	RESULT=SUCCESS	APPID=application_1523100158662_0005	CONTAINERID=container_1523100158662_0005_01_000016
2018-04-07 14:56:54,666 INFO org.apache.hadoop.yarn.server.resourcemanager.scheduler.SchedulerNode: Released container container_1523100158662_0005_01_000016 of capacity <memory:1024, vCores:1> on host d1:59470, which currently has 4 containers, <memory:5120, vCores:4> used and <memory:3072, vCores:4> available, release resources=true
2018-04-07 14:56:54,666 INFO org.apache.hadoop.yarn.server.resourcemanager.scheduler.fair.FairScheduler: Application attempt appattempt_1523100158662_0005_000001 released container container_1523100158662_0005_01_000016 on node: host: d1:59470 #containers=4 available=<memory:3072, vCores:4> used=<memory:5120, vCores:4> with event: FINISHED
2018-04-07 14:56:54,669 INFO org.apache.hadoop.yarn.server.resourcemanager.rmcontainer.RMContainerImpl: container_1523100158662_0005_01_000011 Container Transitioned from RUNNING to COMPLETED
2018-04-07 14:56:54,671 INFO org.apache.hadoop.yarn.server.resourcemanager.scheduler.fair.FSAppAttempt: Completed container: container_1523100158662_0005_01_000011 in state: COMPLETED event:FINISHED
2018-04-07 14:56:54,671 INFO org.apache.hadoop.yarn.server.resourcemanager.RMAuditLogger: USER=root	OPERATION=AM Released Container	TARGET=SchedulerApp	RESULT=SUCCESS	APPID=application_1523100158662_0005	CONTAINERID=container_1523100158662_0005_01_000011
2018-04-07 14:56:54,671 INFO org.apache.hadoop.yarn.server.resourcemanager.scheduler.SchedulerNode: Released container container_1523100158662_0005_01_000011 of capacity <memory:1024, vCores:1> on host d1:59470, which currently has 3 containers, <memory:4096, vCores:3> used and <memory:4096, vCores:5> available, release resources=true
2018-04-07 14:56:54,671 INFO org.apache.hadoop.yarn.server.resourcemanager.scheduler.fair.FairScheduler: Application attempt appattempt_1523100158662_0005_000001 released container container_1523100158662_0005_01_000011 on node: host: d1:59470 #containers=3 available=<memory:4096, vCores:5> used=<memory:4096, vCores:3> with event: FINISHED
2018-04-07 14:56:56,451 INFO org.apache.hadoop.yarn.server.resourcemanager.rmcontainer.RMContainerImpl: container_1523100158662_0005_01_000017 Container Transitioned from RUNNING to COMPLETED
2018-04-07 14:56:56,451 INFO org.apache.hadoop.yarn.server.resourcemanager.scheduler.fair.FSAppAttempt: Completed container: container_1523100158662_0005_01_000017 in state: COMPLETED event:FINISHED
2018-04-07 14:56:56,451 INFO org.apache.hadoop.yarn.server.resourcemanager.RMAuditLogger: USER=root	OPERATION=AM Released Container	TARGET=SchedulerApp	RESULT=SUCCESS	APPID=application_1523100158662_0005	CONTAINERID=container_1523100158662_0005_01_000017
2018-04-07 14:56:56,452 INFO org.apache.hadoop.yarn.server.resourcemanager.scheduler.SchedulerNode: Released container container_1523100158662_0005_01_000017 of capacity <memory:1024, vCores:1> on host d1:59470, which currently has 2 containers, <memory:3072, vCores:2> used and <memory:5120, vCores:6> available, release resources=true
2018-04-07 14:56:56,452 INFO org.apache.hadoop.yarn.server.resourcemanager.scheduler.fair.FairScheduler: Application attempt appattempt_1523100158662_0005_000001 released container container_1523100158662_0005_01_000017 on node: host: d1:59470 #containers=2 available=<memory:5120, vCores:6> used=<memory:3072, vCores:2> with event: FINISHED
2018-04-07 14:56:56,456 INFO org.apache.hadoop.yarn.server.resourcemanager.rmcontainer.RMContainerImpl: container_1523100158662_0005_01_000012 Container Transitioned from RUNNING to COMPLETED
2018-04-07 14:56:56,456 INFO org.apache.hadoop.yarn.server.resourcemanager.scheduler.fair.FSAppAttempt: Completed container: container_1523100158662_0005_01_000012 in state: COMPLETED event:FINISHED
2018-04-07 14:56:56,456 INFO org.apache.hadoop.yarn.server.resourcemanager.RMAuditLogger: USER=root	OPERATION=AM Released Container	TARGET=SchedulerApp	RESULT=SUCCESS	APPID=application_1523100158662_0005	CONTAINERID=container_1523100158662_0005_01_000012
2018-04-07 14:56:56,456 INFO org.apache.hadoop.yarn.server.resourcemanager.scheduler.SchedulerNode: Released container container_1523100158662_0005_01_000012 of capacity <memory:1024, vCores:1> on host d1:59470, which currently has 1 containers, <memory:2048, vCores:1> used and <memory:6144, vCores:7> available, release resources=true
2018-04-07 14:56:56,456 INFO org.apache.hadoop.yarn.server.resourcemanager.scheduler.fair.FairScheduler: Application attempt appattempt_1523100158662_0005_000001 released container container_1523100158662_0005_01_000012 on node: host: d1:59470 #containers=1 available=<memory:6144, vCores:7> used=<memory:2048, vCores:1> with event: FINISHED
2018-04-07 14:56:58,055 INFO org.apache.hadoop.yarn.server.resourcemanager.rmapp.attempt.RMAppAttemptImpl: Updating application attempt appattempt_1523100158662_0005_000001 with final state: FINISHING, and exit status: -1000
2018-04-07 14:56:58,057 INFO org.apache.hadoop.yarn.server.resourcemanager.rmapp.attempt.RMAppAttemptImpl: appattempt_1523100158662_0005_000001 State change from RUNNING to FINAL_SAVING
2018-04-07 14:56:58,057 INFO org.apache.hadoop.yarn.server.resourcemanager.rmapp.attempt.RMAppAttemptImpl: appattempt_1523100158662_0005_000001 State change from FINAL_SAVING to FINISHING
2018-04-07 14:56:58,057 INFO org.apache.hadoop.yarn.server.resourcemanager.rmapp.RMAppImpl: Updating application application_1523100158662_0005 with final state: FINISHING
2018-04-07 14:56:58,058 INFO org.apache.hadoop.yarn.server.resourcemanager.recovery.RMStateStore: Updating info for app: application_1523100158662_0005
2018-04-07 14:56:58,058 INFO org.apache.hadoop.yarn.server.resourcemanager.rmapp.RMAppImpl: application_1523100158662_0005 State change from RUNNING to FINAL_SAVING
2018-04-07 14:56:58,058 INFO org.apache.hadoop.yarn.server.resourcemanager.rmapp.RMAppImpl: application_1523100158662_0005 State change from FINAL_SAVING to FINISHING
2018-04-07 14:56:59,093 INFO org.apache.hadoop.yarn.server.resourcemanager.ApplicationMasterService: application_1523100158662_0005 unregistered successfully. 
2018-04-07 14:57:05,576 INFO org.apache.hadoop.yarn.server.resourcemanager.rmcontainer.RMContainerImpl: container_1523100158662_0005_01_000001 Container Transitioned from RUNNING to COMPLETED
2018-04-07 14:57:05,576 INFO org.apache.hadoop.yarn.server.resourcemanager.scheduler.fair.FSAppAttempt: Completed container: container_1523100158662_0005_01_000001 in state: COMPLETED event:FINISHED
2018-04-07 14:57:05,576 INFO org.apache.hadoop.yarn.server.resourcemanager.RMAuditLogger: USER=root	OPERATION=AM Released Container	TARGET=SchedulerApp	RESULT=SUCCESS	APPID=application_1523100158662_0005	CONTAINERID=container_1523100158662_0005_01_000001
2018-04-07 14:57:05,594 INFO org.apache.hadoop.yarn.server.resourcemanager.scheduler.SchedulerNode: Released container container_1523100158662_0005_01_000001 of capacity <memory:2048, vCores:1> on host d1:59470, which currently has 0 containers, <memory:0, vCores:0> used and <memory:8192, vCores:8> available, release resources=true
2018-04-07 14:57:05,594 INFO org.apache.hadoop.yarn.server.resourcemanager.scheduler.fair.FairScheduler: Application attempt appattempt_1523100158662_0005_000001 released container container_1523100158662_0005_01_000001 on node: host: d1:59470 #containers=0 available=<memory:8192, vCores:8> used=<memory:0, vCores:0> with event: FINISHED
2018-04-07 14:57:05,578 INFO org.apache.hadoop.yarn.server.resourcemanager.ApplicationMasterService: Unregistering app attempt : appattempt_1523100158662_0005_000001
2018-04-07 14:57:05,597 INFO org.apache.hadoop.yarn.server.resourcemanager.security.AMRMTokenSecretManager: Application finished, removing password for appattempt_1523100158662_0005_000001
2018-04-07 14:57:05,598 INFO org.apache.hadoop.yarn.server.resourcemanager.rmapp.attempt.RMAppAttemptImpl: appattempt_1523100158662_0005_000001 State change from FINISHING to FINISHED
2018-04-07 14:57:05,598 INFO org.apache.hadoop.yarn.server.resourcemanager.rmapp.RMAppImpl: application_1523100158662_0005 State change from FINISHING to FINISHED
2018-04-07 14:57:05,599 INFO org.apache.hadoop.yarn.server.resourcemanager.RMAuditLogger: USER=root	OPERATION=Application Finished - Succeeded	TARGET=RMAppManager	RESULT=SUCCESS	APPID=application_1523100158662_0005
2018-04-07 14:57:05,599 INFO org.apache.hadoop.yarn.server.resourcemanager.scheduler.fair.FairScheduler: Application appattempt_1523100158662_0005_000001 is done. finalState=FINISHED
2018-04-07 14:57:05,600 INFO org.apache.hadoop.yarn.server.resourcemanager.scheduler.AppSchedulingInfo: Application application_1523100158662_0005 requests cleared
2018-04-07 14:57:05,601 INFO org.apache.hadoop.yarn.server.resourcemanager.RMAppManager$ApplicationSummary: appId=application_1523100158662_0005,name=word count,user=root,queue=root.root,state=FINISHED,trackingUrl=http://d1:8088/proxy/application_1523100158662_0005/,appMasterHost=d1,startTime=1523112650755,finishTime=1523113018057,finalStatus=SUCCEEDED,memorySeconds=2333602,vcoreSeconds=1897,preemptedAMContainers=0,preemptedNonAMContainers=0,preemptedResources=<memory:0\, vCores:0>,applicationType=MAPREDUCE
2018-04-07 14:57:05,603 INFO org.apache.hadoop.yarn.server.resourcemanager.amlauncher.AMLauncher: Cleaning master appattempt_1523100158662_0005_000001
2018-04-07 15:24:09,832 INFO org.apache.hadoop.yarn.server.resourcemanager.ClientRMService: Allocated new applicationId: 6
2018-04-07 15:25:38,830 INFO org.apache.hadoop.yarn.server.resourcemanager.ClientRMService: Allocated new applicationId: 7
2018-04-07 15:25:51,558 INFO org.apache.hadoop.yarn.server.resourcemanager.rmapp.RMAppImpl: Storing application with id application_1523100158662_0007
2018-04-07 15:25:51,558 INFO org.apache.hadoop.yarn.server.resourcemanager.rmapp.RMAppImpl: application_1523100158662_0007 State change from NEW to NEW_SAVING
2018-04-07 15:25:51,558 INFO org.apache.hadoop.yarn.server.resourcemanager.recovery.RMStateStore: Storing info for app: application_1523100158662_0007
2018-04-07 15:25:51,558 INFO org.apache.hadoop.yarn.server.resourcemanager.rmapp.RMAppImpl: application_1523100158662_0007 State change from NEW_SAVING to SUBMITTED
2018-04-07 15:25:51,565 INFO org.apache.hadoop.yarn.server.resourcemanager.scheduler.fair.FairScheduler: Accepted application application_1523100158662_0007 from user: root, in queue: default, currently num of applications: 1
2018-04-07 15:25:51,579 INFO org.apache.hadoop.yarn.server.resourcemanager.rmapp.RMAppImpl: application_1523100158662_0007 State change from SUBMITTED to ACCEPTED
2018-04-07 15:25:51,579 INFO org.apache.hadoop.yarn.server.resourcemanager.ApplicationMasterService: Registering app attempt : appattempt_1523100158662_0007_000001
2018-04-07 15:25:51,579 INFO org.apache.hadoop.yarn.server.resourcemanager.rmapp.attempt.RMAppAttemptImpl: appattempt_1523100158662_0007_000001 State change from NEW to SUBMITTED
2018-04-07 15:25:51,580 INFO org.apache.hadoop.yarn.server.resourcemanager.scheduler.fair.FairScheduler: Added Application Attempt appattempt_1523100158662_0007_000001 to scheduler from user: root
2018-04-07 15:25:51,584 INFO org.apache.hadoop.yarn.server.resourcemanager.rmapp.attempt.RMAppAttemptImpl: appattempt_1523100158662_0007_000001 State change from SUBMITTED to SCHEDULED
2018-04-07 15:25:51,587 INFO org.apache.hadoop.yarn.server.resourcemanager.ClientRMService: Application with id 7 submitted by user root
2018-04-07 15:25:51,587 INFO org.apache.hadoop.yarn.server.resourcemanager.RMAuditLogger: USER=root	IP=172.17.0.2	OPERATION=Submit Application Request	TARGET=ClientRMService	RESULT=SUCCESS	APPID=application_1523100158662_0007
2018-04-07 15:25:52,328 INFO org.apache.hadoop.yarn.server.resourcemanager.rmcontainer.RMContainerImpl: container_1523100158662_0007_01_000001 Container Transitioned from NEW to ALLOCATED
2018-04-07 15:25:52,328 INFO org.apache.hadoop.yarn.server.resourcemanager.RMAuditLogger: USER=root	OPERATION=AM Allocated Container	TARGET=SchedulerApp	RESULT=SUCCESS	APPID=application_1523100158662_0007	CONTAINERID=container_1523100158662_0007_01_000001
2018-04-07 15:25:52,328 INFO org.apache.hadoop.yarn.server.resourcemanager.scheduler.SchedulerNode: Assigned container container_1523100158662_0007_01_000001 of capacity <memory:2048, vCores:1> on host d1:59470, which has 1 containers, <memory:2048, vCores:1> used and <memory:6144, vCores:7> available after allocation
2018-04-07 15:25:52,353 INFO org.apache.hadoop.yarn.server.resourcemanager.security.NMTokenSecretManagerInRM: Sending NMToken for nodeId : d1:59470 for container : container_1523100158662_0007_01_000001
2018-04-07 15:25:52,418 INFO org.apache.hadoop.yarn.server.resourcemanager.rmcontainer.RMContainerImpl: container_1523100158662_0007_01_000001 Container Transitioned from ALLOCATED to ACQUIRED
2018-04-07 15:25:52,419 INFO org.apache.hadoop.yarn.server.resourcemanager.security.NMTokenSecretManagerInRM: Clear node set for appattempt_1523100158662_0007_000001
2018-04-07 15:25:52,427 INFO org.apache.hadoop.yarn.server.resourcemanager.rmapp.attempt.RMAppAttemptImpl: Storing attempt: AppId: application_1523100158662_0007 AttemptId: appattempt_1523100158662_0007_000001 MasterContainer: Container: [ContainerId: container_1523100158662_0007_01_000001, NodeId: d1:59470, NodeHttpAddress: d1:8042, Resource: <memory:2048, vCores:1>, Priority: 0, Token: Token { kind: ContainerToken, service: 172.17.0.2:59470 }, ]
2018-04-07 15:25:52,431 INFO org.apache.hadoop.yarn.server.resourcemanager.rmapp.attempt.RMAppAttemptImpl: appattempt_1523100158662_0007_000001 State change from SCHEDULED to ALLOCATED_SAVING
2018-04-07 15:25:52,435 INFO org.apache.hadoop.yarn.server.resourcemanager.rmapp.attempt.RMAppAttemptImpl: appattempt_1523100158662_0007_000001 State change from ALLOCATED_SAVING to ALLOCATED
2018-04-07 15:25:52,441 INFO org.apache.hadoop.yarn.server.resourcemanager.amlauncher.AMLauncher: Launching masterappattempt_1523100158662_0007_000001
2018-04-07 15:25:52,466 INFO org.apache.hadoop.yarn.server.resourcemanager.amlauncher.AMLauncher: Setting up container Container: [ContainerId: container_1523100158662_0007_01_000001, NodeId: d1:59470, NodeHttpAddress: d1:8042, Resource: <memory:2048, vCores:1>, Priority: 0, Token: Token { kind: ContainerToken, service: 172.17.0.2:59470 }, ] for AM appattempt_1523100158662_0007_000001
2018-04-07 15:25:52,466 INFO org.apache.hadoop.yarn.server.resourcemanager.amlauncher.AMLauncher: Command to launch container container_1523100158662_0007_01_000001 : $JAVA_HOME/bin/java -Dlog4j.configuration=container-log4j.properties -Dyarn.app.container.log.dir=<LOG_DIR> -Dyarn.app.container.log.filesize=0 -Dhadoop.root.logger=INFO,CLA -Dhadoop.root.logfile=syslog  -Xmx1024m org.apache.hadoop.mapreduce.v2.app.MRAppMaster 1><LOG_DIR>/stdout 2><LOG_DIR>/stderr 
2018-04-07 15:25:52,467 INFO org.apache.hadoop.yarn.server.resourcemanager.security.AMRMTokenSecretManager: Create AMRMToken for ApplicationAttempt: appattempt_1523100158662_0007_000001
2018-04-07 15:25:52,467 INFO org.apache.hadoop.yarn.server.resourcemanager.security.AMRMTokenSecretManager: Creating password for appattempt_1523100158662_0007_000001
2018-04-07 15:25:52,797 INFO org.apache.hadoop.yarn.server.resourcemanager.amlauncher.AMLauncher: Done launching container Container: [ContainerId: container_1523100158662_0007_01_000001, NodeId: d1:59470, NodeHttpAddress: d1:8042, Resource: <memory:2048, vCores:1>, Priority: 0, Token: Token { kind: ContainerToken, service: 172.17.0.2:59470 }, ] for AM appattempt_1523100158662_0007_000001
2018-04-07 15:25:52,797 INFO org.apache.hadoop.yarn.server.resourcemanager.rmapp.attempt.RMAppAttemptImpl: appattempt_1523100158662_0007_000001 State change from ALLOCATED to LAUNCHED
2018-04-07 15:25:53,440 INFO org.apache.hadoop.yarn.server.resourcemanager.rmcontainer.RMContainerImpl: container_1523100158662_0007_01_000001 Container Transitioned from ACQUIRED to RUNNING
2018-04-07 15:27:02,918 INFO SecurityLogger.org.apache.hadoop.ipc.Server: Auth successful for appattempt_1523100158662_0007_000001 (auth:SIMPLE)
2018-04-07 15:27:02,985 INFO org.apache.hadoop.yarn.server.resourcemanager.ApplicationMasterService: AM registration appattempt_1523100158662_0007_000001
2018-04-07 15:27:02,985 INFO org.apache.hadoop.yarn.server.resourcemanager.rmapp.attempt.RMAppAttemptImpl: appattempt_1523100158662_0007_000001 State change from LAUNCHED to RUNNING
2018-04-07 15:27:02,985 INFO org.apache.hadoop.yarn.server.resourcemanager.rmapp.RMAppImpl: application_1523100158662_0007 State change from ACCEPTED to RUNNING
2018-04-07 15:27:02,985 INFO org.apache.hadoop.yarn.server.resourcemanager.RMAuditLogger: USER=root	IP=172.17.0.2	OPERATION=Register App Master	TARGET=ApplicationMasterService	RESULT=SUCCESS	APPID=application_1523100158662_0007	APPATTEMPTID=appattempt_1523100158662_0007_000001
2018-04-07 15:27:08,389 INFO org.apache.hadoop.yarn.server.resourcemanager.rmcontainer.RMContainerImpl: container_1523100158662_0007_01_000002 Container Transitioned from NEW to ALLOCATED
2018-04-07 15:27:08,390 INFO org.apache.hadoop.yarn.server.resourcemanager.RMAuditLogger: USER=root	OPERATION=AM Allocated Container	TARGET=SchedulerApp	RESULT=SUCCESS	APPID=application_1523100158662_0007	CONTAINERID=container_1523100158662_0007_01_000002
2018-04-07 15:27:08,390 INFO org.apache.hadoop.yarn.server.resourcemanager.scheduler.SchedulerNode: Assigned container container_1523100158662_0007_01_000002 of capacity <memory:1024, vCores:1> on host d1:59470, which has 2 containers, <memory:3072, vCores:2> used and <memory:5120, vCores:6> available after allocation
2018-04-07 15:27:09,958 INFO org.apache.hadoop.yarn.server.resourcemanager.security.NMTokenSecretManagerInRM: Sending NMToken for nodeId : d1:59470 for container : container_1523100158662_0007_01_000002
2018-04-07 15:27:09,966 INFO org.apache.hadoop.yarn.server.resourcemanager.rmcontainer.RMContainerImpl: container_1523100158662_0007_01_000002 Container Transitioned from ALLOCATED to ACQUIRED
2018-04-07 15:27:12,688 INFO org.apache.hadoop.yarn.server.resourcemanager.scheduler.AppSchedulingInfo: checking for deactivate of application :application_1523100158662_0007
2018-04-07 15:27:13,404 INFO org.apache.hadoop.yarn.server.resourcemanager.rmcontainer.RMContainerImpl: container_1523100158662_0007_01_000002 Container Transitioned from ACQUIRED to RUNNING
2018-04-07 15:27:26,268 INFO org.apache.hadoop.yarn.server.resourcemanager.rmcontainer.RMContainerImpl: container_1523100158662_0007_01_000002 Container Transitioned from RUNNING to COMPLETED
2018-04-07 15:27:26,268 INFO org.apache.hadoop.yarn.server.resourcemanager.scheduler.fair.FSAppAttempt: Completed container: container_1523100158662_0007_01_000002 in state: COMPLETED event:FINISHED
2018-04-07 15:27:26,268 INFO org.apache.hadoop.yarn.server.resourcemanager.RMAuditLogger: USER=root	OPERATION=AM Released Container	TARGET=SchedulerApp	RESULT=SUCCESS	APPID=application_1523100158662_0007	CONTAINERID=container_1523100158662_0007_01_000002
2018-04-07 15:27:26,268 INFO org.apache.hadoop.yarn.server.resourcemanager.scheduler.SchedulerNode: Released container container_1523100158662_0007_01_000002 of capacity <memory:1024, vCores:1> on host d1:59470, which currently has 1 containers, <memory:2048, vCores:1> used and <memory:6144, vCores:7> available, release resources=true
2018-04-07 15:27:26,268 INFO org.apache.hadoop.yarn.server.resourcemanager.scheduler.fair.FairScheduler: Application attempt appattempt_1523100158662_0007_000001 released container container_1523100158662_0007_01_000002 on node: host: d1:59470 #containers=1 available=<memory:6144, vCores:7> used=<memory:2048, vCores:1> with event: FINISHED
2018-04-07 15:27:27,269 INFO org.apache.hadoop.yarn.server.resourcemanager.rmcontainer.RMContainerImpl: container_1523100158662_0007_01_000003 Container Transitioned from NEW to ALLOCATED
2018-04-07 15:27:27,269 INFO org.apache.hadoop.yarn.server.resourcemanager.RMAuditLogger: USER=root	OPERATION=AM Allocated Container	TARGET=SchedulerApp	RESULT=SUCCESS	APPID=application_1523100158662_0007	CONTAINERID=container_1523100158662_0007_01_000003
2018-04-07 15:27:27,269 INFO org.apache.hadoop.yarn.server.resourcemanager.scheduler.SchedulerNode: Assigned container container_1523100158662_0007_01_000003 of capacity <memory:1024, vCores:1> on host d1:59470, which has 2 containers, <memory:3072, vCores:2> used and <memory:5120, vCores:6> available after allocation
2018-04-07 15:27:28,086 INFO org.apache.hadoop.yarn.server.resourcemanager.rmcontainer.RMContainerImpl: container_1523100158662_0007_01_000003 Container Transitioned from ALLOCATED to ACQUIRED
2018-04-07 15:27:28,273 INFO org.apache.hadoop.yarn.server.resourcemanager.rmcontainer.RMContainerImpl: container_1523100158662_0007_01_000003 Container Transitioned from ACQUIRED to RUNNING
2018-04-07 15:27:28,274 INFO org.apache.hadoop.yarn.server.resourcemanager.rmcontainer.RMContainerImpl: container_1523100158662_0007_01_000004 Container Transitioned from NEW to ALLOCATED
2018-04-07 15:27:28,274 INFO org.apache.hadoop.yarn.server.resourcemanager.RMAuditLogger: USER=root	OPERATION=AM Allocated Container	TARGET=SchedulerApp	RESULT=SUCCESS	APPID=application_1523100158662_0007	CONTAINERID=container_1523100158662_0007_01_000004
2018-04-07 15:27:28,274 INFO org.apache.hadoop.yarn.server.resourcemanager.scheduler.SchedulerNode: Assigned container container_1523100158662_0007_01_000004 of capacity <memory:1024, vCores:1> on host d1:59470, which has 3 containers, <memory:4096, vCores:3> used and <memory:4096, vCores:5> available after allocation
2018-04-07 15:27:29,094 INFO org.apache.hadoop.yarn.server.resourcemanager.rmcontainer.RMContainerImpl: container_1523100158662_0007_01_000004 Container Transitioned from ALLOCATED to ACQUIRED
2018-04-07 15:27:29,276 INFO org.apache.hadoop.yarn.server.resourcemanager.rmcontainer.RMContainerImpl: container_1523100158662_0007_01_000004 Container Transitioned from ACQUIRED to RUNNING
2018-04-07 15:27:29,277 INFO org.apache.hadoop.yarn.server.resourcemanager.rmcontainer.RMContainerImpl: container_1523100158662_0007_01_000005 Container Transitioned from NEW to ALLOCATED
2018-04-07 15:27:29,277 INFO org.apache.hadoop.yarn.server.resourcemanager.RMAuditLogger: USER=root	OPERATION=AM Allocated Container	TARGET=SchedulerApp	RESULT=SUCCESS	APPID=application_1523100158662_0007	CONTAINERID=container_1523100158662_0007_01_000005
2018-04-07 15:27:29,277 INFO org.apache.hadoop.yarn.server.resourcemanager.scheduler.SchedulerNode: Assigned container container_1523100158662_0007_01_000005 of capacity <memory:1024, vCores:1> on host d1:59470, which has 4 containers, <memory:5120, vCores:4> used and <memory:3072, vCores:4> available after allocation
2018-04-07 15:27:30,101 INFO org.apache.hadoop.yarn.server.resourcemanager.rmcontainer.RMContainerImpl: container_1523100158662_0007_01_000005 Container Transitioned from ALLOCATED to ACQUIRED
2018-04-07 15:27:30,280 INFO org.apache.hadoop.yarn.server.resourcemanager.rmcontainer.RMContainerImpl: container_1523100158662_0007_01_000005 Container Transitioned from ACQUIRED to RUNNING
2018-04-07 15:27:30,281 INFO org.apache.hadoop.yarn.server.resourcemanager.rmcontainer.RMContainerImpl: container_1523100158662_0007_01_000006 Container Transitioned from NEW to ALLOCATED
2018-04-07 15:27:30,281 INFO org.apache.hadoop.yarn.server.resourcemanager.RMAuditLogger: USER=root	OPERATION=AM Allocated Container	TARGET=SchedulerApp	RESULT=SUCCESS	APPID=application_1523100158662_0007	CONTAINERID=container_1523100158662_0007_01_000006
2018-04-07 15:27:30,281 INFO org.apache.hadoop.yarn.server.resourcemanager.scheduler.SchedulerNode: Assigned container container_1523100158662_0007_01_000006 of capacity <memory:1024, vCores:1> on host d1:59470, which has 5 containers, <memory:6144, vCores:5> used and <memory:2048, vCores:3> available after allocation
2018-04-07 15:27:31,146 INFO org.apache.hadoop.yarn.server.resourcemanager.rmcontainer.RMContainerImpl: container_1523100158662_0007_01_000006 Container Transitioned from ALLOCATED to ACQUIRED
2018-04-07 15:27:31,285 INFO org.apache.hadoop.yarn.server.resourcemanager.rmcontainer.RMContainerImpl: container_1523100158662_0007_01_000006 Container Transitioned from ACQUIRED to RUNNING
2018-04-07 15:27:31,286 INFO org.apache.hadoop.yarn.server.resourcemanager.rmcontainer.RMContainerImpl: container_1523100158662_0007_01_000007 Container Transitioned from NEW to ALLOCATED
2018-04-07 15:27:31,286 INFO org.apache.hadoop.yarn.server.resourcemanager.RMAuditLogger: USER=root	OPERATION=AM Allocated Container	TARGET=SchedulerApp	RESULT=SUCCESS	APPID=application_1523100158662_0007	CONTAINERID=container_1523100158662_0007_01_000007
2018-04-07 15:27:31,286 INFO org.apache.hadoop.yarn.server.resourcemanager.scheduler.SchedulerNode: Assigned container container_1523100158662_0007_01_000007 of capacity <memory:1024, vCores:1> on host d1:59470, which has 6 containers, <memory:7168, vCores:6> used and <memory:1024, vCores:2> available after allocation
2018-04-07 15:27:32,153 INFO org.apache.hadoop.yarn.server.resourcemanager.rmcontainer.RMContainerImpl: container_1523100158662_0007_01_000007 Container Transitioned from ALLOCATED to ACQUIRED
2018-04-07 15:27:32,292 INFO org.apache.hadoop.yarn.server.resourcemanager.rmcontainer.RMContainerImpl: container_1523100158662_0007_01_000007 Container Transitioned from ACQUIRED to RUNNING
2018-04-07 15:27:32,293 INFO org.apache.hadoop.yarn.server.resourcemanager.rmcontainer.RMContainerImpl: container_1523100158662_0007_01_000008 Container Transitioned from NEW to ALLOCATED
2018-04-07 15:27:32,293 INFO org.apache.hadoop.yarn.server.resourcemanager.RMAuditLogger: USER=root	OPERATION=AM Allocated Container	TARGET=SchedulerApp	RESULT=SUCCESS	APPID=application_1523100158662_0007	CONTAINERID=container_1523100158662_0007_01_000008
2018-04-07 15:27:32,293 INFO org.apache.hadoop.yarn.server.resourcemanager.scheduler.SchedulerNode: Assigned container container_1523100158662_0007_01_000008 of capacity <memory:1024, vCores:1> on host d1:59470, which has 7 containers, <memory:8192, vCores:7> used and <memory:0, vCores:1> available after allocation
2018-04-07 15:27:33,161 INFO org.apache.hadoop.yarn.server.resourcemanager.rmcontainer.RMContainerImpl: container_1523100158662_0007_01_000008 Container Transitioned from ALLOCATED to ACQUIRED
2018-04-07 15:27:33,291 INFO org.apache.hadoop.yarn.server.resourcemanager.rmcontainer.RMContainerImpl: container_1523100158662_0007_01_000008 Container Transitioned from ACQUIRED to RUNNING
2018-04-07 15:27:33,291 INFO org.apache.hadoop.yarn.server.resourcemanager.scheduler.fair.FSAppAttempt: Making reservation: node=d1 app_id=application_1523100158662_0007
2018-04-07 15:27:33,291 INFO org.apache.hadoop.yarn.server.resourcemanager.rmcontainer.RMContainerImpl: container_1523100158662_0007_01_000009 Container Transitioned from NEW to RESERVED
2018-04-07 15:27:33,291 INFO org.apache.hadoop.yarn.server.resourcemanager.scheduler.fair.FSSchedulerNode: Reserved container container_1523100158662_0007_01_000009 on node host: d1:59470 #containers=7 available=<memory:0, vCores:1> used=<memory:8192, vCores:7> for application org.apache.hadoop.yarn.server.resourcemanager.scheduler.fair.FSAppAttempt@64ecf952
2018-04-07 15:27:44,250 INFO org.apache.hadoop.yarn.server.resourcemanager.rmcontainer.RMContainerImpl: container_1523100158662_0007_01_000003 Container Transitioned from RUNNING to COMPLETED
2018-04-07 15:27:44,250 INFO org.apache.hadoop.yarn.server.resourcemanager.scheduler.fair.FSAppAttempt: Completed container: container_1523100158662_0007_01_000003 in state: COMPLETED event:FINISHED
2018-04-07 15:27:44,250 INFO org.apache.hadoop.yarn.server.resourcemanager.RMAuditLogger: USER=root	OPERATION=AM Released Container	TARGET=SchedulerApp	RESULT=SUCCESS	APPID=application_1523100158662_0007	CONTAINERID=container_1523100158662_0007_01_000003
2018-04-07 15:27:44,250 INFO org.apache.hadoop.yarn.server.resourcemanager.scheduler.SchedulerNode: Released container container_1523100158662_0007_01_000003 of capacity <memory:1024, vCores:1> on host d1:59470, which currently has 6 containers, <memory:7168, vCores:6> used and <memory:1024, vCores:2> available, release resources=true
2018-04-07 15:27:44,250 INFO org.apache.hadoop.yarn.server.resourcemanager.scheduler.fair.FairScheduler: Application attempt appattempt_1523100158662_0007_000001 released container container_1523100158662_0007_01_000003 on node: host: d1:59470 #containers=6 available=<memory:1024, vCores:2> used=<memory:7168, vCores:6> with event: FINISHED
2018-04-07 15:27:44,250 INFO org.apache.hadoop.yarn.server.resourcemanager.rmcontainer.RMContainerImpl: container_1523100158662_0007_01_000009 Container Transitioned from NEW to ALLOCATED
2018-04-07 15:27:44,250 INFO org.apache.hadoop.yarn.server.resourcemanager.RMAuditLogger: USER=root	OPERATION=AM Allocated Container	TARGET=SchedulerApp	RESULT=SUCCESS	APPID=application_1523100158662_0007	CONTAINERID=container_1523100158662_0007_01_000009
2018-04-07 15:27:44,250 INFO org.apache.hadoop.yarn.server.resourcemanager.scheduler.fair.FSAppAttempt: Application application_1523100158662_0007 unreserved  on node host: d1:59470 #containers=6 available=<memory:1024, vCores:2> used=<memory:7168, vCores:6>, currently has 0 at priority 10; currentReservation <memory:0, vCores:0>
2018-04-07 15:27:44,250 INFO org.apache.hadoop.yarn.server.resourcemanager.scheduler.SchedulerNode: Assigned container container_1523100158662_0007_01_000009 of capacity <memory:1024, vCores:1> on host d1:59470, which has 7 containers, <memory:8192, vCores:7> used and <memory:0, vCores:1> available after allocation
2018-04-07 15:27:45,209 INFO org.apache.hadoop.yarn.server.resourcemanager.rmcontainer.RMContainerImpl: container_1523100158662_0007_01_000009 Container Transitioned from ALLOCATED to ACQUIRED
2018-04-07 15:27:45,249 INFO org.apache.hadoop.yarn.server.resourcemanager.scheduler.fair.FSAppAttempt: Making reservation: node=d1 app_id=application_1523100158662_0007
2018-04-07 15:27:45,249 INFO org.apache.hadoop.yarn.server.resourcemanager.rmcontainer.RMContainerImpl: container_1523100158662_0007_01_000010 Container Transitioned from NEW to RESERVED
2018-04-07 15:27:45,249 INFO org.apache.hadoop.yarn.server.resourcemanager.scheduler.fair.FSSchedulerNode: Reserved container container_1523100158662_0007_01_000010 on node host: d1:59470 #containers=7 available=<memory:0, vCores:1> used=<memory:8192, vCores:7> for application org.apache.hadoop.yarn.server.resourcemanager.scheduler.fair.FSAppAttempt@64ecf952
2018-04-07 15:27:46,252 INFO org.apache.hadoop.yarn.server.resourcemanager.rmcontainer.RMContainerImpl: container_1523100158662_0007_01_000009 Container Transitioned from ACQUIRED to RUNNING
2018-04-07 15:27:50,348 INFO org.apache.hadoop.yarn.server.resourcemanager.rmcontainer.RMContainerImpl: container_1523100158662_0007_01_000004 Container Transitioned from RUNNING to COMPLETED
2018-04-07 15:27:50,349 INFO org.apache.hadoop.yarn.server.resourcemanager.scheduler.fair.FSAppAttempt: Completed container: container_1523100158662_0007_01_000004 in state: COMPLETED event:FINISHED
2018-04-07 15:27:50,349 INFO org.apache.hadoop.yarn.server.resourcemanager.RMAuditLogger: USER=root	OPERATION=AM Released Container	TARGET=SchedulerApp	RESULT=SUCCESS	APPID=application_1523100158662_0007	CONTAINERID=container_1523100158662_0007_01_000004
2018-04-07 15:27:50,349 INFO org.apache.hadoop.yarn.server.resourcemanager.scheduler.SchedulerNode: Released container container_1523100158662_0007_01_000004 of capacity <memory:1024, vCores:1> on host d1:59470, which currently has 6 containers, <memory:7168, vCores:6> used and <memory:1024, vCores:2> available, release resources=true
2018-04-07 15:27:50,349 INFO org.apache.hadoop.yarn.server.resourcemanager.scheduler.fair.FairScheduler: Application attempt appattempt_1523100158662_0007_000001 released container container_1523100158662_0007_01_000004 on node: host: d1:59470 #containers=6 available=<memory:1024, vCores:2> used=<memory:7168, vCores:6> with event: FINISHED
2018-04-07 15:27:50,349 INFO org.apache.hadoop.yarn.server.resourcemanager.rmcontainer.RMContainerImpl: container_1523100158662_0007_01_000010 Container Transitioned from NEW to ALLOCATED
2018-04-07 15:27:50,350 INFO org.apache.hadoop.yarn.server.resourcemanager.RMAuditLogger: USER=root	OPERATION=AM Allocated Container	TARGET=SchedulerApp	RESULT=SUCCESS	APPID=application_1523100158662_0007	CONTAINERID=container_1523100158662_0007_01_000010
2018-04-07 15:27:50,350 INFO org.apache.hadoop.yarn.server.resourcemanager.scheduler.fair.FSAppAttempt: Application application_1523100158662_0007 unreserved  on node host: d1:59470 #containers=6 available=<memory:1024, vCores:2> used=<memory:7168, vCores:6>, currently has 0 at priority 10; currentReservation <memory:0, vCores:0>
2018-04-07 15:27:50,350 INFO org.apache.hadoop.yarn.server.resourcemanager.scheduler.SchedulerNode: Assigned container container_1523100158662_0007_01_000010 of capacity <memory:1024, vCores:1> on host d1:59470, which has 7 containers, <memory:8192, vCores:7> used and <memory:0, vCores:1> available after allocation
2018-04-07 15:27:51,233 INFO org.apache.hadoop.yarn.server.resourcemanager.rmcontainer.RMContainerImpl: container_1523100158662_0007_01_000010 Container Transitioned from ALLOCATED to ACQUIRED
2018-04-07 15:27:51,351 INFO org.apache.hadoop.yarn.server.resourcemanager.rmcontainer.RMContainerImpl: container_1523100158662_0007_01_000010 Container Transitioned from ACQUIRED to RUNNING
2018-04-07 15:27:51,352 INFO org.apache.hadoop.yarn.server.resourcemanager.scheduler.fair.FSAppAttempt: Making reservation: node=d1 app_id=application_1523100158662_0007
2018-04-07 15:27:51,352 INFO org.apache.hadoop.yarn.server.resourcemanager.rmcontainer.RMContainerImpl: container_1523100158662_0007_01_000011 Container Transitioned from NEW to RESERVED
2018-04-07 15:27:51,352 INFO org.apache.hadoop.yarn.server.resourcemanager.scheduler.fair.FSSchedulerNode: Reserved container container_1523100158662_0007_01_000011 on node host: d1:59470 #containers=7 available=<memory:0, vCores:1> used=<memory:8192, vCores:7> for application org.apache.hadoop.yarn.server.resourcemanager.scheduler.fair.FSAppAttempt@64ecf952
2018-04-07 15:27:52,478 INFO org.apache.hadoop.yarn.server.resourcemanager.rmcontainer.RMContainerImpl: container_1523100158662_0007_01_000005 Container Transitioned from RUNNING to COMPLETED
2018-04-07 15:27:52,478 INFO org.apache.hadoop.yarn.server.resourcemanager.scheduler.fair.FSAppAttempt: Completed container: container_1523100158662_0007_01_000005 in state: COMPLETED event:FINISHED
2018-04-07 15:27:52,478 INFO org.apache.hadoop.yarn.server.resourcemanager.RMAuditLogger: USER=root	OPERATION=AM Released Container	TARGET=SchedulerApp	RESULT=SUCCESS	APPID=application_1523100158662_0007	CONTAINERID=container_1523100158662_0007_01_000005
2018-04-07 15:27:52,478 INFO org.apache.hadoop.yarn.server.resourcemanager.scheduler.SchedulerNode: Released container container_1523100158662_0007_01_000005 of capacity <memory:1024, vCores:1> on host d1:59470, which currently has 6 containers, <memory:7168, vCores:6> used and <memory:1024, vCores:2> available, release resources=true
2018-04-07 15:27:52,478 INFO org.apache.hadoop.yarn.server.resourcemanager.scheduler.fair.FairScheduler: Application attempt appattempt_1523100158662_0007_000001 released container container_1523100158662_0007_01_000005 on node: host: d1:59470 #containers=6 available=<memory:1024, vCores:2> used=<memory:7168, vCores:6> with event: FINISHED
2018-04-07 15:27:52,480 INFO org.apache.hadoop.yarn.server.resourcemanager.rmcontainer.RMContainerImpl: container_1523100158662_0007_01_000011 Container Transitioned from NEW to ALLOCATED
2018-04-07 15:27:52,480 INFO org.apache.hadoop.yarn.server.resourcemanager.RMAuditLogger: USER=root	OPERATION=AM Allocated Container	TARGET=SchedulerApp	RESULT=SUCCESS	APPID=application_1523100158662_0007	CONTAINERID=container_1523100158662_0007_01_000011
2018-04-07 15:27:52,480 INFO org.apache.hadoop.yarn.server.resourcemanager.scheduler.fair.FSAppAttempt: Application application_1523100158662_0007 unreserved  on node host: d1:59470 #containers=6 available=<memory:1024, vCores:2> used=<memory:7168, vCores:6>, currently has 0 at priority 10; currentReservation <memory:0, vCores:0>
2018-04-07 15:27:52,480 INFO org.apache.hadoop.yarn.server.resourcemanager.scheduler.SchedulerNode: Assigned container container_1523100158662_0007_01_000011 of capacity <memory:1024, vCores:1> on host d1:59470, which has 7 containers, <memory:8192, vCores:7> used and <memory:0, vCores:1> available after allocation
2018-04-07 15:27:53,247 INFO org.apache.hadoop.yarn.server.resourcemanager.rmcontainer.RMContainerImpl: container_1523100158662_0007_01_000011 Container Transitioned from ALLOCATED to ACQUIRED
2018-04-07 15:27:53,484 INFO org.apache.hadoop.yarn.server.resourcemanager.rmcontainer.RMContainerImpl: container_1523100158662_0007_01_000011 Container Transitioned from ACQUIRED to RUNNING
2018-04-07 15:27:53,484 INFO org.apache.hadoop.yarn.server.resourcemanager.scheduler.fair.FSAppAttempt: Making reservation: node=d1 app_id=application_1523100158662_0007
2018-04-07 15:27:53,486 INFO org.apache.hadoop.yarn.server.resourcemanager.rmcontainer.RMContainerImpl: container_1523100158662_0007_01_000012 Container Transitioned from NEW to RESERVED
2018-04-07 15:27:53,486 INFO org.apache.hadoop.yarn.server.resourcemanager.scheduler.fair.FSSchedulerNode: Reserved container container_1523100158662_0007_01_000012 on node host: d1:59470 #containers=7 available=<memory:0, vCores:1> used=<memory:8192, vCores:7> for application org.apache.hadoop.yarn.server.resourcemanager.scheduler.fair.FSAppAttempt@64ecf952
2018-04-07 15:27:54,573 INFO org.apache.hadoop.yarn.server.resourcemanager.rmcontainer.RMContainerImpl: container_1523100158662_0007_01_000006 Container Transitioned from RUNNING to COMPLETED
2018-04-07 15:27:54,573 INFO org.apache.hadoop.yarn.server.resourcemanager.scheduler.fair.FSAppAttempt: Completed container: container_1523100158662_0007_01_000006 in state: COMPLETED event:FINISHED
2018-04-07 15:27:54,573 INFO org.apache.hadoop.yarn.server.resourcemanager.RMAuditLogger: USER=root	OPERATION=AM Released Container	TARGET=SchedulerApp	RESULT=SUCCESS	APPID=application_1523100158662_0007	CONTAINERID=container_1523100158662_0007_01_000006
2018-04-07 15:27:54,573 INFO org.apache.hadoop.yarn.server.resourcemanager.scheduler.SchedulerNode: Released container container_1523100158662_0007_01_000006 of capacity <memory:1024, vCores:1> on host d1:59470, which currently has 6 containers, <memory:7168, vCores:6> used and <memory:1024, vCores:2> available, release resources=true
2018-04-07 15:27:54,573 INFO org.apache.hadoop.yarn.server.resourcemanager.scheduler.fair.FairScheduler: Application attempt appattempt_1523100158662_0007_000001 released container container_1523100158662_0007_01_000006 on node: host: d1:59470 #containers=6 available=<memory:1024, vCores:2> used=<memory:7168, vCores:6> with event: FINISHED
2018-04-07 15:27:54,574 INFO org.apache.hadoop.yarn.server.resourcemanager.rmcontainer.RMContainerImpl: container_1523100158662_0007_01_000012 Container Transitioned from NEW to ALLOCATED
2018-04-07 15:27:54,575 INFO org.apache.hadoop.yarn.server.resourcemanager.RMAuditLogger: USER=root	OPERATION=AM Allocated Container	TARGET=SchedulerApp	RESULT=SUCCESS	APPID=application_1523100158662_0007	CONTAINERID=container_1523100158662_0007_01_000012
2018-04-07 15:27:54,575 INFO org.apache.hadoop.yarn.server.resourcemanager.scheduler.fair.FSAppAttempt: Application application_1523100158662_0007 unreserved  on node host: d1:59470 #containers=6 available=<memory:1024, vCores:2> used=<memory:7168, vCores:6>, currently has 0 at priority 10; currentReservation <memory:0, vCores:0>
2018-04-07 15:27:54,575 INFO org.apache.hadoop.yarn.server.resourcemanager.scheduler.SchedulerNode: Assigned container container_1523100158662_0007_01_000012 of capacity <memory:1024, vCores:1> on host d1:59470, which has 7 containers, <memory:8192, vCores:7> used and <memory:0, vCores:1> available after allocation
2018-04-07 15:27:55,270 INFO org.apache.hadoop.yarn.server.resourcemanager.rmcontainer.RMContainerImpl: container_1523100158662_0007_01_000012 Container Transitioned from ALLOCATED to ACQUIRED
2018-04-07 15:27:55,573 INFO org.apache.hadoop.yarn.server.resourcemanager.rmcontainer.RMContainerImpl: container_1523100158662_0007_01_000012 Container Transitioned from ACQUIRED to RUNNING
2018-04-07 15:27:56,275 INFO org.apache.hadoop.yarn.server.resourcemanager.scheduler.AppSchedulingInfo: checking for deactivate of application :application_1523100158662_0007
2018-04-07 15:27:57,283 INFO org.apache.hadoop.yarn.server.resourcemanager.scheduler.AppSchedulingInfo: checking for deactivate of application :application_1523100158662_0007
2018-04-07 15:27:57,773 INFO org.apache.hadoop.yarn.server.resourcemanager.rmcontainer.RMContainerImpl: container_1523100158662_0007_01_000007 Container Transitioned from RUNNING to COMPLETED
2018-04-07 15:27:57,773 INFO org.apache.hadoop.yarn.server.resourcemanager.scheduler.fair.FSAppAttempt: Completed container: container_1523100158662_0007_01_000007 in state: COMPLETED event:FINISHED
2018-04-07 15:27:57,773 INFO org.apache.hadoop.yarn.server.resourcemanager.RMAuditLogger: USER=root	OPERATION=AM Released Container	TARGET=SchedulerApp	RESULT=SUCCESS	APPID=application_1523100158662_0007	CONTAINERID=container_1523100158662_0007_01_000007
2018-04-07 15:27:57,773 INFO org.apache.hadoop.yarn.server.resourcemanager.scheduler.SchedulerNode: Released container container_1523100158662_0007_01_000007 of capacity <memory:1024, vCores:1> on host d1:59470, which currently has 6 containers, <memory:7168, vCores:6> used and <memory:1024, vCores:2> available, release resources=true
2018-04-07 15:27:57,773 INFO org.apache.hadoop.yarn.server.resourcemanager.scheduler.fair.FairScheduler: Application attempt appattempt_1523100158662_0007_000001 released container container_1523100158662_0007_01_000007 on node: host: d1:59470 #containers=6 available=<memory:1024, vCores:2> used=<memory:7168, vCores:6> with event: FINISHED
2018-04-07 15:27:58,778 INFO org.apache.hadoop.yarn.server.resourcemanager.rmcontainer.RMContainerImpl: container_1523100158662_0007_01_000008 Container Transitioned from RUNNING to COMPLETED
2018-04-07 15:27:58,781 INFO org.apache.hadoop.yarn.server.resourcemanager.scheduler.fair.FSAppAttempt: Completed container: container_1523100158662_0007_01_000008 in state: COMPLETED event:FINISHED
2018-04-07 15:27:58,781 INFO org.apache.hadoop.yarn.server.resourcemanager.RMAuditLogger: USER=root	OPERATION=AM Released Container	TARGET=SchedulerApp	RESULT=SUCCESS	APPID=application_1523100158662_0007	CONTAINERID=container_1523100158662_0007_01_000008
2018-04-07 15:27:58,781 INFO org.apache.hadoop.yarn.server.resourcemanager.scheduler.SchedulerNode: Released container container_1523100158662_0007_01_000008 of capacity <memory:1024, vCores:1> on host d1:59470, which currently has 5 containers, <memory:6144, vCores:5> used and <memory:2048, vCores:3> available, release resources=true
2018-04-07 15:27:58,781 INFO org.apache.hadoop.yarn.server.resourcemanager.scheduler.fair.FairScheduler: Application attempt appattempt_1523100158662_0007_000001 released container container_1523100158662_0007_01_000008 on node: host: d1:59470 #containers=5 available=<memory:2048, vCores:3> used=<memory:6144, vCores:5> with event: FINISHED
2018-04-07 15:28:07,945 INFO org.apache.hadoop.yarn.server.resourcemanager.rmcontainer.RMContainerImpl: container_1523100158662_0007_01_000009 Container Transitioned from RUNNING to COMPLETED
2018-04-07 15:28:07,945 INFO org.apache.hadoop.yarn.server.resourcemanager.scheduler.fair.FSAppAttempt: Completed container: container_1523100158662_0007_01_000009 in state: COMPLETED event:FINISHED
2018-04-07 15:28:07,945 INFO org.apache.hadoop.yarn.server.resourcemanager.RMAuditLogger: USER=root	OPERATION=AM Released Container	TARGET=SchedulerApp	RESULT=SUCCESS	APPID=application_1523100158662_0007	CONTAINERID=container_1523100158662_0007_01_000009
2018-04-07 15:28:07,945 INFO org.apache.hadoop.yarn.server.resourcemanager.scheduler.SchedulerNode: Released container container_1523100158662_0007_01_000009 of capacity <memory:1024, vCores:1> on host d1:59470, which currently has 4 containers, <memory:5120, vCores:4> used and <memory:3072, vCores:4> available, release resources=true
2018-04-07 15:28:07,946 INFO org.apache.hadoop.yarn.server.resourcemanager.scheduler.fair.FairScheduler: Application attempt appattempt_1523100158662_0007_000001 released container container_1523100158662_0007_01_000009 on node: host: d1:59470 #containers=4 available=<memory:3072, vCores:4> used=<memory:5120, vCores:4> with event: FINISHED
2018-04-07 15:28:11,892 INFO org.apache.hadoop.yarn.server.resourcemanager.rmcontainer.RMContainerImpl: container_1523100158662_0007_01_000010 Container Transitioned from RUNNING to COMPLETED
2018-04-07 15:28:11,892 INFO org.apache.hadoop.yarn.server.resourcemanager.scheduler.fair.FSAppAttempt: Completed container: container_1523100158662_0007_01_000010 in state: COMPLETED event:FINISHED
2018-04-07 15:28:11,892 INFO org.apache.hadoop.yarn.server.resourcemanager.RMAuditLogger: USER=root	OPERATION=AM Released Container	TARGET=SchedulerApp	RESULT=SUCCESS	APPID=application_1523100158662_0007	CONTAINERID=container_1523100158662_0007_01_000010
2018-04-07 15:28:11,892 INFO org.apache.hadoop.yarn.server.resourcemanager.scheduler.SchedulerNode: Released container container_1523100158662_0007_01_000010 of capacity <memory:1024, vCores:1> on host d1:59470, which currently has 3 containers, <memory:4096, vCores:3> used and <memory:4096, vCores:5> available, release resources=true
2018-04-07 15:28:11,892 INFO org.apache.hadoop.yarn.server.resourcemanager.scheduler.fair.FairScheduler: Application attempt appattempt_1523100158662_0007_000001 released container container_1523100158662_0007_01_000010 on node: host: d1:59470 #containers=3 available=<memory:4096, vCores:5> used=<memory:4096, vCores:3> with event: FINISHED
2018-04-07 15:28:11,893 INFO org.apache.hadoop.yarn.server.resourcemanager.rmcontainer.RMContainerImpl: container_1523100158662_0007_01_000011 Container Transitioned from RUNNING to COMPLETED
2018-04-07 15:28:11,893 INFO org.apache.hadoop.yarn.server.resourcemanager.scheduler.fair.FSAppAttempt: Completed container: container_1523100158662_0007_01_000011 in state: COMPLETED event:FINISHED
2018-04-07 15:28:11,893 INFO org.apache.hadoop.yarn.server.resourcemanager.RMAuditLogger: USER=root	OPERATION=AM Released Container	TARGET=SchedulerApp	RESULT=SUCCESS	APPID=application_1523100158662_0007	CONTAINERID=container_1523100158662_0007_01_000011
2018-04-07 15:28:11,893 INFO org.apache.hadoop.yarn.server.resourcemanager.scheduler.SchedulerNode: Released container container_1523100158662_0007_01_000011 of capacity <memory:1024, vCores:1> on host d1:59470, which currently has 2 containers, <memory:3072, vCores:2> used and <memory:5120, vCores:6> available, release resources=true
2018-04-07 15:28:11,893 INFO org.apache.hadoop.yarn.server.resourcemanager.scheduler.fair.FairScheduler: Application attempt appattempt_1523100158662_0007_000001 released container container_1523100158662_0007_01_000011 on node: host: d1:59470 #containers=2 available=<memory:5120, vCores:6> used=<memory:3072, vCores:2> with event: FINISHED
2018-04-07 15:28:12,884 INFO org.apache.hadoop.yarn.server.resourcemanager.rmapp.attempt.RMAppAttemptImpl: Updating application attempt appattempt_1523100158662_0007_000001 with final state: FINISHING, and exit status: -1000
2018-04-07 15:28:12,885 INFO org.apache.hadoop.yarn.server.resourcemanager.rmapp.attempt.RMAppAttemptImpl: appattempt_1523100158662_0007_000001 State change from RUNNING to FINAL_SAVING
2018-04-07 15:28:12,885 INFO org.apache.hadoop.yarn.server.resourcemanager.rmapp.RMAppImpl: Updating application application_1523100158662_0007 with final state: FINISHING
2018-04-07 15:28:12,885 INFO org.apache.hadoop.yarn.server.resourcemanager.rmapp.RMAppImpl: application_1523100158662_0007 State change from RUNNING to FINAL_SAVING
2018-04-07 15:28:12,885 INFO org.apache.hadoop.yarn.server.resourcemanager.recovery.RMStateStore: Updating info for app: application_1523100158662_0007
2018-04-07 15:28:12,885 INFO org.apache.hadoop.yarn.server.resourcemanager.rmapp.attempt.RMAppAttemptImpl: appattempt_1523100158662_0007_000001 State change from FINAL_SAVING to FINISHING
2018-04-07 15:28:12,885 INFO org.apache.hadoop.yarn.server.resourcemanager.rmapp.RMAppImpl: application_1523100158662_0007 State change from FINAL_SAVING to FINISHING
2018-04-07 15:28:13,137 INFO org.apache.hadoop.yarn.server.resourcemanager.rmcontainer.RMContainerImpl: container_1523100158662_0007_01_000012 Container Transitioned from RUNNING to COMPLETED
2018-04-07 15:28:13,137 INFO org.apache.hadoop.yarn.server.resourcemanager.scheduler.fair.FSAppAttempt: Completed container: container_1523100158662_0007_01_000012 in state: COMPLETED event:FINISHED
2018-04-07 15:28:13,137 INFO org.apache.hadoop.yarn.server.resourcemanager.RMAuditLogger: USER=root	OPERATION=AM Released Container	TARGET=SchedulerApp	RESULT=SUCCESS	APPID=application_1523100158662_0007	CONTAINERID=container_1523100158662_0007_01_000012
2018-04-07 15:28:13,138 INFO org.apache.hadoop.yarn.server.resourcemanager.scheduler.SchedulerNode: Released container container_1523100158662_0007_01_000012 of capacity <memory:1024, vCores:1> on host d1:59470, which currently has 1 containers, <memory:2048, vCores:1> used and <memory:6144, vCores:7> available, release resources=true
2018-04-07 15:28:13,138 INFO org.apache.hadoop.yarn.server.resourcemanager.scheduler.fair.FairScheduler: Application attempt appattempt_1523100158662_0007_000001 released container container_1523100158662_0007_01_000012 on node: host: d1:59470 #containers=1 available=<memory:6144, vCores:7> used=<memory:2048, vCores:1> with event: FINISHED
2018-04-07 15:28:13,893 INFO org.apache.hadoop.yarn.server.resourcemanager.ApplicationMasterService: application_1523100158662_0007 unregistered successfully. 
2018-04-07 15:28:19,151 INFO org.apache.hadoop.yarn.server.resourcemanager.rmcontainer.RMContainerImpl: container_1523100158662_0007_01_000001 Container Transitioned from RUNNING to COMPLETED
2018-04-07 15:28:19,152 INFO org.apache.hadoop.yarn.server.resourcemanager.ApplicationMasterService: Unregistering app attempt : appattempt_1523100158662_0007_000001
2018-04-07 15:28:19,152 INFO org.apache.hadoop.yarn.server.resourcemanager.security.AMRMTokenSecretManager: Application finished, removing password for appattempt_1523100158662_0007_000001
2018-04-07 15:28:19,152 INFO org.apache.hadoop.yarn.server.resourcemanager.rmapp.attempt.RMAppAttemptImpl: appattempt_1523100158662_0007_000001 State change from FINISHING to FINISHED
2018-04-07 15:28:19,152 INFO org.apache.hadoop.yarn.server.resourcemanager.rmapp.RMAppImpl: application_1523100158662_0007 State change from FINISHING to FINISHED
2018-04-07 15:28:19,152 INFO org.apache.hadoop.yarn.server.resourcemanager.RMAuditLogger: USER=root	OPERATION=Application Finished - Succeeded	TARGET=RMAppManager	RESULT=SUCCESS	APPID=application_1523100158662_0007
2018-04-07 15:28:19,152 INFO org.apache.hadoop.yarn.server.resourcemanager.scheduler.fair.FSAppAttempt: Completed container: container_1523100158662_0007_01_000001 in state: COMPLETED event:FINISHED
2018-04-07 15:28:19,152 INFO org.apache.hadoop.yarn.server.resourcemanager.RMAuditLogger: USER=root	OPERATION=AM Released Container	TARGET=SchedulerApp	RESULT=SUCCESS	APPID=application_1523100158662_0007	CONTAINERID=container_1523100158662_0007_01_000001
2018-04-07 15:28:19,152 INFO org.apache.hadoop.yarn.server.resourcemanager.scheduler.SchedulerNode: Released container container_1523100158662_0007_01_000001 of capacity <memory:2048, vCores:1> on host d1:59470, which currently has 0 containers, <memory:0, vCores:0> used and <memory:8192, vCores:8> available, release resources=true
2018-04-07 15:28:19,152 INFO org.apache.hadoop.yarn.server.resourcemanager.scheduler.fair.FairScheduler: Application attempt appattempt_1523100158662_0007_000001 released container container_1523100158662_0007_01_000001 on node: host: d1:59470 #containers=0 available=<memory:8192, vCores:8> used=<memory:0, vCores:0> with event: FINISHED
2018-04-07 15:28:19,152 INFO org.apache.hadoop.yarn.server.resourcemanager.scheduler.fair.FairScheduler: Application appattempt_1523100158662_0007_000001 is done. finalState=FINISHED
2018-04-07 15:28:19,152 INFO org.apache.hadoop.yarn.server.resourcemanager.scheduler.AppSchedulingInfo: Application application_1523100158662_0007 requests cleared
2018-04-07 15:28:19,152 INFO org.apache.hadoop.yarn.server.resourcemanager.amlauncher.AMLauncher: Cleaning master appattempt_1523100158662_0007_000001
2018-04-07 15:28:19,152 INFO org.apache.hadoop.yarn.server.resourcemanager.RMAppManager$ApplicationSummary: appId=application_1523100158662_0007,name=word count,user=root,queue=root.root,state=FINISHED,trackingUrl=http://d1:8088/proxy/application_1523100158662_0007/,appMasterHost=d1,startTime=1523114751525,finishTime=1523114892885,finalStatus=SUCCEEDED,memorySeconds=547080,vcoreSeconds=381,preemptedAMContainers=0,preemptedNonAMContainers=0,preemptedResources=<memory:0\, vCores:0>,applicationType=MAPREDUCE
2018-04-07 15:28:20,178 INFO org.apache.hadoop.yarn.server.resourcemanager.scheduler.fair.FairScheduler: Null container completed...
2018-04-07 15:58:48,179 INFO org.apache.hadoop.yarn.server.resourcemanager.ClientRMService: Allocated new applicationId: 8
2018-04-07 15:58:55,171 INFO org.apache.hadoop.yarn.server.resourcemanager.ClientRMService: Application with id 8 submitted by user root
2018-04-07 15:58:55,171 INFO org.apache.hadoop.yarn.server.resourcemanager.rmapp.RMAppImpl: Storing application with id application_1523100158662_0008
2018-04-07 15:58:55,172 INFO org.apache.hadoop.yarn.server.resourcemanager.rmapp.RMAppImpl: application_1523100158662_0008 State change from NEW to NEW_SAVING
2018-04-07 15:58:55,172 INFO org.apache.hadoop.yarn.server.resourcemanager.recovery.RMStateStore: Storing info for app: application_1523100158662_0008
2018-04-07 15:58:55,173 INFO org.apache.hadoop.yarn.server.resourcemanager.rmapp.RMAppImpl: application_1523100158662_0008 State change from NEW_SAVING to SUBMITTED
2018-04-07 15:58:55,173 INFO org.apache.hadoop.yarn.server.resourcemanager.scheduler.fair.FairScheduler: Accepted application application_1523100158662_0008 from user: root, in queue: default, currently num of applications: 1
2018-04-07 15:58:55,172 INFO org.apache.hadoop.yarn.server.resourcemanager.RMAuditLogger: USER=root	IP=172.17.0.2	OPERATION=Submit Application Request	TARGET=ClientRMService	RESULT=SUCCESS	APPID=application_1523100158662_0008
2018-04-07 15:58:55,174 INFO org.apache.hadoop.yarn.server.resourcemanager.rmapp.RMAppImpl: application_1523100158662_0008 State change from SUBMITTED to ACCEPTED
2018-04-07 15:58:55,177 INFO org.apache.hadoop.yarn.server.resourcemanager.ApplicationMasterService: Registering app attempt : appattempt_1523100158662_0008_000001
2018-04-07 15:58:55,177 INFO org.apache.hadoop.yarn.server.resourcemanager.rmapp.attempt.RMAppAttemptImpl: appattempt_1523100158662_0008_000001 State change from NEW to SUBMITTED
2018-04-07 15:58:55,178 INFO org.apache.hadoop.yarn.server.resourcemanager.scheduler.fair.FairScheduler: Added Application Attempt appattempt_1523100158662_0008_000001 to scheduler from user: root
2018-04-07 15:58:55,178 INFO org.apache.hadoop.yarn.server.resourcemanager.rmapp.attempt.RMAppAttemptImpl: appattempt_1523100158662_0008_000001 State change from SUBMITTED to SCHEDULED
2018-04-07 15:58:56,121 INFO org.apache.hadoop.yarn.server.resourcemanager.rmcontainer.RMContainerImpl: container_1523100158662_0008_01_000001 Container Transitioned from NEW to ALLOCATED
2018-04-07 15:58:56,122 INFO org.apache.hadoop.yarn.server.resourcemanager.RMAuditLogger: USER=root	OPERATION=AM Allocated Container	TARGET=SchedulerApp	RESULT=SUCCESS	APPID=application_1523100158662_0008	CONTAINERID=container_1523100158662_0008_01_000001
2018-04-07 15:58:56,122 INFO org.apache.hadoop.yarn.server.resourcemanager.scheduler.SchedulerNode: Assigned container container_1523100158662_0008_01_000001 of capacity <memory:2048, vCores:1> on host d1:59470, which has 1 containers, <memory:2048, vCores:1> used and <memory:6144, vCores:7> available after allocation
2018-04-07 15:58:56,161 INFO org.apache.hadoop.yarn.server.resourcemanager.security.NMTokenSecretManagerInRM: Sending NMToken for nodeId : d1:59470 for container : container_1523100158662_0008_01_000001
2018-04-07 15:58:56,210 INFO org.apache.hadoop.yarn.server.resourcemanager.rmcontainer.RMContainerImpl: container_1523100158662_0008_01_000001 Container Transitioned from ALLOCATED to ACQUIRED
2018-04-07 15:58:56,246 INFO org.apache.hadoop.yarn.server.resourcemanager.security.NMTokenSecretManagerInRM: Clear node set for appattempt_1523100158662_0008_000001
2018-04-07 15:58:56,246 INFO org.apache.hadoop.yarn.server.resourcemanager.rmapp.attempt.RMAppAttemptImpl: Storing attempt: AppId: application_1523100158662_0008 AttemptId: appattempt_1523100158662_0008_000001 MasterContainer: Container: [ContainerId: container_1523100158662_0008_01_000001, NodeId: d1:59470, NodeHttpAddress: d1:8042, Resource: <memory:2048, vCores:1>, Priority: 0, Token: Token { kind: ContainerToken, service: 172.17.0.2:59470 }, ]
2018-04-07 15:58:56,262 INFO org.apache.hadoop.yarn.server.resourcemanager.rmapp.attempt.RMAppAttemptImpl: appattempt_1523100158662_0008_000001 State change from SCHEDULED to ALLOCATED_SAVING
2018-04-07 15:58:56,269 INFO org.apache.hadoop.yarn.server.resourcemanager.rmapp.attempt.RMAppAttemptImpl: appattempt_1523100158662_0008_000001 State change from ALLOCATED_SAVING to ALLOCATED
2018-04-07 15:58:56,286 INFO org.apache.hadoop.yarn.server.resourcemanager.amlauncher.AMLauncher: Launching masterappattempt_1523100158662_0008_000001
2018-04-07 15:58:56,389 INFO org.apache.hadoop.yarn.server.resourcemanager.amlauncher.AMLauncher: Setting up container Container: [ContainerId: container_1523100158662_0008_01_000001, NodeId: d1:59470, NodeHttpAddress: d1:8042, Resource: <memory:2048, vCores:1>, Priority: 0, Token: Token { kind: ContainerToken, service: 172.17.0.2:59470 }, ] for AM appattempt_1523100158662_0008_000001
2018-04-07 15:58:56,389 INFO org.apache.hadoop.yarn.server.resourcemanager.amlauncher.AMLauncher: Command to launch container container_1523100158662_0008_01_000001 : $JAVA_HOME/bin/java -Dlog4j.configuration=container-log4j.properties -Dyarn.app.container.log.dir=<LOG_DIR> -Dyarn.app.container.log.filesize=0 -Dhadoop.root.logger=INFO,CLA -Dhadoop.root.logfile=syslog  -Xmx1024m org.apache.hadoop.mapreduce.v2.app.MRAppMaster 1><LOG_DIR>/stdout 2><LOG_DIR>/stderr 
2018-04-07 15:58:56,389 INFO org.apache.hadoop.yarn.server.resourcemanager.security.AMRMTokenSecretManager: Create AMRMToken for ApplicationAttempt: appattempt_1523100158662_0008_000001
2018-04-07 15:58:56,417 INFO org.apache.hadoop.yarn.server.resourcemanager.security.AMRMTokenSecretManager: Creating password for appattempt_1523100158662_0008_000001
2018-04-07 15:58:56,882 INFO org.apache.hadoop.yarn.server.resourcemanager.amlauncher.AMLauncher: Done launching container Container: [ContainerId: container_1523100158662_0008_01_000001, NodeId: d1:59470, NodeHttpAddress: d1:8042, Resource: <memory:2048, vCores:1>, Priority: 0, Token: Token { kind: ContainerToken, service: 172.17.0.2:59470 }, ] for AM appattempt_1523100158662_0008_000001
2018-04-07 15:58:56,889 INFO org.apache.hadoop.yarn.server.resourcemanager.rmapp.attempt.RMAppAttemptImpl: appattempt_1523100158662_0008_000001 State change from ALLOCATED to LAUNCHED
2018-04-07 15:58:57,203 INFO org.apache.hadoop.yarn.server.resourcemanager.rmcontainer.RMContainerImpl: container_1523100158662_0008_01_000001 Container Transitioned from ACQUIRED to RUNNING
2018-04-07 15:59:32,187 INFO SecurityLogger.org.apache.hadoop.ipc.Server: Auth successful for appattempt_1523100158662_0008_000001 (auth:SIMPLE)
2018-04-07 15:59:32,207 INFO org.apache.hadoop.yarn.server.resourcemanager.ApplicationMasterService: AM registration appattempt_1523100158662_0008_000001
2018-04-07 15:59:32,208 INFO org.apache.hadoop.yarn.server.resourcemanager.RMAuditLogger: USER=root	IP=172.17.0.2	OPERATION=Register App Master	TARGET=ApplicationMasterService	RESULT=SUCCESS	APPID=application_1523100158662_0008	APPATTEMPTID=appattempt_1523100158662_0008_000001
2018-04-07 15:59:32,208 INFO org.apache.hadoop.yarn.server.resourcemanager.rmapp.attempt.RMAppAttemptImpl: appattempt_1523100158662_0008_000001 State change from LAUNCHED to RUNNING
2018-04-07 15:59:32,208 INFO org.apache.hadoop.yarn.server.resourcemanager.rmapp.RMAppImpl: application_1523100158662_0008 State change from ACCEPTED to RUNNING
2018-04-07 15:59:33,820 INFO org.apache.hadoop.yarn.server.resourcemanager.rmcontainer.RMContainerImpl: container_1523100158662_0008_01_000002 Container Transitioned from NEW to ALLOCATED
2018-04-07 15:59:33,820 INFO org.apache.hadoop.yarn.server.resourcemanager.RMAuditLogger: USER=root	OPERATION=AM Allocated Container	TARGET=SchedulerApp	RESULT=SUCCESS	APPID=application_1523100158662_0008	CONTAINERID=container_1523100158662_0008_01_000002
2018-04-07 15:59:33,821 INFO org.apache.hadoop.yarn.server.resourcemanager.scheduler.SchedulerNode: Assigned container container_1523100158662_0008_01_000002 of capacity <memory:1024, vCores:1> on host d1:59470, which has 2 containers, <memory:3072, vCores:2> used and <memory:5120, vCores:6> available after allocation
2018-04-07 15:59:34,470 INFO org.apache.hadoop.yarn.server.resourcemanager.security.NMTokenSecretManagerInRM: Sending NMToken for nodeId : d1:59470 for container : container_1523100158662_0008_01_000002
2018-04-07 15:59:34,477 INFO org.apache.hadoop.yarn.server.resourcemanager.rmcontainer.RMContainerImpl: container_1523100158662_0008_01_000002 Container Transitioned from ALLOCATED to ACQUIRED
2018-04-07 15:59:36,445 INFO org.apache.hadoop.yarn.server.resourcemanager.scheduler.AppSchedulingInfo: checking for deactivate of application :application_1523100158662_0008
2018-04-07 15:59:37,894 INFO org.apache.hadoop.yarn.server.resourcemanager.rmcontainer.RMContainerImpl: container_1523100158662_0008_01_000002 Container Transitioned from ACQUIRED to RUNNING
2018-04-07 16:00:28,937 INFO org.apache.hadoop.yarn.server.resourcemanager.rmcontainer.RMContainerImpl: container_1523100158662_0008_01_000002 Container Transitioned from RUNNING to COMPLETED
2018-04-07 16:00:28,937 INFO org.apache.hadoop.yarn.server.resourcemanager.scheduler.fair.FSAppAttempt: Completed container: container_1523100158662_0008_01_000002 in state: COMPLETED event:FINISHED
2018-04-07 16:00:28,937 INFO org.apache.hadoop.yarn.server.resourcemanager.RMAuditLogger: USER=root	OPERATION=AM Released Container	TARGET=SchedulerApp	RESULT=SUCCESS	APPID=application_1523100158662_0008	CONTAINERID=container_1523100158662_0008_01_000002
2018-04-07 16:00:28,938 INFO org.apache.hadoop.yarn.server.resourcemanager.scheduler.SchedulerNode: Released container container_1523100158662_0008_01_000002 of capacity <memory:1024, vCores:1> on host d1:59470, which currently has 1 containers, <memory:2048, vCores:1> used and <memory:6144, vCores:7> available, release resources=true
2018-04-07 16:00:28,938 INFO org.apache.hadoop.yarn.server.resourcemanager.scheduler.fair.FairScheduler: Application attempt appattempt_1523100158662_0008_000001 released container container_1523100158662_0008_01_000002 on node: host: d1:59470 #containers=1 available=<memory:6144, vCores:7> used=<memory:2048, vCores:1> with event: FINISHED
2018-04-07 16:00:29,938 INFO org.apache.hadoop.yarn.server.resourcemanager.rmcontainer.RMContainerImpl: container_1523100158662_0008_01_000003 Container Transitioned from NEW to ALLOCATED
2018-04-07 16:00:29,941 INFO org.apache.hadoop.yarn.server.resourcemanager.RMAuditLogger: USER=root	OPERATION=AM Allocated Container	TARGET=SchedulerApp	RESULT=SUCCESS	APPID=application_1523100158662_0008	CONTAINERID=container_1523100158662_0008_01_000003
2018-04-07 16:00:29,941 INFO org.apache.hadoop.yarn.server.resourcemanager.scheduler.SchedulerNode: Assigned container container_1523100158662_0008_01_000003 of capacity <memory:1024, vCores:1> on host d1:59470, which has 2 containers, <memory:3072, vCores:2> used and <memory:5120, vCores:6> available after allocation
2018-04-07 16:00:30,269 INFO org.apache.hadoop.yarn.server.resourcemanager.rmcontainer.RMContainerImpl: container_1523100158662_0008_01_000003 Container Transitioned from ALLOCATED to ACQUIRED
2018-04-07 16:00:30,954 INFO org.apache.hadoop.yarn.server.resourcemanager.rmcontainer.RMContainerImpl: container_1523100158662_0008_01_000003 Container Transitioned from ACQUIRED to RUNNING
2018-04-07 16:00:30,955 INFO org.apache.hadoop.yarn.server.resourcemanager.rmcontainer.RMContainerImpl: container_1523100158662_0008_01_000004 Container Transitioned from NEW to ALLOCATED
2018-04-07 16:00:30,957 INFO org.apache.hadoop.yarn.server.resourcemanager.RMAuditLogger: USER=root	OPERATION=AM Allocated Container	TARGET=SchedulerApp	RESULT=SUCCESS	APPID=application_1523100158662_0008	CONTAINERID=container_1523100158662_0008_01_000004
2018-04-07 16:00:30,957 INFO org.apache.hadoop.yarn.server.resourcemanager.scheduler.SchedulerNode: Assigned container container_1523100158662_0008_01_000004 of capacity <memory:1024, vCores:1> on host d1:59470, which has 3 containers, <memory:4096, vCores:3> used and <memory:4096, vCores:5> available after allocation
2018-04-07 16:00:31,317 INFO org.apache.hadoop.yarn.server.resourcemanager.rmcontainer.RMContainerImpl: container_1523100158662_0008_01_000004 Container Transitioned from ALLOCATED to ACQUIRED
2018-04-07 16:00:31,959 INFO org.apache.hadoop.yarn.server.resourcemanager.rmcontainer.RMContainerImpl: container_1523100158662_0008_01_000004 Container Transitioned from ACQUIRED to RUNNING
2018-04-07 16:00:31,961 INFO org.apache.hadoop.yarn.server.resourcemanager.rmcontainer.RMContainerImpl: container_1523100158662_0008_01_000005 Container Transitioned from NEW to ALLOCATED
2018-04-07 16:00:31,961 INFO org.apache.hadoop.yarn.server.resourcemanager.RMAuditLogger: USER=root	OPERATION=AM Allocated Container	TARGET=SchedulerApp	RESULT=SUCCESS	APPID=application_1523100158662_0008	CONTAINERID=container_1523100158662_0008_01_000005
2018-04-07 16:00:31,961 INFO org.apache.hadoop.yarn.server.resourcemanager.scheduler.SchedulerNode: Assigned container container_1523100158662_0008_01_000005 of capacity <memory:1024, vCores:1> on host d1:59470, which has 4 containers, <memory:5120, vCores:4> used and <memory:3072, vCores:4> available after allocation
2018-04-07 16:00:32,405 INFO org.apache.hadoop.yarn.server.resourcemanager.rmcontainer.RMContainerImpl: container_1523100158662_0008_01_000005 Container Transitioned from ALLOCATED to ACQUIRED
2018-04-07 16:00:32,973 INFO org.apache.hadoop.yarn.server.resourcemanager.rmcontainer.RMContainerImpl: container_1523100158662_0008_01_000005 Container Transitioned from ACQUIRED to RUNNING
2018-04-07 16:00:32,975 INFO org.apache.hadoop.yarn.server.resourcemanager.rmcontainer.RMContainerImpl: container_1523100158662_0008_01_000006 Container Transitioned from NEW to ALLOCATED
2018-04-07 16:00:32,975 INFO org.apache.hadoop.yarn.server.resourcemanager.RMAuditLogger: USER=root	OPERATION=AM Allocated Container	TARGET=SchedulerApp	RESULT=SUCCESS	APPID=application_1523100158662_0008	CONTAINERID=container_1523100158662_0008_01_000006
2018-04-07 16:00:32,975 INFO org.apache.hadoop.yarn.server.resourcemanager.scheduler.SchedulerNode: Assigned container container_1523100158662_0008_01_000006 of capacity <memory:1024, vCores:1> on host d1:59470, which has 5 containers, <memory:6144, vCores:5> used and <memory:2048, vCores:3> available after allocation
2018-04-07 16:00:33,490 INFO org.apache.hadoop.yarn.server.resourcemanager.rmcontainer.RMContainerImpl: container_1523100158662_0008_01_000006 Container Transitioned from ALLOCATED to ACQUIRED
2018-04-07 16:00:33,974 INFO org.apache.hadoop.yarn.server.resourcemanager.rmcontainer.RMContainerImpl: container_1523100158662_0008_01_000007 Container Transitioned from NEW to ALLOCATED
2018-04-07 16:00:33,980 INFO org.apache.hadoop.yarn.server.resourcemanager.RMAuditLogger: USER=root	OPERATION=AM Allocated Container	TARGET=SchedulerApp	RESULT=SUCCESS	APPID=application_1523100158662_0008	CONTAINERID=container_1523100158662_0008_01_000007
2018-04-07 16:00:33,981 INFO org.apache.hadoop.yarn.server.resourcemanager.scheduler.SchedulerNode: Assigned container container_1523100158662_0008_01_000007 of capacity <memory:1024, vCores:1> on host d1:59470, which has 6 containers, <memory:7168, vCores:6> used and <memory:1024, vCores:2> available after allocation
2018-04-07 16:00:34,560 INFO org.apache.hadoop.yarn.server.resourcemanager.rmcontainer.RMContainerImpl: container_1523100158662_0008_01_000007 Container Transitioned from ALLOCATED to ACQUIRED
2018-04-07 16:00:34,996 INFO org.apache.hadoop.yarn.server.resourcemanager.rmcontainer.RMContainerImpl: container_1523100158662_0008_01_000006 Container Transitioned from ACQUIRED to RUNNING
2018-04-07 16:00:34,999 INFO org.apache.hadoop.yarn.server.resourcemanager.rmcontainer.RMContainerImpl: container_1523100158662_0008_01_000008 Container Transitioned from NEW to ALLOCATED
2018-04-07 16:00:35,001 INFO org.apache.hadoop.yarn.server.resourcemanager.RMAuditLogger: USER=root	OPERATION=AM Allocated Container	TARGET=SchedulerApp	RESULT=SUCCESS	APPID=application_1523100158662_0008	CONTAINERID=container_1523100158662_0008_01_000008
2018-04-07 16:00:35,018 INFO org.apache.hadoop.yarn.server.resourcemanager.scheduler.SchedulerNode: Assigned container container_1523100158662_0008_01_000008 of capacity <memory:1024, vCores:1> on host d1:59470, which has 7 containers, <memory:8192, vCores:7> used and <memory:0, vCores:1> available after allocation
2018-04-07 16:00:35,666 INFO org.apache.hadoop.yarn.server.resourcemanager.rmcontainer.RMContainerImpl: container_1523100158662_0008_01_000008 Container Transitioned from ALLOCATED to ACQUIRED
2018-04-07 16:00:36,029 INFO org.apache.hadoop.yarn.server.resourcemanager.rmcontainer.RMContainerImpl: container_1523100158662_0008_01_000007 Container Transitioned from ACQUIRED to RUNNING
2018-04-07 16:00:36,036 INFO org.apache.hadoop.yarn.server.resourcemanager.scheduler.fair.FSAppAttempt: Making reservation: node=d1 app_id=application_1523100158662_0008
2018-04-07 16:00:36,038 INFO org.apache.hadoop.yarn.server.resourcemanager.rmcontainer.RMContainerImpl: container_1523100158662_0008_01_000009 Container Transitioned from NEW to RESERVED
2018-04-07 16:00:36,038 INFO org.apache.hadoop.yarn.server.resourcemanager.scheduler.fair.FSSchedulerNode: Reserved container container_1523100158662_0008_01_000009 on node host: d1:59470 #containers=7 available=<memory:0, vCores:1> used=<memory:8192, vCores:7> for application org.apache.hadoop.yarn.server.resourcemanager.scheduler.fair.FSAppAttempt@2d8ca8d6
2018-04-07 16:00:37,045 INFO org.apache.hadoop.yarn.server.resourcemanager.rmcontainer.RMContainerImpl: container_1523100158662_0008_01_000008 Container Transitioned from ACQUIRED to RUNNING
2018-04-07 16:01:52,865 INFO org.apache.hadoop.yarn.server.resourcemanager.rmcontainer.RMContainerImpl: container_1523100158662_0008_01_000003 Container Transitioned from RUNNING to COMPLETED
2018-04-07 16:01:52,865 INFO org.apache.hadoop.yarn.server.resourcemanager.scheduler.fair.FSAppAttempt: Completed container: container_1523100158662_0008_01_000003 in state: COMPLETED event:FINISHED
2018-04-07 16:01:52,865 INFO org.apache.hadoop.yarn.server.resourcemanager.RMAuditLogger: USER=root	OPERATION=AM Released Container	TARGET=SchedulerApp	RESULT=SUCCESS	APPID=application_1523100158662_0008	CONTAINERID=container_1523100158662_0008_01_000003
2018-04-07 16:01:52,865 INFO org.apache.hadoop.yarn.server.resourcemanager.scheduler.SchedulerNode: Released container container_1523100158662_0008_01_000003 of capacity <memory:1024, vCores:1> on host d1:59470, which currently has 6 containers, <memory:7168, vCores:6> used and <memory:1024, vCores:2> available, release resources=true
2018-04-07 16:01:52,865 INFO org.apache.hadoop.yarn.server.resourcemanager.scheduler.fair.FairScheduler: Application attempt appattempt_1523100158662_0008_000001 released container container_1523100158662_0008_01_000003 on node: host: d1:59470 #containers=6 available=<memory:1024, vCores:2> used=<memory:7168, vCores:6> with event: FINISHED
2018-04-07 16:01:52,866 INFO org.apache.hadoop.yarn.server.resourcemanager.rmcontainer.RMContainerImpl: container_1523100158662_0008_01_000009 Container Transitioned from NEW to ALLOCATED
2018-04-07 16:01:52,866 INFO org.apache.hadoop.yarn.server.resourcemanager.RMAuditLogger: USER=root	OPERATION=AM Allocated Container	TARGET=SchedulerApp	RESULT=SUCCESS	APPID=application_1523100158662_0008	CONTAINERID=container_1523100158662_0008_01_000009
2018-04-07 16:01:52,866 INFO org.apache.hadoop.yarn.server.resourcemanager.scheduler.fair.FSAppAttempt: Application application_1523100158662_0008 unreserved  on node host: d1:59470 #containers=6 available=<memory:1024, vCores:2> used=<memory:7168, vCores:6>, currently has 0 at priority 10; currentReservation <memory:0, vCores:0>
2018-04-07 16:01:52,866 INFO org.apache.hadoop.yarn.server.resourcemanager.scheduler.SchedulerNode: Assigned container container_1523100158662_0008_01_000009 of capacity <memory:1024, vCores:1> on host d1:59470, which has 7 containers, <memory:8192, vCores:7> used and <memory:0, vCores:1> available after allocation
2018-04-07 16:01:53,175 INFO org.apache.hadoop.yarn.server.resourcemanager.scheduler.fair.FSAppAttempt: Making reservation: node=d1 app_id=application_1523100158662_0008
2018-04-07 16:01:53,175 INFO org.apache.hadoop.yarn.server.resourcemanager.rmcontainer.RMContainerImpl: container_1523100158662_0008_01_000010 Container Transitioned from NEW to RESERVED
2018-04-07 16:01:53,175 INFO org.apache.hadoop.yarn.server.resourcemanager.scheduler.fair.FSSchedulerNode: Reserved container container_1523100158662_0008_01_000010 on node host: d1:59470 #containers=7 available=<memory:0, vCores:1> used=<memory:8192, vCores:7> for application org.apache.hadoop.yarn.server.resourcemanager.scheduler.fair.FSAppAttempt@2d8ca8d6
2018-04-07 16:01:53,628 INFO org.apache.hadoop.yarn.server.resourcemanager.rmcontainer.RMContainerImpl: container_1523100158662_0008_01_000008 Container Transitioned from RUNNING to COMPLETED
2018-04-07 16:01:53,628 INFO org.apache.hadoop.yarn.server.resourcemanager.scheduler.fair.FSAppAttempt: Completed container: container_1523100158662_0008_01_000008 in state: COMPLETED event:FINISHED
2018-04-07 16:01:53,629 INFO org.apache.hadoop.yarn.server.resourcemanager.RMAuditLogger: USER=root	OPERATION=AM Released Container	TARGET=SchedulerApp	RESULT=SUCCESS	APPID=application_1523100158662_0008	CONTAINERID=container_1523100158662_0008_01_000008
2018-04-07 16:01:53,629 INFO org.apache.hadoop.yarn.server.resourcemanager.scheduler.SchedulerNode: Released container container_1523100158662_0008_01_000008 of capacity <memory:1024, vCores:1> on host d1:59470, which currently has 6 containers, <memory:7168, vCores:6> used and <memory:1024, vCores:2> available, release resources=true
2018-04-07 16:01:53,629 INFO org.apache.hadoop.yarn.server.resourcemanager.scheduler.fair.FairScheduler: Application attempt appattempt_1523100158662_0008_000001 released container container_1523100158662_0008_01_000008 on node: host: d1:59470 #containers=6 available=<memory:1024, vCores:2> used=<memory:7168, vCores:6> with event: FINISHED
2018-04-07 16:01:53,629 INFO org.apache.hadoop.yarn.server.resourcemanager.rmcontainer.RMContainerImpl: container_1523100158662_0008_01_000010 Container Transitioned from NEW to ALLOCATED
2018-04-07 16:01:53,629 INFO org.apache.hadoop.yarn.server.resourcemanager.RMAuditLogger: USER=root	OPERATION=AM Allocated Container	TARGET=SchedulerApp	RESULT=SUCCESS	APPID=application_1523100158662_0008	CONTAINERID=container_1523100158662_0008_01_000010
2018-04-07 16:01:53,629 INFO org.apache.hadoop.yarn.server.resourcemanager.scheduler.fair.FSAppAttempt: Application application_1523100158662_0008 unreserved  on node host: d1:59470 #containers=6 available=<memory:1024, vCores:2> used=<memory:7168, vCores:6>, currently has 0 at priority 10; currentReservation <memory:0, vCores:0>
2018-04-07 16:01:53,629 INFO org.apache.hadoop.yarn.server.resourcemanager.scheduler.SchedulerNode: Assigned container container_1523100158662_0008_01_000010 of capacity <memory:1024, vCores:1> on host d1:59470, which has 7 containers, <memory:8192, vCores:7> used and <memory:0, vCores:1> available after allocation
2018-04-07 16:01:53,805 INFO org.apache.hadoop.yarn.server.resourcemanager.rmcontainer.RMContainerImpl: container_1523100158662_0008_01_000009 Container Transitioned from ALLOCATED to ACQUIRED
2018-04-07 16:01:53,806 INFO org.apache.hadoop.yarn.server.resourcemanager.rmcontainer.RMContainerImpl: container_1523100158662_0008_01_000010 Container Transitioned from ALLOCATED to ACQUIRED
2018-04-07 16:01:54,462 INFO org.apache.hadoop.yarn.server.resourcemanager.rmcontainer.RMContainerImpl: container_1523100158662_0008_01_000009 Container Transitioned from ACQUIRED to RUNNING
2018-04-07 16:01:54,462 INFO org.apache.hadoop.yarn.server.resourcemanager.rmcontainer.RMContainerImpl: container_1523100158662_0008_01_000010 Container Transitioned from ACQUIRED to RUNNING
2018-04-07 16:01:54,462 INFO org.apache.hadoop.yarn.server.resourcemanager.rmcontainer.RMContainerImpl: container_1523100158662_0008_01_000006 Container Transitioned from RUNNING to COMPLETED
2018-04-07 16:01:54,462 INFO org.apache.hadoop.yarn.server.resourcemanager.scheduler.fair.FSAppAttempt: Completed container: container_1523100158662_0008_01_000006 in state: COMPLETED event:FINISHED
2018-04-07 16:01:54,463 INFO org.apache.hadoop.yarn.server.resourcemanager.RMAuditLogger: USER=root	OPERATION=AM Released Container	TARGET=SchedulerApp	RESULT=SUCCESS	APPID=application_1523100158662_0008	CONTAINERID=container_1523100158662_0008_01_000006
2018-04-07 16:01:54,463 INFO org.apache.hadoop.yarn.server.resourcemanager.scheduler.SchedulerNode: Released container container_1523100158662_0008_01_000006 of capacity <memory:1024, vCores:1> on host d1:59470, which currently has 6 containers, <memory:7168, vCores:6> used and <memory:1024, vCores:2> available, release resources=true
2018-04-07 16:01:54,463 INFO org.apache.hadoop.yarn.server.resourcemanager.scheduler.fair.FairScheduler: Application attempt appattempt_1523100158662_0008_000001 released container container_1523100158662_0008_01_000006 on node: host: d1:59470 #containers=6 available=<memory:1024, vCores:2> used=<memory:7168, vCores:6> with event: FINISHED
2018-04-07 16:01:54,463 INFO org.apache.hadoop.yarn.server.resourcemanager.rmcontainer.RMContainerImpl: container_1523100158662_0008_01_000011 Container Transitioned from NEW to ALLOCATED
2018-04-07 16:01:54,463 INFO org.apache.hadoop.yarn.server.resourcemanager.RMAuditLogger: USER=root	OPERATION=AM Allocated Container	TARGET=SchedulerApp	RESULT=SUCCESS	APPID=application_1523100158662_0008	CONTAINERID=container_1523100158662_0008_01_000011
2018-04-07 16:01:54,463 INFO org.apache.hadoop.yarn.server.resourcemanager.scheduler.SchedulerNode: Assigned container container_1523100158662_0008_01_000011 of capacity <memory:1024, vCores:1> on host d1:59470, which has 7 containers, <memory:8192, vCores:7> used and <memory:0, vCores:1> available after allocation
2018-04-07 16:01:54,734 INFO org.apache.hadoop.yarn.server.resourcemanager.rmcontainer.RMContainerImpl: container_1523100158662_0008_01_000005 Container Transitioned from RUNNING to COMPLETED
2018-04-07 16:01:54,734 INFO org.apache.hadoop.yarn.server.resourcemanager.scheduler.fair.FSAppAttempt: Completed container: container_1523100158662_0008_01_000005 in state: COMPLETED event:FINISHED
2018-04-07 16:01:54,734 INFO org.apache.hadoop.yarn.server.resourcemanager.RMAuditLogger: USER=root	OPERATION=AM Released Container	TARGET=SchedulerApp	RESULT=SUCCESS	APPID=application_1523100158662_0008	CONTAINERID=container_1523100158662_0008_01_000005
2018-04-07 16:01:54,735 INFO org.apache.hadoop.yarn.server.resourcemanager.scheduler.SchedulerNode: Released container container_1523100158662_0008_01_000005 of capacity <memory:1024, vCores:1> on host d1:59470, which currently has 6 containers, <memory:7168, vCores:6> used and <memory:1024, vCores:2> available, release resources=true
2018-04-07 16:01:54,735 INFO org.apache.hadoop.yarn.server.resourcemanager.scheduler.fair.FairScheduler: Application attempt appattempt_1523100158662_0008_000001 released container container_1523100158662_0008_01_000005 on node: host: d1:59470 #containers=6 available=<memory:1024, vCores:2> used=<memory:7168, vCores:6> with event: FINISHED
2018-04-07 16:01:54,735 INFO org.apache.hadoop.yarn.server.resourcemanager.rmcontainer.RMContainerImpl: container_1523100158662_0008_01_000012 Container Transitioned from NEW to ALLOCATED
2018-04-07 16:01:54,735 INFO org.apache.hadoop.yarn.server.resourcemanager.RMAuditLogger: USER=root	OPERATION=AM Allocated Container	TARGET=SchedulerApp	RESULT=SUCCESS	APPID=application_1523100158662_0008	CONTAINERID=container_1523100158662_0008_01_000012
2018-04-07 16:01:54,735 INFO org.apache.hadoop.yarn.server.resourcemanager.scheduler.SchedulerNode: Assigned container container_1523100158662_0008_01_000012 of capacity <memory:1024, vCores:1> on host d1:59470, which has 7 containers, <memory:8192, vCores:7> used and <memory:0, vCores:1> available after allocation
2018-04-07 16:01:54,815 INFO org.apache.hadoop.yarn.server.resourcemanager.rmcontainer.RMContainerImpl: container_1523100158662_0008_01_000011 Container Transitioned from ALLOCATED to ACQUIRED
2018-04-07 16:01:54,816 INFO org.apache.hadoop.yarn.server.resourcemanager.rmcontainer.RMContainerImpl: container_1523100158662_0008_01_000012 Container Transitioned from ALLOCATED to ACQUIRED
2018-04-07 16:01:55,023 INFO org.apache.hadoop.yarn.server.resourcemanager.rmcontainer.RMContainerImpl: container_1523100158662_0008_01_000011 Container Transitioned from ACQUIRED to RUNNING
2018-04-07 16:01:55,024 INFO org.apache.hadoop.yarn.server.resourcemanager.rmcontainer.RMContainerImpl: container_1523100158662_0008_01_000012 Container Transitioned from ACQUIRED to RUNNING
2018-04-07 16:01:55,026 INFO org.apache.hadoop.yarn.server.resourcemanager.rmcontainer.RMContainerImpl: container_1523100158662_0008_01_000004 Container Transitioned from RUNNING to COMPLETED
2018-04-07 16:01:55,026 INFO org.apache.hadoop.yarn.server.resourcemanager.scheduler.fair.FSAppAttempt: Completed container: container_1523100158662_0008_01_000004 in state: COMPLETED event:FINISHED
2018-04-07 16:01:55,026 INFO org.apache.hadoop.yarn.server.resourcemanager.RMAuditLogger: USER=root	OPERATION=AM Released Container	TARGET=SchedulerApp	RESULT=SUCCESS	APPID=application_1523100158662_0008	CONTAINERID=container_1523100158662_0008_01_000004
2018-04-07 16:01:55,026 INFO org.apache.hadoop.yarn.server.resourcemanager.scheduler.SchedulerNode: Released container container_1523100158662_0008_01_000004 of capacity <memory:1024, vCores:1> on host d1:59470, which currently has 6 containers, <memory:7168, vCores:6> used and <memory:1024, vCores:2> available, release resources=true
2018-04-07 16:01:55,026 INFO org.apache.hadoop.yarn.server.resourcemanager.scheduler.fair.FairScheduler: Application attempt appattempt_1523100158662_0008_000001 released container container_1523100158662_0008_01_000004 on node: host: d1:59470 #containers=6 available=<memory:1024, vCores:2> used=<memory:7168, vCores:6> with event: FINISHED
2018-04-07 16:01:55,026 INFO org.apache.hadoop.yarn.server.resourcemanager.rmcontainer.RMContainerImpl: container_1523100158662_0008_01_000013 Container Transitioned from NEW to ALLOCATED
2018-04-07 16:01:55,026 INFO org.apache.hadoop.yarn.server.resourcemanager.RMAuditLogger: USER=root	OPERATION=AM Allocated Container	TARGET=SchedulerApp	RESULT=SUCCESS	APPID=application_1523100158662_0008	CONTAINERID=container_1523100158662_0008_01_000013
2018-04-07 16:01:55,026 INFO org.apache.hadoop.yarn.server.resourcemanager.scheduler.SchedulerNode: Assigned container container_1523100158662_0008_01_000013 of capacity <memory:1024, vCores:1> on host d1:59470, which has 7 containers, <memory:8192, vCores:7> used and <memory:0, vCores:1> available after allocation
2018-04-07 16:01:55,839 INFO org.apache.hadoop.yarn.server.resourcemanager.scheduler.AppSchedulingInfo: checking for deactivate of application :application_1523100158662_0008
2018-04-07 16:01:55,906 INFO org.apache.hadoop.yarn.server.resourcemanager.rmcontainer.RMContainerImpl: container_1523100158662_0008_01_000013 Container Transitioned from ALLOCATED to ACQUIRED
2018-04-07 16:01:56,037 INFO org.apache.hadoop.yarn.server.resourcemanager.rmcontainer.RMContainerImpl: container_1523100158662_0008_01_000007 Container Transitioned from RUNNING to COMPLETED
2018-04-07 16:01:56,038 INFO org.apache.hadoop.yarn.server.resourcemanager.scheduler.fair.FSAppAttempt: Completed container: container_1523100158662_0008_01_000007 in state: COMPLETED event:FINISHED
2018-04-07 16:01:56,038 INFO org.apache.hadoop.yarn.server.resourcemanager.RMAuditLogger: USER=root	OPERATION=AM Released Container	TARGET=SchedulerApp	RESULT=SUCCESS	APPID=application_1523100158662_0008	CONTAINERID=container_1523100158662_0008_01_000007
2018-04-07 16:01:56,039 INFO org.apache.hadoop.yarn.server.resourcemanager.scheduler.SchedulerNode: Released container container_1523100158662_0008_01_000007 of capacity <memory:1024, vCores:1> on host d1:59470, which currently has 6 containers, <memory:7168, vCores:6> used and <memory:1024, vCores:2> available, release resources=true
2018-04-07 16:01:56,039 INFO org.apache.hadoop.yarn.server.resourcemanager.scheduler.fair.FairScheduler: Application attempt appattempt_1523100158662_0008_000001 released container container_1523100158662_0008_01_000007 on node: host: d1:59470 #containers=6 available=<memory:1024, vCores:2> used=<memory:7168, vCores:6> with event: FINISHED
2018-04-07 16:01:57,006 INFO org.apache.hadoop.yarn.server.resourcemanager.rmcontainer.RMContainerImpl: container_1523100158662_0008_01_000013 Container Transitioned from ACQUIRED to RELEASED
2018-04-07 16:01:57,007 INFO org.apache.hadoop.yarn.server.resourcemanager.scheduler.fair.FSAppAttempt: Completed container: container_1523100158662_0008_01_000013 in state: RELEASED event:RELEASED
2018-04-07 16:01:57,007 INFO org.apache.hadoop.yarn.server.resourcemanager.RMAuditLogger: USER=root	IP=172.17.0.2	OPERATION=AM Released Container	TARGET=SchedulerApp	RESULT=SUCCESS	APPID=application_1523100158662_0008	CONTAINERID=container_1523100158662_0008_01_000013
2018-04-07 16:01:57,007 INFO org.apache.hadoop.yarn.server.resourcemanager.scheduler.SchedulerNode: Released container container_1523100158662_0008_01_000013 of capacity <memory:1024, vCores:1> on host d1:59470, which currently has 5 containers, <memory:6144, vCores:5> used and <memory:2048, vCores:3> available, release resources=true
2018-04-07 16:01:57,030 INFO org.apache.hadoop.yarn.server.resourcemanager.scheduler.fair.FairScheduler: Application attempt appattempt_1523100158662_0008_000001 released container container_1523100158662_0008_01_000013 on node: host: d1:59470 #containers=5 available=<memory:2048, vCores:3> used=<memory:6144, vCores:5> with event: RELEASED
2018-04-07 16:02:08,158 INFO org.apache.hadoop.yarn.server.resourcemanager.rmcontainer.RMContainerImpl: container_1523100158662_0008_01_000014 Container Transitioned from NEW to ALLOCATED
2018-04-07 16:02:08,158 INFO org.apache.hadoop.yarn.server.resourcemanager.RMAuditLogger: USER=root	OPERATION=AM Allocated Container	TARGET=SchedulerApp	RESULT=SUCCESS	APPID=application_1523100158662_0008	CONTAINERID=container_1523100158662_0008_01_000014
2018-04-07 16:02:08,158 INFO org.apache.hadoop.yarn.server.resourcemanager.scheduler.SchedulerNode: Assigned container container_1523100158662_0008_01_000014 of capacity <memory:1024, vCores:1> on host d1:59470, which has 6 containers, <memory:7168, vCores:6> used and <memory:1024, vCores:2> available after allocation
2018-04-07 16:02:08,410 INFO org.apache.hadoop.yarn.server.resourcemanager.rmcontainer.RMContainerImpl: container_1523100158662_0008_01_000014 Container Transitioned from ALLOCATED to ACQUIRED
2018-04-07 16:02:09,181 INFO org.apache.hadoop.yarn.server.resourcemanager.rmcontainer.RMContainerImpl: container_1523100158662_0008_01_000014 Container Transitioned from ACQUIRED to RUNNING
2018-04-07 16:02:09,505 INFO org.apache.hadoop.yarn.server.resourcemanager.scheduler.AppSchedulingInfo: checking for deactivate of application :application_1523100158662_0008
2018-04-07 16:02:22,216 INFO org.apache.hadoop.yarn.server.resourcemanager.rmcontainer.RMContainerImpl: container_1523100158662_0008_01_000015 Container Transitioned from NEW to ALLOCATED
2018-04-07 16:02:22,216 INFO org.apache.hadoop.yarn.server.resourcemanager.RMAuditLogger: USER=root	OPERATION=AM Allocated Container	TARGET=SchedulerApp	RESULT=SUCCESS	APPID=application_1523100158662_0008	CONTAINERID=container_1523100158662_0008_01_000015
2018-04-07 16:02:22,216 INFO org.apache.hadoop.yarn.server.resourcemanager.scheduler.SchedulerNode: Assigned container container_1523100158662_0008_01_000015 of capacity <memory:1024, vCores:1> on host d1:59470, which has 7 containers, <memory:8192, vCores:7> used and <memory:0, vCores:1> available after allocation
2018-04-07 16:02:22,593 INFO org.apache.hadoop.yarn.server.resourcemanager.rmcontainer.RMContainerImpl: container_1523100158662_0008_01_000015 Container Transitioned from ALLOCATED to ACQUIRED
2018-04-07 16:02:23,233 INFO org.apache.hadoop.yarn.server.resourcemanager.rmcontainer.RMContainerImpl: container_1523100158662_0008_01_000015 Container Transitioned from ACQUIRED to RUNNING
2018-04-07 16:02:23,630 INFO org.apache.hadoop.yarn.server.resourcemanager.scheduler.AppSchedulingInfo: checking for deactivate of application :application_1523100158662_0008
2018-04-07 16:02:37,652 INFO org.apache.hadoop.yarn.server.resourcemanager.scheduler.fair.FSAppAttempt: Making reservation: node=d1 app_id=application_1523100158662_0008
2018-04-07 16:02:37,657 INFO org.apache.hadoop.yarn.server.resourcemanager.rmcontainer.RMContainerImpl: container_1523100158662_0008_01_000016 Container Transitioned from NEW to RESERVED
2018-04-07 16:02:37,657 INFO org.apache.hadoop.yarn.server.resourcemanager.scheduler.fair.FSSchedulerNode: Reserved container container_1523100158662_0008_01_000016 on node host: d1:59470 #containers=7 available=<memory:0, vCores:1> used=<memory:8192, vCores:7> for application org.apache.hadoop.yarn.server.resourcemanager.scheduler.fair.FSAppAttempt@2d8ca8d6
2018-04-07 16:03:14,544 INFO org.apache.hadoop.yarn.server.resourcemanager.rmcontainer.RMContainerImpl: container_1523100158662_0008_01_000009 Container Transitioned from RUNNING to COMPLETED
2018-04-07 16:03:14,544 INFO org.apache.hadoop.yarn.server.resourcemanager.scheduler.fair.FSAppAttempt: Completed container: container_1523100158662_0008_01_000009 in state: COMPLETED event:FINISHED
2018-04-07 16:03:14,544 INFO org.apache.hadoop.yarn.server.resourcemanager.RMAuditLogger: USER=root	OPERATION=AM Released Container	TARGET=SchedulerApp	RESULT=SUCCESS	APPID=application_1523100158662_0008	CONTAINERID=container_1523100158662_0008_01_000009
2018-04-07 16:03:14,544 INFO org.apache.hadoop.yarn.server.resourcemanager.scheduler.SchedulerNode: Released container container_1523100158662_0008_01_000009 of capacity <memory:1024, vCores:1> on host d1:59470, which currently has 6 containers, <memory:7168, vCores:6> used and <memory:1024, vCores:2> available, release resources=true
2018-04-07 16:03:14,544 INFO org.apache.hadoop.yarn.server.resourcemanager.scheduler.fair.FairScheduler: Application attempt appattempt_1523100158662_0008_000001 released container container_1523100158662_0008_01_000009 on node: host: d1:59470 #containers=6 available=<memory:1024, vCores:2> used=<memory:7168, vCores:6> with event: FINISHED
2018-04-07 16:03:14,544 INFO org.apache.hadoop.yarn.server.resourcemanager.rmcontainer.RMContainerImpl: container_1523100158662_0008_01_000014 Container Transitioned from RUNNING to COMPLETED
2018-04-07 16:03:14,544 INFO org.apache.hadoop.yarn.server.resourcemanager.scheduler.fair.FSAppAttempt: Completed container: container_1523100158662_0008_01_000014 in state: COMPLETED event:FINISHED
2018-04-07 16:03:14,544 INFO org.apache.hadoop.yarn.server.resourcemanager.RMAuditLogger: USER=root	OPERATION=AM Released Container	TARGET=SchedulerApp	RESULT=SUCCESS	APPID=application_1523100158662_0008	CONTAINERID=container_1523100158662_0008_01_000014
2018-04-07 16:03:14,545 INFO org.apache.hadoop.yarn.server.resourcemanager.scheduler.SchedulerNode: Released container container_1523100158662_0008_01_000014 of capacity <memory:1024, vCores:1> on host d1:59470, which currently has 5 containers, <memory:6144, vCores:5> used and <memory:2048, vCores:3> available, release resources=true
2018-04-07 16:03:14,545 INFO org.apache.hadoop.yarn.server.resourcemanager.scheduler.fair.FairScheduler: Application attempt appattempt_1523100158662_0008_000001 released container container_1523100158662_0008_01_000014 on node: host: d1:59470 #containers=5 available=<memory:2048, vCores:3> used=<memory:6144, vCores:5> with event: FINISHED
2018-04-07 16:03:14,545 INFO org.apache.hadoop.yarn.server.resourcemanager.rmcontainer.RMContainerImpl: container_1523100158662_0008_01_000016 Container Transitioned from NEW to ALLOCATED
2018-04-07 16:03:14,545 INFO org.apache.hadoop.yarn.server.resourcemanager.RMAuditLogger: USER=root	OPERATION=AM Allocated Container	TARGET=SchedulerApp	RESULT=SUCCESS	APPID=application_1523100158662_0008	CONTAINERID=container_1523100158662_0008_01_000016
2018-04-07 16:03:14,545 INFO org.apache.hadoop.yarn.server.resourcemanager.scheduler.fair.FSAppAttempt: Application application_1523100158662_0008 unreserved  on node host: d1:59470 #containers=5 available=<memory:2048, vCores:3> used=<memory:6144, vCores:5>, currently has 0 at priority 10; currentReservation <memory:0, vCores:0>
2018-04-07 16:03:14,545 INFO org.apache.hadoop.yarn.server.resourcemanager.scheduler.SchedulerNode: Assigned container container_1523100158662_0008_01_000016 of capacity <memory:1024, vCores:1> on host d1:59470, which has 6 containers, <memory:7168, vCores:6> used and <memory:1024, vCores:2> available after allocation
2018-04-07 16:03:14,684 INFO org.apache.hadoop.yarn.server.resourcemanager.rmcontainer.RMContainerImpl: container_1523100158662_0008_01_000016 Container Transitioned from ALLOCATED to ACQUIRED
2018-04-07 16:03:15,285 INFO org.apache.hadoop.yarn.server.resourcemanager.rmcontainer.RMContainerImpl: container_1523100158662_0008_01_000016 Container Transitioned from ACQUIRED to RUNNING
2018-04-07 16:03:15,290 INFO org.apache.hadoop.yarn.server.resourcemanager.rmcontainer.RMContainerImpl: container_1523100158662_0008_01_000010 Container Transitioned from RUNNING to COMPLETED
2018-04-07 16:03:15,292 INFO org.apache.hadoop.yarn.server.resourcemanager.scheduler.fair.FSAppAttempt: Completed container: container_1523100158662_0008_01_000010 in state: COMPLETED event:FINISHED
2018-04-07 16:03:15,292 INFO org.apache.hadoop.yarn.server.resourcemanager.RMAuditLogger: USER=root	OPERATION=AM Released Container	TARGET=SchedulerApp	RESULT=SUCCESS	APPID=application_1523100158662_0008	CONTAINERID=container_1523100158662_0008_01_000010
2018-04-07 16:03:15,292 INFO org.apache.hadoop.yarn.server.resourcemanager.scheduler.SchedulerNode: Released container container_1523100158662_0008_01_000010 of capacity <memory:1024, vCores:1> on host d1:59470, which currently has 5 containers, <memory:6144, vCores:5> used and <memory:2048, vCores:3> available, release resources=true
2018-04-07 16:03:15,292 INFO org.apache.hadoop.yarn.server.resourcemanager.scheduler.fair.FairScheduler: Application attempt appattempt_1523100158662_0008_000001 released container container_1523100158662_0008_01_000010 on node: host: d1:59470 #containers=5 available=<memory:2048, vCores:3> used=<memory:6144, vCores:5> with event: FINISHED
2018-04-07 16:03:15,292 INFO org.apache.hadoop.yarn.server.resourcemanager.rmcontainer.RMContainerImpl: container_1523100158662_0008_01_000015 Container Transitioned from RUNNING to COMPLETED
2018-04-07 16:03:15,292 INFO org.apache.hadoop.yarn.server.resourcemanager.scheduler.fair.FSAppAttempt: Completed container: container_1523100158662_0008_01_000015 in state: COMPLETED event:FINISHED
2018-04-07 16:03:15,292 INFO org.apache.hadoop.yarn.server.resourcemanager.RMAuditLogger: USER=root	OPERATION=AM Released Container	TARGET=SchedulerApp	RESULT=SUCCESS	APPID=application_1523100158662_0008	CONTAINERID=container_1523100158662_0008_01_000015
2018-04-07 16:03:15,293 INFO org.apache.hadoop.yarn.server.resourcemanager.scheduler.SchedulerNode: Released container container_1523100158662_0008_01_000015 of capacity <memory:1024, vCores:1> on host d1:59470, which currently has 4 containers, <memory:5120, vCores:4> used and <memory:3072, vCores:4> available, release resources=true
2018-04-07 16:03:15,293 INFO org.apache.hadoop.yarn.server.resourcemanager.scheduler.fair.FairScheduler: Application attempt appattempt_1523100158662_0008_000001 released container container_1523100158662_0008_01_000015 on node: host: d1:59470 #containers=4 available=<memory:3072, vCores:4> used=<memory:5120, vCores:4> with event: FINISHED
2018-04-07 16:03:15,693 INFO org.apache.hadoop.yarn.server.resourcemanager.scheduler.AppSchedulingInfo: checking for deactivate of application :application_1523100158662_0008
2018-04-07 16:03:16,549 INFO org.apache.hadoop.yarn.server.resourcemanager.rmcontainer.RMContainerImpl: container_1523100158662_0008_01_000012 Container Transitioned from RUNNING to COMPLETED
2018-04-07 16:03:16,549 INFO org.apache.hadoop.yarn.server.resourcemanager.scheduler.fair.FSAppAttempt: Completed container: container_1523100158662_0008_01_000012 in state: COMPLETED event:FINISHED
2018-04-07 16:03:16,549 INFO org.apache.hadoop.yarn.server.resourcemanager.RMAuditLogger: USER=root	OPERATION=AM Released Container	TARGET=SchedulerApp	RESULT=SUCCESS	APPID=application_1523100158662_0008	CONTAINERID=container_1523100158662_0008_01_000012
2018-04-07 16:03:16,550 INFO org.apache.hadoop.yarn.server.resourcemanager.scheduler.SchedulerNode: Released container container_1523100158662_0008_01_000012 of capacity <memory:1024, vCores:1> on host d1:59470, which currently has 3 containers, <memory:4096, vCores:3> used and <memory:4096, vCores:5> available, release resources=true
2018-04-07 16:03:16,550 INFO org.apache.hadoop.yarn.server.resourcemanager.scheduler.fair.FairScheduler: Application attempt appattempt_1523100158662_0008_000001 released container container_1523100158662_0008_01_000012 on node: host: d1:59470 #containers=3 available=<memory:4096, vCores:5> used=<memory:4096, vCores:3> with event: FINISHED
2018-04-07 16:03:16,551 INFO org.apache.hadoop.yarn.server.resourcemanager.rmcontainer.RMContainerImpl: container_1523100158662_0008_01_000011 Container Transitioned from RUNNING to COMPLETED
2018-04-07 16:03:16,551 INFO org.apache.hadoop.yarn.server.resourcemanager.scheduler.fair.FSAppAttempt: Completed container: container_1523100158662_0008_01_000011 in state: COMPLETED event:FINISHED
2018-04-07 16:03:16,551 INFO org.apache.hadoop.yarn.server.resourcemanager.RMAuditLogger: USER=root	OPERATION=AM Released Container	TARGET=SchedulerApp	RESULT=SUCCESS	APPID=application_1523100158662_0008	CONTAINERID=container_1523100158662_0008_01_000011
2018-04-07 16:03:16,552 INFO org.apache.hadoop.yarn.server.resourcemanager.scheduler.SchedulerNode: Released container container_1523100158662_0008_01_000011 of capacity <memory:1024, vCores:1> on host d1:59470, which currently has 2 containers, <memory:3072, vCores:2> used and <memory:5120, vCores:6> available, release resources=true
2018-04-07 16:03:16,552 INFO org.apache.hadoop.yarn.server.resourcemanager.scheduler.fair.FairScheduler: Application attempt appattempt_1523100158662_0008_000001 released container container_1523100158662_0008_01_000011 on node: host: d1:59470 #containers=2 available=<memory:5120, vCores:6> used=<memory:3072, vCores:2> with event: FINISHED
2018-04-07 16:03:16,555 INFO org.apache.hadoop.yarn.server.resourcemanager.rmcontainer.RMContainerImpl: container_1523100158662_0008_01_000016 Container Transitioned from RUNNING to COMPLETED
2018-04-07 16:03:16,556 INFO org.apache.hadoop.yarn.server.resourcemanager.scheduler.fair.FSAppAttempt: Completed container: container_1523100158662_0008_01_000016 in state: COMPLETED event:FINISHED
2018-04-07 16:03:16,556 INFO org.apache.hadoop.yarn.server.resourcemanager.RMAuditLogger: USER=root	OPERATION=AM Released Container	TARGET=SchedulerApp	RESULT=SUCCESS	APPID=application_1523100158662_0008	CONTAINERID=container_1523100158662_0008_01_000016
2018-04-07 16:03:16,557 INFO org.apache.hadoop.yarn.server.resourcemanager.scheduler.SchedulerNode: Released container container_1523100158662_0008_01_000016 of capacity <memory:1024, vCores:1> on host d1:59470, which currently has 1 containers, <memory:2048, vCores:1> used and <memory:6144, vCores:7> available, release resources=true
2018-04-07 16:03:16,557 INFO org.apache.hadoop.yarn.server.resourcemanager.scheduler.fair.FairScheduler: Application attempt appattempt_1523100158662_0008_000001 released container container_1523100158662_0008_01_000016 on node: host: d1:59470 #containers=1 available=<memory:6144, vCores:7> used=<memory:2048, vCores:1> with event: FINISHED
2018-04-07 16:03:17,169 INFO org.apache.hadoop.yarn.server.resourcemanager.rmapp.attempt.RMAppAttemptImpl: Updating application attempt appattempt_1523100158662_0008_000001 with final state: FINISHING, and exit status: -1000
2018-04-07 16:03:17,170 INFO org.apache.hadoop.yarn.server.resourcemanager.rmapp.attempt.RMAppAttemptImpl: appattempt_1523100158662_0008_000001 State change from RUNNING to FINAL_SAVING
2018-04-07 16:03:17,170 INFO org.apache.hadoop.yarn.server.resourcemanager.rmapp.attempt.RMAppAttemptImpl: appattempt_1523100158662_0008_000001 State change from FINAL_SAVING to FINISHING
2018-04-07 16:03:17,170 INFO org.apache.hadoop.yarn.server.resourcemanager.rmapp.RMAppImpl: Updating application application_1523100158662_0008 with final state: FINISHING
2018-04-07 16:03:17,170 INFO org.apache.hadoop.yarn.server.resourcemanager.recovery.RMStateStore: Updating info for app: application_1523100158662_0008
2018-04-07 16:03:17,171 INFO org.apache.hadoop.yarn.server.resourcemanager.rmapp.RMAppImpl: application_1523100158662_0008 State change from RUNNING to FINAL_SAVING
2018-04-07 16:03:17,171 INFO org.apache.hadoop.yarn.server.resourcemanager.rmapp.RMAppImpl: application_1523100158662_0008 State change from FINAL_SAVING to FINISHING
2018-04-07 16:03:18,200 INFO org.apache.hadoop.yarn.server.resourcemanager.ApplicationMasterService: application_1523100158662_0008 unregistered successfully. 
2018-04-07 16:03:24,602 INFO org.apache.hadoop.yarn.server.resourcemanager.rmcontainer.RMContainerImpl: container_1523100158662_0008_01_000001 Container Transitioned from RUNNING to COMPLETED
2018-04-07 16:03:24,602 INFO org.apache.hadoop.yarn.server.resourcemanager.scheduler.fair.FSAppAttempt: Completed container: container_1523100158662_0008_01_000001 in state: COMPLETED event:FINISHED
2018-04-07 16:03:24,602 INFO org.apache.hadoop.yarn.server.resourcemanager.RMAuditLogger: USER=root	OPERATION=AM Released Container	TARGET=SchedulerApp	RESULT=SUCCESS	APPID=application_1523100158662_0008	CONTAINERID=container_1523100158662_0008_01_000001
2018-04-07 16:03:24,603 INFO org.apache.hadoop.yarn.server.resourcemanager.scheduler.SchedulerNode: Released container container_1523100158662_0008_01_000001 of capacity <memory:2048, vCores:1> on host d1:59470, which currently has 0 containers, <memory:0, vCores:0> used and <memory:8192, vCores:8> available, release resources=true
2018-04-07 16:03:24,612 INFO org.apache.hadoop.yarn.server.resourcemanager.ApplicationMasterService: Unregistering app attempt : appattempt_1523100158662_0008_000001
2018-04-07 16:03:24,617 INFO org.apache.hadoop.yarn.server.resourcemanager.security.AMRMTokenSecretManager: Application finished, removing password for appattempt_1523100158662_0008_000001
2018-04-07 16:03:24,618 INFO org.apache.hadoop.yarn.server.resourcemanager.rmapp.attempt.RMAppAttemptImpl: appattempt_1523100158662_0008_000001 State change from FINISHING to FINISHED
2018-04-07 16:03:24,618 INFO org.apache.hadoop.yarn.server.resourcemanager.rmapp.RMAppImpl: application_1523100158662_0008 State change from FINISHING to FINISHED
2018-04-07 16:03:24,619 INFO org.apache.hadoop.yarn.server.resourcemanager.RMAuditLogger: USER=root	OPERATION=Application Finished - Succeeded	TARGET=RMAppManager	RESULT=SUCCESS	APPID=application_1523100158662_0008
2018-04-07 16:03:24,621 INFO org.apache.hadoop.yarn.server.resourcemanager.scheduler.fair.FairScheduler: Application attempt appattempt_1523100158662_0008_000001 released container container_1523100158662_0008_01_000001 on node: host: d1:59470 #containers=0 available=<memory:8192, vCores:8> used=<memory:0, vCores:0> with event: FINISHED
2018-04-07 16:03:24,651 INFO org.apache.hadoop.yarn.server.resourcemanager.amlauncher.AMLauncher: Cleaning master appattempt_1523100158662_0008_000001
2018-04-07 16:03:24,657 INFO org.apache.hadoop.yarn.server.resourcemanager.scheduler.fair.FairScheduler: Application appattempt_1523100158662_0008_000001 is done. finalState=FINISHED
2018-04-07 16:03:24,660 INFO org.apache.hadoop.yarn.server.resourcemanager.scheduler.AppSchedulingInfo: Application application_1523100158662_0008 requests cleared
2018-04-07 16:03:24,654 INFO org.apache.hadoop.yarn.server.resourcemanager.RMAppManager$ApplicationSummary: appId=application_1523100158662_0008,name=word count,user=root,queue=root.root,state=FINISHED,trackingUrl=http://d1:8088/proxy/application_1523100158662_0008/,appMasterHost=d1,startTime=1523116735171,finishTime=1523116997170,finalStatus=SUCCEEDED,memorySeconds=1571578,vcoreSeconds=1259,preemptedAMContainers=0,preemptedNonAMContainers=0,preemptedResources=<memory:0\, vCores:0>,applicationType=MAPREDUCE
2018-04-07 16:11:27,217 INFO org.apache.hadoop.yarn.server.resourcemanager.ClientRMService: Allocated new applicationId: 9
2018-04-07 16:11:35,056 INFO org.apache.hadoop.yarn.server.resourcemanager.rmapp.RMAppImpl: Storing application with id application_1523100158662_0009
2018-04-07 16:11:35,057 INFO org.apache.hadoop.yarn.server.resourcemanager.rmapp.RMAppImpl: application_1523100158662_0009 State change from NEW to NEW_SAVING
2018-04-07 16:11:35,057 INFO org.apache.hadoop.yarn.server.resourcemanager.recovery.RMStateStore: Storing info for app: application_1523100158662_0009
2018-04-07 16:11:35,057 INFO org.apache.hadoop.yarn.server.resourcemanager.rmapp.RMAppImpl: application_1523100158662_0009 State change from NEW_SAVING to SUBMITTED
2018-04-07 16:11:35,060 INFO org.apache.hadoop.yarn.server.resourcemanager.ClientRMService: Application with id 9 submitted by user root
2018-04-07 16:11:35,061 INFO org.apache.hadoop.yarn.server.resourcemanager.RMAuditLogger: USER=root	IP=172.17.0.2	OPERATION=Submit Application Request	TARGET=ClientRMService	RESULT=SUCCESS	APPID=application_1523100158662_0009
2018-04-07 16:11:35,064 INFO org.apache.hadoop.yarn.server.resourcemanager.scheduler.fair.FairScheduler: Accepted application application_1523100158662_0009 from user: root, in queue: default, currently num of applications: 1
2018-04-07 16:11:35,080 INFO org.apache.hadoop.yarn.server.resourcemanager.rmapp.RMAppImpl: application_1523100158662_0009 State change from SUBMITTED to ACCEPTED
2018-04-07 16:11:35,080 INFO org.apache.hadoop.yarn.server.resourcemanager.ApplicationMasterService: Registering app attempt : appattempt_1523100158662_0009_000001
2018-04-07 16:11:35,081 INFO org.apache.hadoop.yarn.server.resourcemanager.rmapp.attempt.RMAppAttemptImpl: appattempt_1523100158662_0009_000001 State change from NEW to SUBMITTED
2018-04-07 16:11:35,082 INFO org.apache.hadoop.yarn.server.resourcemanager.scheduler.fair.FairScheduler: Added Application Attempt appattempt_1523100158662_0009_000001 to scheduler from user: root
2018-04-07 16:11:35,091 INFO org.apache.hadoop.yarn.server.resourcemanager.rmapp.attempt.RMAppAttemptImpl: appattempt_1523100158662_0009_000001 State change from SUBMITTED to SCHEDULED
2018-04-07 16:11:36,069 INFO org.apache.hadoop.yarn.server.resourcemanager.rmcontainer.RMContainerImpl: container_1523100158662_0009_01_000001 Container Transitioned from NEW to ALLOCATED
2018-04-07 16:11:36,070 INFO org.apache.hadoop.yarn.server.resourcemanager.RMAuditLogger: USER=root	OPERATION=AM Allocated Container	TARGET=SchedulerApp	RESULT=SUCCESS	APPID=application_1523100158662_0009	CONTAINERID=container_1523100158662_0009_01_000001
2018-04-07 16:11:36,070 INFO org.apache.hadoop.yarn.server.resourcemanager.scheduler.SchedulerNode: Assigned container container_1523100158662_0009_01_000001 of capacity <memory:2048, vCores:1> on host d1:59470, which has 1 containers, <memory:2048, vCores:1> used and <memory:6144, vCores:7> available after allocation
2018-04-07 16:11:36,073 INFO org.apache.hadoop.yarn.server.resourcemanager.security.NMTokenSecretManagerInRM: Sending NMToken for nodeId : d1:59470 for container : container_1523100158662_0009_01_000001
2018-04-07 16:11:36,087 INFO org.apache.hadoop.yarn.server.resourcemanager.rmcontainer.RMContainerImpl: container_1523100158662_0009_01_000001 Container Transitioned from ALLOCATED to ACQUIRED
2018-04-07 16:11:36,088 INFO org.apache.hadoop.yarn.server.resourcemanager.security.NMTokenSecretManagerInRM: Clear node set for appattempt_1523100158662_0009_000001
2018-04-07 16:11:36,089 INFO org.apache.hadoop.yarn.server.resourcemanager.rmapp.attempt.RMAppAttemptImpl: Storing attempt: AppId: application_1523100158662_0009 AttemptId: appattempt_1523100158662_0009_000001 MasterContainer: Container: [ContainerId: container_1523100158662_0009_01_000001, NodeId: d1:59470, NodeHttpAddress: d1:8042, Resource: <memory:2048, vCores:1>, Priority: 0, Token: Token { kind: ContainerToken, service: 172.17.0.2:59470 }, ]
2018-04-07 16:11:36,091 INFO org.apache.hadoop.yarn.server.resourcemanager.rmapp.attempt.RMAppAttemptImpl: appattempt_1523100158662_0009_000001 State change from SCHEDULED to ALLOCATED_SAVING
2018-04-07 16:11:36,093 INFO org.apache.hadoop.yarn.server.resourcemanager.rmapp.attempt.RMAppAttemptImpl: appattempt_1523100158662_0009_000001 State change from ALLOCATED_SAVING to ALLOCATED
2018-04-07 16:11:36,096 INFO org.apache.hadoop.yarn.server.resourcemanager.amlauncher.AMLauncher: Launching masterappattempt_1523100158662_0009_000001
2018-04-07 16:11:36,108 INFO org.apache.hadoop.yarn.server.resourcemanager.amlauncher.AMLauncher: Setting up container Container: [ContainerId: container_1523100158662_0009_01_000001, NodeId: d1:59470, NodeHttpAddress: d1:8042, Resource: <memory:2048, vCores:1>, Priority: 0, Token: Token { kind: ContainerToken, service: 172.17.0.2:59470 }, ] for AM appattempt_1523100158662_0009_000001
2018-04-07 16:11:36,109 INFO org.apache.hadoop.yarn.server.resourcemanager.amlauncher.AMLauncher: Command to launch container container_1523100158662_0009_01_000001 : $JAVA_HOME/bin/java -Dlog4j.configuration=container-log4j.properties -Dyarn.app.container.log.dir=<LOG_DIR> -Dyarn.app.container.log.filesize=0 -Dhadoop.root.logger=INFO,CLA -Dhadoop.root.logfile=syslog  -Xmx1024m org.apache.hadoop.mapreduce.v2.app.MRAppMaster 1><LOG_DIR>/stdout 2><LOG_DIR>/stderr 
2018-04-07 16:11:36,109 INFO org.apache.hadoop.yarn.server.resourcemanager.security.AMRMTokenSecretManager: Create AMRMToken for ApplicationAttempt: appattempt_1523100158662_0009_000001
2018-04-07 16:11:36,109 INFO org.apache.hadoop.yarn.server.resourcemanager.security.AMRMTokenSecretManager: Creating password for appattempt_1523100158662_0009_000001
2018-04-07 16:11:36,184 INFO org.apache.hadoop.yarn.server.resourcemanager.amlauncher.AMLauncher: Done launching container Container: [ContainerId: container_1523100158662_0009_01_000001, NodeId: d1:59470, NodeHttpAddress: d1:8042, Resource: <memory:2048, vCores:1>, Priority: 0, Token: Token { kind: ContainerToken, service: 172.17.0.2:59470 }, ] for AM appattempt_1523100158662_0009_000001
2018-04-07 16:11:36,184 INFO org.apache.hadoop.yarn.server.resourcemanager.rmapp.attempt.RMAppAttemptImpl: appattempt_1523100158662_0009_000001 State change from ALLOCATED to LAUNCHED
2018-04-07 16:11:37,077 INFO org.apache.hadoop.yarn.server.resourcemanager.rmcontainer.RMContainerImpl: container_1523100158662_0009_01_000001 Container Transitioned from ACQUIRED to RUNNING
2018-04-07 16:12:20,245 INFO SecurityLogger.org.apache.hadoop.ipc.Server: Auth successful for appattempt_1523100158662_0009_000001 (auth:SIMPLE)
2018-04-07 16:12:20,299 INFO org.apache.hadoop.yarn.server.resourcemanager.ApplicationMasterService: AM registration appattempt_1523100158662_0009_000001
2018-04-07 16:12:20,300 INFO org.apache.hadoop.yarn.server.resourcemanager.RMAuditLogger: USER=root	IP=172.17.0.2	OPERATION=Register App Master	TARGET=ApplicationMasterService	RESULT=SUCCESS	APPID=application_1523100158662_0009	APPATTEMPTID=appattempt_1523100158662_0009_000001
2018-04-07 16:12:20,301 INFO org.apache.hadoop.yarn.server.resourcemanager.rmapp.attempt.RMAppAttemptImpl: appattempt_1523100158662_0009_000001 State change from LAUNCHED to RUNNING
2018-04-07 16:12:20,302 INFO org.apache.hadoop.yarn.server.resourcemanager.rmapp.RMAppImpl: application_1523100158662_0009 State change from ACCEPTED to RUNNING
2018-04-07 16:12:25,531 INFO org.apache.hadoop.yarn.server.resourcemanager.rmcontainer.RMContainerImpl: container_1523100158662_0009_01_000002 Container Transitioned from NEW to ALLOCATED
2018-04-07 16:12:25,531 INFO org.apache.hadoop.yarn.server.resourcemanager.RMAuditLogger: USER=root	OPERATION=AM Allocated Container	TARGET=SchedulerApp	RESULT=SUCCESS	APPID=application_1523100158662_0009	CONTAINERID=container_1523100158662_0009_01_000002
2018-04-07 16:12:25,531 INFO org.apache.hadoop.yarn.server.resourcemanager.scheduler.SchedulerNode: Assigned container container_1523100158662_0009_01_000002 of capacity <memory:1024, vCores:1> on host d1:59470, which has 2 containers, <memory:3072, vCores:2> used and <memory:5120, vCores:6> available after allocation
2018-04-07 16:12:26,758 INFO org.apache.hadoop.yarn.server.resourcemanager.security.NMTokenSecretManagerInRM: Sending NMToken for nodeId : d1:59470 for container : container_1523100158662_0009_01_000002
2018-04-07 16:12:26,764 INFO org.apache.hadoop.yarn.server.resourcemanager.rmcontainer.RMContainerImpl: container_1523100158662_0009_01_000002 Container Transitioned from ALLOCATED to ACQUIRED
2018-04-07 16:12:28,750 INFO org.apache.hadoop.yarn.server.resourcemanager.scheduler.AppSchedulingInfo: checking for deactivate of application :application_1523100158662_0009
2018-04-07 16:12:30,560 INFO org.apache.hadoop.yarn.server.resourcemanager.rmcontainer.RMContainerImpl: container_1523100158662_0009_01_000002 Container Transitioned from ACQUIRED to RUNNING
2018-04-07 16:13:07,870 INFO org.apache.hadoop.yarn.server.resourcemanager.rmcontainer.RMContainerImpl: container_1523100158662_0009_01_000002 Container Transitioned from RUNNING to COMPLETED
2018-04-07 16:13:07,871 INFO org.apache.hadoop.yarn.server.resourcemanager.scheduler.fair.FSAppAttempt: Completed container: container_1523100158662_0009_01_000002 in state: COMPLETED event:FINISHED
2018-04-07 16:13:07,871 INFO org.apache.hadoop.yarn.server.resourcemanager.RMAuditLogger: USER=root	OPERATION=AM Released Container	TARGET=SchedulerApp	RESULT=SUCCESS	APPID=application_1523100158662_0009	CONTAINERID=container_1523100158662_0009_01_000002
2018-04-07 16:13:07,871 INFO org.apache.hadoop.yarn.server.resourcemanager.scheduler.SchedulerNode: Released container container_1523100158662_0009_01_000002 of capacity <memory:1024, vCores:1> on host d1:59470, which currently has 1 containers, <memory:2048, vCores:1> used and <memory:6144, vCores:7> available, release resources=true
2018-04-07 16:13:07,871 INFO org.apache.hadoop.yarn.server.resourcemanager.scheduler.fair.FairScheduler: Application attempt appattempt_1523100158662_0009_000001 released container container_1523100158662_0009_01_000002 on node: host: d1:59470 #containers=1 available=<memory:6144, vCores:7> used=<memory:2048, vCores:1> with event: FINISHED
2018-04-07 16:13:09,735 INFO org.apache.hadoop.yarn.server.resourcemanager.rmcontainer.RMContainerImpl: container_1523100158662_0009_01_000003 Container Transitioned from NEW to ALLOCATED
2018-04-07 16:13:09,752 INFO org.apache.hadoop.yarn.server.resourcemanager.RMAuditLogger: USER=root	OPERATION=AM Allocated Container	TARGET=SchedulerApp	RESULT=SUCCESS	APPID=application_1523100158662_0009	CONTAINERID=container_1523100158662_0009_01_000003
2018-04-07 16:13:09,752 INFO org.apache.hadoop.yarn.server.resourcemanager.scheduler.SchedulerNode: Assigned container container_1523100158662_0009_01_000003 of capacity <memory:1024, vCores:1> on host d1:59470, which has 2 containers, <memory:3072, vCores:2> used and <memory:5120, vCores:6> available after allocation
2018-04-07 16:13:10,162 INFO org.apache.hadoop.yarn.server.resourcemanager.rmcontainer.RMContainerImpl: container_1523100158662_0009_01_000003 Container Transitioned from ALLOCATED to ACQUIRED
2018-04-07 16:13:10,810 INFO org.apache.hadoop.yarn.server.resourcemanager.rmcontainer.RMContainerImpl: container_1523100158662_0009_01_000004 Container Transitioned from NEW to ALLOCATED
2018-04-07 16:13:10,816 INFO org.apache.hadoop.yarn.server.resourcemanager.RMAuditLogger: USER=root	OPERATION=AM Allocated Container	TARGET=SchedulerApp	RESULT=SUCCESS	APPID=application_1523100158662_0009	CONTAINERID=container_1523100158662_0009_01_000004
2018-04-07 16:13:10,817 INFO org.apache.hadoop.yarn.server.resourcemanager.scheduler.SchedulerNode: Assigned container container_1523100158662_0009_01_000004 of capacity <memory:1024, vCores:1> on host d1:59470, which has 3 containers, <memory:4096, vCores:3> used and <memory:4096, vCores:5> available after allocation
2018-04-07 16:13:11,366 INFO org.apache.hadoop.yarn.server.resourcemanager.rmcontainer.RMContainerImpl: container_1523100158662_0009_01_000004 Container Transitioned from ALLOCATED to ACQUIRED
2018-04-07 16:13:11,881 INFO org.apache.hadoop.yarn.server.resourcemanager.rmcontainer.RMContainerImpl: container_1523100158662_0009_01_000003 Container Transitioned from ACQUIRED to RUNNING
2018-04-07 16:13:11,882 INFO org.apache.hadoop.yarn.server.resourcemanager.rmcontainer.RMContainerImpl: container_1523100158662_0009_01_000005 Container Transitioned from NEW to ALLOCATED
2018-04-07 16:13:11,882 INFO org.apache.hadoop.yarn.server.resourcemanager.RMAuditLogger: USER=root	OPERATION=AM Allocated Container	TARGET=SchedulerApp	RESULT=SUCCESS	APPID=application_1523100158662_0009	CONTAINERID=container_1523100158662_0009_01_000005
2018-04-07 16:13:11,883 INFO org.apache.hadoop.yarn.server.resourcemanager.scheduler.SchedulerNode: Assigned container container_1523100158662_0009_01_000005 of capacity <memory:1024, vCores:1> on host d1:59470, which has 4 containers, <memory:5120, vCores:4> used and <memory:3072, vCores:4> available after allocation
2018-04-07 16:13:12,524 INFO org.apache.hadoop.yarn.server.resourcemanager.rmcontainer.RMContainerImpl: container_1523100158662_0009_01_000005 Container Transitioned from ALLOCATED to ACQUIRED
2018-04-07 16:13:12,871 INFO org.apache.hadoop.yarn.server.resourcemanager.rmcontainer.RMContainerImpl: container_1523100158662_0009_01_000004 Container Transitioned from ACQUIRED to RUNNING
2018-04-07 16:13:12,895 INFO org.apache.hadoop.yarn.server.resourcemanager.rmcontainer.RMContainerImpl: container_1523100158662_0009_01_000006 Container Transitioned from NEW to ALLOCATED
2018-04-07 16:13:12,895 INFO org.apache.hadoop.yarn.server.resourcemanager.RMAuditLogger: USER=root	OPERATION=AM Allocated Container	TARGET=SchedulerApp	RESULT=SUCCESS	APPID=application_1523100158662_0009	CONTAINERID=container_1523100158662_0009_01_000006
2018-04-07 16:13:12,895 INFO org.apache.hadoop.yarn.server.resourcemanager.scheduler.SchedulerNode: Assigned container container_1523100158662_0009_01_000006 of capacity <memory:1024, vCores:1> on host d1:59470, which has 5 containers, <memory:6144, vCores:5> used and <memory:2048, vCores:3> available after allocation
2018-04-07 16:13:13,814 INFO org.apache.hadoop.yarn.server.resourcemanager.rmcontainer.RMContainerImpl: container_1523100158662_0009_01_000006 Container Transitioned from ALLOCATED to ACQUIRED
2018-04-07 16:13:13,908 INFO org.apache.hadoop.yarn.server.resourcemanager.rmcontainer.RMContainerImpl: container_1523100158662_0009_01_000005 Container Transitioned from ACQUIRED to RUNNING
2018-04-07 16:13:13,936 INFO org.apache.hadoop.yarn.server.resourcemanager.rmcontainer.RMContainerImpl: container_1523100158662_0009_01_000007 Container Transitioned from NEW to ALLOCATED
2018-04-07 16:13:13,936 INFO org.apache.hadoop.yarn.server.resourcemanager.RMAuditLogger: USER=root	OPERATION=AM Allocated Container	TARGET=SchedulerApp	RESULT=SUCCESS	APPID=application_1523100158662_0009	CONTAINERID=container_1523100158662_0009_01_000007
2018-04-07 16:13:13,937 INFO org.apache.hadoop.yarn.server.resourcemanager.scheduler.SchedulerNode: Assigned container container_1523100158662_0009_01_000007 of capacity <memory:1024, vCores:1> on host d1:59470, which has 6 containers, <memory:7168, vCores:6> used and <memory:1024, vCores:2> available after allocation
2018-04-07 16:13:14,888 INFO org.apache.hadoop.yarn.server.resourcemanager.rmcontainer.RMContainerImpl: container_1523100158662_0009_01_000008 Container Transitioned from NEW to ALLOCATED
2018-04-07 16:13:14,889 INFO org.apache.hadoop.yarn.server.resourcemanager.RMAuditLogger: USER=root	OPERATION=AM Allocated Container	TARGET=SchedulerApp	RESULT=SUCCESS	APPID=application_1523100158662_0009	CONTAINERID=container_1523100158662_0009_01_000008
2018-04-07 16:13:14,889 INFO org.apache.hadoop.yarn.server.resourcemanager.scheduler.SchedulerNode: Assigned container container_1523100158662_0009_01_000008 of capacity <memory:1024, vCores:1> on host d1:59470, which has 7 containers, <memory:8192, vCores:7> used and <memory:0, vCores:1> available after allocation
2018-04-07 16:13:15,114 INFO org.apache.hadoop.yarn.server.resourcemanager.rmcontainer.RMContainerImpl: container_1523100158662_0009_01_000007 Container Transitioned from ALLOCATED to ACQUIRED
2018-04-07 16:13:15,311 INFO org.apache.hadoop.yarn.server.resourcemanager.rmcontainer.RMContainerImpl: container_1523100158662_0009_01_000008 Container Transitioned from ALLOCATED to ACQUIRED
2018-04-07 16:13:16,207 INFO org.apache.hadoop.yarn.server.resourcemanager.rmcontainer.RMContainerImpl: container_1523100158662_0009_01_000006 Container Transitioned from ACQUIRED to RUNNING
2018-04-07 16:13:16,300 INFO org.apache.hadoop.yarn.server.resourcemanager.scheduler.fair.FSAppAttempt: Making reservation: node=d1 app_id=application_1523100158662_0009
2018-04-07 16:13:16,381 INFO org.apache.hadoop.yarn.server.resourcemanager.rmcontainer.RMContainerImpl: container_1523100158662_0009_01_000009 Container Transitioned from NEW to RESERVED
2018-04-07 16:13:16,381 INFO org.apache.hadoop.yarn.server.resourcemanager.scheduler.fair.FSSchedulerNode: Reserved container container_1523100158662_0009_01_000009 on node host: d1:59470 #containers=7 available=<memory:0, vCores:1> used=<memory:8192, vCores:7> for application org.apache.hadoop.yarn.server.resourcemanager.scheduler.fair.FSAppAttempt@601f8638
2018-04-07 16:13:18,821 INFO org.apache.hadoop.yarn.server.resourcemanager.rmcontainer.RMContainerImpl: container_1523100158662_0009_01_000007 Container Transitioned from ACQUIRED to RUNNING
2018-04-07 16:13:19,320 INFO org.apache.hadoop.yarn.server.resourcemanager.rmcontainer.RMContainerImpl: container_1523100158662_0009_01_000008 Container Transitioned from ACQUIRED to RUNNING
2018-04-07 16:14:45,362 INFO org.apache.hadoop.yarn.server.resourcemanager.rmcontainer.RMContainerImpl: container_1523100158662_0009_01_000006 Container Transitioned from RUNNING to COMPLETED
2018-04-07 16:14:45,362 INFO org.apache.hadoop.yarn.server.resourcemanager.scheduler.fair.FSAppAttempt: Completed container: container_1523100158662_0009_01_000006 in state: COMPLETED event:FINISHED
2018-04-07 16:14:45,362 INFO org.apache.hadoop.yarn.server.resourcemanager.RMAuditLogger: USER=root	OPERATION=AM Released Container	TARGET=SchedulerApp	RESULT=SUCCESS	APPID=application_1523100158662_0009	CONTAINERID=container_1523100158662_0009_01_000006
2018-04-07 16:14:45,362 INFO org.apache.hadoop.yarn.server.resourcemanager.scheduler.SchedulerNode: Released container container_1523100158662_0009_01_000006 of capacity <memory:1024, vCores:1> on host d1:59470, which currently has 6 containers, <memory:7168, vCores:6> used and <memory:1024, vCores:2> available, release resources=true
2018-04-07 16:14:45,362 INFO org.apache.hadoop.yarn.server.resourcemanager.scheduler.fair.FairScheduler: Application attempt appattempt_1523100158662_0009_000001 released container container_1523100158662_0009_01_000006 on node: host: d1:59470 #containers=6 available=<memory:1024, vCores:2> used=<memory:7168, vCores:6> with event: FINISHED
2018-04-07 16:14:45,362 INFO org.apache.hadoop.yarn.server.resourcemanager.rmcontainer.RMContainerImpl: container_1523100158662_0009_01_000009 Container Transitioned from NEW to ALLOCATED
2018-04-07 16:14:45,362 INFO org.apache.hadoop.yarn.server.resourcemanager.RMAuditLogger: USER=root	OPERATION=AM Allocated Container	TARGET=SchedulerApp	RESULT=SUCCESS	APPID=application_1523100158662_0009	CONTAINERID=container_1523100158662_0009_01_000009
2018-04-07 16:14:45,362 INFO org.apache.hadoop.yarn.server.resourcemanager.scheduler.fair.FSAppAttempt: Application application_1523100158662_0009 unreserved  on node host: d1:59470 #containers=6 available=<memory:1024, vCores:2> used=<memory:7168, vCores:6>, currently has 0 at priority 10; currentReservation <memory:0, vCores:0>
2018-04-07 16:14:45,363 INFO org.apache.hadoop.yarn.server.resourcemanager.scheduler.SchedulerNode: Assigned container container_1523100158662_0009_01_000009 of capacity <memory:1024, vCores:1> on host d1:59470, which has 7 containers, <memory:8192, vCores:7> used and <memory:0, vCores:1> available after allocation
2018-04-07 16:14:46,190 INFO org.apache.hadoop.yarn.server.resourcemanager.scheduler.fair.FSAppAttempt: Making reservation: node=d1 app_id=application_1523100158662_0009
2018-04-07 16:14:46,190 INFO org.apache.hadoop.yarn.server.resourcemanager.rmcontainer.RMContainerImpl: container_1523100158662_0009_01_000010 Container Transitioned from NEW to RESERVED
2018-04-07 16:14:46,190 INFO org.apache.hadoop.yarn.server.resourcemanager.scheduler.fair.FSSchedulerNode: Reserved container container_1523100158662_0009_01_000010 on node host: d1:59470 #containers=7 available=<memory:0, vCores:1> used=<memory:8192, vCores:7> for application org.apache.hadoop.yarn.server.resourcemanager.scheduler.fair.FSAppAttempt@601f8638
2018-04-07 16:14:46,307 INFO org.apache.hadoop.yarn.server.resourcemanager.rmcontainer.RMContainerImpl: container_1523100158662_0009_01_000009 Container Transitioned from ALLOCATED to ACQUIRED
2018-04-07 16:14:47,088 INFO org.apache.hadoop.yarn.server.resourcemanager.rmcontainer.RMContainerImpl: container_1523100158662_0009_01_000009 Container Transitioned from ACQUIRED to RUNNING
2018-04-07 16:14:47,089 INFO org.apache.hadoop.yarn.server.resourcemanager.rmcontainer.RMContainerImpl: container_1523100158662_0009_01_000005 Container Transitioned from RUNNING to COMPLETED
2018-04-07 16:14:47,089 INFO org.apache.hadoop.yarn.server.resourcemanager.scheduler.fair.FSAppAttempt: Completed container: container_1523100158662_0009_01_000005 in state: COMPLETED event:FINISHED
2018-04-07 16:14:47,090 INFO org.apache.hadoop.yarn.server.resourcemanager.RMAuditLogger: USER=root	OPERATION=AM Released Container	TARGET=SchedulerApp	RESULT=SUCCESS	APPID=application_1523100158662_0009	CONTAINERID=container_1523100158662_0009_01_000005
2018-04-07 16:14:47,090 INFO org.apache.hadoop.yarn.server.resourcemanager.scheduler.SchedulerNode: Released container container_1523100158662_0009_01_000005 of capacity <memory:1024, vCores:1> on host d1:59470, which currently has 6 containers, <memory:7168, vCores:6> used and <memory:1024, vCores:2> available, release resources=true
2018-04-07 16:14:47,090 INFO org.apache.hadoop.yarn.server.resourcemanager.scheduler.fair.FairScheduler: Application attempt appattempt_1523100158662_0009_000001 released container container_1523100158662_0009_01_000005 on node: host: d1:59470 #containers=6 available=<memory:1024, vCores:2> used=<memory:7168, vCores:6> with event: FINISHED
2018-04-07 16:14:47,090 INFO org.apache.hadoop.yarn.server.resourcemanager.rmcontainer.RMContainerImpl: container_1523100158662_0009_01_000010 Container Transitioned from NEW to ALLOCATED
2018-04-07 16:14:47,090 INFO org.apache.hadoop.yarn.server.resourcemanager.RMAuditLogger: USER=root	OPERATION=AM Allocated Container	TARGET=SchedulerApp	RESULT=SUCCESS	APPID=application_1523100158662_0009	CONTAINERID=container_1523100158662_0009_01_000010
2018-04-07 16:14:47,090 INFO org.apache.hadoop.yarn.server.resourcemanager.scheduler.fair.FSAppAttempt: Application application_1523100158662_0009 unreserved  on node host: d1:59470 #containers=6 available=<memory:1024, vCores:2> used=<memory:7168, vCores:6>, currently has 0 at priority 10; currentReservation <memory:0, vCores:0>
2018-04-07 16:14:47,090 INFO org.apache.hadoop.yarn.server.resourcemanager.scheduler.SchedulerNode: Assigned container container_1523100158662_0009_01_000010 of capacity <memory:1024, vCores:1> on host d1:59470, which has 7 containers, <memory:8192, vCores:7> used and <memory:0, vCores:1> available after allocation
2018-04-07 16:14:47,318 INFO org.apache.hadoop.yarn.server.resourcemanager.rmcontainer.RMContainerImpl: container_1523100158662_0009_01_000010 Container Transitioned from ALLOCATED to ACQUIRED
2018-04-07 16:14:47,476 INFO org.apache.hadoop.yarn.server.resourcemanager.rmcontainer.RMContainerImpl: container_1523100158662_0009_01_000010 Container Transitioned from ACQUIRED to RUNNING
2018-04-07 16:14:47,477 INFO org.apache.hadoop.yarn.server.resourcemanager.rmcontainer.RMContainerImpl: container_1523100158662_0009_01_000003 Container Transitioned from RUNNING to COMPLETED
2018-04-07 16:14:47,477 INFO org.apache.hadoop.yarn.server.resourcemanager.scheduler.fair.FSAppAttempt: Completed container: container_1523100158662_0009_01_000003 in state: COMPLETED event:FINISHED
2018-04-07 16:14:47,477 INFO org.apache.hadoop.yarn.server.resourcemanager.RMAuditLogger: USER=root	OPERATION=AM Released Container	TARGET=SchedulerApp	RESULT=SUCCESS	APPID=application_1523100158662_0009	CONTAINERID=container_1523100158662_0009_01_000003
2018-04-07 16:14:47,477 INFO org.apache.hadoop.yarn.server.resourcemanager.scheduler.SchedulerNode: Released container container_1523100158662_0009_01_000003 of capacity <memory:1024, vCores:1> on host d1:59470, which currently has 6 containers, <memory:7168, vCores:6> used and <memory:1024, vCores:2> available, release resources=true
2018-04-07 16:14:47,477 INFO org.apache.hadoop.yarn.server.resourcemanager.scheduler.fair.FairScheduler: Application attempt appattempt_1523100158662_0009_000001 released container container_1523100158662_0009_01_000003 on node: host: d1:59470 #containers=6 available=<memory:1024, vCores:2> used=<memory:7168, vCores:6> with event: FINISHED
2018-04-07 16:14:47,477 INFO org.apache.hadoop.yarn.server.resourcemanager.rmcontainer.RMContainerImpl: container_1523100158662_0009_01_000011 Container Transitioned from NEW to ALLOCATED
2018-04-07 16:14:47,477 INFO org.apache.hadoop.yarn.server.resourcemanager.RMAuditLogger: USER=root	OPERATION=AM Allocated Container	TARGET=SchedulerApp	RESULT=SUCCESS	APPID=application_1523100158662_0009	CONTAINERID=container_1523100158662_0009_01_000011
2018-04-07 16:14:47,477 INFO org.apache.hadoop.yarn.server.resourcemanager.scheduler.SchedulerNode: Assigned container container_1523100158662_0009_01_000011 of capacity <memory:1024, vCores:1> on host d1:59470, which has 7 containers, <memory:8192, vCores:7> used and <memory:0, vCores:1> available after allocation
2018-04-07 16:14:48,327 INFO org.apache.hadoop.yarn.server.resourcemanager.rmcontainer.RMContainerImpl: container_1523100158662_0009_01_000011 Container Transitioned from ALLOCATED to ACQUIRED
2018-04-07 16:14:48,481 INFO org.apache.hadoop.yarn.server.resourcemanager.rmcontainer.RMContainerImpl: container_1523100158662_0009_01_000011 Container Transitioned from ACQUIRED to RUNNING
2018-04-07 16:14:48,485 INFO org.apache.hadoop.yarn.server.resourcemanager.rmcontainer.RMContainerImpl: container_1523100158662_0009_01_000008 Container Transitioned from RUNNING to COMPLETED
2018-04-07 16:14:48,485 INFO org.apache.hadoop.yarn.server.resourcemanager.scheduler.fair.FSAppAttempt: Completed container: container_1523100158662_0009_01_000008 in state: COMPLETED event:FINISHED
2018-04-07 16:14:48,485 INFO org.apache.hadoop.yarn.server.resourcemanager.RMAuditLogger: USER=root	OPERATION=AM Released Container	TARGET=SchedulerApp	RESULT=SUCCESS	APPID=application_1523100158662_0009	CONTAINERID=container_1523100158662_0009_01_000008
2018-04-07 16:14:48,485 INFO org.apache.hadoop.yarn.server.resourcemanager.scheduler.SchedulerNode: Released container container_1523100158662_0009_01_000008 of capacity <memory:1024, vCores:1> on host d1:59470, which currently has 6 containers, <memory:7168, vCores:6> used and <memory:1024, vCores:2> available, release resources=true
2018-04-07 16:14:48,485 INFO org.apache.hadoop.yarn.server.resourcemanager.scheduler.fair.FairScheduler: Application attempt appattempt_1523100158662_0009_000001 released container container_1523100158662_0009_01_000008 on node: host: d1:59470 #containers=6 available=<memory:1024, vCores:2> used=<memory:7168, vCores:6> with event: FINISHED
2018-04-07 16:14:48,487 INFO org.apache.hadoop.yarn.server.resourcemanager.rmcontainer.RMContainerImpl: container_1523100158662_0009_01_000012 Container Transitioned from NEW to ALLOCATED
2018-04-07 16:14:48,488 INFO org.apache.hadoop.yarn.server.resourcemanager.RMAuditLogger: USER=root	OPERATION=AM Allocated Container	TARGET=SchedulerApp	RESULT=SUCCESS	APPID=application_1523100158662_0009	CONTAINERID=container_1523100158662_0009_01_000012
2018-04-07 16:14:48,488 INFO org.apache.hadoop.yarn.server.resourcemanager.scheduler.SchedulerNode: Assigned container container_1523100158662_0009_01_000012 of capacity <memory:1024, vCores:1> on host d1:59470, which has 7 containers, <memory:8192, vCores:7> used and <memory:0, vCores:1> available after allocation
2018-04-07 16:14:49,342 INFO org.apache.hadoop.yarn.server.resourcemanager.rmcontainer.RMContainerImpl: container_1523100158662_0009_01_000012 Container Transitioned from ALLOCATED to ACQUIRED
2018-04-07 16:14:49,487 INFO org.apache.hadoop.yarn.server.resourcemanager.scheduler.fair.FSAppAttempt: Making reservation: node=d1 app_id=application_1523100158662_0009
2018-04-07 16:14:49,487 INFO org.apache.hadoop.yarn.server.resourcemanager.rmcontainer.RMContainerImpl: container_1523100158662_0009_01_000013 Container Transitioned from NEW to RESERVED
2018-04-07 16:14:49,487 INFO org.apache.hadoop.yarn.server.resourcemanager.scheduler.fair.FSSchedulerNode: Reserved container container_1523100158662_0009_01_000013 on node host: d1:59470 #containers=7 available=<memory:0, vCores:1> used=<memory:8192, vCores:7> for application org.apache.hadoop.yarn.server.resourcemanager.scheduler.fair.FSAppAttempt@601f8638
2018-04-07 16:14:50,357 INFO org.apache.hadoop.yarn.server.resourcemanager.scheduler.AppSchedulingInfo: checking for deactivate of application :application_1523100158662_0009
2018-04-07 16:14:50,496 INFO org.apache.hadoop.yarn.server.resourcemanager.rmcontainer.RMContainerImpl: container_1523100158662_0009_01_000012 Container Transitioned from ACQUIRED to RUNNING
2018-04-07 16:14:50,498 INFO org.apache.hadoop.yarn.server.resourcemanager.scheduler.fair.FairScheduler: Releasing reservation that cannot be satisfied for application appattempt_1523100158662_0009_000001 on node host: d1:59470 #containers=7 available=<memory:0, vCores:1> used=<memory:8192, vCores:7>
2018-04-07 16:14:50,498 INFO org.apache.hadoop.yarn.server.resourcemanager.scheduler.fair.FSAppAttempt: Application application_1523100158662_0009 unreserved  on node host: d1:59470 #containers=7 available=<memory:0, vCores:1> used=<memory:8192, vCores:7>, currently has 0 at priority 10; currentReservation <memory:0, vCores:0>
2018-04-07 16:14:51,377 INFO org.apache.hadoop.yarn.server.resourcemanager.scheduler.AppSchedulingInfo: checking for deactivate of application :application_1523100158662_0009
2018-04-07 16:14:52,943 INFO org.apache.hadoop.yarn.server.resourcemanager.rmcontainer.RMContainerImpl: container_1523100158662_0009_01_000007 Container Transitioned from RUNNING to COMPLETED
2018-04-07 16:14:52,944 INFO org.apache.hadoop.yarn.server.resourcemanager.scheduler.fair.FSAppAttempt: Completed container: container_1523100158662_0009_01_000007 in state: COMPLETED event:FINISHED
2018-04-07 16:14:52,944 INFO org.apache.hadoop.yarn.server.resourcemanager.RMAuditLogger: USER=root	OPERATION=AM Released Container	TARGET=SchedulerApp	RESULT=SUCCESS	APPID=application_1523100158662_0009	CONTAINERID=container_1523100158662_0009_01_000007
2018-04-07 16:14:52,944 INFO org.apache.hadoop.yarn.server.resourcemanager.scheduler.SchedulerNode: Released container container_1523100158662_0009_01_000007 of capacity <memory:1024, vCores:1> on host d1:59470, which currently has 6 containers, <memory:7168, vCores:6> used and <memory:1024, vCores:2> available, release resources=true
2018-04-07 16:14:52,944 INFO org.apache.hadoop.yarn.server.resourcemanager.scheduler.fair.FairScheduler: Application attempt appattempt_1523100158662_0009_000001 released container container_1523100158662_0009_01_000007 on node: host: d1:59470 #containers=6 available=<memory:1024, vCores:2> used=<memory:7168, vCores:6> with event: FINISHED
2018-04-07 16:14:52,948 INFO org.apache.hadoop.yarn.server.resourcemanager.rmcontainer.RMContainerImpl: container_1523100158662_0009_01_000004 Container Transitioned from RUNNING to COMPLETED
2018-04-07 16:14:52,948 INFO org.apache.hadoop.yarn.server.resourcemanager.scheduler.fair.FSAppAttempt: Completed container: container_1523100158662_0009_01_000004 in state: COMPLETED event:FINISHED
2018-04-07 16:14:52,948 INFO org.apache.hadoop.yarn.server.resourcemanager.RMAuditLogger: USER=root	OPERATION=AM Released Container	TARGET=SchedulerApp	RESULT=SUCCESS	APPID=application_1523100158662_0009	CONTAINERID=container_1523100158662_0009_01_000004
2018-04-07 16:14:52,948 INFO org.apache.hadoop.yarn.server.resourcemanager.scheduler.SchedulerNode: Released container container_1523100158662_0009_01_000004 of capacity <memory:1024, vCores:1> on host d1:59470, which currently has 5 containers, <memory:6144, vCores:5> used and <memory:2048, vCores:3> available, release resources=true
2018-04-07 16:14:52,948 INFO org.apache.hadoop.yarn.server.resourcemanager.scheduler.fair.FairScheduler: Application attempt appattempt_1523100158662_0009_000001 released container container_1523100158662_0009_01_000004 on node: host: d1:59470 #containers=5 available=<memory:2048, vCores:3> used=<memory:6144, vCores:5> with event: FINISHED
2018-04-07 16:15:07,084 INFO org.apache.hadoop.yarn.server.resourcemanager.rmcontainer.RMContainerImpl: container_1523100158662_0009_01_000014 Container Transitioned from NEW to ALLOCATED
2018-04-07 16:15:07,084 INFO org.apache.hadoop.yarn.server.resourcemanager.RMAuditLogger: USER=root	OPERATION=AM Allocated Container	TARGET=SchedulerApp	RESULT=SUCCESS	APPID=application_1523100158662_0009	CONTAINERID=container_1523100158662_0009_01_000014
2018-04-07 16:15:07,084 INFO org.apache.hadoop.yarn.server.resourcemanager.scheduler.SchedulerNode: Assigned container container_1523100158662_0009_01_000014 of capacity <memory:1024, vCores:1> on host d1:59470, which has 6 containers, <memory:7168, vCores:6> used and <memory:1024, vCores:2> available after allocation
2018-04-07 16:15:08,080 INFO org.apache.hadoop.yarn.server.resourcemanager.rmcontainer.RMContainerImpl: container_1523100158662_0009_01_000014 Container Transitioned from ALLOCATED to ACQUIRED
2018-04-07 16:15:09,083 INFO org.apache.hadoop.yarn.server.resourcemanager.rmcontainer.RMContainerImpl: container_1523100158662_0009_01_000014 Container Transitioned from ACQUIRED to RUNNING
2018-04-07 16:15:09,093 INFO org.apache.hadoop.yarn.server.resourcemanager.scheduler.AppSchedulingInfo: checking for deactivate of application :application_1523100158662_0009
2018-04-07 16:15:23,185 INFO org.apache.hadoop.yarn.server.resourcemanager.rmcontainer.RMContainerImpl: container_1523100158662_0009_01_000015 Container Transitioned from NEW to ALLOCATED
2018-04-07 16:15:23,186 INFO org.apache.hadoop.yarn.server.resourcemanager.RMAuditLogger: USER=root	OPERATION=AM Allocated Container	TARGET=SchedulerApp	RESULT=SUCCESS	APPID=application_1523100158662_0009	CONTAINERID=container_1523100158662_0009_01_000015
2018-04-07 16:15:23,186 INFO org.apache.hadoop.yarn.server.resourcemanager.scheduler.SchedulerNode: Assigned container container_1523100158662_0009_01_000015 of capacity <memory:1024, vCores:1> on host d1:59470, which has 7 containers, <memory:8192, vCores:7> used and <memory:0, vCores:1> available after allocation
2018-04-07 16:15:23,839 INFO org.apache.hadoop.yarn.server.resourcemanager.rmcontainer.RMContainerImpl: container_1523100158662_0009_01_000015 Container Transitioned from ALLOCATED to ACQUIRED
2018-04-07 16:15:25,018 INFO org.apache.hadoop.yarn.server.resourcemanager.scheduler.AppSchedulingInfo: checking for deactivate of application :application_1523100158662_0009
2018-04-07 16:15:25,238 INFO org.apache.hadoop.yarn.server.resourcemanager.rmcontainer.RMContainerImpl: container_1523100158662_0009_01_000015 Container Transitioned from ACQUIRED to RUNNING
2018-04-07 16:15:38,363 INFO org.apache.hadoop.yarn.server.resourcemanager.scheduler.fair.FSAppAttempt: Making reservation: node=d1 app_id=application_1523100158662_0009
2018-04-07 16:15:38,363 INFO org.apache.hadoop.yarn.server.resourcemanager.rmcontainer.RMContainerImpl: container_1523100158662_0009_01_000016 Container Transitioned from NEW to RESERVED
2018-04-07 16:15:38,363 INFO org.apache.hadoop.yarn.server.resourcemanager.scheduler.fair.FSSchedulerNode: Reserved container container_1523100158662_0009_01_000016 on node host: d1:59470 #containers=7 available=<memory:0, vCores:1> used=<memory:8192, vCores:7> for application org.apache.hadoop.yarn.server.resourcemanager.scheduler.fair.FSAppAttempt@601f8638
2018-04-07 16:15:41,504 INFO org.apache.hadoop.yarn.server.resourcemanager.rmcontainer.RMContainerImpl: container_1523100158662_0009_01_000015 Container Transitioned from RUNNING to COMPLETED
2018-04-07 16:15:41,505 INFO org.apache.hadoop.yarn.server.resourcemanager.scheduler.fair.FSAppAttempt: Completed container: container_1523100158662_0009_01_000015 in state: COMPLETED event:FINISHED
2018-04-07 16:15:41,505 INFO org.apache.hadoop.yarn.server.resourcemanager.RMAuditLogger: USER=root	OPERATION=AM Released Container	TARGET=SchedulerApp	RESULT=SUCCESS	APPID=application_1523100158662_0009	CONTAINERID=container_1523100158662_0009_01_000015
2018-04-07 16:15:41,505 INFO org.apache.hadoop.yarn.server.resourcemanager.scheduler.SchedulerNode: Released container container_1523100158662_0009_01_000015 of capacity <memory:1024, vCores:1> on host d1:59470, which currently has 6 containers, <memory:7168, vCores:6> used and <memory:1024, vCores:2> available, release resources=true
2018-04-07 16:15:41,505 INFO org.apache.hadoop.yarn.server.resourcemanager.scheduler.fair.FairScheduler: Application attempt appattempt_1523100158662_0009_000001 released container container_1523100158662_0009_01_000015 on node: host: d1:59470 #containers=6 available=<memory:1024, vCores:2> used=<memory:7168, vCores:6> with event: FINISHED
2018-04-07 16:15:41,506 INFO org.apache.hadoop.yarn.server.resourcemanager.rmcontainer.RMContainerImpl: container_1523100158662_0009_01_000010 Container Transitioned from RUNNING to COMPLETED
2018-04-07 16:15:41,506 INFO org.apache.hadoop.yarn.server.resourcemanager.scheduler.fair.FSAppAttempt: Completed container: container_1523100158662_0009_01_000010 in state: COMPLETED event:FINISHED
2018-04-07 16:15:41,506 INFO org.apache.hadoop.yarn.server.resourcemanager.RMAuditLogger: USER=root	OPERATION=AM Released Container	TARGET=SchedulerApp	RESULT=SUCCESS	APPID=application_1523100158662_0009	CONTAINERID=container_1523100158662_0009_01_000010
2018-04-07 16:15:41,506 INFO org.apache.hadoop.yarn.server.resourcemanager.scheduler.SchedulerNode: Released container container_1523100158662_0009_01_000010 of capacity <memory:1024, vCores:1> on host d1:59470, which currently has 5 containers, <memory:6144, vCores:5> used and <memory:2048, vCores:3> available, release resources=true
2018-04-07 16:15:41,506 INFO org.apache.hadoop.yarn.server.resourcemanager.scheduler.fair.FairScheduler: Application attempt appattempt_1523100158662_0009_000001 released container container_1523100158662_0009_01_000010 on node: host: d1:59470 #containers=5 available=<memory:2048, vCores:3> used=<memory:6144, vCores:5> with event: FINISHED
2018-04-07 16:15:41,507 INFO org.apache.hadoop.yarn.server.resourcemanager.rmcontainer.RMContainerImpl: container_1523100158662_0009_01_000016 Container Transitioned from NEW to ALLOCATED
2018-04-07 16:15:41,507 INFO org.apache.hadoop.yarn.server.resourcemanager.RMAuditLogger: USER=root	OPERATION=AM Allocated Container	TARGET=SchedulerApp	RESULT=SUCCESS	APPID=application_1523100158662_0009	CONTAINERID=container_1523100158662_0009_01_000016
2018-04-07 16:15:41,507 INFO org.apache.hadoop.yarn.server.resourcemanager.scheduler.fair.FSAppAttempt: Application application_1523100158662_0009 unreserved  on node host: d1:59470 #containers=5 available=<memory:2048, vCores:3> used=<memory:6144, vCores:5>, currently has 0 at priority 10; currentReservation <memory:0, vCores:0>
2018-04-07 16:15:41,507 INFO org.apache.hadoop.yarn.server.resourcemanager.scheduler.SchedulerNode: Assigned container container_1523100158662_0009_01_000016 of capacity <memory:1024, vCores:1> on host d1:59470, which has 6 containers, <memory:7168, vCores:6> used and <memory:1024, vCores:2> available after allocation
2018-04-07 16:15:42,451 INFO org.apache.hadoop.yarn.server.resourcemanager.rmcontainer.RMContainerImpl: container_1523100158662_0009_01_000016 Container Transitioned from ALLOCATED to ACQUIRED
2018-04-07 16:15:42,965 INFO org.apache.hadoop.yarn.server.resourcemanager.rmcontainer.RMContainerImpl: container_1523100158662_0009_01_000016 Container Transitioned from ACQUIRED to RUNNING
2018-04-07 16:15:42,965 INFO org.apache.hadoop.yarn.server.resourcemanager.rmcontainer.RMContainerImpl: container_1523100158662_0009_01_000012 Container Transitioned from RUNNING to COMPLETED
2018-04-07 16:15:42,966 INFO org.apache.hadoop.yarn.server.resourcemanager.scheduler.fair.FSAppAttempt: Completed container: container_1523100158662_0009_01_000012 in state: COMPLETED event:FINISHED
2018-04-07 16:15:42,966 INFO org.apache.hadoop.yarn.server.resourcemanager.RMAuditLogger: USER=root	OPERATION=AM Released Container	TARGET=SchedulerApp	RESULT=SUCCESS	APPID=application_1523100158662_0009	CONTAINERID=container_1523100158662_0009_01_000012
2018-04-07 16:15:42,966 INFO org.apache.hadoop.yarn.server.resourcemanager.scheduler.SchedulerNode: Released container container_1523100158662_0009_01_000012 of capacity <memory:1024, vCores:1> on host d1:59470, which currently has 5 containers, <memory:6144, vCores:5> used and <memory:2048, vCores:3> available, release resources=true
2018-04-07 16:15:42,966 INFO org.apache.hadoop.yarn.server.resourcemanager.scheduler.fair.FairScheduler: Application attempt appattempt_1523100158662_0009_000001 released container container_1523100158662_0009_01_000012 on node: host: d1:59470 #containers=5 available=<memory:2048, vCores:3> used=<memory:6144, vCores:5> with event: FINISHED
2018-04-07 16:15:43,461 INFO org.apache.hadoop.yarn.server.resourcemanager.scheduler.AppSchedulingInfo: checking for deactivate of application :application_1523100158662_0009
2018-04-07 16:15:43,549 INFO org.apache.hadoop.yarn.server.resourcemanager.rmcontainer.RMContainerImpl: container_1523100158662_0009_01_000014 Container Transitioned from RUNNING to COMPLETED
2018-04-07 16:15:43,550 INFO org.apache.hadoop.yarn.server.resourcemanager.scheduler.fair.FSAppAttempt: Completed container: container_1523100158662_0009_01_000014 in state: COMPLETED event:FINISHED
2018-04-07 16:15:43,550 INFO org.apache.hadoop.yarn.server.resourcemanager.RMAuditLogger: USER=root	OPERATION=AM Released Container	TARGET=SchedulerApp	RESULT=SUCCESS	APPID=application_1523100158662_0009	CONTAINERID=container_1523100158662_0009_01_000014
2018-04-07 16:15:43,550 INFO org.apache.hadoop.yarn.server.resourcemanager.scheduler.SchedulerNode: Released container container_1523100158662_0009_01_000014 of capacity <memory:1024, vCores:1> on host d1:59470, which currently has 4 containers, <memory:5120, vCores:4> used and <memory:3072, vCores:4> available, release resources=true
2018-04-07 16:15:43,550 INFO org.apache.hadoop.yarn.server.resourcemanager.scheduler.fair.FairScheduler: Application attempt appattempt_1523100158662_0009_000001 released container container_1523100158662_0009_01_000014 on node: host: d1:59470 #containers=4 available=<memory:3072, vCores:4> used=<memory:5120, vCores:4> with event: FINISHED
2018-04-07 16:15:43,552 INFO org.apache.hadoop.yarn.server.resourcemanager.rmcontainer.RMContainerImpl: container_1523100158662_0009_01_000009 Container Transitioned from RUNNING to COMPLETED
2018-04-07 16:15:43,552 INFO org.apache.hadoop.yarn.server.resourcemanager.scheduler.fair.FSAppAttempt: Completed container: container_1523100158662_0009_01_000009 in state: COMPLETED event:FINISHED
2018-04-07 16:15:43,552 INFO org.apache.hadoop.yarn.server.resourcemanager.RMAuditLogger: USER=root	OPERATION=AM Released Container	TARGET=SchedulerApp	RESULT=SUCCESS	APPID=application_1523100158662_0009	CONTAINERID=container_1523100158662_0009_01_000009
2018-04-07 16:15:43,552 INFO org.apache.hadoop.yarn.server.resourcemanager.scheduler.SchedulerNode: Released container container_1523100158662_0009_01_000009 of capacity <memory:1024, vCores:1> on host d1:59470, which currently has 3 containers, <memory:4096, vCores:3> used and <memory:4096, vCores:5> available, release resources=true
2018-04-07 16:15:43,552 INFO org.apache.hadoop.yarn.server.resourcemanager.scheduler.fair.FairScheduler: Application attempt appattempt_1523100158662_0009_000001 released container container_1523100158662_0009_01_000009 on node: host: d1:59470 #containers=3 available=<memory:4096, vCores:5> used=<memory:4096, vCores:3> with event: FINISHED
2018-04-07 16:15:44,663 INFO org.apache.hadoop.yarn.server.resourcemanager.rmcontainer.RMContainerImpl: container_1523100158662_0009_01_000016 Container Transitioned from RUNNING to COMPLETED
2018-04-07 16:15:44,674 INFO org.apache.hadoop.yarn.server.resourcemanager.scheduler.fair.FSAppAttempt: Completed container: container_1523100158662_0009_01_000016 in state: COMPLETED event:FINISHED
2018-04-07 16:15:44,675 INFO org.apache.hadoop.yarn.server.resourcemanager.RMAuditLogger: USER=root	OPERATION=AM Released Container	TARGET=SchedulerApp	RESULT=SUCCESS	APPID=application_1523100158662_0009	CONTAINERID=container_1523100158662_0009_01_000016
2018-04-07 16:15:44,678 INFO org.apache.hadoop.yarn.server.resourcemanager.scheduler.SchedulerNode: Released container container_1523100158662_0009_01_000016 of capacity <memory:1024, vCores:1> on host d1:59470, which currently has 2 containers, <memory:3072, vCores:2> used and <memory:5120, vCores:6> available, release resources=true
2018-04-07 16:15:44,678 INFO org.apache.hadoop.yarn.server.resourcemanager.scheduler.fair.FairScheduler: Application attempt appattempt_1523100158662_0009_000001 released container container_1523100158662_0009_01_000016 on node: host: d1:59470 #containers=2 available=<memory:5120, vCores:6> used=<memory:3072, vCores:2> with event: FINISHED
2018-04-07 16:15:44,689 INFO org.apache.hadoop.yarn.server.resourcemanager.rmcontainer.RMContainerImpl: container_1523100158662_0009_01_000011 Container Transitioned from RUNNING to COMPLETED
2018-04-07 16:15:44,689 INFO org.apache.hadoop.yarn.server.resourcemanager.scheduler.fair.FSAppAttempt: Completed container: container_1523100158662_0009_01_000011 in state: COMPLETED event:FINISHED
2018-04-07 16:15:44,689 INFO org.apache.hadoop.yarn.server.resourcemanager.RMAuditLogger: USER=root	OPERATION=AM Released Container	TARGET=SchedulerApp	RESULT=SUCCESS	APPID=application_1523100158662_0009	CONTAINERID=container_1523100158662_0009_01_000011
2018-04-07 16:15:44,691 INFO org.apache.hadoop.yarn.server.resourcemanager.scheduler.SchedulerNode: Released container container_1523100158662_0009_01_000011 of capacity <memory:1024, vCores:1> on host d1:59470, which currently has 1 containers, <memory:2048, vCores:1> used and <memory:6144, vCores:7> available, release resources=true
2018-04-07 16:15:44,691 INFO org.apache.hadoop.yarn.server.resourcemanager.scheduler.fair.FairScheduler: Application attempt appattempt_1523100158662_0009_000001 released container container_1523100158662_0009_01_000011 on node: host: d1:59470 #containers=1 available=<memory:6144, vCores:7> used=<memory:2048, vCores:1> with event: FINISHED
2018-04-07 16:15:45,109 INFO org.apache.hadoop.yarn.server.resourcemanager.rmapp.attempt.RMAppAttemptImpl: Updating application attempt appattempt_1523100158662_0009_000001 with final state: FINISHING, and exit status: -1000
2018-04-07 16:15:45,109 INFO org.apache.hadoop.yarn.server.resourcemanager.rmapp.attempt.RMAppAttemptImpl: appattempt_1523100158662_0009_000001 State change from RUNNING to FINAL_SAVING
2018-04-07 16:15:45,109 INFO org.apache.hadoop.yarn.server.resourcemanager.rmapp.RMAppImpl: Updating application application_1523100158662_0009 with final state: FINISHING
2018-04-07 16:15:45,133 INFO org.apache.hadoop.yarn.server.resourcemanager.rmapp.RMAppImpl: application_1523100158662_0009 State change from RUNNING to FINAL_SAVING
2018-04-07 16:15:45,133 INFO org.apache.hadoop.yarn.server.resourcemanager.rmapp.attempt.RMAppAttemptImpl: appattempt_1523100158662_0009_000001 State change from FINAL_SAVING to FINISHING
2018-04-07 16:15:45,133 INFO org.apache.hadoop.yarn.server.resourcemanager.recovery.RMStateStore: Updating info for app: application_1523100158662_0009
2018-04-07 16:15:45,141 INFO org.apache.hadoop.yarn.server.resourcemanager.rmapp.RMAppImpl: application_1523100158662_0009 State change from FINAL_SAVING to FINISHING
2018-04-07 16:15:46,192 INFO org.apache.hadoop.yarn.server.resourcemanager.ApplicationMasterService: application_1523100158662_0009 unregistered successfully. 
2018-04-07 16:15:52,738 INFO org.apache.hadoop.yarn.server.resourcemanager.rmcontainer.RMContainerImpl: container_1523100158662_0009_01_000001 Container Transitioned from RUNNING to COMPLETED
2018-04-07 16:15:52,739 INFO org.apache.hadoop.yarn.server.resourcemanager.scheduler.fair.FSAppAttempt: Completed container: container_1523100158662_0009_01_000001 in state: COMPLETED event:FINISHED
2018-04-07 16:15:52,739 INFO org.apache.hadoop.yarn.server.resourcemanager.RMAuditLogger: USER=root	OPERATION=AM Released Container	TARGET=SchedulerApp	RESULT=SUCCESS	APPID=application_1523100158662_0009	CONTAINERID=container_1523100158662_0009_01_000001
2018-04-07 16:15:52,741 INFO org.apache.hadoop.yarn.server.resourcemanager.scheduler.SchedulerNode: Released container container_1523100158662_0009_01_000001 of capacity <memory:2048, vCores:1> on host d1:59470, which currently has 0 containers, <memory:0, vCores:0> used and <memory:8192, vCores:8> available, release resources=true
2018-04-07 16:15:52,742 INFO org.apache.hadoop.yarn.server.resourcemanager.scheduler.fair.FairScheduler: Application attempt appattempt_1523100158662_0009_000001 released container container_1523100158662_0009_01_000001 on node: host: d1:59470 #containers=0 available=<memory:8192, vCores:8> used=<memory:0, vCores:0> with event: FINISHED
2018-04-07 16:15:52,743 INFO org.apache.hadoop.yarn.server.resourcemanager.ApplicationMasterService: Unregistering app attempt : appattempt_1523100158662_0009_000001
2018-04-07 16:15:52,743 INFO org.apache.hadoop.yarn.server.resourcemanager.security.AMRMTokenSecretManager: Application finished, removing password for appattempt_1523100158662_0009_000001
2018-04-07 16:15:52,743 INFO org.apache.hadoop.yarn.server.resourcemanager.rmapp.attempt.RMAppAttemptImpl: appattempt_1523100158662_0009_000001 State change from FINISHING to FINISHED
2018-04-07 16:15:52,745 INFO org.apache.hadoop.yarn.server.resourcemanager.rmapp.RMAppImpl: application_1523100158662_0009 State change from FINISHING to FINISHED
2018-04-07 16:15:52,749 INFO org.apache.hadoop.yarn.server.resourcemanager.RMAuditLogger: USER=root	OPERATION=Application Finished - Succeeded	TARGET=RMAppManager	RESULT=SUCCESS	APPID=application_1523100158662_0009
2018-04-07 16:15:52,752 INFO org.apache.hadoop.yarn.server.resourcemanager.RMAppManager$ApplicationSummary: appId=application_1523100158662_0009,name=word count,user=root,queue=root.root,state=FINISHED,trackingUrl=http://d1:8088/proxy/application_1523100158662_0009/,appMasterHost=d1,startTime=1523117495050,finishTime=1523117745109,finalStatus=SUCCEEDED,memorySeconds=1452121,vcoreSeconds=1156,preemptedAMContainers=0,preemptedNonAMContainers=0,preemptedResources=<memory:0\, vCores:0>,applicationType=MAPREDUCE
2018-04-07 16:15:52,753 INFO org.apache.hadoop.yarn.server.resourcemanager.scheduler.fair.FairScheduler: Application appattempt_1523100158662_0009_000001 is done. finalState=FINISHED
2018-04-07 16:15:52,753 INFO org.apache.hadoop.yarn.server.resourcemanager.scheduler.AppSchedulingInfo: Application application_1523100158662_0009 requests cleared
2018-04-07 16:15:52,761 INFO org.apache.hadoop.yarn.server.resourcemanager.amlauncher.AMLauncher: Cleaning master appattempt_1523100158662_0009_000001
2018-04-07 16:15:54,002 INFO org.apache.hadoop.yarn.server.resourcemanager.scheduler.fair.FairScheduler: Null container completed...
2018-04-07 16:15:54,007 INFO org.apache.hadoop.yarn.server.resourcemanager.scheduler.fair.FairScheduler: Null container completed...
2018-04-07 17:33:53,503 INFO org.apache.hadoop.yarn.server.resourcemanager.ClientRMService: Allocated new applicationId: 10
2018-04-07 17:34:06,928 INFO org.apache.hadoop.yarn.server.resourcemanager.ClientRMService: Application with id 10 submitted by user root
2018-04-07 17:34:06,928 INFO org.apache.hadoop.yarn.server.resourcemanager.RMAuditLogger: USER=root	IP=172.17.0.2	OPERATION=Submit Application Request	TARGET=ClientRMService	RESULT=SUCCESS	APPID=application_1523100158662_0010
2018-04-07 17:34:06,928 INFO org.apache.hadoop.yarn.server.resourcemanager.rmapp.RMAppImpl: Storing application with id application_1523100158662_0010
2018-04-07 17:34:06,928 INFO org.apache.hadoop.yarn.server.resourcemanager.rmapp.RMAppImpl: application_1523100158662_0010 State change from NEW to NEW_SAVING
2018-04-07 17:34:06,928 INFO org.apache.hadoop.yarn.server.resourcemanager.recovery.RMStateStore: Storing info for app: application_1523100158662_0010
2018-04-07 17:34:06,929 INFO org.apache.hadoop.yarn.server.resourcemanager.rmapp.RMAppImpl: application_1523100158662_0010 State change from NEW_SAVING to SUBMITTED
2018-04-07 17:34:06,936 INFO org.apache.hadoop.yarn.server.resourcemanager.scheduler.fair.FairScheduler: Accepted application application_1523100158662_0010 from user: root, in queue: default, currently num of applications: 1
2018-04-07 17:34:06,938 INFO org.apache.hadoop.yarn.server.resourcemanager.rmapp.RMAppImpl: application_1523100158662_0010 State change from SUBMITTED to ACCEPTED
2018-04-07 17:34:06,938 INFO org.apache.hadoop.yarn.server.resourcemanager.ApplicationMasterService: Registering app attempt : appattempt_1523100158662_0010_000001
2018-04-07 17:34:06,938 INFO org.apache.hadoop.yarn.server.resourcemanager.rmapp.attempt.RMAppAttemptImpl: appattempt_1523100158662_0010_000001 State change from NEW to SUBMITTED
2018-04-07 17:34:06,938 INFO org.apache.hadoop.yarn.server.resourcemanager.scheduler.fair.FairScheduler: Added Application Attempt appattempt_1523100158662_0010_000001 to scheduler from user: root
2018-04-07 17:34:06,948 INFO org.apache.hadoop.yarn.server.resourcemanager.rmapp.attempt.RMAppAttemptImpl: appattempt_1523100158662_0010_000001 State change from SUBMITTED to SCHEDULED
2018-04-07 17:34:07,822 INFO org.apache.hadoop.yarn.server.resourcemanager.rmcontainer.RMContainerImpl: container_1523100158662_0010_01_000001 Container Transitioned from NEW to ALLOCATED
2018-04-07 17:34:07,825 INFO org.apache.hadoop.yarn.server.resourcemanager.RMAuditLogger: USER=root	OPERATION=AM Allocated Container	TARGET=SchedulerApp	RESULT=SUCCESS	APPID=application_1523100158662_0010	CONTAINERID=container_1523100158662_0010_01_000001
2018-04-07 17:34:07,825 INFO org.apache.hadoop.yarn.server.resourcemanager.scheduler.SchedulerNode: Assigned container container_1523100158662_0010_01_000001 of capacity <memory:2048, vCores:1> on host d1:59470, which has 1 containers, <memory:2048, vCores:1> used and <memory:6144, vCores:7> available after allocation
2018-04-07 17:34:07,830 INFO org.apache.hadoop.yarn.server.resourcemanager.security.NMTokenSecretManagerInRM: Sending NMToken for nodeId : d1:59470 for container : container_1523100158662_0010_01_000001
2018-04-07 17:34:07,873 INFO org.apache.hadoop.yarn.server.resourcemanager.rmcontainer.RMContainerImpl: container_1523100158662_0010_01_000001 Container Transitioned from ALLOCATED to ACQUIRED
2018-04-07 17:34:07,873 INFO org.apache.hadoop.yarn.server.resourcemanager.security.NMTokenSecretManagerInRM: Clear node set for appattempt_1523100158662_0010_000001
2018-04-07 17:34:07,874 INFO org.apache.hadoop.yarn.server.resourcemanager.rmapp.attempt.RMAppAttemptImpl: Storing attempt: AppId: application_1523100158662_0010 AttemptId: appattempt_1523100158662_0010_000001 MasterContainer: Container: [ContainerId: container_1523100158662_0010_01_000001, NodeId: d1:59470, NodeHttpAddress: d1:8042, Resource: <memory:2048, vCores:1>, Priority: 0, Token: Token { kind: ContainerToken, service: 172.17.0.2:59470 }, ]
2018-04-07 17:34:07,875 INFO org.apache.hadoop.yarn.server.resourcemanager.rmapp.attempt.RMAppAttemptImpl: appattempt_1523100158662_0010_000001 State change from SCHEDULED to ALLOCATED_SAVING
2018-04-07 17:34:07,890 INFO org.apache.hadoop.yarn.server.resourcemanager.rmapp.attempt.RMAppAttemptImpl: appattempt_1523100158662_0010_000001 State change from ALLOCATED_SAVING to ALLOCATED
2018-04-07 17:34:07,902 INFO org.apache.hadoop.yarn.server.resourcemanager.amlauncher.AMLauncher: Launching masterappattempt_1523100158662_0010_000001
2018-04-07 17:34:07,936 INFO org.apache.hadoop.yarn.server.resourcemanager.amlauncher.AMLauncher: Setting up container Container: [ContainerId: container_1523100158662_0010_01_000001, NodeId: d1:59470, NodeHttpAddress: d1:8042, Resource: <memory:2048, vCores:1>, Priority: 0, Token: Token { kind: ContainerToken, service: 172.17.0.2:59470 }, ] for AM appattempt_1523100158662_0010_000001
2018-04-07 17:34:07,937 INFO org.apache.hadoop.yarn.server.resourcemanager.amlauncher.AMLauncher: Command to launch container container_1523100158662_0010_01_000001 : $JAVA_HOME/bin/java -Dlog4j.configuration=container-log4j.properties -Dyarn.app.container.log.dir=<LOG_DIR> -Dyarn.app.container.log.filesize=0 -Dhadoop.root.logger=INFO,CLA -Dhadoop.root.logfile=syslog  -Xmx1024m org.apache.hadoop.mapreduce.v2.app.MRAppMaster 1><LOG_DIR>/stdout 2><LOG_DIR>/stderr 
2018-04-07 17:34:07,939 INFO org.apache.hadoop.yarn.server.resourcemanager.security.AMRMTokenSecretManager: Create AMRMToken for ApplicationAttempt: appattempt_1523100158662_0010_000001
2018-04-07 17:34:07,939 INFO org.apache.hadoop.yarn.server.resourcemanager.security.AMRMTokenSecretManager: Creating password for appattempt_1523100158662_0010_000001
2018-04-07 17:34:08,163 INFO org.apache.hadoop.yarn.server.resourcemanager.amlauncher.AMLauncher: Done launching container Container: [ContainerId: container_1523100158662_0010_01_000001, NodeId: d1:59470, NodeHttpAddress: d1:8042, Resource: <memory:2048, vCores:1>, Priority: 0, Token: Token { kind: ContainerToken, service: 172.17.0.2:59470 }, ] for AM appattempt_1523100158662_0010_000001
2018-04-07 17:34:08,166 INFO org.apache.hadoop.yarn.server.resourcemanager.rmapp.attempt.RMAppAttemptImpl: appattempt_1523100158662_0010_000001 State change from ALLOCATED to LAUNCHED
2018-04-07 17:34:08,841 INFO org.apache.hadoop.yarn.server.resourcemanager.rmcontainer.RMContainerImpl: container_1523100158662_0010_01_000001 Container Transitioned from ACQUIRED to RUNNING
2018-04-07 17:35:27,029 INFO SecurityLogger.org.apache.hadoop.ipc.Server: Auth successful for appattempt_1523100158662_0010_000001 (auth:SIMPLE)
2018-04-07 17:35:27,061 INFO org.apache.hadoop.yarn.server.resourcemanager.ApplicationMasterService: AM registration appattempt_1523100158662_0010_000001
2018-04-07 17:35:27,062 INFO org.apache.hadoop.yarn.server.resourcemanager.RMAuditLogger: USER=root	IP=172.17.0.2	OPERATION=Register App Master	TARGET=ApplicationMasterService	RESULT=SUCCESS	APPID=application_1523100158662_0010	APPATTEMPTID=appattempt_1523100158662_0010_000001
2018-04-07 17:35:27,065 INFO org.apache.hadoop.yarn.server.resourcemanager.rmapp.attempt.RMAppAttemptImpl: appattempt_1523100158662_0010_000001 State change from LAUNCHED to RUNNING
2018-04-07 17:35:27,065 INFO org.apache.hadoop.yarn.server.resourcemanager.rmapp.RMAppImpl: application_1523100158662_0010 State change from ACCEPTED to RUNNING
2018-04-07 17:35:32,497 INFO org.apache.hadoop.yarn.server.resourcemanager.rmcontainer.RMContainerImpl: container_1523100158662_0010_01_000002 Container Transitioned from NEW to ALLOCATED
2018-04-07 17:35:32,497 INFO org.apache.hadoop.yarn.server.resourcemanager.RMAuditLogger: USER=root	OPERATION=AM Allocated Container	TARGET=SchedulerApp	RESULT=SUCCESS	APPID=application_1523100158662_0010	CONTAINERID=container_1523100158662_0010_01_000002
2018-04-07 17:35:32,497 INFO org.apache.hadoop.yarn.server.resourcemanager.scheduler.SchedulerNode: Assigned container container_1523100158662_0010_01_000002 of capacity <memory:1024, vCores:1> on host d1:59470, which has 2 containers, <memory:3072, vCores:2> used and <memory:5120, vCores:6> available after allocation
2018-04-07 17:35:32,773 INFO org.apache.hadoop.yarn.server.resourcemanager.security.NMTokenSecretManagerInRM: Sending NMToken for nodeId : d1:59470 for container : container_1523100158662_0010_01_000002
2018-04-07 17:35:32,782 INFO org.apache.hadoop.yarn.server.resourcemanager.rmcontainer.RMContainerImpl: container_1523100158662_0010_01_000002 Container Transitioned from ALLOCATED to ACQUIRED
2018-04-07 17:35:34,743 INFO org.apache.hadoop.yarn.server.resourcemanager.scheduler.AppSchedulingInfo: checking for deactivate of application :application_1523100158662_0010
2018-04-07 17:35:35,499 INFO org.apache.hadoop.yarn.server.resourcemanager.rmcontainer.RMContainerImpl: container_1523100158662_0010_01_000002 Container Transitioned from ACQUIRED to RUNNING
2018-04-07 17:36:42,479 INFO org.apache.hadoop.yarn.server.resourcemanager.rmcontainer.RMContainerImpl: container_1523100158662_0010_01_000002 Container Transitioned from RUNNING to COMPLETED
2018-04-07 17:36:42,479 INFO org.apache.hadoop.yarn.server.resourcemanager.scheduler.fair.FSAppAttempt: Completed container: container_1523100158662_0010_01_000002 in state: COMPLETED event:FINISHED
2018-04-07 17:36:42,479 INFO org.apache.hadoop.yarn.server.resourcemanager.RMAuditLogger: USER=root	OPERATION=AM Released Container	TARGET=SchedulerApp	RESULT=SUCCESS	APPID=application_1523100158662_0010	CONTAINERID=container_1523100158662_0010_01_000002
2018-04-07 17:36:42,481 INFO org.apache.hadoop.yarn.server.resourcemanager.scheduler.SchedulerNode: Released container container_1523100158662_0010_01_000002 of capacity <memory:1024, vCores:1> on host d1:59470, which currently has 1 containers, <memory:2048, vCores:1> used and <memory:6144, vCores:7> available, release resources=true
2018-04-07 17:36:42,481 INFO org.apache.hadoop.yarn.server.resourcemanager.scheduler.fair.FairScheduler: Application attempt appattempt_1523100158662_0010_000001 released container container_1523100158662_0010_01_000002 on node: host: d1:59470 #containers=1 available=<memory:6144, vCores:7> used=<memory:2048, vCores:1> with event: FINISHED
2018-04-07 17:36:44,497 INFO org.apache.hadoop.yarn.server.resourcemanager.rmcontainer.RMContainerImpl: container_1523100158662_0010_01_000003 Container Transitioned from NEW to ALLOCATED
2018-04-07 17:36:44,498 INFO org.apache.hadoop.yarn.server.resourcemanager.RMAuditLogger: USER=root	OPERATION=AM Allocated Container	TARGET=SchedulerApp	RESULT=SUCCESS	APPID=application_1523100158662_0010	CONTAINERID=container_1523100158662_0010_01_000003
2018-04-07 17:36:44,498 INFO org.apache.hadoop.yarn.server.resourcemanager.scheduler.SchedulerNode: Assigned container container_1523100158662_0010_01_000003 of capacity <memory:1024, vCores:1> on host d1:59470, which has 2 containers, <memory:3072, vCores:2> used and <memory:5120, vCores:6> available after allocation
2018-04-07 17:36:44,693 INFO org.apache.hadoop.yarn.server.resourcemanager.rmcontainer.RMContainerImpl: container_1523100158662_0010_01_000003 Container Transitioned from ALLOCATED to ACQUIRED
2018-04-07 17:36:45,537 INFO org.apache.hadoop.yarn.server.resourcemanager.rmcontainer.RMContainerImpl: container_1523100158662_0010_01_000003 Container Transitioned from ACQUIRED to RUNNING
2018-04-07 17:36:45,542 INFO org.apache.hadoop.yarn.server.resourcemanager.rmcontainer.RMContainerImpl: container_1523100158662_0010_01_000004 Container Transitioned from NEW to ALLOCATED
2018-04-07 17:36:45,543 INFO org.apache.hadoop.yarn.server.resourcemanager.RMAuditLogger: USER=root	OPERATION=AM Allocated Container	TARGET=SchedulerApp	RESULT=SUCCESS	APPID=application_1523100158662_0010	CONTAINERID=container_1523100158662_0010_01_000004
2018-04-07 17:36:45,543 INFO org.apache.hadoop.yarn.server.resourcemanager.scheduler.SchedulerNode: Assigned container container_1523100158662_0010_01_000004 of capacity <memory:1024, vCores:1> on host d1:59470, which has 3 containers, <memory:4096, vCores:3> used and <memory:4096, vCores:5> available after allocation
2018-04-07 17:36:46,195 INFO org.apache.hadoop.yarn.server.resourcemanager.rmcontainer.RMContainerImpl: container_1523100158662_0010_01_000004 Container Transitioned from ALLOCATED to ACQUIRED
2018-04-07 17:36:46,539 INFO org.apache.hadoop.yarn.server.resourcemanager.rmcontainer.RMContainerImpl: container_1523100158662_0010_01_000005 Container Transitioned from NEW to ALLOCATED
2018-04-07 17:36:46,539 INFO org.apache.hadoop.yarn.server.resourcemanager.RMAuditLogger: USER=root	OPERATION=AM Allocated Container	TARGET=SchedulerApp	RESULT=SUCCESS	APPID=application_1523100158662_0010	CONTAINERID=container_1523100158662_0010_01_000005
2018-04-07 17:36:46,539 INFO org.apache.hadoop.yarn.server.resourcemanager.scheduler.SchedulerNode: Assigned container container_1523100158662_0010_01_000005 of capacity <memory:1024, vCores:1> on host d1:59470, which has 4 containers, <memory:5120, vCores:4> used and <memory:3072, vCores:4> available after allocation
2018-04-07 17:36:47,355 INFO org.apache.hadoop.yarn.server.resourcemanager.rmcontainer.RMContainerImpl: container_1523100158662_0010_01_000005 Container Transitioned from ALLOCATED to ACQUIRED
2018-04-07 17:36:47,590 INFO org.apache.hadoop.yarn.server.resourcemanager.rmcontainer.RMContainerImpl: container_1523100158662_0010_01_000004 Container Transitioned from ACQUIRED to RUNNING
2018-04-07 17:36:47,606 INFO org.apache.hadoop.yarn.server.resourcemanager.rmcontainer.RMContainerImpl: container_1523100158662_0010_01_000006 Container Transitioned from NEW to ALLOCATED
2018-04-07 17:36:47,607 INFO org.apache.hadoop.yarn.server.resourcemanager.RMAuditLogger: USER=root	OPERATION=AM Allocated Container	TARGET=SchedulerApp	RESULT=SUCCESS	APPID=application_1523100158662_0010	CONTAINERID=container_1523100158662_0010_01_000006
2018-04-07 17:36:47,664 INFO org.apache.hadoop.yarn.server.resourcemanager.scheduler.SchedulerNode: Assigned container container_1523100158662_0010_01_000006 of capacity <memory:1024, vCores:1> on host d1:59470, which has 5 containers, <memory:6144, vCores:5> used and <memory:2048, vCores:3> available after allocation
2018-04-07 17:36:48,557 INFO org.apache.hadoop.yarn.server.resourcemanager.rmcontainer.RMContainerImpl: container_1523100158662_0010_01_000005 Container Transitioned from ACQUIRED to RUNNING
2018-04-07 17:36:48,559 INFO org.apache.hadoop.yarn.server.resourcemanager.rmcontainer.RMContainerImpl: container_1523100158662_0010_01_000007 Container Transitioned from NEW to ALLOCATED
2018-04-07 17:36:48,559 INFO org.apache.hadoop.yarn.server.resourcemanager.RMAuditLogger: USER=root	OPERATION=AM Allocated Container	TARGET=SchedulerApp	RESULT=SUCCESS	APPID=application_1523100158662_0010	CONTAINERID=container_1523100158662_0010_01_000007
2018-04-07 17:36:48,560 INFO org.apache.hadoop.yarn.server.resourcemanager.scheduler.SchedulerNode: Assigned container container_1523100158662_0010_01_000007 of capacity <memory:1024, vCores:1> on host d1:59470, which has 6 containers, <memory:7168, vCores:6> used and <memory:1024, vCores:2> available after allocation
2018-04-07 17:36:48,667 INFO org.apache.hadoop.yarn.server.resourcemanager.rmcontainer.RMContainerImpl: container_1523100158662_0010_01_000006 Container Transitioned from ALLOCATED to ACQUIRED
2018-04-07 17:36:48,906 INFO org.apache.hadoop.yarn.server.resourcemanager.rmcontainer.RMContainerImpl: container_1523100158662_0010_01_000007 Container Transitioned from ALLOCATED to ACQUIRED
2018-04-07 17:36:49,562 INFO org.apache.hadoop.yarn.server.resourcemanager.rmcontainer.RMContainerImpl: container_1523100158662_0010_01_000008 Container Transitioned from NEW to ALLOCATED
2018-04-07 17:36:49,562 INFO org.apache.hadoop.yarn.server.resourcemanager.RMAuditLogger: USER=root	OPERATION=AM Allocated Container	TARGET=SchedulerApp	RESULT=SUCCESS	APPID=application_1523100158662_0010	CONTAINERID=container_1523100158662_0010_01_000008
2018-04-07 17:36:49,562 INFO org.apache.hadoop.yarn.server.resourcemanager.scheduler.SchedulerNode: Assigned container container_1523100158662_0010_01_000008 of capacity <memory:1024, vCores:1> on host d1:59470, which has 7 containers, <memory:8192, vCores:7> used and <memory:0, vCores:1> available after allocation
2018-04-07 17:36:50,078 INFO org.apache.hadoop.yarn.server.resourcemanager.rmcontainer.RMContainerImpl: container_1523100158662_0010_01_000008 Container Transitioned from ALLOCATED to ACQUIRED
2018-04-07 17:36:50,580 INFO org.apache.hadoop.yarn.server.resourcemanager.rmcontainer.RMContainerImpl: container_1523100158662_0010_01_000006 Container Transitioned from ACQUIRED to RUNNING
2018-04-07 17:36:50,693 INFO org.apache.hadoop.yarn.server.resourcemanager.rmcontainer.RMContainerImpl: container_1523100158662_0010_01_000007 Container Transitioned from ACQUIRED to RUNNING
2018-04-07 17:36:50,694 INFO org.apache.hadoop.yarn.server.resourcemanager.scheduler.fair.FSAppAttempt: Making reservation: node=d1 app_id=application_1523100158662_0010
2018-04-07 17:36:50,694 INFO org.apache.hadoop.yarn.server.resourcemanager.rmcontainer.RMContainerImpl: container_1523100158662_0010_01_000009 Container Transitioned from NEW to RESERVED
2018-04-07 17:36:50,694 INFO org.apache.hadoop.yarn.server.resourcemanager.scheduler.fair.FSSchedulerNode: Reserved container container_1523100158662_0010_01_000009 on node host: d1:59470 #containers=7 available=<memory:0, vCores:1> used=<memory:8192, vCores:7> for application org.apache.hadoop.yarn.server.resourcemanager.scheduler.fair.FSAppAttempt@223fd695
2018-04-07 17:36:51,618 INFO org.apache.hadoop.yarn.server.resourcemanager.rmcontainer.RMContainerImpl: container_1523100158662_0010_01_000008 Container Transitioned from ACQUIRED to RUNNING
2018-04-07 17:40:13,860 INFO org.apache.hadoop.yarn.server.resourcemanager.rmcontainer.RMContainerImpl: container_1523100158662_0010_01_000007 Container Transitioned from RUNNING to COMPLETED
2018-04-07 17:40:13,860 INFO org.apache.hadoop.yarn.server.resourcemanager.scheduler.fair.FSAppAttempt: Completed container: container_1523100158662_0010_01_000007 in state: COMPLETED event:FINISHED
2018-04-07 17:40:13,860 INFO org.apache.hadoop.yarn.server.resourcemanager.RMAuditLogger: USER=root	OPERATION=AM Released Container	TARGET=SchedulerApp	RESULT=SUCCESS	APPID=application_1523100158662_0010	CONTAINERID=container_1523100158662_0010_01_000007
2018-04-07 17:40:13,860 INFO org.apache.hadoop.yarn.server.resourcemanager.scheduler.SchedulerNode: Released container container_1523100158662_0010_01_000007 of capacity <memory:1024, vCores:1> on host d1:59470, which currently has 6 containers, <memory:7168, vCores:6> used and <memory:1024, vCores:2> available, release resources=true
2018-04-07 17:40:13,860 INFO org.apache.hadoop.yarn.server.resourcemanager.scheduler.fair.FairScheduler: Application attempt appattempt_1523100158662_0010_000001 released container container_1523100158662_0010_01_000007 on node: host: d1:59470 #containers=6 available=<memory:1024, vCores:2> used=<memory:7168, vCores:6> with event: FINISHED
2018-04-07 17:40:13,861 INFO org.apache.hadoop.yarn.server.resourcemanager.rmcontainer.RMContainerImpl: container_1523100158662_0010_01_000009 Container Transitioned from NEW to ALLOCATED
2018-04-07 17:40:13,861 INFO org.apache.hadoop.yarn.server.resourcemanager.RMAuditLogger: USER=root	OPERATION=AM Allocated Container	TARGET=SchedulerApp	RESULT=SUCCESS	APPID=application_1523100158662_0010	CONTAINERID=container_1523100158662_0010_01_000009
2018-04-07 17:40:13,861 INFO org.apache.hadoop.yarn.server.resourcemanager.scheduler.fair.FSAppAttempt: Application application_1523100158662_0010 unreserved  on node host: d1:59470 #containers=6 available=<memory:1024, vCores:2> used=<memory:7168, vCores:6>, currently has 0 at priority 10; currentReservation <memory:0, vCores:0>
2018-04-07 17:40:13,861 INFO org.apache.hadoop.yarn.server.resourcemanager.scheduler.SchedulerNode: Assigned container container_1523100158662_0010_01_000009 of capacity <memory:1024, vCores:1> on host d1:59470, which has 7 containers, <memory:8192, vCores:7> used and <memory:0, vCores:1> available after allocation
2018-04-07 17:40:14,198 INFO org.apache.hadoop.yarn.server.resourcemanager.rmcontainer.RMContainerImpl: container_1523100158662_0010_01_000009 Container Transitioned from ALLOCATED to ACQUIRED
2018-04-07 17:40:14,866 INFO org.apache.hadoop.yarn.server.resourcemanager.rmcontainer.RMContainerImpl: container_1523100158662_0010_01_000009 Container Transitioned from ACQUIRED to RUNNING
2018-04-07 17:40:14,868 INFO org.apache.hadoop.yarn.server.resourcemanager.scheduler.fair.FSAppAttempt: Making reservation: node=d1 app_id=application_1523100158662_0010
2018-04-07 17:40:14,868 INFO org.apache.hadoop.yarn.server.resourcemanager.rmcontainer.RMContainerImpl: container_1523100158662_0010_01_000010 Container Transitioned from NEW to RESERVED
2018-04-07 17:40:14,882 INFO org.apache.hadoop.yarn.server.resourcemanager.scheduler.fair.FSSchedulerNode: Reserved container container_1523100158662_0010_01_000010 on node host: d1:59470 #containers=7 available=<memory:0, vCores:1> used=<memory:8192, vCores:7> for application org.apache.hadoop.yarn.server.resourcemanager.scheduler.fair.FSAppAttempt@223fd695
2018-04-07 17:40:24,925 INFO org.apache.hadoop.yarn.server.resourcemanager.rmcontainer.RMContainerImpl: container_1523100158662_0010_01_000008 Container Transitioned from RUNNING to COMPLETED
2018-04-07 17:40:24,925 INFO org.apache.hadoop.yarn.server.resourcemanager.scheduler.fair.FSAppAttempt: Completed container: container_1523100158662_0010_01_000008 in state: COMPLETED event:FINISHED
2018-04-07 17:40:24,925 INFO org.apache.hadoop.yarn.server.resourcemanager.RMAuditLogger: USER=root	OPERATION=AM Released Container	TARGET=SchedulerApp	RESULT=SUCCESS	APPID=application_1523100158662_0010	CONTAINERID=container_1523100158662_0010_01_000008
2018-04-07 17:40:24,925 INFO org.apache.hadoop.yarn.server.resourcemanager.scheduler.SchedulerNode: Released container container_1523100158662_0010_01_000008 of capacity <memory:1024, vCores:1> on host d1:59470, which currently has 6 containers, <memory:7168, vCores:6> used and <memory:1024, vCores:2> available, release resources=true
2018-04-07 17:40:24,925 INFO org.apache.hadoop.yarn.server.resourcemanager.scheduler.fair.FairScheduler: Application attempt appattempt_1523100158662_0010_000001 released container container_1523100158662_0010_01_000008 on node: host: d1:59470 #containers=6 available=<memory:1024, vCores:2> used=<memory:7168, vCores:6> with event: FINISHED
2018-04-07 17:40:24,925 INFO org.apache.hadoop.yarn.server.resourcemanager.rmcontainer.RMContainerImpl: container_1523100158662_0010_01_000004 Container Transitioned from RUNNING to COMPLETED
2018-04-07 17:40:24,925 INFO org.apache.hadoop.yarn.server.resourcemanager.scheduler.fair.FSAppAttempt: Completed container: container_1523100158662_0010_01_000004 in state: COMPLETED event:FINISHED
2018-04-07 17:40:24,925 INFO org.apache.hadoop.yarn.server.resourcemanager.RMAuditLogger: USER=root	OPERATION=AM Released Container	TARGET=SchedulerApp	RESULT=SUCCESS	APPID=application_1523100158662_0010	CONTAINERID=container_1523100158662_0010_01_000004
2018-04-07 17:40:24,925 INFO org.apache.hadoop.yarn.server.resourcemanager.scheduler.SchedulerNode: Released container container_1523100158662_0010_01_000004 of capacity <memory:1024, vCores:1> on host d1:59470, which currently has 5 containers, <memory:6144, vCores:5> used and <memory:2048, vCores:3> available, release resources=true
2018-04-07 17:40:24,925 INFO org.apache.hadoop.yarn.server.resourcemanager.scheduler.fair.FairScheduler: Application attempt appattempt_1523100158662_0010_000001 released container container_1523100158662_0010_01_000004 on node: host: d1:59470 #containers=5 available=<memory:2048, vCores:3> used=<memory:6144, vCores:5> with event: FINISHED
2018-04-07 17:40:24,926 INFO org.apache.hadoop.yarn.server.resourcemanager.rmcontainer.RMContainerImpl: container_1523100158662_0010_01_000006 Container Transitioned from RUNNING to COMPLETED
2018-04-07 17:40:24,926 INFO org.apache.hadoop.yarn.server.resourcemanager.scheduler.fair.FSAppAttempt: Completed container: container_1523100158662_0010_01_000006 in state: COMPLETED event:FINISHED
2018-04-07 17:40:24,926 INFO org.apache.hadoop.yarn.server.resourcemanager.RMAuditLogger: USER=root	OPERATION=AM Released Container	TARGET=SchedulerApp	RESULT=SUCCESS	APPID=application_1523100158662_0010	CONTAINERID=container_1523100158662_0010_01_000006
2018-04-07 17:40:24,926 INFO org.apache.hadoop.yarn.server.resourcemanager.scheduler.SchedulerNode: Released container container_1523100158662_0010_01_000006 of capacity <memory:1024, vCores:1> on host d1:59470, which currently has 4 containers, <memory:5120, vCores:4> used and <memory:3072, vCores:4> available, release resources=true
2018-04-07 17:40:24,926 INFO org.apache.hadoop.yarn.server.resourcemanager.scheduler.fair.FairScheduler: Application attempt appattempt_1523100158662_0010_000001 released container container_1523100158662_0010_01_000006 on node: host: d1:59470 #containers=4 available=<memory:3072, vCores:4> used=<memory:5120, vCores:4> with event: FINISHED
2018-04-07 17:40:24,926 INFO org.apache.hadoop.yarn.server.resourcemanager.rmcontainer.RMContainerImpl: container_1523100158662_0010_01_000010 Container Transitioned from NEW to ALLOCATED
2018-04-07 17:40:24,926 INFO org.apache.hadoop.yarn.server.resourcemanager.RMAuditLogger: USER=root	OPERATION=AM Allocated Container	TARGET=SchedulerApp	RESULT=SUCCESS	APPID=application_1523100158662_0010	CONTAINERID=container_1523100158662_0010_01_000010
2018-04-07 17:40:24,926 INFO org.apache.hadoop.yarn.server.resourcemanager.scheduler.fair.FSAppAttempt: Application application_1523100158662_0010 unreserved  on node host: d1:59470 #containers=4 available=<memory:3072, vCores:4> used=<memory:5120, vCores:4>, currently has 0 at priority 10; currentReservation <memory:0, vCores:0>
2018-04-07 17:40:24,926 INFO org.apache.hadoop.yarn.server.resourcemanager.scheduler.SchedulerNode: Assigned container container_1523100158662_0010_01_000010 of capacity <memory:1024, vCores:1> on host d1:59470, which has 5 containers, <memory:6144, vCores:5> used and <memory:2048, vCores:3> available after allocation
2018-04-07 17:40:25,413 INFO org.apache.hadoop.yarn.server.resourcemanager.rmcontainer.RMContainerImpl: container_1523100158662_0010_01_000010 Container Transitioned from ALLOCATED to ACQUIRED
